HSD.py[2018-07-02 16:57:28][ERROR]：文件 HSD.py 第1110行报错：division by zero
HSD.py[2018-07-02 17:04:27][ERROR]：文件 HSD.py 第1108行报错：division by zero
HSD.py[2018-07-02 17:07:21][ERROR]：文件 HSD.py 第1108行报错：division by zero
HSD.py[2018-07-02 17:07:49][ERROR]：文件 HSD.py 第1108行报错：division by zero
HSD.py[2018-07-02 17:08:20][ERROR]：文件 HSD.py 第1108行报错：division by zero
exception.py[2018-07-02 17:10:32][ERROR]：Internal Server Error: /zhangting/tomorrow/
Traceback (most recent call last):
  File "D:\ProgramFiles\Anaconda3\lib\site-packages\django-1.11.8-py3.6.egg\django\core\handlers\exception.py", line 41, in inner
    response = get_response(request)
  File "D:\ProgramFiles\Anaconda3\lib\site-packages\django-1.11.8-py3.6.egg\django\core\handlers\base.py", line 249, in _legacy_get_response
    response = self._get_response(request)
  File "D:\ProgramFiles\Anaconda3\lib\site-packages\django-1.11.8-py3.6.egg\django\core\handlers\base.py", line 187, in _get_response
    response = self.process_exception_by_middleware(e, request)
  File "D:\ProgramFiles\Anaconda3\lib\site-packages\django-1.11.8-py3.6.egg\django\core\handlers\base.py", line 185, in _get_response
    response = wrapped_callback(request, *callback_args, **callback_kwargs)
  File "D:\tools\Tools\Carry\mysite\views.py", line 739, in zhangting
    zt_tomorrow = ZT.yanzen(rq_date=rq_date)
  File "D:\tools\Tools\Carry\mysite\HSD.py", line 658, in yanzen
    jyzt[rq_date].append(code)
KeyError: '2018-07-02'
exception.py[2018-07-02 17:17:33][ERROR]：Internal Server Error: /zhangting/tomorrow/
Traceback (most recent call last):
  File "D:\ProgramFiles\Anaconda3\lib\site-packages\django-1.11.8-py3.6.egg\django\core\handlers\exception.py", line 41, in inner
    response = get_response(request)
  File "D:\ProgramFiles\Anaconda3\lib\site-packages\django-1.11.8-py3.6.egg\django\core\handlers\base.py", line 249, in _legacy_get_response
    response = self._get_response(request)
  File "D:\ProgramFiles\Anaconda3\lib\site-packages\django-1.11.8-py3.6.egg\django\core\handlers\base.py", line 187, in _get_response
    response = self.process_exception_by_middleware(e, request)
  File "D:\ProgramFiles\Anaconda3\lib\site-packages\django-1.11.8-py3.6.egg\django\core\handlers\base.py", line 185, in _get_response
    response = wrapped_callback(request, *callback_args, **callback_kwargs)
  File "D:\tools\Tools\Carry\mysite\views.py", line 739, in zhangting
    zt_tomorrow = ZT.yanzen(rq_date=rq_date)
  File "D:\tools\Tools\Carry\mysite\HSD.py", line 659, in yanzen
    jyzt[rq_date].append(code)
KeyError: '2018-07-02'
exception.py[2018-07-02 17:21:07][ERROR]：Internal Server Error: /zhangting/tomorrow/
Traceback (most recent call last):
  File "D:\ProgramFiles\Anaconda3\lib\site-packages\django-1.11.8-py3.6.egg\django\core\handlers\exception.py", line 41, in inner
    response = get_response(request)
  File "D:\ProgramFiles\Anaconda3\lib\site-packages\django-1.11.8-py3.6.egg\django\core\handlers\base.py", line 249, in _legacy_get_response
    response = self._get_response(request)
  File "D:\ProgramFiles\Anaconda3\lib\site-packages\django-1.11.8-py3.6.egg\django\core\handlers\base.py", line 187, in _get_response
    response = self.process_exception_by_middleware(e, request)
  File "D:\ProgramFiles\Anaconda3\lib\site-packages\django-1.11.8-py3.6.egg\django\core\handlers\base.py", line 185, in _get_response
    response = wrapped_callback(request, *callback_args, **callback_kwargs)
  File "D:\tools\Tools\Carry\mysite\views.py", line 739, in zhangting
    zt_tomorrow = ZT.yanzen(rq_date=rq_date)
  File "D:\tools\Tools\Carry\mysite\HSD.py", line 661, in yanzen
    jyzt = Counter(jyzt).most_common()
  File "D:\ProgramFiles\Anaconda3\lib\collections\__init__.py", line 552, in most_common
    return sorted(self.items(), key=_itemgetter(1), reverse=True)
TypeError: '<' not supported between instances of 'list' and 'str'
exception.py[2018-07-02 17:22:46][ERROR]：Internal Server Error: /zhangting/tomorrow/
Traceback (most recent call last):
  File "D:\ProgramFiles\Anaconda3\lib\site-packages\django-1.11.8-py3.6.egg\django\core\handlers\exception.py", line 41, in inner
    response = get_response(request)
  File "D:\ProgramFiles\Anaconda3\lib\site-packages\django-1.11.8-py3.6.egg\django\core\handlers\base.py", line 249, in _legacy_get_response
    response = self._get_response(request)
  File "D:\ProgramFiles\Anaconda3\lib\site-packages\django-1.11.8-py3.6.egg\django\core\handlers\base.py", line 187, in _get_response
    response = self.process_exception_by_middleware(e, request)
  File "D:\ProgramFiles\Anaconda3\lib\site-packages\django-1.11.8-py3.6.egg\django\core\handlers\base.py", line 185, in _get_response
    response = wrapped_callback(request, *callback_args, **callback_kwargs)
  File "D:\tools\Tools\Carry\mysite\views.py", line 739, in zhangting
    zt_tomorrow = ZT.yanzen(rq_date=rq_date)
  File "D:\tools\Tools\Carry\mysite\HSD.py", line 662, in yanzen
    jyzt = Counter(jyzt).most_common()
  File "D:\ProgramFiles\Anaconda3\lib\collections\__init__.py", line 552, in most_common
    return sorted(self.items(), key=_itemgetter(1), reverse=True)
TypeError: '<' not supported between instances of 'list' and 'str'
exception.py[2018-07-02 17:36:59][ERROR]：Internal Server Error: /zhangting/tomorrow/
Traceback (most recent call last):
  File "D:\ProgramFiles\Anaconda3\lib\site-packages\django-1.11.8-py3.6.egg\django\core\handlers\exception.py", line 41, in inner
    response = get_response(request)
  File "D:\ProgramFiles\Anaconda3\lib\site-packages\django-1.11.8-py3.6.egg\django\core\handlers\base.py", line 249, in _legacy_get_response
    response = self._get_response(request)
  File "D:\ProgramFiles\Anaconda3\lib\site-packages\django-1.11.8-py3.6.egg\django\core\handlers\base.py", line 187, in _get_response
    response = self.process_exception_by_middleware(e, request)
  File "D:\ProgramFiles\Anaconda3\lib\site-packages\django-1.11.8-py3.6.egg\django\core\handlers\base.py", line 185, in _get_response
    response = wrapped_callback(request, *callback_args, **callback_kwargs)
  File "D:\tools\Tools\Carry\mysite\views.py", line 739, in zhangting
    zt_tomorrow = ZT.yanzen(rq_date=rq_date)
  File "D:\tools\Tools\Carry\mysite\HSD.py", line 659, in yanzen
    jyzt_l[rq_date].append(code)
TypeError: list indices must be integers or slices, not str
exception.py[2018-07-02 17:37:45][ERROR]：Internal Server Error: /zhangting/tomorrow/
Traceback (most recent call last):
  File "D:\ProgramFiles\Anaconda3\lib\site-packages\django-1.11.8-py3.6.egg\django\core\handlers\exception.py", line 41, in inner
    response = get_response(request)
  File "D:\ProgramFiles\Anaconda3\lib\site-packages\django-1.11.8-py3.6.egg\django\core\handlers\base.py", line 249, in _legacy_get_response
    response = self._get_response(request)
  File "D:\ProgramFiles\Anaconda3\lib\site-packages\django-1.11.8-py3.6.egg\django\core\handlers\base.py", line 187, in _get_response
    response = self.process_exception_by_middleware(e, request)
  File "D:\ProgramFiles\Anaconda3\lib\site-packages\django-1.11.8-py3.6.egg\django\core\handlers\base.py", line 185, in _get_response
    response = wrapped_callback(request, *callback_args, **callback_kwargs)
  File "D:\tools\Tools\Carry\mysite\views.py", line 744, in zhangting
    zt_tomorrow[i][2] = range(zt_tomorrow[i][2])  # ['★' for j in range(zt_tomorrow[i][2])]
TypeError: 'str' object cannot be interpreted as an integer
