exception.py[2018-06-06 10:54:16][ERROR]：Internal Server Error: /tj/
Traceback (most recent call last):
  File "D:\ProgramFiles\Anaconda3\lib\site-packages\django-1.11.8-py3.6.egg\django\core\handlers\exception.py", line 41, in inner
    response = get_response(request)
  File "D:\ProgramFiles\Anaconda3\lib\site-packages\django-1.11.8-py3.6.egg\django\core\handlers\base.py", line 249, in _legacy_get_response
    response = self._get_response(request)
  File "D:\ProgramFiles\Anaconda3\lib\site-packages\django-1.11.8-py3.6.egg\django\core\handlers\base.py", line 187, in _get_response
    response = self.process_exception_by_middleware(e, request)
  File "D:\ProgramFiles\Anaconda3\lib\site-packages\django-1.11.8-py3.6.egg\django\core\handlers\base.py", line 185, in _get_response
    response = wrapped_callback(request, *callback_args, **callback_kwargs)
  File "D:\tools\Tools\Carry\mysite\views.py", line 466, in tongji
    res_size = len(_res)
NameError: name '_res' is not defined
HSD.py[2018-06-06 12:05:40][ERROR]：文件 HSD.py 第1045行报错：'2018-03-06' is not in list
HSD.py[2018-06-06 12:06:49][ERROR]：文件 HSD.py 第1045行报错：'2018-03-06' is not in list
HSD.py[2018-06-06 12:13:26][ERROR]：文件 HSD.py 第1045行报错：'2018-03-06' is not in list
