base.py[2018-09-13 12:39:35][WARNING]£ºNot Found: /favicon.ico
base.py[2018-09-13 12:39:35][WARNING]£ºNot Found: /favicon.ico
base.py[2018-09-13 13:34:55][WARNING]£ºNot Found: /favicon.ico
base.py[2018-09-13 13:35:03][WARNING]£ºNot Found: /favicon.ico
wsgi.py[2018-09-13 13:39:15][INFO]£º200 GET / (::1) 1309.48ms
web.py[2018-09-13 13:39:15][INFO]£º200 GET /static/css/style.css (::1) 413.13ms
web.py[2018-09-13 13:39:15][INFO]£º200 GET /static/css/jcarousel.css (::1) 1.98ms
web.py[2018-09-13 13:39:15][INFO]£º200 GET /static/js/jquery-1.7.1.min.js (::1) 4.01ms
web.py[2018-09-13 13:39:15][INFO]£º200 GET /static/js/ddsmoothmenu.js (::1) 1.00ms
web.py[2018-09-13 13:39:15][INFO]£º200 GET /static/js/jquery.flexslider-min.js (::1) 2.01ms
web.py[2018-09-13 13:39:15][INFO]£º200 GET /static/css/flexslider.css (::1) 2.03ms
web.py[2018-09-13 13:39:15][INFO]£º200 GET /static/js/mosaic.1.0.1.js (::1) 2.98ms
web.py[2018-09-13 13:39:15][INFO]£º200 GET /static/js/jquery.tipsy.js (::1) 1.00ms
web.py[2018-09-13 13:39:15][INFO]£º200 GET /static/js/md5.js (::1) 1.00ms
web.py[2018-09-13 13:39:15][INFO]£º200 GET /static/js/jquery.jcarousel.min.js (::1) 2.01ms
web.py[2018-09-13 13:39:15][INFO]£º200 GET /static/images/featured/featured-1.jpg (::1) 2.01ms
web.py[2018-09-13 13:39:15][INFO]£º200 GET /static/images/featured/featured-2.jpg (::1) 3.01ms
web.py[2018-09-13 13:39:15][INFO]£º200 GET /static/images/featured/featured-3.jpg (::1) 4.01ms
web.py[2018-09-13 13:39:15][INFO]£º200 GET /static/images/header-bg.jpg (::1) 2.01ms
web.py[2018-09-13 13:39:15][INFO]£º200 GET /static/images/work/work-1.jpg (::1) 3.01ms
web.py[2018-09-13 13:39:15][INFO]£º200 GET /static/images/work/work-4.jpg (::1) 2.01ms
web.py[2018-09-13 13:39:15][INFO]£º200 GET /static/images/work/work-2.jpg (::1) 1.00ms
web.py[2018-09-13 13:39:15][INFO]£º200 GET /static/images/work/work-3.jpg (::1) 2.01ms
web.py[2018-09-13 13:39:15][INFO]£º200 GET /static/images/logo.png (::1) 2.00ms
web.py[2018-09-13 13:39:15][INFO]£º200 GET /static/images/down.gif (::1) 1.00ms
web.py[2018-09-13 13:39:15][INFO]£º200 GET /static/images/bg_direction_nav.png (::1) 1.00ms
web.py[2018-09-13 13:39:15][INFO]£º200 GET /static/images/bg_control_nav.png (::1) 2.00ms
web.py[2018-09-13 13:39:15][INFO]£º200 GET /static/kairui.ico (::1) 1.00ms
web.py[2018-09-13 13:39:17][INFO]£º200 GET /static/images/next-horizontal.png (::1) 1.00ms
web.py[2018-09-13 13:39:17][INFO]£º200 GET /static/images/prev-horizontal.png (::1) 1.00ms
wsgi.py[2018-09-13 13:39:25][INFO]£º200 GET / (127.0.0.1) 15.07ms
wsgi.py[2018-09-13 13:39:50][INFO]£º200 GET / (127.0.0.1) 8.04ms
wsgi.py[2018-09-13 13:41:14][INFO]£º200 GET /tj/ (127.0.0.1) 68.18ms
base.py[2018-09-13 13:41:42][WARNING]£ºNot Found: /favicon.ico
wsgi.py[2018-09-13 13:41:50][INFO]£º200 GET / (127.0.0.1) 9.02ms
web.py[2018-09-13 13:41:50][INFO]£º200 GET /static/css/style.css (127.0.0.1) 1.00ms
web.py[2018-09-13 13:41:50][INFO]£º200 GET /static/css/flexslider.css (127.0.0.1) 1.00ms
web.py[2018-09-13 13:41:50][INFO]£º200 GET /static/css/jcarousel.css (127.0.0.1) 1.00ms
web.py[2018-09-13 13:41:50][INFO]£º200 GET /static/js/jquery-1.7.1.min.js (127.0.0.1) 1.00ms
web.py[2018-09-13 13:41:50][INFO]£º200 GET /static/js/jquery.flexslider-min.js (127.0.0.1) 1.00ms
web.py[2018-09-13 13:41:50][INFO]£º200 GET /static/js/ddsmoothmenu.js (127.0.0.1) 1.00ms
web.py[2018-09-13 13:41:50][INFO]£º200 GET /static/js/jquery.jcarousel.min.js (127.0.0.1) 1.00ms
web.py[2018-09-13 13:41:50][INFO]£º200 GET /static/js/mosaic.1.0.1.js (127.0.0.1) 1.00ms
web.py[2018-09-13 13:41:50][INFO]£º200 GET /static/js/jquery.tipsy.js (127.0.0.1) 1.00ms
web.py[2018-09-13 13:41:50][INFO]£º200 GET /static/js/md5.js (127.0.0.1) 1.00ms
web.py[2018-09-13 13:41:50][INFO]£º200 GET /static/images/featured/featured-1.jpg (127.0.0.1) 2.00ms
web.py[2018-09-13 13:41:50][INFO]£º200 GET /static/images/featured/featured-2.jpg (127.0.0.1) 2.01ms
web.py[2018-09-13 13:41:50][INFO]£º200 GET /static/images/featured/featured-3.jpg (127.0.0.1) 3.01ms
web.py[2018-09-13 13:41:50][INFO]£º200 GET /static/images/work/work-1.jpg (127.0.0.1) 1.00ms
web.py[2018-09-13 13:41:50][INFO]£º200 GET /static/images/work/work-2.jpg (127.0.0.1) 1.03ms
web.py[2018-09-13 13:41:50][INFO]£º200 GET /static/images/work/work-3.jpg (127.0.0.1) 1.00ms
web.py[2018-09-13 13:41:50][INFO]£º200 GET /static/images/work/work-4.jpg (127.0.0.1) 1.00ms
web.py[2018-09-13 13:41:50][INFO]£º200 GET /static/images/header-bg.jpg (127.0.0.1) 1.00ms
web.py[2018-09-13 13:41:50][INFO]£º200 GET /static/images/logo.png (127.0.0.1) 1.00ms
web.py[2018-09-13 13:41:50][INFO]£º200 GET /static/images/down.gif (127.0.0.1) 1.00ms
web.py[2018-09-13 13:41:50][INFO]£º200 GET /static/images/bg_direction_nav.png (127.0.0.1) 1.00ms
web.py[2018-09-13 13:41:50][INFO]£º200 GET /static/images/bg_control_nav.png (127.0.0.1) 1.00ms
web.py[2018-09-13 13:41:50][INFO]£º200 GET /static/kairui.ico (127.0.0.1) 0.00ms
web.py[2018-09-13 13:41:57][INFO]£º200 GET /static/images/next-horizontal.png (127.0.0.1) 1.00ms
web.py[2018-09-13 13:41:57][INFO]£º200 GET /static/images/prev-horizontal.png (127.0.0.1) 1.00ms
wsgi.py[2018-09-13 13:42:35][INFO]£º200 GET / (127.0.0.1) 15.04ms
web.py[2018-09-13 13:42:35][INFO]£º200 GET /static/kairui.ico (127.0.0.1) 1.00ms
wsgi.py[2018-09-13 13:42:36][INFO]£º200 GET / (127.0.0.1) 26.10ms
web.py[2018-09-13 13:42:36][INFO]£º200 GET /static/kairui.ico (127.0.0.1) 0.00ms
wsgi.py[2018-09-13 13:42:42][INFO]£º200 GET / (127.0.0.1) 11.03ms
wsgi.py[2018-09-13 13:43:46][INFO]£º200 GET / (127.0.0.1) 1359.63ms
wsgi.py[2018-09-13 13:45:15][INFO]£º200 GET / (192.168.2.204) 7.02ms
wsgi.py[2018-09-13 13:45:53][INFO]£º200 GET / (192.168.2.204) 5.01ms
wsgi.py[2018-09-13 13:47:29][INFO]£º200 GET / (192.168.2.204) 8.02ms
wsgi.py[2018-09-13 13:48:35][INFO]£º200 GET / (192.168.2.204) 8.02ms
web.py[2018-09-13 13:48:47][WARNING]£º404 POST /user/login/ (192.168.2.204) 1.00ms
wsgi.py[2018-09-13 13:49:07][INFO]£º200 GET / (192.168.2.204) 4.99ms
wsgi.py[2018-09-13 13:49:20][INFO]£º200 GET / (192.168.2.204) 6.02ms
wsgi.py[2018-09-13 13:50:22][INFO]£º200 GET / (192.168.2.204) 5.01ms
wsgi.py[2018-09-13 13:52:20][INFO]£º200 GET / (192.168.2.204) 6.02ms
wsgi.py[2018-09-13 13:52:21][INFO]£º200 GET / (192.168.2.204) 5.04ms
wsgi.py[2018-09-13 13:52:24][INFO]£º200 GET /tj/ (192.168.2.204) 74.20ms
wsgi.py[2018-09-13 13:52:26][INFO]£º200 GET /tj/?datetimes=2018-09-13&id=None&type=1&end_date=2018-09-13&when=0 (192.168.2.204) 229.61ms
wsgi.py[2018-09-13 13:52:28][INFO]£º200 GET /tj/?datetimes=2018-09-13&id=0&type=1&end_date=2018-09-13&page=up (192.168.2.204) 25.07ms
wsgi.py[2018-09-13 13:52:30][INFO]£º200 GET / (192.168.2.204) 5.04ms
wsgi.py[2018-09-13 13:52:39][INFO]£º200 GET / (192.168.2.204) 5.04ms
web.py[2018-09-13 13:52:41][WARNING]£º404 GET /user/information/ (192.168.2.204) 1.03ms
web.py[2018-09-13 13:52:50][WARNING]£º404 GET /user/information/ (192.168.2.204) 0.00ms
web.py[2018-09-13 13:52:58][WARNING]£º404 GET /work/log/add/ (192.168.2.204) 0.00ms
wsgi.py[2018-09-13 13:53:10][INFO]£º200 GET / (192.168.2.204) 5.02ms
web.py[2018-09-13 13:53:14][WARNING]£º404 GET /cfmmc/dataPage/ (192.168.2.204) 0.00ms
web.py[2018-09-13 13:53:20][WARNING]£º404 GET /cfmmc/dataLocal/ (192.168.2.204) 1.00ms
web.py[2018-09-13 13:53:35][WARNING]£º404 GET /cfmmc/dataLocal/ (192.168.2.204) 0.00ms
web.py[2018-09-13 13:53:40][WARNING]£º404 GET /cfmmc/dataLocal/ (192.168.2.204) 0.00ms
wsgi.py[2018-09-13 13:53:45][INFO]£º200 GET /stockDatas/ (192.168.2.204) 290.77ms
wsgi.py[2018-09-13 13:53:54][INFO]£º200 GET /zx/ (192.168.2.204) 110.32ms
wsgi.py[2018-09-13 13:54:00][INFO]£º200 GET /moni/ (192.168.2.204) 10.02ms
wsgi.py[2018-09-13 13:54:03][INFO]£º200 GET /moni/?zsds=100&ydzs=100&zyds=200&cqdc=6&database=1&dates=2018-09-07&end_date=2018-09-13&fa=1 (192.168.2.204) 767.04ms
wsgi.py[2018-09-13 13:54:10][INFO]£º200 GET / (192.168.2.204) 5.04ms
web.py[2018-09-13 13:55:17][WARNING]£º404 GET / (192.168.2.204) 2.00ms
web.py[2018-09-13 13:55:18][WARNING]£º404 GET / (192.168.2.204) 1.00ms
web.py[2018-09-13 13:55:19][WARNING]£º404 GET / (192.168.2.204) 0.00ms
web.py[2018-09-13 13:55:39][WARNING]£º404 GET / (192.168.2.204) 0.00ms
web.py[2018-09-13 13:55:40][WARNING]£º404 GET / (192.168.2.204) 0.00ms
web.py[2018-09-13 13:55:40][WARNING]£º404 GET / (192.168.2.204) 1.00ms
wsgi.py[2018-09-13 13:57:48][INFO]£º200 GET / (192.168.2.204) 1241.30ms
wsgi.py[2018-09-13 13:57:49][INFO]£º200 GET / (192.168.2.204) 11.06ms
wsgi.py[2018-09-13 13:57:51][INFO]£º200 GET /cfmmc/dataLocal/ (192.168.2.204) 86.21ms
wsgi.py[2018-09-13 13:57:53][INFO]£º200 GET /cfmmc/dataPage/?host=1001 (192.168.2.204) 33.06ms
wsgi.py[2018-09-13 14:04:06][INFO]£º200 GET / (192.168.2.204) 1233.31ms
wsgi.py[2018-09-13 14:04:14][INFO]£º200 GET / (192.168.2.204) 5.01ms
web.py[2018-09-13 14:04:15][INFO]£º200 GET /static/css/style.css (192.168.2.204) 412.09ms
web.py[2018-09-13 14:04:15][INFO]£º304 GET /static/js/jquery.flexslider-min.js (192.168.2.204) 4.01ms
web.py[2018-09-13 14:04:15][INFO]£º304 GET /static/js/ddsmoothmenu.js (192.168.2.204) 0.00ms
web.py[2018-09-13 14:04:15][INFO]£º304 GET /static/js/jquery.jcarousel.min.js (192.168.2.204) 1.03ms
web.py[2018-09-13 14:04:15][INFO]£º304 GET /static/js/mosaic.1.0.1.js (192.168.2.204) 0.97ms
web.py[2018-09-13 14:04:15][INFO]£º304 GET /static/js/jquery.tipsy.js (192.168.2.204) 0.00ms
web.py[2018-09-13 14:04:15][INFO]£º304 GET /static/images/featured/featured-2.jpg (192.168.2.204) 1.04ms
web.py[2018-09-13 14:04:15][INFO]£º304 GET /static/images/featured/featured-3.jpg (192.168.2.204) 0.97ms
web.py[2018-09-13 14:04:15][INFO]£º304 GET /static/images/featured/featured-1.jpg (192.168.2.204) 0.97ms
web.py[2018-09-13 14:04:15][INFO]£º304 GET /static/images/logo.png (192.168.2.204) 0.98ms
wsgi.py[2018-09-13 14:04:23][INFO]£º200 GET / (192.168.2.204) 7.02ms
web.py[2018-09-13 14:04:23][INFO]£º304 GET /static/css/style.css (192.168.2.204) 0.00ms
web.py[2018-09-13 14:04:23][INFO]£º304 GET /static/css/flexslider.css (192.168.2.204) 1.01ms
web.py[2018-09-13 14:04:23][INFO]£º304 GET /static/css/jcarousel.css (192.168.2.204) 1.04ms
web.py[2018-09-13 14:04:23][INFO]£º304 GET /static/js/jquery-1.7.1.min.js (192.168.2.204) 1.00ms
web.py[2018-09-13 14:04:23][INFO]£º304 GET /static/js/ddsmoothmenu.js (192.168.2.204) 1.00ms
web.py[2018-09-13 14:04:23][INFO]£º304 GET /static/js/jquery.flexslider-min.js (192.168.2.204) 1.00ms
web.py[2018-09-13 14:04:23][INFO]£º304 GET /static/js/jquery.jcarousel.min.js (192.168.2.204) 1.00ms
web.py[2018-09-13 14:04:23][INFO]£º304 GET /static/js/mosaic.1.0.1.js (192.168.2.204) 0.99ms
web.py[2018-09-13 14:04:23][INFO]£º304 GET /static/js/jquery.tipsy.js (192.168.2.204) 1.00ms
web.py[2018-09-13 14:04:23][INFO]£º304 GET /static/js/md5.js (192.168.2.204) 1.00ms
web.py[2018-09-13 14:04:23][INFO]£º304 GET /static/images/featured/featured-1.jpg (192.168.2.204) 0.00ms
web.py[2018-09-13 14:04:23][INFO]£º304 GET /static/images/featured/featured-2.jpg (192.168.2.204) 0.00ms
web.py[2018-09-13 14:04:23][INFO]£º304 GET /static/images/featured/featured-3.jpg (192.168.2.204) 1.00ms
web.py[2018-09-13 14:04:23][INFO]£º304 GET /static/images/work/work-1.jpg (192.168.2.204) 1.00ms
web.py[2018-09-13 14:04:23][INFO]£º304 GET /static/images/work/work-2.jpg (192.168.2.204) 1.00ms
web.py[2018-09-13 14:04:23][INFO]£º304 GET /static/images/work/work-3.jpg (192.168.2.204) 1.00ms
web.py[2018-09-13 14:04:23][INFO]£º304 GET /static/images/work/work-4.jpg (192.168.2.204) 1.00ms
web.py[2018-09-13 14:04:23][INFO]£º304 GET /static/images/down.gif (192.168.2.204) 1.00ms
web.py[2018-09-13 14:04:23][INFO]£º304 GET /static/images/logo.png (192.168.2.204) 1.00ms
web.py[2018-09-13 14:04:23][INFO]£º304 GET /static/images/header-bg.jpg (192.168.2.204) 1.00ms
wsgi.py[2018-09-13 14:04:25][INFO]£º200 GET / (192.168.2.204) 5.01ms
web.py[2018-09-13 14:04:25][INFO]£º200 GET /static/kairui.ico (192.168.2.204) 1.00ms
wsgi.py[2018-09-13 14:04:34][INFO]£º200 GET /systems/ (192.168.2.204) 5.01ms
wsgi.py[2018-09-13 14:04:46][INFO]£º200 GET /systems/ (192.168.2.204) 7.02ms
wsgi.py[2018-09-13 14:05:06][INFO]£º200 GET /get_system/ (192.168.2.204) 20013.79ms
wsgi.py[2018-09-13 14:05:06][INFO]£º200 GET / (192.168.2.204) 7.02ms
wsgi.py[2018-09-13 14:05:26][INFO]£º200 GET /get_system/ (192.168.2.204) 20014.36ms
wsgi.py[2018-09-13 14:05:46][INFO]£º200 GET /get_system/ (192.168.2.204) 20014.59ms
wsgi.py[2018-09-13 14:06:06][INFO]£º200 GET /get_system/ (192.168.2.204) 20010.49ms
wsgi.py[2018-09-13 14:06:26][INFO]£º200 GET /get_system/ (192.168.2.204) 20006.25ms
wsgi.py[2018-09-13 14:06:36][INFO]£º200 GET / (192.168.2.204) 1272.38ms
wsgi.py[2018-09-13 14:06:37][INFO]£º200 GET / (192.168.2.204) 6.02ms
wsgi.py[2018-09-13 14:06:44][INFO]£º200 GET / (192.168.2.204) 5.65ms
wsgi.py[2018-09-13 14:06:49][INFO]£º200 GET /systems/ (192.168.2.204) 6.04ms
wsgi.py[2018-09-13 14:07:09][INFO]£º200 GET /get_system/ (192.168.2.204) 20013.63ms
wsgi.py[2018-09-13 14:07:09][INFO]£º200 GET / (192.168.2.204) 6.02ms
wsgi.py[2018-09-13 14:07:29][INFO]£º200 GET /get_system/ (192.168.2.204) 20013.46ms
wsgi.py[2018-09-13 14:07:29][INFO]£º200 GET / (192.168.2.204) 6.01ms
wsgi.py[2018-09-13 14:07:49][INFO]£º200 GET /get_system/ (192.168.2.204) 20013.34ms
wsgi.py[2018-09-13 14:08:09][INFO]£º200 GET /get_system/ (192.168.2.204) 20015.05ms
wsgi.py[2018-09-13 14:08:29][INFO]£º200 GET /get_system/ (192.168.2.204) 20015.12ms
wsgi.py[2018-09-13 14:08:49][INFO]£º200 GET /get_system/ (192.168.2.204) 20014.01ms
wsgi.py[2018-09-13 14:15:29][INFO]£º200 GET / (192.168.2.204) 1278.40ms
wsgi.py[2018-09-13 14:15:36][INFO]£º200 GET / (192.168.2.204) 1271.38ms
wsgi.py[2018-09-13 14:15:41][INFO]£º200 GET /systems/ (192.168.2.204) 1320.51ms
wsgi.py[2018-09-13 14:15:44][INFO]£º200 GET / (192.168.2.204) 5.01ms
wsgi.py[2018-09-13 14:15:45][INFO]£º200 GET / (192.168.2.204) 7.00ms
wsgi.py[2018-09-13 14:15:45][INFO]£º200 GET / (192.168.2.204) 6.02ms
wsgi.py[2018-09-13 14:15:49][INFO]£º200 GET / (192.168.2.204) 5.01ms
wsgi.py[2018-09-13 14:15:55][INFO]£º200 GET /cfmmc/dataLocal/ (192.168.2.204) 95.28ms
wsgi.py[2018-09-13 14:15:56][INFO]£º200 GET / (192.168.2.204) 5.01ms
wsgi.py[2018-09-13 14:16:03][INFO]£º200 GET /get_system/ (192.168.2.204) 21247.88ms
wsgi.py[2018-09-13 14:16:03][INFO]£º200 GET /tj/ (192.168.2.204) 115.33ms
wsgi.py[2018-09-13 14:16:03][INFO]£º200 GET /tj/ (192.168.2.204) 27.04ms
wsgi.py[2018-09-13 14:16:12][INFO]£º200 GET /systems/ (192.168.2.204) 8.02ms
wsgi.py[2018-09-13 14:16:23][INFO]£º200 GET /get_system/ (192.168.2.204) 20013.27ms
wsgi.py[2018-09-13 14:16:24][INFO]£º200 GET / (192.168.2.204) 6.01ms
wsgi.py[2018-09-13 14:16:26][INFO]£º200 GET / (192.168.2.204) 11.03ms
web.py[2018-09-13 14:16:27][INFO]£º200 GET /static/css/style.css (192.168.2.204) 408.08ms
web.py[2018-09-13 14:16:27][INFO]£º200 GET /static/css/jcarousel.css (192.168.2.204) 1.02ms
web.py[2018-09-13 14:16:27][INFO]£º200 GET /static/js/jquery-1.7.1.min.js (192.168.2.204) 2.01ms
web.py[2018-09-13 14:16:27][INFO]£º200 GET /static/js/ddsmoothmenu.js (192.168.2.204) 2.00ms
web.py[2018-09-13 14:16:27][INFO]£º200 GET /static/js/jquery.flexslider-min.js (192.168.2.204) 1.00ms
web.py[2018-09-13 14:16:27][INFO]£º200 GET /static/js/mosaic.1.0.1.js (192.168.2.204) 2.01ms
web.py[2018-09-13 14:16:27][INFO]£º200 GET /static/js/jquery.tipsy.js (192.168.2.204) 0.97ms
web.py[2018-09-13 14:16:27][INFO]£º200 GET /static/js/md5.js (192.168.2.204) 2.01ms
web.py[2018-09-13 14:16:27][INFO]£º200 GET /static/css/flexslider.css (192.168.2.204) 1.00ms
web.py[2018-09-13 14:16:27][INFO]£º200 GET /static/js/jquery.jcarousel.min.js (192.168.2.204) 2.00ms
web.py[2018-09-13 14:16:27][INFO]£º200 GET /static/images/featured/featured-1.jpg (192.168.2.204) 1.00ms
web.py[2018-09-13 14:16:27][INFO]£º200 GET /static/images/featured/featured-2.jpg (192.168.2.204) 2.01ms
web.py[2018-09-13 14:16:27][INFO]£º200 GET /static/images/featured/featured-3.jpg (192.168.2.204) 3.01ms
web.py[2018-09-13 14:16:27][INFO]£º200 GET /static/images/work/work-1.jpg (192.168.2.204) 2.01ms
web.py[2018-09-13 14:16:27][INFO]£º200 GET /static/images/work/work-2.jpg (192.168.2.204) 1.00ms
web.py[2018-09-13 14:16:27][INFO]£º200 GET /static/images/work/work-3.jpg (192.168.2.204) 1.00ms
web.py[2018-09-13 14:16:27][INFO]£º200 GET /static/images/work/work-4.jpg (192.168.2.204) 2.01ms
web.py[2018-09-13 14:16:27][INFO]£º200 GET /static/images/header-bg.jpg (192.168.2.204) 1.00ms
web.py[2018-09-13 14:16:27][INFO]£º200 GET /static/images/logo.png (192.168.2.204) 1.00ms
web.py[2018-09-13 14:16:27][INFO]£º200 GET /static/images/down.gif (192.168.2.204) 1.00ms
web.py[2018-09-13 14:16:27][INFO]£º200 GET /static/images/bg_direction_nav.png (192.168.2.204) 1.00ms
web.py[2018-09-13 14:16:27][INFO]£º200 GET /static/images/bg_control_nav.png (192.168.2.204) 1.00ms
web.py[2018-09-13 14:16:27][INFO]£º200 GET /static/kairui.ico (192.168.2.204) 1.00ms
wsgi.py[2018-09-13 14:16:28][INFO]£º200 GET /get_system/ (192.168.2.204) 20014.59ms
web.py[2018-09-13 14:16:28][INFO]£º200 GET /favicon.ico (::1) 386.04ms
wsgi.py[2018-09-13 14:16:31][INFO]£º200 GET /get_system/ (192.168.2.204) 20014.79ms
wsgi.py[2018-09-13 14:16:31][INFO]£º200 GET / (192.168.2.204) 6.02ms
wsgi.py[2018-09-13 14:16:38][INFO]£º200 GET /systems/ (192.168.2.204) 6.04ms
wsgi.py[2018-09-13 14:16:40][INFO]£º200 GET / (192.168.2.204) 6.02ms
wsgi.py[2018-09-13 14:16:43][INFO]£º200 GET / (192.168.2.204) 4.52ms
wsgi.py[2018-09-13 14:16:58][INFO]£º200 GET /get_system/ (192.168.2.204) 20014.54ms
wsgi.py[2018-09-13 14:17:18][INFO]£º200 GET /get_system/ (192.168.2.204) 20014.70ms
wsgi.py[2018-09-13 14:17:24][INFO]£º200 GET /get_system/ (192.168.2.204) 20015.68ms
wsgi.py[2018-09-13 14:17:27][INFO]£º200 GET /get_system/ (192.168.2.204) 20016.45ms
wsgi.py[2018-09-13 14:17:30][INFO]£º200 GET /get_system/ (192.168.2.204) 20016.48ms
wsgi.py[2018-09-13 14:17:38][INFO]£º200 GET /get_system/ (192.168.2.204) 20013.18ms
wsgi.py[2018-09-13 14:17:44][INFO]£º200 GET /get_system/ (192.168.2.204) 20014.76ms
wsgi.py[2018-09-13 14:17:47][INFO]£º200 GET /get_system/ (192.168.2.204) 20017.76ms
wsgi.py[2018-09-13 14:18:04][INFO]£º200 GET /get_system/ (192.168.2.204) 20015.49ms
wsgi.py[2018-09-13 14:19:51][INFO]£º200 GET / (192.168.2.204) 7.02ms
wsgi.py[2018-09-13 14:20:10][INFO]£º200 GET / (192.168.2.204) 9.02ms
wsgi.py[2018-09-13 14:20:13][INFO]£º200 GET /cfmmc/dataLocal/ (192.168.2.204) 95.25ms
wsgi.py[2018-09-13 14:20:14][INFO]£º200 GET / (192.168.2.204) 5.01ms
wsgi.py[2018-09-13 14:20:18][INFO]£º200 GET /cfmmc/dataLocal/ (192.168.2.204) 29.08ms
wsgi.py[2018-09-13 14:20:20][INFO]£º200 GET /cfmmc/dataPage/?host=1001 (192.168.2.204) 33.09ms
wsgi.py[2018-09-13 14:21:45][INFO]£º200 GET /cfmmc/dataLocal/ (192.168.2.204) 28.07ms
wsgi.py[2018-09-13 14:21:49][INFO]£º200 GET /cfmmc/dataLocal/sdhg/ (192.168.2.204) 3.01ms
wsgi.py[2018-09-13 14:21:56][INFO]£º200 GET /cfmmc/dataLocal/ (192.168.2.204) 28.10ms
wsgi.py[2018-09-13 14:32:31][INFO]£º200 GET / (192.168.2.204) 1341.57ms
wsgi.py[2018-09-13 14:32:34][INFO]£º200 GET / (192.168.2.204) 1207.20ms
wsgi.py[2018-09-13 14:32:36][INFO]£º200 GET / (192.168.2.204) 1202.12ms
wsgi.py[2018-09-13 14:32:37][INFO]£º200 GET / (192.168.2.204) 6.01ms
wsgi.py[2018-09-13 14:32:38][INFO]£º200 GET / (192.168.2.204) 5.01ms
wsgi.py[2018-09-13 14:32:40][INFO]£º200 GET /tj/ (192.168.2.204) 74.20ms
wsgi.py[2018-09-13 14:32:41][INFO]£º200 GET / (192.168.2.204) 5.01ms
wsgi.py[2018-09-13 14:32:42][INFO]£º200 GET / (192.168.2.204) 5.51ms
wsgi.py[2018-09-13 14:32:43][INFO]£º200 GET / (192.168.2.204) 9.02ms
wsgi.py[2018-09-13 14:32:43][INFO]£º200 GET / (192.168.2.204) 5.01ms
wsgi.py[2018-09-13 14:39:53][INFO]£º200 GET / (192.168.2.204) 1220.25ms
web.py[2018-09-13 14:39:53][INFO]£º200 GET /static/css/flexslider.css (192.168.2.204) 415.13ms
web.py[2018-09-13 14:39:53][INFO]£º200 GET /static/css/style.css (192.168.2.204) 2.01ms
web.py[2018-09-13 14:39:53][INFO]£º200 GET /static/js/jquery-1.7.1.min.js (192.168.2.204) 3.01ms
web.py[2018-09-13 14:39:53][INFO]£º200 GET /static/js/ddsmoothmenu.js (192.168.2.204) 1.00ms
web.py[2018-09-13 14:39:53][INFO]£º200 GET /static/js/jquery.flexslider-min.js (192.168.2.204) 1.02ms
web.py[2018-09-13 14:39:53][INFO]£º200 GET /static/js/jquery.tipsy.js (192.168.2.204) 2.01ms
web.py[2018-09-13 14:39:53][INFO]£º200 GET /static/js/md5.js (192.168.2.204) 1.00ms
web.py[2018-09-13 14:39:53][INFO]£º200 GET /static/css/jcarousel.css (192.168.2.204) 1.02ms
web.py[2018-09-13 14:39:53][INFO]£º200 GET /static/js/jquery.jcarousel.min.js (192.168.2.204) 1.00ms
web.py[2018-09-13 14:39:53][INFO]£º200 GET /static/js/mosaic.1.0.1.js (192.168.2.204) 1.00ms
web.py[2018-09-13 14:39:53][INFO]£º200 GET /static/images/featured/featured-1.jpg (192.168.2.204) 2.03ms
web.py[2018-09-13 14:39:53][INFO]£º200 GET /static/images/featured/featured-2.jpg (192.168.2.204) 2.01ms
web.py[2018-09-13 14:39:53][INFO]£º200 GET /static/images/featured/featured-3.jpg (192.168.2.204) 3.02ms
web.py[2018-09-13 14:39:53][INFO]£º200 GET /static/images/work/work-4.jpg (192.168.2.204) 2.00ms
web.py[2018-09-13 14:39:53][INFO]£º200 GET /static/images/work/work-2.jpg (192.168.2.204) 1.00ms
web.py[2018-09-13 14:39:53][INFO]£º200 GET /static/images/work/work-1.jpg (192.168.2.204) 1.00ms
web.py[2018-09-13 14:39:53][INFO]£º200 GET /static/images/header-bg.jpg (192.168.2.204) 2.01ms
web.py[2018-09-13 14:39:53][INFO]£º200 GET /static/images/work/work-3.jpg (192.168.2.204) 1.00ms
web.py[2018-09-13 14:39:53][INFO]£º200 GET /static/images/logo.png (192.168.2.204) 1.00ms
web.py[2018-09-13 14:39:53][INFO]£º200 GET /static/images/down.gif (192.168.2.204) 1.00ms
web.py[2018-09-13 14:39:53][INFO]£º200 GET /static/images/bg_direction_nav.png (192.168.2.204) 1.00ms
web.py[2018-09-13 14:39:53][INFO]£º200 GET /static/images/bg_control_nav.png (192.168.2.204) 1.00ms
web.py[2018-09-13 14:39:53][INFO]£º200 GET /static/kairui.ico (192.168.2.204) 1.00ms
wsgi.py[2018-09-13 14:39:57][INFO]£º200 GET / (192.168.2.204) 1228.30ms
web.py[2018-09-13 14:39:58][INFO]£º200 GET /static/css/style.css (192.168.2.204) 396.08ms
web.py[2018-09-13 14:39:58][INFO]£º200 GET /static/css/jcarousel.css (192.168.2.204) 5.01ms
web.py[2018-09-13 14:39:58][INFO]£º200 GET /static/js/jquery-1.7.1.min.js (192.168.2.204) 4.01ms
web.py[2018-09-13 14:39:58][INFO]£º200 GET /static/js/ddsmoothmenu.js (192.168.2.204) 2.01ms
web.py[2018-09-13 14:39:58][INFO]£º200 GET /static/js/jquery.flexslider-min.js (192.168.2.204) 2.01ms
web.py[2018-09-13 14:39:58][INFO]£º200 GET /static/css/flexslider.css (192.168.2.204) 1.00ms
web.py[2018-09-13 14:39:58][INFO]£º200 GET /static/js/mosaic.1.0.1.js (192.168.2.204) 1.00ms
web.py[2018-09-13 14:39:58][INFO]£º200 GET /static/js/jquery.tipsy.js (192.168.2.204) 2.01ms
web.py[2018-09-13 14:39:58][INFO]£º200 GET /static/js/jquery.jcarousel.min.js (192.168.2.204) 0.97ms
web.py[2018-09-13 14:39:58][INFO]£º200 GET /static/js/md5.js (192.168.2.204) 1.00ms
web.py[2018-09-13 14:39:58][INFO]£º200 GET /static/images/featured/featured-1.jpg (192.168.2.204) 2.01ms
web.py[2018-09-13 14:39:58][INFO]£º200 GET /static/images/featured/featured-2.jpg (192.168.2.204) 2.01ms
web.py[2018-09-13 14:39:58][INFO]£º200 GET /static/images/featured/featured-3.jpg (192.168.2.204) 2.01ms
web.py[2018-09-13 14:39:58][INFO]£º200 GET /static/images/work/work-2.jpg (192.168.2.204) 1.00ms
web.py[2018-09-13 14:39:58][INFO]£º200 GET /static/images/work/work-1.jpg (192.168.2.204) 2.01ms
web.py[2018-09-13 14:39:58][INFO]£º200 GET /static/images/work/work-3.jpg (192.168.2.204) 1.00ms
web.py[2018-09-13 14:39:58][INFO]£º200 GET /static/images/header-bg.jpg (192.168.2.204) 1.00ms
web.py[2018-09-13 14:39:58][INFO]£º200 GET /static/images/work/work-4.jpg (192.168.2.204) 1.00ms
web.py[2018-09-13 14:39:58][INFO]£º200 GET /static/images/logo.png (192.168.2.204) 1.00ms
web.py[2018-09-13 14:39:58][INFO]£º200 GET /static/images/down.gif (192.168.2.204) 1.00ms
web.py[2018-09-13 14:39:58][INFO]£º200 GET /static/images/bg_direction_nav.png (192.168.2.204) 1.00ms
web.py[2018-09-13 14:39:58][INFO]£º200 GET /static/images/bg_control_nav.png (192.168.2.204) 1.00ms
web.py[2018-09-13 14:39:58][INFO]£º200 GET /static/kairui.ico (192.168.2.204) 2.01ms
wsgi.py[2018-09-13 14:40:00][INFO]£º200 GET / (192.168.2.204) 5.01ms
web.py[2018-09-13 14:40:40][INFO]£º200 GET /static/images/prev-horizontal.png (192.168.2.204) 405.08ms
web.py[2018-09-13 14:40:40][INFO]£º200 GET /static/images/next-horizontal.png (192.168.2.204) 1.00ms
wsgi.py[2018-09-13 14:40:43][INFO]£º200 GET / (192.168.2.204) 1298.45ms
wsgi.py[2018-09-13 14:40:45][INFO]£º200 GET / (192.168.2.204) 1219.22ms
wsgi.py[2018-09-13 14:40:48][INFO]£º200 GET / (192.168.2.204) 1223.28ms
web.py[2018-09-13 14:50:24][INFO]£º200 GET /static/images/prev-horizontal.png (192.168.2.204) 393.05ms
web.py[2018-09-13 14:50:24][INFO]£º200 GET /static/images/next-horizontal.png (192.168.2.204) 1.02ms
wsgi.py[2018-09-13 14:50:24][INFO]£º200 GET / (192.168.2.204) 175.45ms
web.py[2018-09-13 14:50:24][INFO]£º304 GET /static/css/style.css (192.168.2.204) 2.01ms
web.py[2018-09-13 14:50:24][INFO]£º200 GET /static/kairui.ico (192.168.2.204) 2.01ms
wsgi.py[2018-09-13 14:50:28][INFO]£º200 GET / (192.168.2.204) 168.45ms
wsgi.py[2018-09-13 14:50:31][INFO]£º200 GET / (192.168.2.204) 167.44ms
wsgi.py[2018-09-13 14:51:58][INFO]£º200 GET / (192.168.2.204) 157.36ms
web.py[2018-09-13 14:51:59][INFO]£º200 GET /static/kairui.ico (192.168.2.204) 412.10ms
wsgi.py[2018-09-13 14:52:11][INFO]£º200 GET / (192.168.2.204) 171.45ms
wsgi.py[2018-09-13 14:52:14][INFO]£º200 GET / (192.168.2.204) 169.45ms
wsgi.py[2018-09-13 15:44:00][INFO]£º200 GET / (192.168.2.204) 4259.43ms
web.py[2018-09-13 15:44:01][INFO]£º304 GET /static/css/style.css (192.168.2.204) 423.15ms
wsgi.py[2018-09-13 15:44:10][INFO]£º200 POST /user/login/ (192.168.2.204) 68.66ms
exception.py[2018-09-13 15:44:19][ERROR]£ºInternal Server Error: /user/login/
Traceback (most recent call last):
  File "D:\ProgramFiles\Anaconda3\lib\site-packages\django_redis\cache.py", line 33, in _decorator
    return method(self, *args, **kwargs)
  File "D:\ProgramFiles\Anaconda3\lib\site-packages\django_redis\cache.py", line 125, in has_key
    return self.client.has_key(*args, **kwargs)
  File "D:\ProgramFiles\Anaconda3\lib\site-packages\django_redis\client\default.py", line 473, in has_key
    raise ConnectionInterrupted(connection=client, parent=e)
django_redis.exceptions.ConnectionInterrupted: Redis ConnectionError: Error 10061 connecting to None:6379. ÓÉÓÚÄ¿±ê¼ÆËã»ú»ý¼«¾Ü¾ø£¬ÎÞ·¨Á¬½Ó¡£.

During handling of the above exception, another exception occurred:

Traceback (most recent call last):
  File "D:\ProgramFiles\Anaconda3\lib\site-packages\django-1.11.8-py3.6.egg\django\core\handlers\base.py", line 131, in get_response
    response = middleware_method(request, response)
  File "D:\ProgramFiles\Anaconda3\lib\site-packages\django-1.11.8-py3.6.egg\django\contrib\sessions\middleware.py", line 58, in process_response
    request.session.save()
  File "D:\ProgramFiles\Anaconda3\lib\site-packages\django-1.11.8-py3.6.egg\django\contrib\sessions\backends\cache.py", line 57, in save
    return self.create()
  File "D:\ProgramFiles\Anaconda3\lib\site-packages\django-1.11.8-py3.6.egg\django\contrib\sessions\backends\cache.py", line 44, in create
    self._session_key = self._get_new_session_key()
  File "D:\ProgramFiles\Anaconda3\lib\site-packages\django-1.11.8-py3.6.egg\django\contrib\sessions\backends\base.py", line 164, in _get_new_session_key
    if not self.exists(session_key):
  File "D:\ProgramFiles\Anaconda3\lib\site-packages\django-1.11.8-py3.6.egg\django\contrib\sessions\backends\cache.py", line 71, in exists
    return session_key and (self.cache_key_prefix + session_key) in self._cache
  File "D:\ProgramFiles\Anaconda3\lib\site-packages\django-1.11.8-py3.6.egg\django\core\cache\backends\base.py", line 203, in __contains__
    return self.has_key(key)
  File "D:\ProgramFiles\Anaconda3\lib\site-packages\django_redis\cache.py", line 40, in _decorator
    raise e.parent
  File "D:\ProgramFiles\Anaconda3\lib\site-packages\django_redis\client\default.py", line 471, in has_key
    return client.exists(key)
  File "D:\ProgramFiles\Anaconda3\lib\site-packages\redis\client.py", line 951, in exists
    return self.execute_command('EXISTS', name)
  File "D:\ProgramFiles\Anaconda3\lib\site-packages\redis\client.py", line 673, in execute_command
    connection.send_command(*args)
  File "D:\ProgramFiles\Anaconda3\lib\site-packages\redis\connection.py", line 610, in send_command
    self.send_packed_command(self.pack_command(*args))
  File "D:\ProgramFiles\Anaconda3\lib\site-packages\redis\connection.py", line 585, in send_packed_command
    self.connect()
  File "D:\ProgramFiles\Anaconda3\lib\site-packages\redis\connection.py", line 489, in connect
    raise ConnectionError(self._error_message(e))
redis.exceptions.ConnectionError: Error 10061 connecting to None:6379. ÓÉÓÚÄ¿±ê¼ÆËã»ú»ý¼«¾Ü¾ø£¬ÎÞ·¨Á¬½Ó¡£.
wsgi.py[2018-09-13 15:44:19][INFO]£º200 POST /user/login/ (192.168.2.204) 4194.25ms
exception.py[2018-09-13 15:44:23][ERROR]£ºInternal Server Error: /user/login/
Traceback (most recent call last):
  File "D:\ProgramFiles\Anaconda3\lib\site-packages\django_redis\cache.py", line 33, in _decorator
    return method(self, *args, **kwargs)
  File "D:\ProgramFiles\Anaconda3\lib\site-packages\django_redis\cache.py", line 125, in has_key
    return self.client.has_key(*args, **kwargs)
  File "D:\ProgramFiles\Anaconda3\lib\site-packages\django_redis\client\default.py", line 473, in has_key
    raise ConnectionInterrupted(connection=client, parent=e)
django_redis.exceptions.ConnectionInterrupted: Redis ConnectionError: Error 10061 connecting to None:6379. ÓÉÓÚÄ¿±ê¼ÆËã»ú»ý¼«¾Ü¾ø£¬ÎÞ·¨Á¬½Ó¡£.

During handling of the above exception, another exception occurred:

Traceback (most recent call last):
  File "D:\ProgramFiles\Anaconda3\lib\site-packages\django-1.11.8-py3.6.egg\django\core\handlers\base.py", line 131, in get_response
    response = middleware_method(request, response)
  File "D:\ProgramFiles\Anaconda3\lib\site-packages\django-1.11.8-py3.6.egg\django\contrib\sessions\middleware.py", line 58, in process_response
    request.session.save()
  File "D:\ProgramFiles\Anaconda3\lib\site-packages\django-1.11.8-py3.6.egg\django\contrib\sessions\backends\cache.py", line 57, in save
    return self.create()
  File "D:\ProgramFiles\Anaconda3\lib\site-packages\django-1.11.8-py3.6.egg\django\contrib\sessions\backends\cache.py", line 44, in create
    self._session_key = self._get_new_session_key()
  File "D:\ProgramFiles\Anaconda3\lib\site-packages\django-1.11.8-py3.6.egg\django\contrib\sessions\backends\base.py", line 164, in _get_new_session_key
    if not self.exists(session_key):
  File "D:\ProgramFiles\Anaconda3\lib\site-packages\django-1.11.8-py3.6.egg\django\contrib\sessions\backends\cache.py", line 71, in exists
    return session_key and (self.cache_key_prefix + session_key) in self._cache
  File "D:\ProgramFiles\Anaconda3\lib\site-packages\django-1.11.8-py3.6.egg\django\core\cache\backends\base.py", line 203, in __contains__
    return self.has_key(key)
  File "D:\ProgramFiles\Anaconda3\lib\site-packages\django_redis\cache.py", line 40, in _decorator
    raise e.parent
  File "D:\ProgramFiles\Anaconda3\lib\site-packages\django_redis\client\default.py", line 471, in has_key
    return client.exists(key)
  File "D:\ProgramFiles\Anaconda3\lib\site-packages\redis\client.py", line 951, in exists
    return self.execute_command('EXISTS', name)
  File "D:\ProgramFiles\Anaconda3\lib\site-packages\redis\client.py", line 673, in execute_command
    connection.send_command(*args)
  File "D:\ProgramFiles\Anaconda3\lib\site-packages\redis\connection.py", line 610, in send_command
    self.send_packed_command(self.pack_command(*args))
  File "D:\ProgramFiles\Anaconda3\lib\site-packages\redis\connection.py", line 585, in send_packed_command
    self.connect()
  File "D:\ProgramFiles\Anaconda3\lib\site-packages\redis\connection.py", line 489, in connect
    raise ConnectionError(self._error_message(e))
redis.exceptions.ConnectionError: Error 10061 connecting to None:6379. ÓÉÓÚÄ¿±ê¼ÆËã»ú»ý¼«¾Ü¾ø£¬ÎÞ·¨Á¬½Ó¡£.
wsgi.py[2018-09-13 15:44:23][INFO]£º200 POST /user/login/ (192.168.2.204) 4047.97ms
exception.py[2018-09-13 15:44:27][ERROR]£ºInternal Server Error: /user/login/
Traceback (most recent call last):
  File "D:\ProgramFiles\Anaconda3\lib\site-packages\django_redis\cache.py", line 33, in _decorator
    return method(self, *args, **kwargs)
  File "D:\ProgramFiles\Anaconda3\lib\site-packages\django_redis\cache.py", line 125, in has_key
    return self.client.has_key(*args, **kwargs)
  File "D:\ProgramFiles\Anaconda3\lib\site-packages\django_redis\client\default.py", line 473, in has_key
    raise ConnectionInterrupted(connection=client, parent=e)
django_redis.exceptions.ConnectionInterrupted: Redis ConnectionError: Error 10061 connecting to None:6379. ÓÉÓÚÄ¿±ê¼ÆËã»ú»ý¼«¾Ü¾ø£¬ÎÞ·¨Á¬½Ó¡£.

During handling of the above exception, another exception occurred:

Traceback (most recent call last):
  File "D:\ProgramFiles\Anaconda3\lib\site-packages\django-1.11.8-py3.6.egg\django\core\handlers\base.py", line 131, in get_response
    response = middleware_method(request, response)
  File "D:\ProgramFiles\Anaconda3\lib\site-packages\django-1.11.8-py3.6.egg\django\contrib\sessions\middleware.py", line 58, in process_response
    request.session.save()
  File "D:\ProgramFiles\Anaconda3\lib\site-packages\django-1.11.8-py3.6.egg\django\contrib\sessions\backends\cache.py", line 57, in save
    return self.create()
  File "D:\ProgramFiles\Anaconda3\lib\site-packages\django-1.11.8-py3.6.egg\django\contrib\sessions\backends\cache.py", line 44, in create
    self._session_key = self._get_new_session_key()
  File "D:\ProgramFiles\Anaconda3\lib\site-packages\django-1.11.8-py3.6.egg\django\contrib\sessions\backends\base.py", line 164, in _get_new_session_key
    if not self.exists(session_key):
  File "D:\ProgramFiles\Anaconda3\lib\site-packages\django-1.11.8-py3.6.egg\django\contrib\sessions\backends\cache.py", line 71, in exists
    return session_key and (self.cache_key_prefix + session_key) in self._cache
  File "D:\ProgramFiles\Anaconda3\lib\site-packages\django-1.11.8-py3.6.egg\django\core\cache\backends\base.py", line 203, in __contains__
    return self.has_key(key)
  File "D:\ProgramFiles\Anaconda3\lib\site-packages\django_redis\cache.py", line 40, in _decorator
    raise e.parent
  File "D:\ProgramFiles\Anaconda3\lib\site-packages\django_redis\client\default.py", line 471, in has_key
    return client.exists(key)
  File "D:\ProgramFiles\Anaconda3\lib\site-packages\redis\client.py", line 951, in exists
    return self.execute_command('EXISTS', name)
  File "D:\ProgramFiles\Anaconda3\lib\site-packages\redis\client.py", line 673, in execute_command
    connection.send_command(*args)
  File "D:\ProgramFiles\Anaconda3\lib\site-packages\redis\connection.py", line 610, in send_command
    self.send_packed_command(self.pack_command(*args))
  File "D:\ProgramFiles\Anaconda3\lib\site-packages\redis\connection.py", line 585, in send_packed_command
    self.connect()
  File "D:\ProgramFiles\Anaconda3\lib\site-packages\redis\connection.py", line 489, in connect
    raise ConnectionError(self._error_message(e))
redis.exceptions.ConnectionError: Error 10061 connecting to None:6379. ÓÉÓÚÄ¿±ê¼ÆËã»ú»ý¼«¾Ü¾ø£¬ÎÞ·¨Á¬½Ó¡£.
wsgi.py[2018-09-13 15:44:28][INFO]£º200 POST /user/login/ (192.168.2.204) 4051.98ms
wsgi.py[2018-09-13 15:44:28][INFO]£º200 POST /user/login/ (192.168.2.204) 4.09ms
wsgi.py[2018-09-13 15:44:28][INFO]£º200 GET /user/register/ (192.168.2.204) 51.06ms
web.py[2018-09-13 15:44:28][INFO]£º200 GET /static/css/layui.css (192.168.2.204) 3.01ms
web.py[2018-09-13 15:44:28][INFO]£º200 GET /static/js/jquery.min(1).js (192.168.2.204) 4.01ms
wsgi.py[2018-09-13 15:44:28][INFO]£º200 GET /captcha/image/c138fd56aaa1a44c4e18dbf332fe3de7d0786c76/ (192.168.2.204) 14.04ms
web.py[2018-09-13 15:44:28][INFO]£º200 GET /favicon.ico (192.168.2.204) 1.00ms
wsgi.py[2018-09-13 15:44:29][INFO]£º200 GET /captcha/refresh/ (192.168.2.204) 36.10ms
wsgi.py[2018-09-13 15:44:29][INFO]£º200 GET /captcha/image/e1305e09f7b4aa974a0d36faa89c91b631a398b0/ (192.168.2.204) 7.02ms
wsgi.py[2018-09-13 15:44:33][INFO]£º200 GET / (192.168.2.204) 7.02ms
wsgi.py[2018-09-13 15:44:39][INFO]£º200 POST /user/login/ (192.168.2.204) 7.06ms
exception.py[2018-09-13 15:44:55][ERROR]£ºInternal Server Error: /user/login/
Traceback (most recent call last):
  File "D:\ProgramFiles\Anaconda3\lib\site-packages\django_redis\cache.py", line 33, in _decorator
    return method(self, *args, **kwargs)
  File "D:\ProgramFiles\Anaconda3\lib\site-packages\django_redis\cache.py", line 125, in has_key
    return self.client.has_key(*args, **kwargs)
  File "D:\ProgramFiles\Anaconda3\lib\site-packages\django_redis\client\default.py", line 473, in has_key
    raise ConnectionInterrupted(connection=client, parent=e)
django_redis.exceptions.ConnectionInterrupted: Redis ConnectionError: Error 10061 connecting to None:6379. ÓÉÓÚÄ¿±ê¼ÆËã»ú»ý¼«¾Ü¾ø£¬ÎÞ·¨Á¬½Ó¡£.

During handling of the above exception, another exception occurred:

Traceback (most recent call last):
  File "D:\ProgramFiles\Anaconda3\lib\site-packages\django-1.11.8-py3.6.egg\django\core\handlers\base.py", line 131, in get_response
    response = middleware_method(request, response)
  File "D:\ProgramFiles\Anaconda3\lib\site-packages\django-1.11.8-py3.6.egg\django\contrib\sessions\middleware.py", line 58, in process_response
    request.session.save()
  File "D:\ProgramFiles\Anaconda3\lib\site-packages\django-1.11.8-py3.6.egg\django\contrib\sessions\backends\cache.py", line 57, in save
    return self.create()
  File "D:\ProgramFiles\Anaconda3\lib\site-packages\django-1.11.8-py3.6.egg\django\contrib\sessions\backends\cache.py", line 44, in create
    self._session_key = self._get_new_session_key()
  File "D:\ProgramFiles\Anaconda3\lib\site-packages\django-1.11.8-py3.6.egg\django\contrib\sessions\backends\base.py", line 164, in _get_new_session_key
    if not self.exists(session_key):
  File "D:\ProgramFiles\Anaconda3\lib\site-packages\django-1.11.8-py3.6.egg\django\contrib\sessions\backends\cache.py", line 71, in exists
    return session_key and (self.cache_key_prefix + session_key) in self._cache
  File "D:\ProgramFiles\Anaconda3\lib\site-packages\django-1.11.8-py3.6.egg\django\core\cache\backends\base.py", line 203, in __contains__
    return self.has_key(key)
  File "D:\ProgramFiles\Anaconda3\lib\site-packages\django_redis\cache.py", line 40, in _decorator
    raise e.parent
  File "D:\ProgramFiles\Anaconda3\lib\site-packages\django_redis\client\default.py", line 471, in has_key
    return client.exists(key)
  File "D:\ProgramFiles\Anaconda3\lib\site-packages\redis\client.py", line 951, in exists
    return self.execute_command('EXISTS', name)
  File "D:\ProgramFiles\Anaconda3\lib\site-packages\redis\client.py", line 673, in execute_command
    connection.send_command(*args)
  File "D:\ProgramFiles\Anaconda3\lib\site-packages\redis\connection.py", line 610, in send_command
    self.send_packed_command(self.pack_command(*args))
  File "D:\ProgramFiles\Anaconda3\lib\site-packages\redis\connection.py", line 585, in send_packed_command
    self.connect()
  File "D:\ProgramFiles\Anaconda3\lib\site-packages\redis\connection.py", line 489, in connect
    raise ConnectionError(self._error_message(e))
redis.exceptions.ConnectionError: Error 10061 connecting to None:6379. ÓÉÓÚÄ¿±ê¼ÆËã»ú»ý¼«¾Ü¾ø£¬ÎÞ·¨Á¬½Ó¡£.
wsgi.py[2018-09-13 15:44:55][INFO]£º200 POST /user/login/ (192.168.2.204) 4048.91ms
exception.py[2018-09-13 15:44:59][ERROR]£ºInternal Server Error: /user/login/
Traceback (most recent call last):
  File "D:\ProgramFiles\Anaconda3\lib\site-packages\django_redis\cache.py", line 33, in _decorator
    return method(self, *args, **kwargs)
  File "D:\ProgramFiles\Anaconda3\lib\site-packages\django_redis\cache.py", line 125, in has_key
    return self.client.has_key(*args, **kwargs)
  File "D:\ProgramFiles\Anaconda3\lib\site-packages\django_redis\client\default.py", line 473, in has_key
    raise ConnectionInterrupted(connection=client, parent=e)
django_redis.exceptions.ConnectionInterrupted: Redis ConnectionError: Error 10061 connecting to None:6379. ÓÉÓÚÄ¿±ê¼ÆËã»ú»ý¼«¾Ü¾ø£¬ÎÞ·¨Á¬½Ó¡£.

During handling of the above exception, another exception occurred:

Traceback (most recent call last):
  File "D:\ProgramFiles\Anaconda3\lib\site-packages\django-1.11.8-py3.6.egg\django\core\handlers\base.py", line 131, in get_response
    response = middleware_method(request, response)
  File "D:\ProgramFiles\Anaconda3\lib\site-packages\django-1.11.8-py3.6.egg\django\contrib\sessions\middleware.py", line 58, in process_response
    request.session.save()
  File "D:\ProgramFiles\Anaconda3\lib\site-packages\django-1.11.8-py3.6.egg\django\contrib\sessions\backends\cache.py", line 57, in save
    return self.create()
  File "D:\ProgramFiles\Anaconda3\lib\site-packages\django-1.11.8-py3.6.egg\django\contrib\sessions\backends\cache.py", line 44, in create
    self._session_key = self._get_new_session_key()
  File "D:\ProgramFiles\Anaconda3\lib\site-packages\django-1.11.8-py3.6.egg\django\contrib\sessions\backends\base.py", line 164, in _get_new_session_key
    if not self.exists(session_key):
  File "D:\ProgramFiles\Anaconda3\lib\site-packages\django-1.11.8-py3.6.egg\django\contrib\sessions\backends\cache.py", line 71, in exists
    return session_key and (self.cache_key_prefix + session_key) in self._cache
  File "D:\ProgramFiles\Anaconda3\lib\site-packages\django-1.11.8-py3.6.egg\django\core\cache\backends\base.py", line 203, in __contains__
    return self.has_key(key)
  File "D:\ProgramFiles\Anaconda3\lib\site-packages\django_redis\cache.py", line 40, in _decorator
    raise e.parent
  File "D:\ProgramFiles\Anaconda3\lib\site-packages\django_redis\client\default.py", line 471, in has_key
    return client.exists(key)
  File "D:\ProgramFiles\Anaconda3\lib\site-packages\redis\client.py", line 951, in exists
    return self.execute_command('EXISTS', name)
  File "D:\ProgramFiles\Anaconda3\lib\site-packages\redis\client.py", line 673, in execute_command
    connection.send_command(*args)
  File "D:\ProgramFiles\Anaconda3\lib\site-packages\redis\connection.py", line 610, in send_command
    self.send_packed_command(self.pack_command(*args))
  File "D:\ProgramFiles\Anaconda3\lib\site-packages\redis\connection.py", line 585, in send_packed_command
    self.connect()
  File "D:\ProgramFiles\Anaconda3\lib\site-packages\redis\connection.py", line 489, in connect
    raise ConnectionError(self._error_message(e))
redis.exceptions.ConnectionError: Error 10061 connecting to None:6379. ÓÉÓÚÄ¿±ê¼ÆËã»ú»ý¼«¾Ü¾ø£¬ÎÞ·¨Á¬½Ó¡£.
wsgi.py[2018-09-13 15:44:59][INFO]£º200 POST /user/login/ (192.168.2.204) 4050.53ms
exception.py[2018-09-13 15:45:03][ERROR]£ºInternal Server Error: /user/login/
Traceback (most recent call last):
  File "D:\ProgramFiles\Anaconda3\lib\site-packages\django_redis\cache.py", line 33, in _decorator
    return method(self, *args, **kwargs)
  File "D:\ProgramFiles\Anaconda3\lib\site-packages\django_redis\cache.py", line 125, in has_key
    return self.client.has_key(*args, **kwargs)
  File "D:\ProgramFiles\Anaconda3\lib\site-packages\django_redis\client\default.py", line 473, in has_key
    raise ConnectionInterrupted(connection=client, parent=e)
django_redis.exceptions.ConnectionInterrupted: Redis ConnectionError: Error 10061 connecting to None:6379. ÓÉÓÚÄ¿±ê¼ÆËã»ú»ý¼«¾Ü¾ø£¬ÎÞ·¨Á¬½Ó¡£.

During handling of the above exception, another exception occurred:

Traceback (most recent call last):
  File "D:\ProgramFiles\Anaconda3\lib\site-packages\django-1.11.8-py3.6.egg\django\core\handlers\base.py", line 131, in get_response
    response = middleware_method(request, response)
  File "D:\ProgramFiles\Anaconda3\lib\site-packages\django-1.11.8-py3.6.egg\django\contrib\sessions\middleware.py", line 58, in process_response
    request.session.save()
  File "D:\ProgramFiles\Anaconda3\lib\site-packages\django-1.11.8-py3.6.egg\django\contrib\sessions\backends\cache.py", line 57, in save
    return self.create()
  File "D:\ProgramFiles\Anaconda3\lib\site-packages\django-1.11.8-py3.6.egg\django\contrib\sessions\backends\cache.py", line 44, in create
    self._session_key = self._get_new_session_key()
  File "D:\ProgramFiles\Anaconda3\lib\site-packages\django-1.11.8-py3.6.egg\django\contrib\sessions\backends\base.py", line 164, in _get_new_session_key
    if not self.exists(session_key):
  File "D:\ProgramFiles\Anaconda3\lib\site-packages\django-1.11.8-py3.6.egg\django\contrib\sessions\backends\cache.py", line 71, in exists
    return session_key and (self.cache_key_prefix + session_key) in self._cache
  File "D:\ProgramFiles\Anaconda3\lib\site-packages\django-1.11.8-py3.6.egg\django\core\cache\backends\base.py", line 203, in __contains__
    return self.has_key(key)
  File "D:\ProgramFiles\Anaconda3\lib\site-packages\django_redis\cache.py", line 40, in _decorator
    raise e.parent
  File "D:\ProgramFiles\Anaconda3\lib\site-packages\django_redis\client\default.py", line 471, in has_key
    return client.exists(key)
  File "D:\ProgramFiles\Anaconda3\lib\site-packages\redis\client.py", line 951, in exists
    return self.execute_command('EXISTS', name)
  File "D:\ProgramFiles\Anaconda3\lib\site-packages\redis\client.py", line 673, in execute_command
    connection.send_command(*args)
  File "D:\ProgramFiles\Anaconda3\lib\site-packages\redis\connection.py", line 610, in send_command
    self.send_packed_command(self.pack_command(*args))
  File "D:\ProgramFiles\Anaconda3\lib\site-packages\redis\connection.py", line 585, in send_packed_command
    self.connect()
  File "D:\ProgramFiles\Anaconda3\lib\site-packages\redis\connection.py", line 489, in connect
    raise ConnectionError(self._error_message(e))
redis.exceptions.ConnectionError: Error 10061 connecting to None:6379. ÓÉÓÚÄ¿±ê¼ÆËã»ú»ý¼«¾Ü¾ø£¬ÎÞ·¨Á¬½Ó¡£.
wsgi.py[2018-09-13 15:45:03][INFO]£º200 POST /user/login/ (192.168.2.204) 4037.57ms
exception.py[2018-09-13 15:45:07][ERROR]£ºInternal Server Error: /user/login/
Traceback (most recent call last):
  File "D:\ProgramFiles\Anaconda3\lib\site-packages\django_redis\cache.py", line 33, in _decorator
    return method(self, *args, **kwargs)
  File "D:\ProgramFiles\Anaconda3\lib\site-packages\django_redis\cache.py", line 125, in has_key
    return self.client.has_key(*args, **kwargs)
  File "D:\ProgramFiles\Anaconda3\lib\site-packages\django_redis\client\default.py", line 473, in has_key
    raise ConnectionInterrupted(connection=client, parent=e)
django_redis.exceptions.ConnectionInterrupted: Redis ConnectionError: Error 10061 connecting to None:6379. ÓÉÓÚÄ¿±ê¼ÆËã»ú»ý¼«¾Ü¾ø£¬ÎÞ·¨Á¬½Ó¡£.

During handling of the above exception, another exception occurred:

Traceback (most recent call last):
  File "D:\ProgramFiles\Anaconda3\lib\site-packages\django-1.11.8-py3.6.egg\django\core\handlers\base.py", line 131, in get_response
    response = middleware_method(request, response)
  File "D:\ProgramFiles\Anaconda3\lib\site-packages\django-1.11.8-py3.6.egg\django\contrib\sessions\middleware.py", line 58, in process_response
    request.session.save()
  File "D:\ProgramFiles\Anaconda3\lib\site-packages\django-1.11.8-py3.6.egg\django\contrib\sessions\backends\cache.py", line 57, in save
    return self.create()
  File "D:\ProgramFiles\Anaconda3\lib\site-packages\django-1.11.8-py3.6.egg\django\contrib\sessions\backends\cache.py", line 44, in create
    self._session_key = self._get_new_session_key()
  File "D:\ProgramFiles\Anaconda3\lib\site-packages\django-1.11.8-py3.6.egg\django\contrib\sessions\backends\base.py", line 164, in _get_new_session_key
    if not self.exists(session_key):
  File "D:\ProgramFiles\Anaconda3\lib\site-packages\django-1.11.8-py3.6.egg\django\contrib\sessions\backends\cache.py", line 71, in exists
    return session_key and (self.cache_key_prefix + session_key) in self._cache
  File "D:\ProgramFiles\Anaconda3\lib\site-packages\django-1.11.8-py3.6.egg\django\core\cache\backends\base.py", line 203, in __contains__
    return self.has_key(key)
  File "D:\ProgramFiles\Anaconda3\lib\site-packages\django_redis\cache.py", line 40, in _decorator
    raise e.parent
  File "D:\ProgramFiles\Anaconda3\lib\site-packages\django_redis\client\default.py", line 471, in has_key
    return client.exists(key)
  File "D:\ProgramFiles\Anaconda3\lib\site-packages\redis\client.py", line 951, in exists
    return self.execute_command('EXISTS', name)
  File "D:\ProgramFiles\Anaconda3\lib\site-packages\redis\client.py", line 673, in execute_command
    connection.send_command(*args)
  File "D:\ProgramFiles\Anaconda3\lib\site-packages\redis\connection.py", line 610, in send_command
    self.send_packed_command(self.pack_command(*args))
  File "D:\ProgramFiles\Anaconda3\lib\site-packages\redis\connection.py", line 585, in send_packed_command
    self.connect()
  File "D:\ProgramFiles\Anaconda3\lib\site-packages\redis\connection.py", line 489, in connect
    raise ConnectionError(self._error_message(e))
redis.exceptions.ConnectionError: Error 10061 connecting to None:6379. ÓÉÓÚÄ¿±ê¼ÆËã»ú»ý¼«¾Ü¾ø£¬ÎÞ·¨Á¬½Ó¡£.
wsgi.py[2018-09-13 15:45:07][INFO]£º200 POST /user/login/ (192.168.2.204) 4052.19ms
wsgi.py[2018-09-13 15:46:52][INFO]£º200 GET / (192.168.2.204) 170.45ms
web.py[2018-09-13 15:46:52][INFO]£º304 GET /static/css/style.css (192.168.2.204) 430.17ms
web.py[2018-09-13 15:47:37][INFO]£º200 GET /static/images/next-horizontal.png (192.168.2.204) 3.01ms
web.py[2018-09-13 15:47:37][INFO]£º200 GET /static/images/prev-horizontal.png (192.168.2.204) 1.00ms
wsgi.py[2018-09-13 15:47:40][INFO]£º200 GET / (192.168.2.204) 155.44ms
wsgi.py[2018-09-13 15:47:50][INFO]£º200 GET / (192.168.2.204) 5.01ms
wsgi.py[2018-09-13 15:52:01][INFO]£º200 GET / (192.168.2.204) 169.45ms
web.py[2018-09-13 15:52:01][INFO]£º200 GET /static/kairui.ico (192.168.2.204) 467.27ms
wsgi.py[2018-09-13 15:52:29][INFO]£º200 GET / (192.168.2.204) 14.04ms
web.py[2018-09-13 15:52:29][INFO]£º200 GET /static/kairui.ico (192.168.2.204) 1.00ms
wsgi.py[2018-09-13 15:52:39][INFO]£º200 GET / (192.168.2.204) 11.03ms
web.py[2018-09-13 15:52:40][INFO]£º200 GET /static/kairui.ico (192.168.2.204) 1.00ms
wsgi.py[2018-09-13 15:54:09][INFO]£º200 GET / (192.168.2.204) 167.44ms
web.py[2018-09-13 15:54:09][INFO]£º200 GET /static/kairui.ico (192.168.2.204) 470.28ms
wsgi.py[2018-09-13 15:59:39][INFO]£º200 GET / (192.168.2.204) 147.80ms
web.py[2018-09-13 15:59:40][INFO]£º200 GET /static/kairui.ico (192.168.2.204) 476.26ms
wsgi.py[2018-09-13 15:59:46][INFO]£º200 GET / (192.168.2.204) 19.02ms
web.py[2018-09-13 15:59:46][INFO]£º200 GET /static/kairui.ico (192.168.2.204) 1.00ms
wsgi.py[2018-09-13 16:01:06][INFO]£º200 GET / (192.168.2.204) 7.02ms
wsgi.py[2018-09-13 16:01:08][INFO]£º200 GET / (192.168.2.204) 162.17ms
wsgi.py[2018-09-13 16:02:53][INFO]£º200 GET / (192.168.2.204) 153.35ms
wsgi.py[2018-09-13 16:02:55][INFO]£º200 GET / (192.168.2.204) 165.44ms
wsgi.py[2018-09-13 16:04:51][INFO]£º200 GET / (192.168.2.204) 160.82ms
wsgi.py[2018-09-13 16:04:52][INFO]£º200 GET / (192.168.2.204) 179.50ms
wsgi.py[2018-09-13 16:06:25][INFO]£º200 GET / (192.168.2.204) 149.42ms
wsgi.py[2018-09-13 16:06:26][INFO]£º200 GET / (192.168.2.204) 196.52ms
wsgi.py[2018-09-13 16:06:27][INFO]£º200 GET / (192.168.2.204) 150.06ms
wsgi.py[2018-09-13 16:06:28][INFO]£º200 GET / (192.168.2.204) 8.02ms
wsgi.py[2018-09-13 16:18:54][INFO]£º200 GET / (192.168.2.204) 168.45ms
wsgi.py[2018-09-13 16:18:56][INFO]£º200 GET / (192.168.2.204) 195.53ms
wsgi.py[2018-09-13 16:18:57][INFO]£º200 GET / (192.168.2.204) 6.98ms
exception.py[2018-09-13 18:06:17][ERROR]£ºInternal Server Error: /cfmmc/huice/y1000/
Traceback (most recent call last):
  File "D:\ProgramFiles\Anaconda3\lib\site-packages\django-1.11.8-py3.6.egg\django\core\handlers\exception.py", line 41, in inner
    response = get_response(request)
  File "D:\ProgramFiles\Anaconda3\lib\site-packages\django-1.11.8-py3.6.egg\django\core\handlers\base.py", line 249, in _legacy_get_response
    response = self._get_response(request)
  File "D:\ProgramFiles\Anaconda3\lib\site-packages\django-1.11.8-py3.6.egg\django\core\handlers\base.py", line 187, in _get_response
    response = self.process_exception_by_middleware(e, request)
  File "D:\ProgramFiles\Anaconda3\lib\site-packages\django-1.11.8-py3.6.egg\django\core\handlers\base.py", line 185, in _get_response
    response = wrapped_callback(request, *callback_args, **callback_kwargs)
  File "D:\tools\Tools\Carry\mysite\views.py", line 2257, in cfmmc_huice
    hc, hcd, huizong, init_money = viewUtil.cfmmc_hc_data(host, start_date, end_date)
  File "D:\tools\Tools\Carry\mysite\viewUtil.py", line 668, in cfmmc_hc_data
    hc, huizong = HSD.huices(res, huizong, init_money, rq_date, end_date, pinzhong)
  File "D:\tools\Tools\Carry\mysite\HSD.py", line 1308, in huices
    this_ccsj = (pinzhong[code_index[j[7]]][j[1][:-3]] - pinzhong[code_index[j[7]]][j[0][:-3]])*j[6]
KeyError: '2018-09-13 21:24'
base.py[2018-09-13 18:06:30][WARNING]£ºNot Found: /favicon.ico
exception.py[2018-09-13 18:08:37][ERROR]£ºInternal Server Error: /cfmmc/huice/
Traceback (most recent call last):
  File "D:\ProgramFiles\Anaconda3\lib\site-packages\django-1.11.8-py3.6.egg\django\core\handlers\exception.py", line 41, in inner
    response = get_response(request)
  File "D:\ProgramFiles\Anaconda3\lib\site-packages\django-1.11.8-py3.6.egg\django\core\handlers\base.py", line 249, in _legacy_get_response
    response = self._get_response(request)
  File "D:\ProgramFiles\Anaconda3\lib\site-packages\django-1.11.8-py3.6.egg\django\core\handlers\base.py", line 187, in _get_response
    response = self.process_exception_by_middleware(e, request)
  File "D:\ProgramFiles\Anaconda3\lib\site-packages\django-1.11.8-py3.6.egg\django\core\handlers\base.py", line 185, in _get_response
    response = wrapped_callback(request, *callback_args, **callback_kwargs)
  File "D:\tools\Tools\Carry\mysite\views.py", line 2257, in cfmmc_huice
    hc, hcd, huizong, init_money = viewUtil.cfmmc_hc_data(host, start_date, end_date)
  File "D:\tools\Tools\Carry\mysite\viewUtil.py", line 668, in cfmmc_hc_data
    hc, huizong = HSD.huices(res, huizong, init_money, rq_date, end_date, pinzhong)
  File "D:\tools\Tools\Carry\mysite\HSD.py", line 1308, in huices
    this_ccsj = (pinzhong[code_index[j[7]]][j[1][:-3]] - pinzhong[code_index[j[7]]][j[0][:-3]])*j[6]
KeyError: '2018-09-13 21:24'
exception.py[2018-09-13 18:53:31][ERROR]£ºInternal Server Error: /cfmmc/huice/
Traceback (most recent call last):
  File "D:\ProgramFiles\Anaconda3\lib\site-packages\django-1.11.8-py3.6.egg\django\core\handlers\exception.py", line 41, in inner
    response = get_response(request)
  File "D:\ProgramFiles\Anaconda3\lib\site-packages\django-1.11.8-py3.6.egg\django\core\handlers\base.py", line 249, in _legacy_get_response
    response = self._get_response(request)
  File "D:\ProgramFiles\Anaconda3\lib\site-packages\django-1.11.8-py3.6.egg\django\core\handlers\base.py", line 187, in _get_response
    response = self.process_exception_by_middleware(e, request)
  File "D:\ProgramFiles\Anaconda3\lib\site-packages\django-1.11.8-py3.6.egg\django\core\handlers\base.py", line 185, in _get_response
    response = wrapped_callback(request, *callback_args, **callback_kwargs)
  File "D:\tools\Tools\Carry\mysite\views.py", line 2257, in cfmmc_huice
    hc, hcd, huizong, init_money = viewUtil.cfmmc_hc_data(host, start_date, end_date)
  File "D:\tools\Tools\Carry\mysite\viewUtil.py", line 602, in cfmmc_hc_data
    results2 = HSD.cfmmc_get_result(host, rq_date, end_date)
  File "D:\tools\Tools\Carry\mysite\HSD.py", line 2042, in cfmmc_get_result
    _d = [host, i[0], dc[i[1]], i[2], dc[i[3]], i[4], i[5], '¿Õ' if 'Âò' in i[6] else '¶à', i[7], i[8]]
KeyError: '00231017'
exception.py[2018-09-13 18:54:10][ERROR]£ºInternal Server Error: /cfmmc/huice/
Traceback (most recent call last):
  File "D:\ProgramFiles\Anaconda3\lib\site-packages\django-1.11.8-py3.6.egg\django\core\handlers\exception.py", line 41, in inner
    response = get_response(request)
  File "D:\ProgramFiles\Anaconda3\lib\site-packages\django-1.11.8-py3.6.egg\django\core\handlers\base.py", line 249, in _legacy_get_response
    response = self._get_response(request)
  File "D:\ProgramFiles\Anaconda3\lib\site-packages\django-1.11.8-py3.6.egg\django\core\handlers\base.py", line 187, in _get_response
    response = self.process_exception_by_middleware(e, request)
  File "D:\ProgramFiles\Anaconda3\lib\site-packages\django-1.11.8-py3.6.egg\django\core\handlers\base.py", line 185, in _get_response
    response = wrapped_callback(request, *callback_args, **callback_kwargs)
  File "D:\tools\Tools\Carry\mysite\views.py", line 2257, in cfmmc_huice
    hc, hcd, huizong, init_money = viewUtil.cfmmc_hc_data(host, start_date, end_date)
  File "D:\tools\Tools\Carry\mysite\viewUtil.py", line 602, in cfmmc_hc_data
    results2 = HSD.cfmmc_get_result(host, rq_date, end_date)
  File "D:\tools\Tools\Carry\mysite\HSD.py", line 2042, in cfmmc_get_result
    _d = [host, i[0], dc[i[1]], i[2], dc[i[3]], i[4], i[5], '¿Õ' if 'Âò' in i[6] else '¶à', i[7], i[8]]
KeyError: '00455860'
exception.py[2018-09-14 10:18:30][ERROR]£ºInternal Server Error: /cfmmc/bs/m1001_J1901_1M/
Traceback (most recent call last):
  File "D:\ProgramFiles\Anaconda3\lib\site-packages\django-1.11.8-py3.6.egg\django\core\handlers\exception.py", line 41, in inner
    response = get_response(request)
  File "D:\ProgramFiles\Anaconda3\lib\site-packages\django-1.11.8-py3.6.egg\django\core\handlers\base.py", line 249, in _legacy_get_response
    response = self._get_response(request)
  File "D:\ProgramFiles\Anaconda3\lib\site-packages\django-1.11.8-py3.6.egg\django\core\handlers\base.py", line 187, in _get_response
    response = self.process_exception_by_middleware(e, request)
  File "D:\ProgramFiles\Anaconda3\lib\site-packages\django-1.11.8-py3.6.egg\django\core\handlers\base.py", line 185, in _get_response
    response = wrapped_callback(request, *callback_args, **callback_kwargs)
  File "D:\tools\Tools\Carry\mysite\views.py", line 2172, in cfmmc_bs
    data2.append(data3.send(i))
  File "D:\tools\Tools\Carry\mysite\viewUtil.py", line 808, in future_macd
    da2 = [_t, _o, _c, _l, _h, da[i][5], 0, round(dc[i]['macd'], 2), round(dc[i]['diff'], 2), round(dc[i]['dea'], 2)]
IndexError: list index out of range
base.py[2018-09-14 10:18:30][WARNING]£ºNot Found: /favicon.ico
exception.py[2018-09-14 10:43:20][ERROR]£ºInternal Server Error: /cfmmc/bs/m1001_J1901_1M/
Traceback (most recent call last):
  File "D:\ProgramFiles\Anaconda3\lib\site-packages\django-1.11.8-py3.6.egg\django\core\handlers\exception.py", line 41, in inner
    response = get_response(request)
  File "D:\ProgramFiles\Anaconda3\lib\site-packages\django-1.11.8-py3.6.egg\django\core\handlers\base.py", line 249, in _legacy_get_response
    response = self._get_response(request)
  File "D:\ProgramFiles\Anaconda3\lib\site-packages\django-1.11.8-py3.6.egg\django\core\handlers\base.py", line 187, in _get_response
    response = self.process_exception_by_middleware(e, request)
  File "D:\ProgramFiles\Anaconda3\lib\site-packages\django-1.11.8-py3.6.egg\django\core\handlers\base.py", line 185, in _get_response
    response = wrapped_callback(request, *callback_args, **callback_kwargs)
  File "D:\tools\Tools\Carry\mysite\views.py", line 2172, in cfmmc_bs
    data2.append(data3.send(i))
  File "D:\tools\Tools\Carry\mysite\viewUtil.py", line 808, in future_macd
    da2 = [_t, _o, _c, _l, _h, da[i][5], 0, round(dc[i]['macd'], 2), round(dc[i]['diff'], 2), round(dc[i]['dea'], 2)]
IndexError: list index out of range
exception.py[2018-09-14 10:47:17][ERROR]£ºInternal Server Error: /cfmmc/bs/m1001_J1901_1M/
Traceback (most recent call last):
  File "D:\ProgramFiles\Anaconda3\lib\site-packages\django-1.11.8-py3.6.egg\django\core\handlers\exception.py", line 41, in inner
    response = get_response(request)
  File "D:\ProgramFiles\Anaconda3\lib\site-packages\django-1.11.8-py3.6.egg\django\core\handlers\base.py", line 249, in _legacy_get_response
    response = self._get_response(request)
  File "D:\ProgramFiles\Anaconda3\lib\site-packages\django-1.11.8-py3.6.egg\django\core\handlers\base.py", line 187, in _get_response
    response = self.process_exception_by_middleware(e, request)
  File "D:\ProgramFiles\Anaconda3\lib\site-packages\django-1.11.8-py3.6.egg\django\core\handlers\base.py", line 185, in _get_response
    response = wrapped_callback(request, *callback_args, **callback_kwargs)
  File "D:\tools\Tools\Carry\mysite\views.py", line 2173, in cfmmc_bs
    data2.append(data3.send(i))
  File "D:\tools\Tools\Carry\mysite\viewUtil.py", line 808, in future_macd
    da2 = [_t, _o, _c, _l, _h, da[i][5], 0, round(dc[i]['macd'], 2), round(dc[i]['diff'], 2), round(dc[i]['dea'], 2)]
IndexError: list index out of range
exception.py[2018-09-14 15:36:25][ERROR]£ºInternal Server Error: /cfmmc/bs/y1001_J1901/
Traceback (most recent call last):
  File "D:\ProgramFiles\Anaconda3\lib\site-packages\django-1.11.8-py3.6.egg\django\core\handlers\exception.py", line 41, in inner
    response = get_response(request)
  File "D:\ProgramFiles\Anaconda3\lib\site-packages\django-1.11.8-py3.6.egg\django\core\handlers\base.py", line 249, in _legacy_get_response
    response = self._get_response(request)
  File "D:\ProgramFiles\Anaconda3\lib\site-packages\django-1.11.8-py3.6.egg\django\core\handlers\base.py", line 187, in _get_response
    response = self.process_exception_by_middleware(e, request)
  File "D:\ProgramFiles\Anaconda3\lib\site-packages\django-1.11.8-py3.6.egg\django\core\handlers\base.py", line 185, in _get_response
    response = wrapped_callback(request, *callback_args, **callback_kwargs)
  File "D:\tools\Tools\Carry\mysite\views.py", line 2169, in cfmmc_bs
    for i,bs in data2bs:#data2:
  File "D:\tools\Tools\Carry\mysite\viewUtil.py", line 728, in future_data_cycle
    for j in data:
TypeError: 'NoneType' object is not iterable
base.py[2018-09-14 15:36:25][WARNING]£ºNot Found: /favicon.ico
exception.py[2018-09-14 15:47:48][ERROR]£ºInternal Server Error: /cfmmc/bs/y1000_RB1810/
Traceback (most recent call last):
  File "D:\ProgramFiles\Anaconda3\lib\site-packages\django-1.11.8-py3.6.egg\django\core\handlers\exception.py", line 41, in inner
    response = get_response(request)
  File "D:\ProgramFiles\Anaconda3\lib\site-packages\django-1.11.8-py3.6.egg\django\core\handlers\base.py", line 249, in _legacy_get_response
    response = self._get_response(request)
  File "D:\ProgramFiles\Anaconda3\lib\site-packages\django-1.11.8-py3.6.egg\django\core\handlers\base.py", line 187, in _get_response
    response = self.process_exception_by_middleware(e, request)
  File "D:\ProgramFiles\Anaconda3\lib\site-packages\django-1.11.8-py3.6.egg\django\core\handlers\base.py", line 185, in _get_response
    response = wrapped_callback(request, *callback_args, **callback_kwargs)
  File "D:\tools\Tools\Carry\mysite\views.py", line 2156, in cfmmc_bs
    for i,bs in data2bs:#data2:
  File "D:\tools\Tools\Carry\mysite\viewUtil.py", line 729, in future_data_cycle
    ts = j[0][:10]
TypeError: 'datetime.datetime' object is not subscriptable
exception.py[2018-09-14 16:45:22][ERROR]£ºInternal Server Error: /cfmmc/bs/m1000_RB1810/
Traceback (most recent call last):
  File "D:\ProgramFiles\Anaconda3\lib\site-packages\django-1.11.8-py3.6.egg\django\core\handlers\exception.py", line 41, in inner
    response = get_response(request)
  File "D:\ProgramFiles\Anaconda3\lib\site-packages\django-1.11.8-py3.6.egg\django\core\handlers\base.py", line 249, in _legacy_get_response
    response = self._get_response(request)
  File "D:\ProgramFiles\Anaconda3\lib\site-packages\django-1.11.8-py3.6.egg\django\core\handlers\base.py", line 187, in _get_response
    response = self.process_exception_by_middleware(e, request)
  File "D:\ProgramFiles\Anaconda3\lib\site-packages\django-1.11.8-py3.6.egg\django\core\handlers\base.py", line 185, in _get_response
    response = wrapped_callback(request, *callback_args, **callback_kwargs)
  File "D:\tools\Tools\Carry\mysite\views.py", line 2156, in cfmmc_bs
    for i,bs in data2bs:#data2:
  File "D:\tools\Tools\Carry\mysite\viewUtil.py", line 726, in future_data_cycle
    for j in data:
  File "D:\tools\Tools\Carry\mysite\HSD.py", line 324, in get_data
    for i in self.data_day(code, sd + day):
  File "D:\tools\Tools\Carry\mysite\HSD.py", line 299, in data_day
    data = self._coll.find({'datetime': {'$gte': date, '$lt': date + day}, 'code': code}, {sort: [['datetime',1]]},  # Model.find(condition, fields, {sort: [['_id', -1]]}, callback);
NameError: name 'sort' is not defined
exception.py[2018-09-14 16:45:37][ERROR]£ºInternal Server Error: /cfmmc/bs/m1000_RB1810/
Traceback (most recent call last):
  File "D:\ProgramFiles\Anaconda3\lib\site-packages\django-1.11.8-py3.6.egg\django\core\handlers\exception.py", line 41, in inner
    response = get_response(request)
  File "D:\ProgramFiles\Anaconda3\lib\site-packages\django-1.11.8-py3.6.egg\django\core\handlers\base.py", line 249, in _legacy_get_response
    response = self._get_response(request)
  File "D:\ProgramFiles\Anaconda3\lib\site-packages\django-1.11.8-py3.6.egg\django\core\handlers\base.py", line 187, in _get_response
    response = self.process_exception_by_middleware(e, request)
  File "D:\ProgramFiles\Anaconda3\lib\site-packages\django-1.11.8-py3.6.egg\django\core\handlers\base.py", line 185, in _get_response
    response = wrapped_callback(request, *callback_args, **callback_kwargs)
  File "D:\tools\Tools\Carry\mysite\views.py", line 2156, in cfmmc_bs
    for i,bs in data2bs:#data2:
  File "D:\tools\Tools\Carry\mysite\viewUtil.py", line 726, in future_data_cycle
    for j in data:
  File "D:\tools\Tools\Carry\mysite\HSD.py", line 324, in get_data
    for i in self.data_day(code, sd + day):
  File "D:\tools\Tools\Carry\mysite\HSD.py", line 300, in data_day
    projection=['datetime', 'open', 'high', 'low', 'close','trade'])
  File "D:\ProgramFiles\Anaconda3\lib\site-packages\pymongo\collection.py", line 1400, in find
    return Cursor(self, *args, **kwargs)
TypeError: __init__() got multiple values for argument 'projection'
exception.py[2018-09-14 16:46:02][ERROR]£ºInternal Server Error: /cfmmc/bs/m1000_RB1810/
Traceback (most recent call last):
  File "D:\ProgramFiles\Anaconda3\lib\site-packages\django-1.11.8-py3.6.egg\django\core\handlers\exception.py", line 41, in inner
    response = get_response(request)
  File "D:\ProgramFiles\Anaconda3\lib\site-packages\django-1.11.8-py3.6.egg\django\core\handlers\base.py", line 249, in _legacy_get_response
    response = self._get_response(request)
  File "D:\ProgramFiles\Anaconda3\lib\site-packages\django-1.11.8-py3.6.egg\django\core\handlers\base.py", line 187, in _get_response
    response = self.process_exception_by_middleware(e, request)
  File "D:\ProgramFiles\Anaconda3\lib\site-packages\django-1.11.8-py3.6.egg\django\core\handlers\base.py", line 185, in _get_response
    response = wrapped_callback(request, *callback_args, **callback_kwargs)
  File "D:\tools\Tools\Carry\mysite\views.py", line 2156, in cfmmc_bs
    for i,bs in data2bs:#data2:
  File "D:\tools\Tools\Carry\mysite\viewUtil.py", line 726, in future_data_cycle
    for j in data:
  File "D:\tools\Tools\Carry\mysite\HSD.py", line 324, in get_data
    for i in self.data_day(code, sd + day):
  File "D:\tools\Tools\Carry\mysite\HSD.py", line 299, in data_day
    data = self._coll.find({'datetime': {'$gte': date, '$lt': date + day}, 'code': code}, null, {'sort': [['datetime',1]]},  # Model.find(condition, fields, {sort: [['_id', -1]]}, callback);
NameError: name 'null' is not defined
exception.py[2018-09-14 16:46:21][ERROR]£ºInternal Server Error: /cfmmc/bs/m1000_RB1810/
Traceback (most recent call last):
  File "D:\ProgramFiles\Anaconda3\lib\site-packages\django-1.11.8-py3.6.egg\django\core\handlers\exception.py", line 41, in inner
    response = get_response(request)
  File "D:\ProgramFiles\Anaconda3\lib\site-packages\django-1.11.8-py3.6.egg\django\core\handlers\base.py", line 249, in _legacy_get_response
    response = self._get_response(request)
  File "D:\ProgramFiles\Anaconda3\lib\site-packages\django-1.11.8-py3.6.egg\django\core\handlers\base.py", line 187, in _get_response
    response = self.process_exception_by_middleware(e, request)
  File "D:\ProgramFiles\Anaconda3\lib\site-packages\django-1.11.8-py3.6.egg\django\core\handlers\base.py", line 185, in _get_response
    response = wrapped_callback(request, *callback_args, **callback_kwargs)
  File "D:\tools\Tools\Carry\mysite\views.py", line 2156, in cfmmc_bs
    for i,bs in data2bs:#data2:
  File "D:\tools\Tools\Carry\mysite\viewUtil.py", line 726, in future_data_cycle
    for j in data:
  File "D:\tools\Tools\Carry\mysite\HSD.py", line 324, in get_data
    for i in self.data_day(code, sd + day):
  File "D:\tools\Tools\Carry\mysite\HSD.py", line 299, in data_day
    data = self._coll.find({'datetime': {'$gte': date, '$lt': date + day}, 'code': code}, null, {sort: [['datetime',1]]},  # Model.find(condition, fields, {sort: [['_id', -1]]}, callback);
NameError: name 'null' is not defined
exception.py[2018-09-14 17:44:28][ERROR]£ºInternal Server Error: /cfmmc/bs/y1001_RB1805/
Traceback (most recent call last):
  File "D:\ProgramFiles\Anaconda3\lib\site-packages\django-1.11.8-py3.6.egg\django\core\handlers\exception.py", line 41, in inner
    response = get_response(request)
  File "D:\ProgramFiles\Anaconda3\lib\site-packages\django-1.11.8-py3.6.egg\django\core\handlers\base.py", line 249, in _legacy_get_response
    response = self._get_response(request)
  File "D:\ProgramFiles\Anaconda3\lib\site-packages\django-1.11.8-py3.6.egg\django\core\handlers\base.py", line 187, in _get_response
    response = self.process_exception_by_middleware(e, request)
  File "D:\ProgramFiles\Anaconda3\lib\site-packages\django-1.11.8-py3.6.egg\django\core\handlers\base.py", line 185, in _get_response
    response = wrapped_callback(request, *callback_args, **callback_kwargs)
  File "D:\tools\Tools\Carry\mysite\views.py", line 2156, in cfmmc_bs
    for i,bs in data2bs:#data2:
  File "D:\tools\Tools\Carry\mysite\viewUtil.py", line 748, in future_data_cycle
    yield [j0, o, j[2], l, h, v], bs2
UnboundLocalError: local variable 'j0' referenced before assignment
exception.py[2018-09-14 17:49:24][ERROR]£ºInternal Server Error: /cfmmc/bs/y1001_RB1805/
Traceback (most recent call last):
  File "D:\ProgramFiles\Anaconda3\lib\site-packages\django-1.11.8-py3.6.egg\django\core\handlers\exception.py", line 41, in inner
    response = get_response(request)
  File "D:\ProgramFiles\Anaconda3\lib\site-packages\django-1.11.8-py3.6.egg\django\core\handlers\base.py", line 249, in _legacy_get_response
    response = self._get_response(request)
  File "D:\ProgramFiles\Anaconda3\lib\site-packages\django-1.11.8-py3.6.egg\django\core\handlers\base.py", line 187, in _get_response
    response = self.process_exception_by_middleware(e, request)
  File "D:\ProgramFiles\Anaconda3\lib\site-packages\django-1.11.8-py3.6.egg\django\core\handlers\base.py", line 185, in _get_response
    response = wrapped_callback(request, *callback_args, **callback_kwargs)
  File "D:\tools\Tools\Carry\mysite\views.py", line 2156, in cfmmc_bs
    for i,bs in data2bs:#data2:
  File "D:\tools\Tools\Carry\mysite\viewUtil.py", line 749, in future_data_cycle
    yield [j0, o, j[2], l, h, v], bs2
UnboundLocalError: local variable 'j0' referenced before assignment
exception.py[2018-09-14 17:53:33][ERROR]£ºInternal Server Error: /cfmmc/bs/y1001_J1805/
Traceback (most recent call last):
  File "D:\ProgramFiles\Anaconda3\lib\site-packages\django-1.11.8-py3.6.egg\django\core\handlers\exception.py", line 41, in inner
    response = get_response(request)
  File "D:\ProgramFiles\Anaconda3\lib\site-packages\django-1.11.8-py3.6.egg\django\core\handlers\base.py", line 249, in _legacy_get_response
    response = self._get_response(request)
  File "D:\ProgramFiles\Anaconda3\lib\site-packages\django-1.11.8-py3.6.egg\django\core\handlers\base.py", line 187, in _get_response
    response = self.process_exception_by_middleware(e, request)
  File "D:\ProgramFiles\Anaconda3\lib\site-packages\django-1.11.8-py3.6.egg\django\core\handlers\base.py", line 185, in _get_response
    response = wrapped_callback(request, *callback_args, **callback_kwargs)
  File "D:\tools\Tools\Carry\mysite\views.py", line 2156, in cfmmc_bs
    for i,bs in data2bs:#data2:
  File "D:\tools\Tools\Carry\mysite\viewUtil.py", line 748, in future_data_cycle
    yield [j0, o, j[2], l, h, v], bs2
UnboundLocalError: local variable 'j0' referenced before assignment
exception.py[2018-09-14 17:54:29][ERROR]£ºInternal Server Error: /cfmmc/bs/y1001_J1805/
Traceback (most recent call last):
  File "D:\ProgramFiles\Anaconda3\lib\site-packages\django-1.11.8-py3.6.egg\django\core\handlers\exception.py", line 41, in inner
    response = get_response(request)
  File "D:\ProgramFiles\Anaconda3\lib\site-packages\django-1.11.8-py3.6.egg\django\core\handlers\base.py", line 249, in _legacy_get_response
    response = self._get_response(request)
  File "D:\ProgramFiles\Anaconda3\lib\site-packages\django-1.11.8-py3.6.egg\django\core\handlers\base.py", line 187, in _get_response
    response = self.process_exception_by_middleware(e, request)
  File "D:\ProgramFiles\Anaconda3\lib\site-packages\django-1.11.8-py3.6.egg\django\core\handlers\base.py", line 185, in _get_response
    response = wrapped_callback(request, *callback_args, **callback_kwargs)
  File "D:\tools\Tools\Carry\mysite\views.py", line 2156, in cfmmc_bs
    for i,bs in data2bs:#data2:
  File "D:\tools\Tools\Carry\mysite\viewUtil.py", line 749, in future_data_cycle
    yield [j0, o, j[2], l, h, v], bs2
UnboundLocalError: local variable 'j0' referenced before assignment
exception.py[2018-09-14 18:40:59][ERROR]£ºInternal Server Error: /
Traceback (most recent call last):
  File "D:\ProgramFiles\Anaconda3\lib\site-packages\django-1.11.8-py3.6.egg\django\core\handlers\exception.py", line 41, in inner
    response = get_response(request)
  File "D:\ProgramFiles\Anaconda3\lib\site-packages\django-1.11.8-py3.6.egg\django\core\handlers\base.py", line 249, in _legacy_get_response
    response = self._get_response(request)
  File "D:\ProgramFiles\Anaconda3\lib\site-packages\django-1.11.8-py3.6.egg\django\core\handlers\base.py", line 187, in _get_response
    response = self.process_exception_by_middleware(e, request)
  File "D:\ProgramFiles\Anaconda3\lib\site-packages\django-1.11.8-py3.6.egg\django\core\handlers\base.py", line 185, in _get_response
    response = wrapped_callback(request, *callback_args, **callback_kwargs)
  File "D:\tools\Tools\Carry\mysite\views.py", line 261, in index
    print([rq.session[i] for i in rq.session])
  File "D:\tools\Tools\Carry\mysite\views.py", line 261, in <listcomp>
    print([rq.session[i] for i in rq.session])
  File "D:\ProgramFiles\Anaconda3\lib\site-packages\django-1.11.8-py3.6.egg\django\contrib\sessions\backends\base.py", line 57, in __getitem__
    return self._session[key]
KeyError: 0
exception.py[2018-09-14 18:42:34][ERROR]£ºInternal Server Error: /
Traceback (most recent call last):
  File "D:\ProgramFiles\Anaconda3\lib\site-packages\django-1.11.8-py3.6.egg\django\core\handlers\exception.py", line 41, in inner
    response = get_response(request)
  File "D:\ProgramFiles\Anaconda3\lib\site-packages\django-1.11.8-py3.6.egg\django\core\handlers\base.py", line 249, in _legacy_get_response
    response = self._get_response(request)
  File "D:\ProgramFiles\Anaconda3\lib\site-packages\django-1.11.8-py3.6.egg\django\core\handlers\base.py", line 187, in _get_response
    response = self.process_exception_by_middleware(e, request)
  File "D:\ProgramFiles\Anaconda3\lib\site-packages\django-1.11.8-py3.6.egg\django\core\handlers\base.py", line 185, in _get_response
    response = wrapped_callback(request, *callback_args, **callback_kwargs)
  File "D:\tools\Tools\Carry\mysite\views.py", line 261, in index
    for i in rq.session:
  File "D:\ProgramFiles\Anaconda3\lib\site-packages\django-1.11.8-py3.6.egg\django\contrib\sessions\backends\base.py", line 57, in __getitem__
    return self._session[key]
KeyError: 0
base.py[2018-09-16 11:39:40][WARNING]£ºNot Found: /login
base.py[2018-09-16 11:39:40][WARNING]£ºNot Found: /favicon.ico
base.py[2018-09-16 11:39:44][WARNING]£ºNot Found: /login/
exception.py[2018-09-16 11:40:23][ERROR]£ºInternal Server Error: /user/login/
Traceback (most recent call last):
  File "D:\ProgramFiles\Anaconda3\lib\site-packages\django-1.11.8-py3.6.egg\django\core\handlers\exception.py", line 41, in inner
    response = get_response(request)
  File "D:\ProgramFiles\Anaconda3\lib\site-packages\django-1.11.8-py3.6.egg\django\core\handlers\base.py", line 249, in _legacy_get_response
    response = self._get_response(request)
  File "D:\ProgramFiles\Anaconda3\lib\site-packages\django-1.11.8-py3.6.egg\django\core\handlers\base.py", line 187, in _get_response
    response = self.process_exception_by_middleware(e, request)
  File "D:\ProgramFiles\Anaconda3\lib\site-packages\django-1.11.8-py3.6.egg\django\core\handlers\base.py", line 185, in _get_response
    response = wrapped_callback(request, *callback_args, **callback_kwargs)
  File "D:\tools\Tools\Carry\mysite\views.py", line 304, in login
    return JsonResponse({"result": message,"iphone":iphone})
UnboundLocalError: local variable 'message' referenced before assignment
exception.py[2018-09-16 11:40:44][ERROR]£ºInternal Server Error: /user/login/
Traceback (most recent call last):
  File "D:\ProgramFiles\Anaconda3\lib\site-packages\django-1.11.8-py3.6.egg\django\core\handlers\exception.py", line 41, in inner
    response = get_response(request)
  File "D:\ProgramFiles\Anaconda3\lib\site-packages\django-1.11.8-py3.6.egg\django\core\handlers\base.py", line 249, in _legacy_get_response
    response = self._get_response(request)
  File "D:\ProgramFiles\Anaconda3\lib\site-packages\django-1.11.8-py3.6.egg\django\core\handlers\base.py", line 198, in _get_response
    "returned None instead." % (callback.__module__, view_name)
ValueError: The view mysite.views.login didn't return an HttpResponse object. It returned None instead.
HSD.py[2018-09-16 12:24:18][ERROR]£ºÎÄ¼þ HSD.py µÚ1424ÐÐ±¨´í£ºmin() arg is an empty sequence
HSD.py[2018-09-16 12:24:50][ERROR]£ºÎÄ¼þ HSD.py µÚ1424ÐÐ±¨´í£ºmin() arg is an empty sequence
HSD.py[2018-09-16 12:24:50][ERROR]£ºÎÄ¼þ HSD.py µÚ1424ÐÐ±¨´í£ºmin() arg is an empty sequence
exception.py[2018-09-16 13:56:52][ERROR]£ºInternal Server Error: /cfmmc/bs/m1000_TA901/
Traceback (most recent call last):
  File "D:\ProgramFiles\Anaconda3\lib\site-packages\django-1.11.8-py3.6.egg\django\core\handlers\exception.py", line 41, in inner
    response = get_response(request)
  File "D:\ProgramFiles\Anaconda3\lib\site-packages\django-1.11.8-py3.6.egg\django\core\handlers\base.py", line 249, in _legacy_get_response
    response = self._get_response(request)
  File "D:\ProgramFiles\Anaconda3\lib\site-packages\django-1.11.8-py3.6.egg\django\core\handlers\base.py", line 187, in _get_response
    response = self.process_exception_by_middleware(e, request)
  File "D:\ProgramFiles\Anaconda3\lib\site-packages\django-1.11.8-py3.6.egg\django\core\handlers\base.py", line 185, in _get_response
    response = wrapped_callback(request, *callback_args, **callback_kwargs)
  File "D:\tools\Tools\Carry\mysite\views.py", line 2176, in cfmmc_bs
    for i, bs in data2bs:  # data2:
  File "D:\tools\Tools\Carry\mysite\viewUtil.py", line 674, in future_data_cycle
    print(data[:3])
TypeError: 'generator' object is not subscriptable
base.py[2018-09-16 13:56:52][WARNING]£ºNot Found: /favicon.ico
wsgi.py[2018-09-17 09:05:37][INFO]£º200 GET / (192.168.2.204) 227.37ms
wsgi.py[2018-09-17 09:05:55][INFO]£º200 GET / (192.168.2.204) 145.41ms
wsgi.py[2018-09-17 09:12:15][INFO]£º200 GET / (192.168.2.204) 155.63ms
wsgi.py[2018-09-17 09:12:16][INFO]£º200 GET / (192.168.2.204) 202.74ms
HSD.py[2018-09-17 09:43:49][ERROR]£ºÎÄ¼þ HSD.py µÚ1424ÐÐ±¨´í£ºdivision by zero
HSD.py[2018-09-17 09:45:15][ERROR]£ºÎÄ¼þ HSD.py µÚ1424ÐÐ±¨´í£ºdivision by zero
HSD.py[2018-09-17 10:17:43][ERROR]£ºÎÄ¼þ HSD.py µÚ1424ÐÐ±¨´í£ºdivision by zero
HSD.py[2018-09-17 10:19:08][ERROR]£ºÎÄ¼þ HSD.py µÚ1424ÐÐ±¨´í£ºdivision by zero
exception.py[2018-09-17 12:20:05][ERROR]£ºInternal Server Error: /
Traceback (most recent call last):
  File "D:\ProgramFiles\Anaconda3\lib\site-packages\django-1.11.8-py3.6.egg\django\core\handlers\base.py", line 131, in get_response
    response = middleware_method(request, response)
  File "D:\ProgramFiles\Anaconda3\lib\site-packages\django-1.11.8-py3.6.egg\django\middleware\clickjacking.py", line 32, in process_response
    if response.get('X-Frame-Options') is not None:
AttributeError: 'generator' object has no attribute 'get'
base.py[2018-09-17 12:20:05][WARNING]£ºNot Found: /favicon.ico
HSD.py[2018-09-17 14:26:41][ERROR]£ºÎÄ¼þ HSD.py µÚ1424ÐÐ±¨´í£ºdivision by zero
HSD.py[2018-09-17 14:26:48][ERROR]£ºÎÄ¼þ HSD.py µÚ1424ÐÐ±¨´í£ºdivision by zero
HSD.py[2018-09-17 14:26:52][ERROR]£ºÎÄ¼þ HSD.py µÚ1424ÐÐ±¨´í£ºdivision by zero
HSD.py[2018-09-17 14:26:58][ERROR]£ºÎÄ¼þ HSD.py µÚ1424ÐÐ±¨´í£ºdivision by zero
HSD.py[2018-09-17 14:28:40][ERROR]£ºÎÄ¼þ HSD.py µÚ1424ÐÐ±¨´í£ºdivision by zero
HSD.py[2018-09-17 14:34:21][ERROR]£ºÎÄ¼þ HSD.py µÚ1424ÐÐ±¨´í£ºdivision by zero
HSD.py[2018-09-17 14:34:25][ERROR]£ºÎÄ¼þ HSD.py µÚ1424ÐÐ±¨´í£ºdivision by zero
HSD.py[2018-09-17 14:35:09][ERROR]£ºÎÄ¼þ HSD.py µÚ1424ÐÐ±¨´í£ºdivision by zero
HSD.py[2018-09-17 14:35:18][ERROR]£ºÎÄ¼þ HSD.py µÚ1424ÐÐ±¨´í£ºdivision by zero
HSD.py[2018-09-17 14:36:46][ERROR]£ºÎÄ¼þ HSD.py µÚ1424ÐÐ±¨´í£ºdivision by zero
HSD.py[2018-09-17 14:36:56][ERROR]£ºÎÄ¼þ HSD.py µÚ1424ÐÐ±¨´í£ºdivision by zero
HSD.py[2018-09-17 14:37:30][ERROR]£ºÎÄ¼þ HSD.py µÚ1424ÐÐ±¨´í£ºdivision by zero
HSD.py[2018-09-17 14:37:55][ERROR]£ºÎÄ¼þ HSD.py µÚ1424ÐÐ±¨´í£ºdivision by zero
HSD.py[2018-09-17 14:39:55][ERROR]£ºÎÄ¼þ HSD.py µÚ1424ÐÐ±¨´í£ºdivision by zero
HSD.py[2018-09-17 14:41:16][ERROR]£ºÎÄ¼þ HSD.py µÚ1424ÐÐ±¨´í£ºdivision by zero
HSD.py[2018-09-17 14:42:08][ERROR]£ºÎÄ¼þ HSD.py µÚ1424ÐÐ±¨´í£ºdivision by zero
wsgi.py[2018-09-17 15:25:40][INFO]£º200 GET / (192.168.2.204) 178.47ms
wsgi.py[2018-09-17 15:25:41][INFO]£º200 GET / (192.168.2.204) 174.51ms
wsgi.py[2018-09-17 15:25:42][INFO]£º200 GET / (192.168.2.204) 9.02ms
wsgi.py[2018-09-17 15:25:44][INFO]£º200 GET / (192.168.2.204) 10.03ms
wsgi.py[2018-09-17 15:25:44][INFO]£º200 GET / (192.168.2.204) 10.05ms
exception.py[2018-09-17 17:02:33][ERROR]£ºInternal Server Error: /cfmmc/huice/m1000/
Traceback (most recent call last):
  File "D:\ProgramFiles\Anaconda3\lib\site-packages\django-1.11.8-py3.6.egg\django\core\handlers\exception.py", line 41, in inner
    response = get_response(request)
  File "D:\ProgramFiles\Anaconda3\lib\site-packages\django-1.11.8-py3.6.egg\django\core\handlers\base.py", line 249, in _legacy_get_response
    response = self._get_response(request)
  File "D:\ProgramFiles\Anaconda3\lib\site-packages\django-1.11.8-py3.6.egg\django\core\handlers\base.py", line 187, in _get_response
    response = self.process_exception_by_middleware(e, request)
  File "D:\ProgramFiles\Anaconda3\lib\site-packages\django-1.11.8-py3.6.egg\django\core\handlers\base.py", line 185, in _get_response
    response = wrapped_callback(request, *callback_args, **callback_kwargs)
  File "D:\tools\Tools\Carry\mysite\views.py", line 2263, in cfmmc_huice
    funcs = (viewUtil.MyThread(cfmmc.get_data),viewUtil.MyThread(cfmmc.varieties),viewUtil.MyThread(cfmmc.get_qy),viewUtil.MyThread(cfmmc.init_money))
  File "D:\tools\Tools\Carry\mysite\viewUtil.py", line 831, in __init__
    self.f_name = target.func.__name__
AttributeError: 'function' object has no attribute 'func'
HSD.py[2018-09-17 17:03:12][ERROR]£ºÎÄ¼þ HSD.py µÚ1424ÐÐ±¨´í£ºdivision by zero
HSD.py[2018-09-17 17:10:11][ERROR]£ºÎÄ¼þ HSD.py µÚ1424ÐÐ±¨´í£ºdivision by zero
exception.py[2018-09-17 17:25:41][ERROR]£ºInternal Server Error: /cfmmc/huice/
Traceback (most recent call last):
  File "D:\ProgramFiles\Anaconda3\lib\site-packages\django-1.11.8-py3.6.egg\django\core\handlers\exception.py", line 41, in inner
    response = get_response(request)
  File "D:\ProgramFiles\Anaconda3\lib\site-packages\django-1.11.8-py3.6.egg\django\core\handlers\base.py", line 249, in _legacy_get_response
    response = self._get_response(request)
  File "D:\ProgramFiles\Anaconda3\lib\site-packages\django-1.11.8-py3.6.egg\django\core\handlers\base.py", line 187, in _get_response
    response = self.process_exception_by_middleware(e, request)
  File "D:\ProgramFiles\Anaconda3\lib\site-packages\django-1.11.8-py3.6.egg\django\core\handlers\base.py", line 185, in _get_response
    response = wrapped_callback(request, *callback_args, **callback_kwargs)
  File "D:\tools\Tools\Carry\mysite\views.py", line 2268, in cfmmc_huice
    _result = viewUtil.runThread(cfmmc.get_data,cfmmc.varieties,cfmmc.get_qy,cfmmc.init_money)
  File "D:\tools\Tools\Carry\mysite\viewUtil.py", line 843, in runThread
    _funcs = [MyThread(*i) for i in funcs] #(viewUtil.MyThread(cfmmc.get_data), viewUtil.MyThread(cfmmc.varieties),viewUtil.MyThread(cfmmc.get_qy), viewUtil.MyThread(cfmmc.init_money))
  File "D:\tools\Tools\Carry\mysite\viewUtil.py", line 843, in <listcomp>
    _funcs = [MyThread(*i) for i in funcs] #(viewUtil.MyThread(cfmmc.get_data), viewUtil.MyThread(cfmmc.varieties),viewUtil.MyThread(cfmmc.get_qy), viewUtil.MyThread(cfmmc.init_money))
TypeError: type object argument after * must be an iterable, not method
