exception.py[2018-10-11 15:03:37][ERROR]：Internal Server Error: /tj/
Traceback (most recent call last):
  File "D:\ProgramFiles\Anaconda3\lib\site-packages\django-1.11.8-py3.6.egg\django\core\handlers\exception.py", line 41, in inner
    response = get_response(request)
  File "D:\ProgramFiles\Anaconda3\lib\site-packages\django-1.11.8-py3.6.egg\django\core\handlers\base.py", line 249, in _legacy_get_response
    response = self._get_response(request)
  File "D:\ProgramFiles\Anaconda3\lib\site-packages\django-1.11.8-py3.6.egg\django\core\handlers\base.py", line 187, in _get_response
    response = self.process_exception_by_middleware(e, request)
  File "D:\ProgramFiles\Anaconda3\lib\site-packages\django-1.11.8-py3.6.egg\django\core\handlers\base.py", line 185, in _get_response
    response = wrapped_callback(request, *callback_args, **callback_kwargs)
  File "D:\tools\Tools\Carry\mysite\views.py", line 1186, in tongji
    results2, _ = HSD.huice_order_record() #HSD.sp_order_record(rq_date, end_date)
  File "D:\tools\Tools\Carry\mysite\HSD.py", line 949, in huice_order_record
    for j in range(dt[3]):
TypeError: 'float' object cannot be interpreted as an integer
HSD.py[2018-10-11 15:08:25][ERROR]：文件 HSD.py 第1737行报错：division by zero
exception.py[2018-10-11 15:13:13][ERROR]：Internal Server Error: /zhangting/tomorrow/
Traceback (most recent call last):
  File "D:\ProgramFiles\Anaconda3\lib\site-packages\django-1.11.8-py3.6.egg\django\core\handlers\exception.py", line 41, in inner
    response = get_response(request)
  File "D:\ProgramFiles\Anaconda3\lib\site-packages\django-1.11.8-py3.6.egg\django\core\handlers\base.py", line 249, in _legacy_get_response
    response = self._get_response(request)
  File "D:\ProgramFiles\Anaconda3\lib\site-packages\django-1.11.8-py3.6.egg\django\core\handlers\base.py", line 187, in _get_response
    response = self.process_exception_by_middleware(e, request)
  File "D:\ProgramFiles\Anaconda3\lib\site-packages\django-1.11.8-py3.6.egg\django\core\handlers\base.py", line 185, in _get_response
    response = wrapped_callback(request, *callback_args, **callback_kwargs)
  File "D:\tools\Tools\Carry\mysite\views.py", line 1634, in zhangting
    zt_tomorrow[i][2] = range(zt_tomorrow[i][2])  # ['★' for j in range(zt_tomorrow[i][2])]
TypeError: 'str' object cannot be interpreted as an integer
HSD.py[2018-10-11 15:17:06][ERROR]：文件 HSD.py 第1737行报错：division by zero
base.py[2018-10-11 15:41:30][WARNING]：Not Found: /interface_huice/
exception.py[2018-10-11 15:44:10][ERROR]：Internal Server Error: /again/huice/
Traceback (most recent call last):
  File "D:\ProgramFiles\Anaconda3\lib\site-packages\django-1.11.8-py3.6.egg\django\core\handlers\exception.py", line 41, in inner
    response = get_response(request)
  File "D:\ProgramFiles\Anaconda3\lib\site-packages\django-1.11.8-py3.6.egg\django\core\handlers\base.py", line 249, in _legacy_get_response
    response = self._get_response(request)
  File "D:\ProgramFiles\Anaconda3\lib\site-packages\django-1.11.8-py3.6.egg\django\core\handlers\base.py", line 187, in _get_response
    response = self.process_exception_by_middleware(e, request)
  File "D:\ProgramFiles\Anaconda3\lib\site-packages\django-1.11.8-py3.6.egg\django\core\handlers\base.py", line 185, in _get_response
    response = wrapped_callback(request, *callback_args, **callback_kwargs)
  File "D:\tools\Tools\Carry\mysite\views.py", line 2638, in interface_huice
    results2, _ = HSD.huice_order_record()
TypeError: huice_order_record() missing 1 required positional argument: 'user'
HSD.py[2018-10-11 15:44:31][ERROR]：文件 HSD.py 第1713行报错：division by zero
HSD.py[2018-10-11 15:50:57][ERROR]：文件 HSD.py 第1713行报错：division by zero
HSD.py[2018-10-11 15:53:17][ERROR]：文件 HSD.py 第1713行报错：division by zero
HSD.py[2018-10-11 15:53:25][ERROR]：文件 HSD.py 第1713行报错：division by zero
HSD.py[2018-10-11 15:53:41][ERROR]：文件 HSD.py 第1713行报错：division by zero
HSD.py[2018-10-11 15:53:55][ERROR]：文件 HSD.py 第1713行报错：division by zero
HSD.py[2018-10-11 15:54:08][ERROR]：文件 HSD.py 第1713行报错：division by zero
HSD.py[2018-10-11 15:54:34][ERROR]：文件 HSD.py 第1713行报错：division by zero
HSD.py[2018-10-11 15:54:48][ERROR]：文件 HSD.py 第1713行报错：division by zero
HSD.py[2018-10-11 15:55:26][ERROR]：文件 HSD.py 第1713行报错：division by zero
HSD.py[2018-10-11 15:55:41][ERROR]：文件 HSD.py 第1713行报错：division by zero
HSD.py[2018-10-11 15:57:19][ERROR]：文件 HSD.py 第1713行报错：division by zero
HSD.py[2018-10-11 16:00:13][ERROR]：文件 HSD.py 第1713行报错：division by zero
exception.py[2018-10-11 16:23:41][ERROR]：Internal Server Error: /again/huice/
Traceback (most recent call last):
  File "D:\ProgramFiles\Anaconda3\lib\site-packages\django-1.11.8-py3.6.egg\django\template\base.py", line 507, in parse
    compile_func = self.tags[command]
KeyError: 'asrf_token'

During handling of the above exception, another exception occurred:

Traceback (most recent call last):
  File "D:\ProgramFiles\Anaconda3\lib\site-packages\django-1.11.8-py3.6.egg\django\core\handlers\exception.py", line 41, in inner
    response = get_response(request)
  File "D:\ProgramFiles\Anaconda3\lib\site-packages\django-1.11.8-py3.6.egg\django\core\handlers\base.py", line 249, in _legacy_get_response
    response = self._get_response(request)
  File "D:\ProgramFiles\Anaconda3\lib\site-packages\django-1.11.8-py3.6.egg\django\core\handlers\base.py", line 187, in _get_response
    response = self.process_exception_by_middleware(e, request)
  File "D:\ProgramFiles\Anaconda3\lib\site-packages\django-1.11.8-py3.6.egg\django\core\handlers\base.py", line 185, in _get_response
    response = wrapped_callback(request, *callback_args, **callback_kwargs)
  File "D:\tools\Tools\Carry\mysite\views.py", line 2636, in interface_huice
    return render(rq,'interface_huice.html',{'user_name':user_name,'ids':ids})
  File "D:\ProgramFiles\Anaconda3\lib\site-packages\django-1.11.8-py3.6.egg\django\shortcuts.py", line 30, in render
    content = loader.render_to_string(template_name, context, request, using=using)
  File "D:\ProgramFiles\Anaconda3\lib\site-packages\django-1.11.8-py3.6.egg\django\template\loader.py", line 67, in render_to_string
    template = get_template(template_name, using=using)
  File "D:\ProgramFiles\Anaconda3\lib\site-packages\django-1.11.8-py3.6.egg\django\template\loader.py", line 21, in get_template
    return engine.get_template(template_name)
  File "D:\ProgramFiles\Anaconda3\lib\site-packages\django-1.11.8-py3.6.egg\django\template\backends\django.py", line 39, in get_template
    return Template(self.engine.get_template(template_name), self)
  File "D:\ProgramFiles\Anaconda3\lib\site-packages\django-1.11.8-py3.6.egg\django\template\engine.py", line 162, in get_template
    template, origin = self.find_template(template_name)
  File "D:\ProgramFiles\Anaconda3\lib\site-packages\django-1.11.8-py3.6.egg\django\template\engine.py", line 136, in find_template
    name, template_dirs=dirs, skip=skip,
  File "D:\ProgramFiles\Anaconda3\lib\site-packages\django-1.11.8-py3.6.egg\django\template\loaders\base.py", line 44, in get_template
    contents, origin, origin.template_name, self.engine,
  File "D:\ProgramFiles\Anaconda3\lib\site-packages\django-1.11.8-py3.6.egg\django\template\base.py", line 191, in __init__
    self.nodelist = self.compile_nodelist()
  File "D:\ProgramFiles\Anaconda3\lib\site-packages\django-1.11.8-py3.6.egg\django\template\base.py", line 230, in compile_nodelist
    return parser.parse()
  File "D:\ProgramFiles\Anaconda3\lib\site-packages\django-1.11.8-py3.6.egg\django\template\base.py", line 515, in parse
    raise self.error(token, e)
  File "D:\ProgramFiles\Anaconda3\lib\site-packages\django-1.11.8-py3.6.egg\django\template\base.py", line 513, in parse
    compiled_result = compile_func(self, token)
  File "D:\ProgramFiles\Anaconda3\lib\site-packages\django-1.11.8-py3.6.egg\django\template\loader_tags.py", line 312, in do_extends
    nodelist = parser.parse()
  File "D:\ProgramFiles\Anaconda3\lib\site-packages\django-1.11.8-py3.6.egg\django\template\base.py", line 515, in parse
    raise self.error(token, e)
  File "D:\ProgramFiles\Anaconda3\lib\site-packages\django-1.11.8-py3.6.egg\django\template\base.py", line 513, in parse
    compiled_result = compile_func(self, token)
  File "D:\ProgramFiles\Anaconda3\lib\site-packages\django-1.11.8-py3.6.egg\django\template\loader_tags.py", line 255, in do_block
    nodelist = parser.parse(('endblock',))
  File "D:\ProgramFiles\Anaconda3\lib\site-packages\django-1.11.8-py3.6.egg\django\template\base.py", line 509, in parse
    self.invalid_block_tag(token, command, parse_until)
  File "D:\ProgramFiles\Anaconda3\lib\site-packages\django-1.11.8-py3.6.egg\django\template\base.py", line 565, in invalid_block_tag
    get_text_list(["'%s'" % p for p in parse_until], 'or'),
django.template.exceptions.TemplateSyntaxError: Invalid block tag on line 37: 'asrf_token', expected 'endblock'. Did you forget to register or load this tag?
exception.py[2018-10-11 16:29:29][ERROR]：Internal Server Error: /again/huice/
Traceback (most recent call last):
  File "D:\ProgramFiles\Anaconda3\lib\site-packages\django-1.11.8-py3.6.egg\django\template\base.py", line 507, in parse
    compile_func = self.tags[command]
KeyError: 'endblock'

During handling of the above exception, another exception occurred:

Traceback (most recent call last):
  File "D:\ProgramFiles\Anaconda3\lib\site-packages\django-1.11.8-py3.6.egg\django\core\handlers\exception.py", line 41, in inner
    response = get_response(request)
  File "D:\ProgramFiles\Anaconda3\lib\site-packages\django-1.11.8-py3.6.egg\django\core\handlers\base.py", line 249, in _legacy_get_response
    response = self._get_response(request)
  File "D:\ProgramFiles\Anaconda3\lib\site-packages\django-1.11.8-py3.6.egg\django\core\handlers\base.py", line 187, in _get_response
    response = self.process_exception_by_middleware(e, request)
  File "D:\ProgramFiles\Anaconda3\lib\site-packages\django-1.11.8-py3.6.egg\django\core\handlers\base.py", line 185, in _get_response
    response = wrapped_callback(request, *callback_args, **callback_kwargs)
  File "D:\tools\Tools\Carry\mysite\views.py", line 2636, in interface_huice
    return render(rq,'interface_huice.html',{'user_name':user_name,'qx':qx,'clouds':clouds})
  File "D:\ProgramFiles\Anaconda3\lib\site-packages\django-1.11.8-py3.6.egg\django\shortcuts.py", line 30, in render
    content = loader.render_to_string(template_name, context, request, using=using)
  File "D:\ProgramFiles\Anaconda3\lib\site-packages\django-1.11.8-py3.6.egg\django\template\loader.py", line 67, in render_to_string
    template = get_template(template_name, using=using)
  File "D:\ProgramFiles\Anaconda3\lib\site-packages\django-1.11.8-py3.6.egg\django\template\loader.py", line 21, in get_template
    return engine.get_template(template_name)
  File "D:\ProgramFiles\Anaconda3\lib\site-packages\django-1.11.8-py3.6.egg\django\template\backends\django.py", line 39, in get_template
    return Template(self.engine.get_template(template_name), self)
  File "D:\ProgramFiles\Anaconda3\lib\site-packages\django-1.11.8-py3.6.egg\django\template\engine.py", line 162, in get_template
    template, origin = self.find_template(template_name)
  File "D:\ProgramFiles\Anaconda3\lib\site-packages\django-1.11.8-py3.6.egg\django\template\engine.py", line 136, in find_template
    name, template_dirs=dirs, skip=skip,
  File "D:\ProgramFiles\Anaconda3\lib\site-packages\django-1.11.8-py3.6.egg\django\template\loaders\base.py", line 44, in get_template
    contents, origin, origin.template_name, self.engine,
  File "D:\ProgramFiles\Anaconda3\lib\site-packages\django-1.11.8-py3.6.egg\django\template\base.py", line 191, in __init__
    self.nodelist = self.compile_nodelist()
  File "D:\ProgramFiles\Anaconda3\lib\site-packages\django-1.11.8-py3.6.egg\django\template\base.py", line 230, in compile_nodelist
    return parser.parse()
  File "D:\ProgramFiles\Anaconda3\lib\site-packages\django-1.11.8-py3.6.egg\django\template\base.py", line 515, in parse
    raise self.error(token, e)
  File "D:\ProgramFiles\Anaconda3\lib\site-packages\django-1.11.8-py3.6.egg\django\template\base.py", line 513, in parse
    compiled_result = compile_func(self, token)
  File "D:\ProgramFiles\Anaconda3\lib\site-packages\django-1.11.8-py3.6.egg\django\template\loader_tags.py", line 312, in do_extends
    nodelist = parser.parse()
  File "D:\ProgramFiles\Anaconda3\lib\site-packages\django-1.11.8-py3.6.egg\django\template\base.py", line 515, in parse
    raise self.error(token, e)
  File "D:\ProgramFiles\Anaconda3\lib\site-packages\django-1.11.8-py3.6.egg\django\template\base.py", line 513, in parse
    compiled_result = compile_func(self, token)
  File "D:\ProgramFiles\Anaconda3\lib\site-packages\django-1.11.8-py3.6.egg\django\template\loader_tags.py", line 255, in do_block
    nodelist = parser.parse(('endblock',))
  File "D:\ProgramFiles\Anaconda3\lib\site-packages\django-1.11.8-py3.6.egg\django\template\base.py", line 515, in parse
    raise self.error(token, e)
  File "D:\ProgramFiles\Anaconda3\lib\site-packages\django-1.11.8-py3.6.egg\django\template\base.py", line 513, in parse
    compiled_result = compile_func(self, token)
  File "D:\ProgramFiles\Anaconda3\lib\site-packages\django-1.11.8-py3.6.egg\django\template\defaulttags.py", line 969, in do_if
    nodelist = parser.parse(('elif', 'else', 'endif'))
  File "D:\ProgramFiles\Anaconda3\lib\site-packages\django-1.11.8-py3.6.egg\django\template\base.py", line 509, in parse
    self.invalid_block_tag(token, command, parse_until)
  File "D:\ProgramFiles\Anaconda3\lib\site-packages\django-1.11.8-py3.6.egg\django\template\base.py", line 565, in invalid_block_tag
    get_text_list(["'%s'" % p for p in parse_until], 'or'),
django.template.exceptions.TemplateSyntaxError: Invalid block tag on line 95: 'endblock', expected 'elif'，'else' or 'endif'. Did you forget to register or load this tag?
exception.py[2018-10-11 16:32:45][ERROR]：Internal Server Error: /user/cloud/public/download/
Traceback (most recent call last):
  File "D:\ProgramFiles\Anaconda3\lib\site-packages\django-1.11.8-py3.6.egg\django\core\handlers\exception.py", line 41, in inner
    response = get_response(request)
  File "D:\ProgramFiles\Anaconda3\lib\site-packages\django-1.11.8-py3.6.egg\django\core\handlers\base.py", line 249, in _legacy_get_response
    response = self._get_response(request)
  File "D:\ProgramFiles\Anaconda3\lib\site-packages\django-1.11.8-py3.6.egg\django\core\handlers\base.py", line 187, in _get_response
    response = self.process_exception_by_middleware(e, request)
  File "D:\ProgramFiles\Anaconda3\lib\site-packages\django-1.11.8-py3.6.egg\django\core\handlers\base.py", line 185, in _get_response
    response = wrapped_callback(request, *callback_args, **callback_kwargs)
  File "D:\tools\Tools\Carry\mysite\views.py", line 766, in user_cloud_public_download
    path_file = os.path.join(path_root, name + '_+_' + file_name)
TypeError: unsupported operand type(s) for +: 'NoneType' and 'str'
HSD.py[2018-10-11 16:33:50][ERROR]：文件 HSD.py 第1713行报错：division by zero
HSD.py[2018-10-11 16:43:35][ERROR]：文件 HSD.py 第1713行报错：division by zero
HSD.py[2018-10-11 17:11:53][ERROR]：文件 HSD.py 第1713行报错：division by zero
HSD.py[2018-10-11 17:12:23][ERROR]：文件 HSD.py 第1713行报错：division by zero
HSD.py[2018-10-11 17:14:08][ERROR]：文件 HSD.py 第1713行报错：division by zero
HSD.py[2018-10-11 17:17:33][ERROR]：文件 HSD.py 第1713行报错：division by zero
HSD.py[2018-10-11 17:29:13][ERROR]：文件 HSD.py 第1710行报错：division by zero
exception.py[2018-10-11 17:37:51][ERROR]：Internal Server Error: /again/huice/
Traceback (most recent call last):
  File "D:\ProgramFiles\Anaconda3\lib\site-packages\django-1.11.8-py3.6.egg\django\template\base.py", line 507, in parse
    compile_func = self.tags[command]
KeyError: 'endblock'

During handling of the above exception, another exception occurred:

Traceback (most recent call last):
  File "D:\ProgramFiles\Anaconda3\lib\site-packages\django-1.11.8-py3.6.egg\django\core\handlers\exception.py", line 41, in inner
    response = get_response(request)
  File "D:\ProgramFiles\Anaconda3\lib\site-packages\django-1.11.8-py3.6.egg\django\core\handlers\base.py", line 249, in _legacy_get_response
    response = self._get_response(request)
  File "D:\ProgramFiles\Anaconda3\lib\site-packages\django-1.11.8-py3.6.egg\django\core\handlers\base.py", line 187, in _get_response
    response = self.process_exception_by_middleware(e, request)
  File "D:\ProgramFiles\Anaconda3\lib\site-packages\django-1.11.8-py3.6.egg\django\core\handlers\base.py", line 185, in _get_response
    response = wrapped_callback(request, *callback_args, **callback_kwargs)
  File "D:\tools\Tools\Carry\mysite\views.py", line 2614, in interface_huice
    return render(rq, 'interface_huice.html', {'user_name': user_name, 'clouds': clouds})
  File "D:\ProgramFiles\Anaconda3\lib\site-packages\django-1.11.8-py3.6.egg\django\shortcuts.py", line 30, in render
    content = loader.render_to_string(template_name, context, request, using=using)
  File "D:\ProgramFiles\Anaconda3\lib\site-packages\django-1.11.8-py3.6.egg\django\template\loader.py", line 67, in render_to_string
    template = get_template(template_name, using=using)
  File "D:\ProgramFiles\Anaconda3\lib\site-packages\django-1.11.8-py3.6.egg\django\template\loader.py", line 21, in get_template
    return engine.get_template(template_name)
  File "D:\ProgramFiles\Anaconda3\lib\site-packages\django-1.11.8-py3.6.egg\django\template\backends\django.py", line 39, in get_template
    return Template(self.engine.get_template(template_name), self)
  File "D:\ProgramFiles\Anaconda3\lib\site-packages\django-1.11.8-py3.6.egg\django\template\engine.py", line 162, in get_template
    template, origin = self.find_template(template_name)
  File "D:\ProgramFiles\Anaconda3\lib\site-packages\django-1.11.8-py3.6.egg\django\template\engine.py", line 136, in find_template
    name, template_dirs=dirs, skip=skip,
  File "D:\ProgramFiles\Anaconda3\lib\site-packages\django-1.11.8-py3.6.egg\django\template\loaders\base.py", line 44, in get_template
    contents, origin, origin.template_name, self.engine,
  File "D:\ProgramFiles\Anaconda3\lib\site-packages\django-1.11.8-py3.6.egg\django\template\base.py", line 191, in __init__
    self.nodelist = self.compile_nodelist()
  File "D:\ProgramFiles\Anaconda3\lib\site-packages\django-1.11.8-py3.6.egg\django\template\base.py", line 230, in compile_nodelist
    return parser.parse()
  File "D:\ProgramFiles\Anaconda3\lib\site-packages\django-1.11.8-py3.6.egg\django\template\base.py", line 515, in parse
    raise self.error(token, e)
  File "D:\ProgramFiles\Anaconda3\lib\site-packages\django-1.11.8-py3.6.egg\django\template\base.py", line 513, in parse
    compiled_result = compile_func(self, token)
  File "D:\ProgramFiles\Anaconda3\lib\site-packages\django-1.11.8-py3.6.egg\django\template\loader_tags.py", line 312, in do_extends
    nodelist = parser.parse()
  File "D:\ProgramFiles\Anaconda3\lib\site-packages\django-1.11.8-py3.6.egg\django\template\base.py", line 515, in parse
    raise self.error(token, e)
  File "D:\ProgramFiles\Anaconda3\lib\site-packages\django-1.11.8-py3.6.egg\django\template\base.py", line 513, in parse
    compiled_result = compile_func(self, token)
  File "D:\ProgramFiles\Anaconda3\lib\site-packages\django-1.11.8-py3.6.egg\django\template\loader_tags.py", line 255, in do_block
    nodelist = parser.parse(('endblock',))
  File "D:\ProgramFiles\Anaconda3\lib\site-packages\django-1.11.8-py3.6.egg\django\template\base.py", line 515, in parse
    raise self.error(token, e)
  File "D:\ProgramFiles\Anaconda3\lib\site-packages\django-1.11.8-py3.6.egg\django\template\base.py", line 513, in parse
    compiled_result = compile_func(self, token)
  File "D:\ProgramFiles\Anaconda3\lib\site-packages\django-1.11.8-py3.6.egg\django\template\defaulttags.py", line 983, in do_if
    nodelist = parser.parse(('endif',))
  File "D:\ProgramFiles\Anaconda3\lib\site-packages\django-1.11.8-py3.6.egg\django\template\base.py", line 509, in parse
    self.invalid_block_tag(token, command, parse_until)
  File "D:\ProgramFiles\Anaconda3\lib\site-packages\django-1.11.8-py3.6.egg\django\template\base.py", line 565, in invalid_block_tag
    get_text_list(["'%s'" % p for p in parse_until], 'or'),
django.template.exceptions.TemplateSyntaxError: Invalid block tag on line 2181: 'endblock', expected 'endif'. Did you forget to register or load this tag?
exception.py[2018-10-11 17:45:23][ERROR]：Internal Server Error: /again/huice/
Traceback (most recent call last):
  File "D:\ProgramFiles\Anaconda3\lib\site-packages\django-1.11.8-py3.6.egg\django\template\base.py", line 507, in parse
    compile_func = self.tags[command]
KeyError: 'endblock'

During handling of the above exception, another exception occurred:

Traceback (most recent call last):
  File "D:\ProgramFiles\Anaconda3\lib\site-packages\django-1.11.8-py3.6.egg\django\core\handlers\exception.py", line 41, in inner
    response = get_response(request)
  File "D:\ProgramFiles\Anaconda3\lib\site-packages\django-1.11.8-py3.6.egg\django\core\handlers\base.py", line 249, in _legacy_get_response
    response = self._get_response(request)
  File "D:\ProgramFiles\Anaconda3\lib\site-packages\django-1.11.8-py3.6.egg\django\core\handlers\base.py", line 187, in _get_response
    response = self.process_exception_by_middleware(e, request)
  File "D:\ProgramFiles\Anaconda3\lib\site-packages\django-1.11.8-py3.6.egg\django\core\handlers\base.py", line 185, in _get_response
    response = wrapped_callback(request, *callback_args, **callback_kwargs)
  File "D:\tools\Tools\Carry\mysite\views.py", line 2623, in interface_huice
    return render(rq, 'interface_huice.html', resp)
  File "D:\ProgramFiles\Anaconda3\lib\site-packages\django-1.11.8-py3.6.egg\django\shortcuts.py", line 30, in render
    content = loader.render_to_string(template_name, context, request, using=using)
  File "D:\ProgramFiles\Anaconda3\lib\site-packages\django-1.11.8-py3.6.egg\django\template\loader.py", line 67, in render_to_string
    template = get_template(template_name, using=using)
  File "D:\ProgramFiles\Anaconda3\lib\site-packages\django-1.11.8-py3.6.egg\django\template\loader.py", line 21, in get_template
    return engine.get_template(template_name)
  File "D:\ProgramFiles\Anaconda3\lib\site-packages\django-1.11.8-py3.6.egg\django\template\backends\django.py", line 39, in get_template
    return Template(self.engine.get_template(template_name), self)
  File "D:\ProgramFiles\Anaconda3\lib\site-packages\django-1.11.8-py3.6.egg\django\template\engine.py", line 162, in get_template
    template, origin = self.find_template(template_name)
  File "D:\ProgramFiles\Anaconda3\lib\site-packages\django-1.11.8-py3.6.egg\django\template\engine.py", line 136, in find_template
    name, template_dirs=dirs, skip=skip,
  File "D:\ProgramFiles\Anaconda3\lib\site-packages\django-1.11.8-py3.6.egg\django\template\loaders\base.py", line 44, in get_template
    contents, origin, origin.template_name, self.engine,
  File "D:\ProgramFiles\Anaconda3\lib\site-packages\django-1.11.8-py3.6.egg\django\template\base.py", line 191, in __init__
    self.nodelist = self.compile_nodelist()
  File "D:\ProgramFiles\Anaconda3\lib\site-packages\django-1.11.8-py3.6.egg\django\template\base.py", line 230, in compile_nodelist
    return parser.parse()
  File "D:\ProgramFiles\Anaconda3\lib\site-packages\django-1.11.8-py3.6.egg\django\template\base.py", line 515, in parse
    raise self.error(token, e)
  File "D:\ProgramFiles\Anaconda3\lib\site-packages\django-1.11.8-py3.6.egg\django\template\base.py", line 513, in parse
    compiled_result = compile_func(self, token)
  File "D:\ProgramFiles\Anaconda3\lib\site-packages\django-1.11.8-py3.6.egg\django\template\loader_tags.py", line 312, in do_extends
    nodelist = parser.parse()
  File "D:\ProgramFiles\Anaconda3\lib\site-packages\django-1.11.8-py3.6.egg\django\template\base.py", line 515, in parse
    raise self.error(token, e)
  File "D:\ProgramFiles\Anaconda3\lib\site-packages\django-1.11.8-py3.6.egg\django\template\base.py", line 513, in parse
    compiled_result = compile_func(self, token)
  File "D:\ProgramFiles\Anaconda3\lib\site-packages\django-1.11.8-py3.6.egg\django\template\loader_tags.py", line 255, in do_block
    nodelist = parser.parse(('endblock',))
  File "D:\ProgramFiles\Anaconda3\lib\site-packages\django-1.11.8-py3.6.egg\django\template\base.py", line 515, in parse
    raise self.error(token, e)
  File "D:\ProgramFiles\Anaconda3\lib\site-packages\django-1.11.8-py3.6.egg\django\template\base.py", line 513, in parse
    compiled_result = compile_func(self, token)
  File "D:\ProgramFiles\Anaconda3\lib\site-packages\django-1.11.8-py3.6.egg\django\template\defaulttags.py", line 983, in do_if
    nodelist = parser.parse(('endif',))
  File "D:\ProgramFiles\Anaconda3\lib\site-packages\django-1.11.8-py3.6.egg\django\template\base.py", line 509, in parse
    self.invalid_block_tag(token, command, parse_until)
  File "D:\ProgramFiles\Anaconda3\lib\site-packages\django-1.11.8-py3.6.egg\django\template\base.py", line 565, in invalid_block_tag
    get_text_list(["'%s'" % p for p in parse_until], 'or'),
django.template.exceptions.TemplateSyntaxError: Invalid block tag on line 2089: 'endblock', expected 'endif'. Did you forget to register or load this tag?
exception.py[2018-10-11 17:47:36][ERROR]：Internal Server Error: /again/huice/
Traceback (most recent call last):
  File "D:\ProgramFiles\Anaconda3\lib\site-packages\django-1.11.8-py3.6.egg\django\template\base.py", line 507, in parse
    compile_func = self.tags[command]
KeyError: 'endblock'

During handling of the above exception, another exception occurred:

Traceback (most recent call last):
  File "D:\ProgramFiles\Anaconda3\lib\site-packages\django-1.11.8-py3.6.egg\django\core\handlers\exception.py", line 41, in inner
    response = get_response(request)
  File "D:\ProgramFiles\Anaconda3\lib\site-packages\django-1.11.8-py3.6.egg\django\core\handlers\base.py", line 249, in _legacy_get_response
    response = self._get_response(request)
  File "D:\ProgramFiles\Anaconda3\lib\site-packages\django-1.11.8-py3.6.egg\django\core\handlers\base.py", line 187, in _get_response
    response = self.process_exception_by_middleware(e, request)
  File "D:\ProgramFiles\Anaconda3\lib\site-packages\django-1.11.8-py3.6.egg\django\core\handlers\base.py", line 185, in _get_response
    response = wrapped_callback(request, *callback_args, **callback_kwargs)
  File "D:\tools\Tools\Carry\mysite\views.py", line 2623, in interface_huice
    return render(rq, 'interface_huice.html', resp)
  File "D:\ProgramFiles\Anaconda3\lib\site-packages\django-1.11.8-py3.6.egg\django\shortcuts.py", line 30, in render
    content = loader.render_to_string(template_name, context, request, using=using)
  File "D:\ProgramFiles\Anaconda3\lib\site-packages\django-1.11.8-py3.6.egg\django\template\loader.py", line 67, in render_to_string
    template = get_template(template_name, using=using)
  File "D:\ProgramFiles\Anaconda3\lib\site-packages\django-1.11.8-py3.6.egg\django\template\loader.py", line 21, in get_template
    return engine.get_template(template_name)
  File "D:\ProgramFiles\Anaconda3\lib\site-packages\django-1.11.8-py3.6.egg\django\template\backends\django.py", line 39, in get_template
    return Template(self.engine.get_template(template_name), self)
  File "D:\ProgramFiles\Anaconda3\lib\site-packages\django-1.11.8-py3.6.egg\django\template\engine.py", line 162, in get_template
    template, origin = self.find_template(template_name)
  File "D:\ProgramFiles\Anaconda3\lib\site-packages\django-1.11.8-py3.6.egg\django\template\engine.py", line 136, in find_template
    name, template_dirs=dirs, skip=skip,
  File "D:\ProgramFiles\Anaconda3\lib\site-packages\django-1.11.8-py3.6.egg\django\template\loaders\base.py", line 44, in get_template
    contents, origin, origin.template_name, self.engine,
  File "D:\ProgramFiles\Anaconda3\lib\site-packages\django-1.11.8-py3.6.egg\django\template\base.py", line 191, in __init__
    self.nodelist = self.compile_nodelist()
  File "D:\ProgramFiles\Anaconda3\lib\site-packages\django-1.11.8-py3.6.egg\django\template\base.py", line 230, in compile_nodelist
    return parser.parse()
  File "D:\ProgramFiles\Anaconda3\lib\site-packages\django-1.11.8-py3.6.egg\django\template\base.py", line 515, in parse
    raise self.error(token, e)
  File "D:\ProgramFiles\Anaconda3\lib\site-packages\django-1.11.8-py3.6.egg\django\template\base.py", line 513, in parse
    compiled_result = compile_func(self, token)
  File "D:\ProgramFiles\Anaconda3\lib\site-packages\django-1.11.8-py3.6.egg\django\template\loader_tags.py", line 312, in do_extends
    nodelist = parser.parse()
  File "D:\ProgramFiles\Anaconda3\lib\site-packages\django-1.11.8-py3.6.egg\django\template\base.py", line 515, in parse
    raise self.error(token, e)
  File "D:\ProgramFiles\Anaconda3\lib\site-packages\django-1.11.8-py3.6.egg\django\template\base.py", line 513, in parse
    compiled_result = compile_func(self, token)
  File "D:\ProgramFiles\Anaconda3\lib\site-packages\django-1.11.8-py3.6.egg\django\template\loader_tags.py", line 255, in do_block
    nodelist = parser.parse(('endblock',))
  File "D:\ProgramFiles\Anaconda3\lib\site-packages\django-1.11.8-py3.6.egg\django\template\base.py", line 515, in parse
    raise self.error(token, e)
  File "D:\ProgramFiles\Anaconda3\lib\site-packages\django-1.11.8-py3.6.egg\django\template\base.py", line 513, in parse
    compiled_result = compile_func(self, token)
  File "D:\ProgramFiles\Anaconda3\lib\site-packages\django-1.11.8-py3.6.egg\django\template\defaulttags.py", line 983, in do_if
    nodelist = parser.parse(('endif',))
  File "D:\ProgramFiles\Anaconda3\lib\site-packages\django-1.11.8-py3.6.egg\django\template\base.py", line 509, in parse
    self.invalid_block_tag(token, command, parse_until)
  File "D:\ProgramFiles\Anaconda3\lib\site-packages\django-1.11.8-py3.6.egg\django\template\base.py", line 565, in invalid_block_tag
    get_text_list(["'%s'" % p for p in parse_until], 'or'),
django.template.exceptions.TemplateSyntaxError: Invalid block tag on line 2089: 'endblock', expected 'endif'. Did you forget to register or load this tag?
HSD.py[2018-10-11 17:54:58][ERROR]：文件 HSD.py 第1710行报错：division by zero
HSD.py[2018-10-11 18:41:45][ERROR]：文件 HSD.py 第1710行报错：division by zero
HSD.py[2018-10-11 18:48:19][ERROR]：文件 HSD.py 第1710行报错：division by zero
exception.py[2018-10-12 10:38:10][ERROR]：Internal Server Error: /cfmmc/login/
Traceback (most recent call last):
  File "D:\tools\Tools\Carry\mysite\HSD.py", line 368, in runSqlData
    cur.execute(sql, params)
  File "D:\ProgramFiles\Anaconda3\lib\site-packages\DBUtils\SteadyDB.py", line 605, in tough_method
    result = method(*args, **kwargs)  # try to execute
  File "D:\ProgramFiles\Anaconda3\lib\site-packages\pymysql\cursors.py", line 163, in execute
    query = self.mogrify(query, args)
  File "D:\ProgramFiles\Anaconda3\lib\site-packages\pymysql\cursors.py", line 142, in mogrify
    query = query % self._escape_args(args, conn)
TypeError: not enough arguments for format string

During handling of the above exception, another exception occurred:

Traceback (most recent call last):
  File "D:\ProgramFiles\Anaconda3\lib\site-packages\django-1.11.8-py3.6.egg\django\core\handlers\exception.py", line 41, in inner
    response = get_response(request)
  File "D:\ProgramFiles\Anaconda3\lib\site-packages\django-1.11.8-py3.6.egg\django\core\handlers\base.py", line 249, in _legacy_get_response
    response = self._get_response(request)
  File "D:\ProgramFiles\Anaconda3\lib\site-packages\django-1.11.8-py3.6.egg\django\core\handlers\base.py", line 187, in _get_response
    response = self.process_exception_by_middleware(e, request)
  File "D:\ProgramFiles\Anaconda3\lib\site-packages\django-1.11.8-py3.6.egg\django\core\handlers\base.py", line 185, in _get_response
    response = wrapped_callback(request, *callback_args, **callback_kwargs)
  File "D:\tools\Tools\Carry\mysite\views.py", line 2190, in cfmmc_login
    HSD.runSqlData('carry_investment',sql,(userID,password,'',1,createTime))
  File "D:\tools\Tools\Carry\mysite\HSD.py", line 376, in runSqlData
    cur.execute(sql, params)
  File "D:\ProgramFiles\Anaconda3\lib\site-packages\DBUtils\SteadyDB.py", line 605, in tough_method
    result = method(*args, **kwargs)  # try to execute
  File "D:\ProgramFiles\Anaconda3\lib\site-packages\pymysql\cursors.py", line 163, in execute
    query = self.mogrify(query, args)
  File "D:\ProgramFiles\Anaconda3\lib\site-packages\pymysql\cursors.py", line 142, in mogrify
    query = query % self._escape_args(args, conn)
TypeError: not enough arguments for format string
base.py[2018-10-12 10:38:11][WARNING]：Not Found: /favicon.ico
base.py[2018-10-12 10:44:17][WARNING]：Not Found: /cfmmc/
HSD.py[2018-10-12 11:10:10][ERROR]：文件 HSD.py 第1710行报错：division by zero
HSD.py[2018-10-12 11:13:43][ERROR]：文件 HSD.py 第1710行报错：division by zero
HSD.py[2018-10-12 11:42:28][ERROR]：文件 HSD.py 第1710行报错：division by zero
HSD.py[2018-10-12 11:47:07][ERROR]：文件 HSD.py 第1711行报错：division by zero
HSD.py[2018-10-12 11:52:55][ERROR]：文件 HSD.py 第1710行报错：division by zero
HSD.py[2018-10-12 11:53:31][ERROR]：文件 HSD.py 第1710行报错：division by zero
HSD.py[2018-10-12 12:07:56][ERROR]：文件 HSD.py 第1711行报错：division by zero
HSD.py[2018-10-12 12:12:07][ERROR]：文件 HSD.py 第1711行报错：division by zero
HSD.py[2018-10-12 13:57:10][ERROR]：文件 HSD.py 第1711行报错：division by zero
HSD.py[2018-10-12 14:26:34][ERROR]：文件 HSD.py 第1711行报错：division by zero
exception.py[2018-10-12 14:30:50][ERROR]：Internal Server Error: /again/huice/
Traceback (most recent call last):
  File "D:\ProgramFiles\Anaconda3\lib\site-packages\django-1.11.8-py3.6.egg\django\core\handlers\exception.py", line 41, in inner
    response = get_response(request)
  File "D:\ProgramFiles\Anaconda3\lib\site-packages\django-1.11.8-py3.6.egg\django\core\handlers\base.py", line 249, in _legacy_get_response
    response = self._get_response(request)
  File "D:\ProgramFiles\Anaconda3\lib\site-packages\django-1.11.8-py3.6.egg\django\core\handlers\base.py", line 187, in _get_response
    response = self.process_exception_by_middleware(e, request)
  File "D:\ProgramFiles\Anaconda3\lib\site-packages\django-1.11.8-py3.6.egg\django\core\handlers\base.py", line 185, in _get_response
    response = wrapped_callback(request, *callback_args, **callback_kwargs)
  File "D:\tools\Tools\Carry\mysite\views.py", line 2617, in interface_huice
    resp = viewUtil.get_interface_huice(hc_name)
  File "D:\tools\Tools\Carry\mysite\viewUtil.py", line 1254, in get_interface_huice
    results2, _ = HSD.huice_order_record(hc_name,datas)
ValueError: too many values to unpack (expected 2)
HSD.py[2018-10-12 14:32:19][ERROR]：文件 HSD.py 第1711行报错：division by zero
HSD.py[2018-10-12 16:49:51][ERROR]：文件 HSD.py 第1711行报错：division by zero
HSD.py[2018-10-12 16:57:24][ERROR]：文件 HSD.py 第1711行报错：division by zero
HSD.py[2018-10-12 16:57:48][ERROR]：文件 HSD.py 第1711行报错：division by zero
exception.py[2018-10-12 17:40:03][ERROR]：Internal Server Error: /again/huice/
Traceback (most recent call last):
  File "D:\ProgramFiles\Anaconda3\lib\site-packages\django-1.11.8-py3.6.egg\django\core\handlers\exception.py", line 41, in inner
    response = get_response(request)
  File "D:\ProgramFiles\Anaconda3\lib\site-packages\django-1.11.8-py3.6.egg\django\core\handlers\base.py", line 249, in _legacy_get_response
    response = self._get_response(request)
  File "D:\ProgramFiles\Anaconda3\lib\site-packages\django-1.11.8-py3.6.egg\django\core\handlers\base.py", line 187, in _get_response
    response = self.process_exception_by_middleware(e, request)
  File "D:\ProgramFiles\Anaconda3\lib\site-packages\django-1.11.8-py3.6.egg\django\core\handlers\base.py", line 185, in _get_response
    response = wrapped_callback(request, *callback_args, **callback_kwargs)
  File "D:\tools\Tools\Carry\mysite\views.py", line 2629, in interface_huice
    pzs = cfmmc.varieties()
NameError: name 'cfmmc' is not defined
HSD.py[2018-10-12 18:02:00][ERROR]：文件 HSD.py 第1711行报错：division by zero
exception.py[2018-10-12 18:02:04][ERROR]：Internal Server Error: /again/huice/
Traceback (most recent call last):
  File "D:\ProgramFiles\Anaconda3\lib\site-packages\django-1.11.8-py3.6.egg\django\core\handlers\exception.py", line 41, in inner
    response = get_response(request)
  File "D:\ProgramFiles\Anaconda3\lib\site-packages\django-1.11.8-py3.6.egg\django\core\handlers\base.py", line 249, in _legacy_get_response
    response = self._get_response(request)
  File "D:\ProgramFiles\Anaconda3\lib\site-packages\django-1.11.8-py3.6.egg\django\core\handlers\base.py", line 187, in _get_response
    response = self.process_exception_by_middleware(e, request)
  File "D:\ProgramFiles\Anaconda3\lib\site-packages\django-1.11.8-py3.6.egg\django\core\handlers\base.py", line 185, in _get_response
    response = wrapped_callback(request, *callback_args, **callback_kwargs)
  File "D:\tools\Tools\Carry\mysite\views.py", line 2631, in interface_huice
    pzs = cfmmc.varieties()
NameError: name 'cfmmc' is not defined
HSD.py[2018-10-12 18:03:17][ERROR]：文件 HSD.py 第1711行报错：division by zero
exception.py[2018-10-12 18:03:17][ERROR]：Internal Server Error: /again/huice/
Traceback (most recent call last):
  File "D:\ProgramFiles\Anaconda3\lib\site-packages\django-1.11.8-py3.6.egg\django\core\handlers\exception.py", line 41, in inner
    response = get_response(request)
  File "D:\ProgramFiles\Anaconda3\lib\site-packages\django-1.11.8-py3.6.egg\django\core\handlers\base.py", line 249, in _legacy_get_response
    response = self._get_response(request)
  File "D:\ProgramFiles\Anaconda3\lib\site-packages\django-1.11.8-py3.6.egg\django\core\handlers\base.py", line 187, in _get_response
    response = self.process_exception_by_middleware(e, request)
  File "D:\ProgramFiles\Anaconda3\lib\site-packages\django-1.11.8-py3.6.egg\django\core\handlers\base.py", line 185, in _get_response
    response = wrapped_callback(request, *callback_args, **callback_kwargs)
  File "D:\tools\Tools\Carry\mysite\views.py", line 2794, in interface_huice
    for d in data:
UnboundLocalError: local variable 'data' referenced before assignment
HSD.py[2018-10-12 18:18:41][ERROR]：文件 HSD.py 第1711行报错：division by zero
exception.py[2018-10-12 18:18:41][ERROR]：Internal Server Error: /again/huice/
Traceback (most recent call last):
  File "D:\ProgramFiles\Anaconda3\lib\site-packages\django-1.11.8-py3.6.egg\django\core\handlers\exception.py", line 41, in inner
    response = get_response(request)
  File "D:\ProgramFiles\Anaconda3\lib\site-packages\django-1.11.8-py3.6.egg\django\core\handlers\base.py", line 249, in _legacy_get_response
    response = self._get_response(request)
  File "D:\ProgramFiles\Anaconda3\lib\site-packages\django-1.11.8-py3.6.egg\django\core\handlers\base.py", line 187, in _get_response
    response = self.process_exception_by_middleware(e, request)
  File "D:\ProgramFiles\Anaconda3\lib\site-packages\django-1.11.8-py3.6.egg\django\core\handlers\base.py", line 185, in _get_response
    response = wrapped_callback(request, *callback_args, **callback_kwargs)
  File "D:\tools\Tools\Carry\mysite\views.py", line 2794, in interface_huice
    for d in data:
UnboundLocalError: local variable 'data' referenced before assignment
HSD.py[2018-10-15 08:57:52][ERROR]：文件 HSD.py 第1711行报错：division by zero
exception.py[2018-10-15 08:57:52][ERROR]：Internal Server Error: /again/huice/
Traceback (most recent call last):
  File "D:\ProgramFiles\Anaconda3\lib\site-packages\django-1.11.8-py3.6.egg\django\core\handlers\exception.py", line 41, in inner
    response = get_response(request)
  File "D:\ProgramFiles\Anaconda3\lib\site-packages\django-1.11.8-py3.6.egg\django\core\handlers\base.py", line 249, in _legacy_get_response
    response = self._get_response(request)
  File "D:\ProgramFiles\Anaconda3\lib\site-packages\django-1.11.8-py3.6.egg\django\core\handlers\base.py", line 187, in _get_response
    response = self.process_exception_by_middleware(e, request)
  File "D:\ProgramFiles\Anaconda3\lib\site-packages\django-1.11.8-py3.6.egg\django\core\handlers\base.py", line 185, in _get_response
    response = wrapped_callback(request, *callback_args, **callback_kwargs)
  File "D:\tools\Tools\Carry\mysite\views.py", line 2799, in interface_huice
    for d in data:
UnboundLocalError: local variable 'data' referenced before assignment
base.py[2018-10-15 08:57:52][WARNING]：Not Found: /favicon.ico
HSD.py[2018-10-15 10:09:26][ERROR]：文件 HSD.py 第1721行报错：division by zero
HSD.py[2018-10-15 10:10:37][ERROR]：文件 HSD.py 第1721行报错：division by zero
exception.py[2018-10-15 10:10:37][ERROR]：Internal Server Error: /again/huice/
Traceback (most recent call last):
  File "D:\ProgramFiles\Anaconda3\lib\site-packages\django-1.11.8-py3.6.egg\django\core\handlers\exception.py", line 41, in inner
    response = get_response(request)
  File "D:\ProgramFiles\Anaconda3\lib\site-packages\django-1.11.8-py3.6.egg\django\core\handlers\base.py", line 249, in _legacy_get_response
    response = self._get_response(request)
  File "D:\ProgramFiles\Anaconda3\lib\site-packages\django-1.11.8-py3.6.egg\django\core\handlers\base.py", line 187, in _get_response
    response = self.process_exception_by_middleware(e, request)
  File "D:\ProgramFiles\Anaconda3\lib\site-packages\django-1.11.8-py3.6.egg\django\core\handlers\base.py", line 185, in _get_response
    response = wrapped_callback(request, *callback_args, **callback_kwargs)
  File "D:\tools\Tools\Carry\mysite\views.py", line 2618, in interface_huice
    hc, huizong, init_money = viewUtil.get_interface_huice(hc_name)
ValueError: too many values to unpack (expected 3)
HSD.py[2018-10-15 10:10:42][ERROR]：文件 HSD.py 第1721行报错：division by zero
HSD.py[2018-10-15 10:11:59][ERROR]：文件 HSD.py 第1721行报错：division by zero
HSD.py[2018-10-15 10:12:02][ERROR]：文件 HSD.py 第1721行报错：division by zero
HSD.py[2018-10-15 10:12:04][ERROR]：文件 HSD.py 第1721行报错：division by zero
exception.py[2018-10-15 10:35:27][ERROR]：Internal Server Error: /again/huice/
Traceback (most recent call last):
  File "D:\ProgramFiles\Anaconda3\lib\site-packages\django-1.11.8-py3.6.egg\django\core\handlers\exception.py", line 41, in inner
    response = get_response(request)
  File "D:\ProgramFiles\Anaconda3\lib\site-packages\django-1.11.8-py3.6.egg\django\core\handlers\base.py", line 249, in _legacy_get_response
    response = self._get_response(request)
  File "D:\ProgramFiles\Anaconda3\lib\site-packages\django-1.11.8-py3.6.egg\django\core\handlers\base.py", line 187, in _get_response
    response = self.process_exception_by_middleware(e, request)
  File "D:\ProgramFiles\Anaconda3\lib\site-packages\django-1.11.8-py3.6.egg\django\core\handlers\base.py", line 185, in _get_response
    response = wrapped_callback(request, *callback_args, **callback_kwargs)
  File "D:\tools\Tools\Carry\mysite\views.py", line 2619, in interface_huice
    hc, huizong, init_money = data_huice.send(None)
  File "D:\tools\Tools\Carry\mysite\viewUtil.py", line 1305, in get_interface_huice
    hc, huizong = HSD.huices(res, huizong, init_money, None, str(datetime.datetime.now())[:10], pinzhong)
  File "D:\tools\Tools\Carry\mysite\HSD.py", line 1600, in huices
    if j[7] not in code_index:
IndexError: list index out of range
HSD.py[2018-10-15 10:42:47][ERROR]：文件 HSD.py 第1706行报错：division by zero
HSD.py[2018-10-15 10:43:28][ERROR]：文件 HSD.py 第1706行报错：division by zero
HSD.py[2018-10-15 10:43:28][ERROR]：文件 HSD.py 第1706行报错：division by zero
HSD.py[2018-10-15 10:48:26][ERROR]：文件 HSD.py 第1706行报错：division by zero
exception.py[2018-10-15 11:55:10][ERROR]：Internal Server Error: /moni/
Traceback (most recent call last):
  File "D:\ProgramFiles\Anaconda3\lib\site-packages\django-1.11.8-py3.6.egg\django\core\handlers\exception.py", line 41, in inner
    response = get_response(request)
  File "D:\ProgramFiles\Anaconda3\lib\site-packages\django-1.11.8-py3.6.egg\django\core\handlers\base.py", line 249, in _legacy_get_response
    response = self._get_response(request)
  File "D:\ProgramFiles\Anaconda3\lib\site-packages\django-1.11.8-py3.6.egg\django\core\handlers\base.py", line 187, in _get_response
    response = self.process_exception_by_middleware(e, request)
  File "D:\ProgramFiles\Anaconda3\lib\site-packages\django-1.11.8-py3.6.egg\django\core\handlers\base.py", line 185, in _get_response
    response = wrapped_callback(request, *callback_args, **callback_kwargs)
  File "D:\tools\Tools\Carry\mysite\views.py", line 1641, in moni
    reverse=reverse, param=param)
  File "D:\tools\Tools\Carry\mysite\HSD.py", line 1267, in main2
    res, first_time = self.trd(_fa, reverse=reverse, param=param)
  File "D:\tools\Tools\Carry\mysite\DataIndex.py", line 2610, in trd
    res, first_time = fa.send((True, dt3, dates, qzpc))
  File "D:\tools\Tools\Carry\mysite\DataIndex.py", line 2378, in fa19
    print(ma10,ma20,mas)
NameError: name 'ma20' is not defined
exception.py[2018-10-15 11:57:00][ERROR]：Internal Server Error: /moni/
Traceback (most recent call last):
  File "D:\ProgramFiles\Anaconda3\lib\site-packages\django-1.11.8-py3.6.egg\django\core\handlers\exception.py", line 41, in inner
    response = get_response(request)
  File "D:\ProgramFiles\Anaconda3\lib\site-packages\django-1.11.8-py3.6.egg\django\core\handlers\base.py", line 249, in _legacy_get_response
    response = self._get_response(request)
  File "D:\ProgramFiles\Anaconda3\lib\site-packages\django-1.11.8-py3.6.egg\django\core\handlers\base.py", line 187, in _get_response
    response = self.process_exception_by_middleware(e, request)
  File "D:\ProgramFiles\Anaconda3\lib\site-packages\django-1.11.8-py3.6.egg\django\core\handlers\base.py", line 185, in _get_response
    response = wrapped_callback(request, *callback_args, **callback_kwargs)
  File "D:\tools\Tools\Carry\mysite\views.py", line 1641, in moni
    reverse=reverse, param=param)
  File "D:\tools\Tools\Carry\mysite\HSD.py", line 1267, in main2
    res, first_time = self.trd(_fa, reverse=reverse, param=param)
  File "D:\tools\Tools\Carry\mysite\DataIndex.py", line 2607, in trd
    res, first_time = fa.send((True, dt3, dates, qzpc))
  File "D:\tools\Tools\Carry\mysite\DataIndex.py", line 2354, in fa19
    dt2['mul'], dt2['cd'], dt2['high'], dt2['low'], dt2['ma10'], dt2['ma120']
KeyError: 'ma10'
exception.py[2018-10-15 12:00:39][ERROR]：Internal Server Error: /moni/
Traceback (most recent call last):
  File "D:\ProgramFiles\Anaconda3\lib\site-packages\django-1.11.8-py3.6.egg\django\core\handlers\exception.py", line 41, in inner
    response = get_response(request)
  File "D:\ProgramFiles\Anaconda3\lib\site-packages\django-1.11.8-py3.6.egg\django\core\handlers\base.py", line 249, in _legacy_get_response
    response = self._get_response(request)
  File "D:\ProgramFiles\Anaconda3\lib\site-packages\django-1.11.8-py3.6.egg\django\core\handlers\base.py", line 187, in _get_response
    response = self.process_exception_by_middleware(e, request)
  File "D:\ProgramFiles\Anaconda3\lib\site-packages\django-1.11.8-py3.6.egg\django\core\handlers\base.py", line 185, in _get_response
    response = wrapped_callback(request, *callback_args, **callback_kwargs)
  File "D:\tools\Tools\Carry\mysite\views.py", line 1641, in moni
    reverse=reverse, param=param)
  File "D:\tools\Tools\Carry\mysite\HSD.py", line 1267, in main2
    res, first_time = self.trd(_fa, reverse=reverse, param=param)
  File "D:\tools\Tools\Carry\mysite\DataIndex.py", line 2600, in trd
    dt3 = data2.send(df2)
  File "D:\tools\Tools\Carry\mysite\DataIndex.py", line 258, in vis
    dc[ind]['ma10'] = sum(da[ind - j][4] for j in range(10)) / 10  # 移动平均值 10均线
  File "D:\tools\Tools\Carry\mysite\DataIndex.py", line 258, in <genexpr>
    dc[ind]['ma10'] = sum(da[ind - j][4] for j in range(10)) / 10  # 移动平均值 10均线
IndexError: tuple index out of range
exception.py[2018-10-15 12:02:46][ERROR]：Internal Server Error: /moni/
Traceback (most recent call last):
  File "D:\ProgramFiles\Anaconda3\lib\site-packages\django-1.11.8-py3.6.egg\django\core\handlers\exception.py", line 41, in inner
    response = get_response(request)
  File "D:\ProgramFiles\Anaconda3\lib\site-packages\django-1.11.8-py3.6.egg\django\core\handlers\base.py", line 249, in _legacy_get_response
    response = self._get_response(request)
  File "D:\ProgramFiles\Anaconda3\lib\site-packages\django-1.11.8-py3.6.egg\django\core\handlers\base.py", line 187, in _get_response
    response = self.process_exception_by_middleware(e, request)
  File "D:\ProgramFiles\Anaconda3\lib\site-packages\django-1.11.8-py3.6.egg\django\core\handlers\base.py", line 185, in _get_response
    response = wrapped_callback(request, *callback_args, **callback_kwargs)
  File "D:\tools\Tools\Carry\mysite\views.py", line 1641, in moni
    reverse=reverse, param=param)
  File "D:\tools\Tools\Carry\mysite\HSD.py", line 1267, in main2
    res, first_time = self.trd(_fa, reverse=reverse, param=param)
  File "D:\tools\Tools\Carry\mysite\DataIndex.py", line 2600, in trd
    dt3 = data2.send(df2)
  File "D:\tools\Tools\Carry\mysite\DataIndex.py", line 258, in vis
    dc[ind]['ma10'] = sum(da[ind - j]['close'] for j in range(10)) / 10  # 移动平均值 10均线
  File "D:\tools\Tools\Carry\mysite\DataIndex.py", line 258, in <genexpr>
    dc[ind]['ma10'] = sum(da[ind - j]['close'] for j in range(10)) / 10  # 移动平均值 10均线
IndexError: tuple index out of range
base.py[2018-10-16 09:33:00][WARNING]：Not Found: /favicon.ico
base.py[2018-10-16 09:49:48][WARNING]：Not Found: /favicon.ico
HSD.py[2018-10-16 09:52:39][ERROR]：文件 HSD.py 第1706行报错：division by zero
exception.py[2018-10-16 10:48:27][ERROR]：Internal Server Error: /moni/
Traceback (most recent call last):
  File "D:\ProgramFiles\Anaconda3\lib\site-packages\django-1.11.8-py3.6.egg\django\core\handlers\exception.py", line 41, in inner
    response = get_response(request)
  File "D:\ProgramFiles\Anaconda3\lib\site-packages\django-1.11.8-py3.6.egg\django\core\handlers\base.py", line 249, in _legacy_get_response
    response = self._get_response(request)
  File "D:\ProgramFiles\Anaconda3\lib\site-packages\django-1.11.8-py3.6.egg\django\core\handlers\base.py", line 187, in _get_response
    response = self.process_exception_by_middleware(e, request)
  File "D:\ProgramFiles\Anaconda3\lib\site-packages\django-1.11.8-py3.6.egg\django\core\handlers\base.py", line 185, in _get_response
    response = wrapped_callback(request, *callback_args, **callback_kwargs)
  File "D:\tools\Tools\Carry\mysite\views.py", line 1635, in moni
    red_key = ''.join(('moni', dates, end_date, fa, database, reverse, zsds, ydzs, zyds, cqdc))
TypeError: sequence item 1: expected str instance, NoneType found
exception.py[2018-10-16 10:51:07][ERROR]：Internal Server Error: /moni/
Traceback (most recent call last):
  File "D:\ProgramFiles\Anaconda3\lib\site-packages\django-1.11.8-py3.6.egg\django\core\handlers\exception.py", line 41, in inner
    response = get_response(request)
  File "D:\ProgramFiles\Anaconda3\lib\site-packages\django-1.11.8-py3.6.egg\django\core\handlers\base.py", line 249, in _legacy_get_response
    response = self._get_response(request)
  File "D:\ProgramFiles\Anaconda3\lib\site-packages\django-1.11.8-py3.6.egg\django\core\handlers\base.py", line 187, in _get_response
    response = self.process_exception_by_middleware(e, request)
  File "D:\ProgramFiles\Anaconda3\lib\site-packages\django-1.11.8-py3.6.egg\django\core\handlers\base.py", line 185, in _get_response
    response = wrapped_callback(request, *callback_args, **callback_kwargs)
  File "D:\tools\Tools\Carry\mysite\views.py", line 1635, in moni
    red_key = ''.join(('moni', dates, end_date, fa, database, reverse, zsds, ydzs, zyds, cqdc))
TypeError: sequence item 3: expected str instance, NoneType found
exception.py[2018-10-16 10:51:36][ERROR]：Internal Server Error: /moni/
Traceback (most recent call last):
  File "D:\ProgramFiles\Anaconda3\lib\site-packages\django-1.11.8-py3.6.egg\django\core\handlers\exception.py", line 41, in inner
    response = get_response(request)
  File "D:\ProgramFiles\Anaconda3\lib\site-packages\django-1.11.8-py3.6.egg\django\core\handlers\base.py", line 249, in _legacy_get_response
    response = self._get_response(request)
  File "D:\ProgramFiles\Anaconda3\lib\site-packages\django-1.11.8-py3.6.egg\django\core\handlers\base.py", line 187, in _get_response
    response = self.process_exception_by_middleware(e, request)
  File "D:\ProgramFiles\Anaconda3\lib\site-packages\django-1.11.8-py3.6.egg\django\core\handlers\base.py", line 185, in _get_response
    response = wrapped_callback(request, *callback_args, **callback_kwargs)
  File "D:\tools\Tools\Carry\mysite\views.py", line 1636, in moni
    red_key = ''.join(('moni', dates, end_date, fa, database, reverse, zsds, ydzs, zyds, cqdc))
TypeError: sequence item 3: expected str instance, NoneType found
HSD.py[2018-10-16 10:58:25][ERROR]：文件：manage.py 第233行报错： Object of type 'method' is not JSON serializable
HSD.py[2018-10-16 10:58:56][ERROR]：文件：manage.py 第233行报错： Object of type 'method' is not JSON serializable
HSD.py[2018-10-16 11:05:13][ERROR]：文件：manage.py 第233行报错： Object of type 'method' is not JSON serializable
HSD.py[2018-10-16 11:10:17][ERROR]：文件：manage.py 第233行报错： Object of type 'method' is not JSON serializable
HSD.py[2018-10-16 11:10:34][ERROR]：文件：manage.py 第233行报错： Object of type 'method' is not JSON serializable
exception.py[2018-10-16 11:47:27][ERROR]：Internal Server Error: /moni/
Traceback (most recent call last):
  File "D:\ProgramFiles\Anaconda3\lib\site-packages\django-1.11.8-py3.6.egg\django\core\handlers\exception.py", line 41, in inner
    response = get_response(request)
  File "D:\ProgramFiles\Anaconda3\lib\site-packages\django-1.11.8-py3.6.egg\django\core\handlers\base.py", line 249, in _legacy_get_response
    response = self._get_response(request)
  File "D:\ProgramFiles\Anaconda3\lib\site-packages\django-1.11.8-py3.6.egg\django\core\handlers\base.py", line 187, in _get_response
    response = self.process_exception_by_middleware(e, request)
  File "D:\ProgramFiles\Anaconda3\lib\site-packages\django-1.11.8-py3.6.egg\django\core\handlers\base.py", line 185, in _get_response
    response = wrapped_callback(request, *callback_args, **callback_kwargs)
  File "D:\tools\Tools\Carry\mysite\views.py", line 1667, in moni
    end_date = str(dates - datetime.timedelta(days=1))[:10]  # + datetime.timedelta(days=1)
TypeError: unsupported operand type(s) for -: 'str' and 'datetime.timedelta'
