base.py[2018-03-07 16:35:00][WARNING]：Not Found: /favicon.ico
base.py[2018-03-07 18:16:24][WARNING]：Not Found: /favicon.ico
HSD.py[2018-03-08 11:47:49][ERROR]：list index out of range
HSD.py[2018-03-08 11:48:01][ERROR]：list index out of range
HSD.py[2018-03-08 11:48:11][ERROR]：list index out of range
HSD.py[2018-03-08 11:48:14][ERROR]：list indices must be integers or slices, not str
HSD.py[2018-03-08 11:48:33][ERROR]：list index out of range
HSD.py[2018-03-08 11:48:34][ERROR]：list index out of range
HSD.py[2018-03-08 11:48:36][ERROR]：list index out of range
HSD.py[2018-03-08 11:48:44][ERROR]：list index out of range
HSD.py[2018-03-08 11:48:50][ERROR]：list indices must be integers or slices, not str
HSD.py[2018-03-08 11:48:50][ERROR]：list index out of range
HSD.py[2018-03-08 11:48:57][ERROR]：list index out of range
exception.py[2018-03-08 11:48:57][ERROR]：Internal Server Error: /jyzt/
Traceback (most recent call last):
  File "D:\ProgramFiles\Anaconda3\lib\site-packages\django-1.11.8-py3.6.egg\django\core\handlers\exception.py", line 41, in inner
    response = get_response(request)
  File "D:\ProgramFiles\Anaconda3\lib\site-packages\django-1.11.8-py3.6.egg\django\core\handlers\base.py", line 249, in _legacy_get_response
    response = self._get_response(request)
  File "D:\ProgramFiles\Anaconda3\lib\site-packages\django-1.11.8-py3.6.egg\django\core\handlers\base.py", line 187, in _get_response
    response = self.process_exception_by_middleware(e, request)
  File "D:\ProgramFiles\Anaconda3\lib\site-packages\django-1.11.8-py3.6.egg\django\core\handlers\base.py", line 185, in _get_response
    response = wrapped_callback(request, *callback_args, **callback_kwargs)
  File "D:\tools\Tools\2018年3月5日\Carry\mysite\views.py", line 530, in jyzt
    zt = ZT.yanzen()
  File "D:\tools\Tools\2018年3月5日\Carry\mysite\HSD.py", line 495, in yanzen
    with open('log\\jyzt_gp.txt') as f: # 保存
FileNotFoundError: [Errno 2] No such file or directory: 'log\\jyzt_gp.txt'
HSD.py[2018-03-08 11:50:58][ERROR]：list index out of range
HSD.py[2018-03-08 11:51:06][ERROR]：list index out of range
HSD.py[2018-03-08 11:51:16][ERROR]：list index out of range
HSD.py[2018-03-08 11:51:19][ERROR]：list indices must be integers or slices, not str
HSD.py[2018-03-08 11:51:33][ERROR]：list index out of range
HSD.py[2018-03-08 11:51:35][ERROR]：list index out of range
HSD.py[2018-03-08 11:51:37][ERROR]：list index out of range
HSD.py[2018-03-08 11:51:45][ERROR]：list index out of range
HSD.py[2018-03-08 11:51:50][ERROR]：list indices must be integers or slices, not str
HSD.py[2018-03-08 11:51:50][ERROR]：list index out of range
HSD.py[2018-03-08 11:51:55][ERROR]：list index out of range
base.py[2018-03-08 12:05:45][WARNING]：Not Found: /zhangting/jyzt
base.py[2018-03-08 12:05:57][WARNING]：Not Found: /zyzt
base.py[2018-03-08 12:06:11][WARNING]：Not Found: /zyzt/
base.py[2018-03-08 12:06:16][WARNING]：Not Found: /zyzt
base.py[2018-03-08 13:33:22][WARNING]：Not Found: /jyzt/
base.py[2018-03-08 15:20:08][WARNING]：Not Found: /favicon.ico
base.py[2018-03-08 15:20:09][WARNING]：Not Found: /favicon.ico
base.py[2018-03-08 15:20:09][WARNING]：Not Found: /favicon.ico
views.py[2018-03-08 15:28:48][ERROR]：Object of type 'datetime' is not JSON serializable
views.py[2018-03-08 15:45:50][ERROR]：name 'cache' is not defined
views.py[2018-03-08 15:45:50][ERROR]：name 'cache' is not defined
views.py[2018-03-08 15:45:50][ERROR]：name 'cache' is not defined
views.py[2018-03-08 15:45:50][ERROR]：name 'cache' is not defined
views.py[2018-03-08 15:46:04][ERROR]：name 'cache' is not defined
views.py[2018-03-08 15:46:04][ERROR]：name 'cache' is not defined
views.py[2018-03-08 15:46:04][ERROR]：name 'cache' is not defined
views.py[2018-03-08 15:46:04][ERROR]：name 'cache' is not defined
views.py[2018-03-08 15:46:04][ERROR]：name 'cache' is not defined
views.py[2018-03-08 15:46:04][ERROR]：name 'cache' is not defined
exception.py[2018-03-08 15:46:04][ERROR]：Internal Server Error: /getkline
Traceback (most recent call last):
  File "D:\ProgramFiles\Anaconda3\lib\site-packages\django-1.11.8-py3.6.egg\django\core\handlers\exception.py", line 41, in inner
    response = get_response(request)
  File "D:\ProgramFiles\Anaconda3\lib\site-packages\django-1.11.8-py3.6.egg\django\core\handlers\base.py", line 249, in _legacy_get_response
    response = self._get_response(request)
  File "D:\ProgramFiles\Anaconda3\lib\site-packages\django-1.11.8-py3.6.egg\django\core\handlers\base.py", line 187, in _get_response
    response = self.process_exception_by_middleware(e, request)
  File "D:\ProgramFiles\Anaconda3\lib\site-packages\django-1.11.8-py3.6.egg\django\core\handlers\base.py", line 185, in _get_response
    response = wrapped_callback(request, *callback_args, **callback_kwargs)
  File "D:\ProgramFiles\Anaconda3\lib\site-packages\django-1.11.8-py3.6.egg\django\utils\decorators.py", line 149, in _wrapped_view
    response = view_func(request, *args, **kwargs)
  File "D:\ProgramFiles\Anaconda3\lib\site-packages\dwebsocket\decorators.py", line 16, in new_func
    response = func(request, *args, **kwargs)
  File "D:\ProgramFiles\Anaconda3\lib\site-packages\django-1.11.8-py3.6.egg\django\views\decorators\csrf.py", line 58, in wrapped_view
    return view_func(*args, **kwargs)
  File "D:\tools\Tools\2018年3月5日\Carry\mysite\views.py", line 526, in getkline
    times,opens,high,low,close,vol=objArr #if objArr else (ticker.TickerTime*1000,ticker.Price,ticker.Price,ticker.Price,ticker.Price,ticker.Qty)
TypeError: 'NoneType' object is not iterable
views.py[2018-03-08 15:46:16][ERROR]：name 'cache' is not defined
views.py[2018-03-08 15:46:17][ERROR]：name 'cache' is not defined
views.py[2018-03-08 15:46:17][ERROR]：name 'cache' is not defined
views.py[2018-03-08 15:46:17][ERROR]：name 'cache' is not defined
views.py[2018-03-08 15:46:17][ERROR]：name 'cache' is not defined
views.py[2018-03-08 15:46:17][ERROR]：name 'cache' is not defined
exception.py[2018-03-08 15:46:17][ERROR]：Internal Server Error: /getkline
Traceback (most recent call last):
  File "D:\ProgramFiles\Anaconda3\lib\site-packages\django-1.11.8-py3.6.egg\django\core\handlers\exception.py", line 41, in inner
    response = get_response(request)
  File "D:\ProgramFiles\Anaconda3\lib\site-packages\django-1.11.8-py3.6.egg\django\core\handlers\base.py", line 249, in _legacy_get_response
    response = self._get_response(request)
  File "D:\ProgramFiles\Anaconda3\lib\site-packages\django-1.11.8-py3.6.egg\django\core\handlers\base.py", line 187, in _get_response
    response = self.process_exception_by_middleware(e, request)
  File "D:\ProgramFiles\Anaconda3\lib\site-packages\django-1.11.8-py3.6.egg\django\core\handlers\base.py", line 185, in _get_response
    response = wrapped_callback(request, *callback_args, **callback_kwargs)
  File "D:\ProgramFiles\Anaconda3\lib\site-packages\django-1.11.8-py3.6.egg\django\utils\decorators.py", line 149, in _wrapped_view
    response = view_func(request, *args, **kwargs)
  File "D:\ProgramFiles\Anaconda3\lib\site-packages\dwebsocket\decorators.py", line 16, in new_func
    response = func(request, *args, **kwargs)
  File "D:\ProgramFiles\Anaconda3\lib\site-packages\django-1.11.8-py3.6.egg\django\views\decorators\csrf.py", line 58, in wrapped_view
    return view_func(*args, **kwargs)
  File "D:\tools\Tools\2018年3月5日\Carry\mysite\views.py", line 526, in getkline
    times,opens,high,low,close,vol=objArr #if objArr else (ticker.TickerTime*1000,ticker.Price,ticker.Price,ticker.Price,ticker.Price,ticker.Qty)
TypeError: 'NoneType' object is not iterable
views.py[2018-03-08 15:47:05][ERROR]：name 'cache' is not defined
views.py[2018-03-08 15:47:05][ERROR]：name 'cache' is not defined
views.py[2018-03-08 15:47:05][ERROR]：name 'cache' is not defined
views.py[2018-03-08 15:47:05][ERROR]：name 'cache' is not defined
views.py[2018-03-08 15:47:08][ERROR]：name 'cache' is not defined
views.py[2018-03-08 15:47:09][ERROR]：name 'cache' is not defined
views.py[2018-03-08 15:47:09][ERROR]：name 'cache' is not defined
views.py[2018-03-08 15:47:09][ERROR]：name 'cache' is not defined
views.py[2018-03-08 15:47:09][ERROR]：name 'cache' is not defined
views.py[2018-03-08 15:47:09][ERROR]：name 'cache' is not defined
exception.py[2018-03-08 15:47:09][ERROR]：Internal Server Error: /getkline
Traceback (most recent call last):
  File "D:\ProgramFiles\Anaconda3\lib\site-packages\django-1.11.8-py3.6.egg\django\core\handlers\exception.py", line 41, in inner
    response = get_response(request)
  File "D:\ProgramFiles\Anaconda3\lib\site-packages\django-1.11.8-py3.6.egg\django\core\handlers\base.py", line 249, in _legacy_get_response
    response = self._get_response(request)
  File "D:\ProgramFiles\Anaconda3\lib\site-packages\django-1.11.8-py3.6.egg\django\core\handlers\base.py", line 187, in _get_response
    response = self.process_exception_by_middleware(e, request)
  File "D:\ProgramFiles\Anaconda3\lib\site-packages\django-1.11.8-py3.6.egg\django\core\handlers\base.py", line 185, in _get_response
    response = wrapped_callback(request, *callback_args, **callback_kwargs)
  File "D:\ProgramFiles\Anaconda3\lib\site-packages\django-1.11.8-py3.6.egg\django\utils\decorators.py", line 149, in _wrapped_view
    response = view_func(request, *args, **kwargs)
  File "D:\ProgramFiles\Anaconda3\lib\site-packages\dwebsocket\decorators.py", line 16, in new_func
    response = func(request, *args, **kwargs)
  File "D:\ProgramFiles\Anaconda3\lib\site-packages\django-1.11.8-py3.6.egg\django\views\decorators\csrf.py", line 58, in wrapped_view
    return view_func(*args, **kwargs)
  File "D:\tools\Tools\2018年3月5日\Carry\mysite\views.py", line 527, in getkline
    times,opens,high,low,close,vol=objArr #if objArr else (ticker.TickerTime*1000,ticker.Price,ticker.Price,ticker.Price,ticker.Price,ticker.Qty)
TypeError: 'NoneType' object is not iterable
base.py[2018-03-08 17:44:08][WARNING]：Not Found: /favicon.ico
base.py[2018-03-09 09:54:06][WARNING]：Not Found: /favicon.ico
base.py[2018-03-12 09:04:42][WARNING]：Not Found: /favicon.ico
exception.py[2018-03-12 13:26:00][ERROR]：Internal Server Error: /getkline
Traceback (most recent call last):
  File "D:\ProgramFiles\Anaconda3\lib\site-packages\django-1.11.8-py3.6.egg\django\core\handlers\exception.py", line 41, in inner
    response = get_response(request)
  File "D:\ProgramFiles\Anaconda3\lib\site-packages\django-1.11.8-py3.6.egg\django\core\handlers\base.py", line 249, in _legacy_get_response
    response = self._get_response(request)
  File "D:\ProgramFiles\Anaconda3\lib\site-packages\django-1.11.8-py3.6.egg\django\core\handlers\base.py", line 187, in _get_response
    response = self.process_exception_by_middleware(e, request)
  File "D:\ProgramFiles\Anaconda3\lib\site-packages\django-1.11.8-py3.6.egg\django\core\handlers\base.py", line 185, in _get_response
    response = wrapped_callback(request, *callback_args, **callback_kwargs)
  File "D:\ProgramFiles\Anaconda3\lib\site-packages\django-1.11.8-py3.6.egg\django\utils\decorators.py", line 149, in _wrapped_view
    response = view_func(request, *args, **kwargs)
  File "D:\ProgramFiles\Anaconda3\lib\site-packages\dwebsocket\decorators.py", line 16, in new_func
    response = func(request, *args, **kwargs)
  File "D:\ProgramFiles\Anaconda3\lib\site-packages\django-1.11.8-py3.6.egg\django\views\decorators\csrf.py", line 58, in wrapped_view
    return view_func(*args, **kwargs)
  File "D:\tools\Tools\2018年3月5日\Carry\mysite\views.py", line 523, in getkline
    if is_time and int(times/60)==int(is_time/60): #若不满一分钟,修改数据
OverflowError: integer division result too large for a float
exception.py[2018-03-12 13:28:08][ERROR]：Internal Server Error: /getkline
Traceback (most recent call last):
  File "D:\ProgramFiles\Anaconda3\lib\site-packages\django-1.11.8-py3.6.egg\django\core\handlers\exception.py", line 41, in inner
    response = get_response(request)
  File "D:\ProgramFiles\Anaconda3\lib\site-packages\django-1.11.8-py3.6.egg\django\core\handlers\base.py", line 249, in _legacy_get_response
    response = self._get_response(request)
  File "D:\ProgramFiles\Anaconda3\lib\site-packages\django-1.11.8-py3.6.egg\django\core\handlers\base.py", line 187, in _get_response
    response = self.process_exception_by_middleware(e, request)
  File "D:\ProgramFiles\Anaconda3\lib\site-packages\django-1.11.8-py3.6.egg\django\core\handlers\base.py", line 185, in _get_response
    response = wrapped_callback(request, *callback_args, **callback_kwargs)
  File "D:\ProgramFiles\Anaconda3\lib\site-packages\django-1.11.8-py3.6.egg\django\utils\decorators.py", line 149, in _wrapped_view
    response = view_func(request, *args, **kwargs)
  File "D:\ProgramFiles\Anaconda3\lib\site-packages\dwebsocket\decorators.py", line 16, in new_func
    response = func(request, *args, **kwargs)
  File "D:\ProgramFiles\Anaconda3\lib\site-packages\django-1.11.8-py3.6.egg\django\views\decorators\csrf.py", line 58, in wrapped_view
    return view_func(*args, **kwargs)
  File "D:\tools\Tools\2018年3月5日\Carry\mysite\views.py", line 524, in getkline
    if is_time and int(times/60)==int(is_time/60): #若不满一分钟,修改数据
OverflowError: integer division result too large for a float
exception.py[2018-03-12 13:29:36][ERROR]：Internal Server Error: /getkline
Traceback (most recent call last):
  File "D:\ProgramFiles\Anaconda3\lib\site-packages\django-1.11.8-py3.6.egg\django\core\handlers\exception.py", line 41, in inner
    response = get_response(request)
  File "D:\ProgramFiles\Anaconda3\lib\site-packages\django-1.11.8-py3.6.egg\django\core\handlers\base.py", line 249, in _legacy_get_response
    response = self._get_response(request)
  File "D:\ProgramFiles\Anaconda3\lib\site-packages\django-1.11.8-py3.6.egg\django\core\handlers\base.py", line 187, in _get_response
    response = self.process_exception_by_middleware(e, request)
  File "D:\ProgramFiles\Anaconda3\lib\site-packages\django-1.11.8-py3.6.egg\django\core\handlers\base.py", line 185, in _get_response
    response = wrapped_callback(request, *callback_args, **callback_kwargs)
  File "D:\ProgramFiles\Anaconda3\lib\site-packages\django-1.11.8-py3.6.egg\django\utils\decorators.py", line 149, in _wrapped_view
    response = view_func(request, *args, **kwargs)
  File "D:\ProgramFiles\Anaconda3\lib\site-packages\dwebsocket\decorators.py", line 16, in new_func
    response = func(request, *args, **kwargs)
  File "D:\ProgramFiles\Anaconda3\lib\site-packages\django-1.11.8-py3.6.egg\django\views\decorators\csrf.py", line 58, in wrapped_view
    return view_func(*args, **kwargs)
  File "D:\tools\Tools\2018年3月5日\Carry\mysite\views.py", line 523, in getkline
    print('times......',int(times),int(is_time))
TypeError: int() argument must be a string, a bytes-like object or a number, not 'NoneType'
exception.py[2018-03-12 19:32:41][ERROR]：Internal Server Error: /tj/4
Traceback (most recent call last):
  File "D:\ProgramFiles\Anaconda3\lib\site-packages\django-1.11.8-py3.6.egg\django\template\defaulttags.py", line 1038, in find_library
    return parser.libraries[name]
KeyError: 'mvote'

During handling of the above exception, another exception occurred:

Traceback (most recent call last):
  File "D:\ProgramFiles\Anaconda3\lib\site-packages\django-1.11.8-py3.6.egg\django\core\handlers\exception.py", line 41, in inner
    response = get_response(request)
  File "D:\ProgramFiles\Anaconda3\lib\site-packages\django-1.11.8-py3.6.egg\django\core\handlers\base.py", line 249, in _legacy_get_response
    response = self._get_response(request)
  File "D:\ProgramFiles\Anaconda3\lib\site-packages\django-1.11.8-py3.6.egg\django\core\handlers\base.py", line 187, in _get_response
    response = self.process_exception_by_middleware(e, request)
  File "D:\ProgramFiles\Anaconda3\lib\site-packages\django-1.11.8-py3.6.egg\django\core\handlers\base.py", line 185, in _get_response
    response = wrapped_callback(request, *callback_args, **callback_kwargs)
  File "D:\tools\Tools\2018年3月5日\Carry\mysite\views.py", line 374, in tongji
    return render(rq,'tongji.html',{'results':results,'dates':rq_date,'ids':HSD.IDS,'huizong':huizong,'id_name':id_name})
  File "D:\ProgramFiles\Anaconda3\lib\site-packages\django-1.11.8-py3.6.egg\django\shortcuts.py", line 30, in render
    content = loader.render_to_string(template_name, context, request, using=using)
  File "D:\ProgramFiles\Anaconda3\lib\site-packages\django-1.11.8-py3.6.egg\django\template\loader.py", line 67, in render_to_string
    template = get_template(template_name, using=using)
  File "D:\ProgramFiles\Anaconda3\lib\site-packages\django-1.11.8-py3.6.egg\django\template\loader.py", line 21, in get_template
    return engine.get_template(template_name)
  File "D:\ProgramFiles\Anaconda3\lib\site-packages\django-1.11.8-py3.6.egg\django\template\backends\django.py", line 39, in get_template
    return Template(self.engine.get_template(template_name), self)
  File "D:\ProgramFiles\Anaconda3\lib\site-packages\django-1.11.8-py3.6.egg\django\template\engine.py", line 162, in get_template
    template, origin = self.find_template(template_name)
  File "D:\ProgramFiles\Anaconda3\lib\site-packages\django-1.11.8-py3.6.egg\django\template\engine.py", line 136, in find_template
    name, template_dirs=dirs, skip=skip,
  File "D:\ProgramFiles\Anaconda3\lib\site-packages\django-1.11.8-py3.6.egg\django\template\loaders\base.py", line 44, in get_template
    contents, origin, origin.template_name, self.engine,
  File "D:\ProgramFiles\Anaconda3\lib\site-packages\django-1.11.8-py3.6.egg\django\template\base.py", line 191, in __init__
    self.nodelist = self.compile_nodelist()
  File "D:\ProgramFiles\Anaconda3\lib\site-packages\django-1.11.8-py3.6.egg\django\template\base.py", line 230, in compile_nodelist
    return parser.parse()
  File "D:\ProgramFiles\Anaconda3\lib\site-packages\django-1.11.8-py3.6.egg\django\template\base.py", line 515, in parse
    raise self.error(token, e)
  File "D:\ProgramFiles\Anaconda3\lib\site-packages\django-1.11.8-py3.6.egg\django\template\base.py", line 513, in parse
    compiled_result = compile_func(self, token)
  File "D:\ProgramFiles\Anaconda3\lib\site-packages\django-1.11.8-py3.6.egg\django\template\loader_tags.py", line 312, in do_extends
    nodelist = parser.parse()
  File "D:\ProgramFiles\Anaconda3\lib\site-packages\django-1.11.8-py3.6.egg\django\template\base.py", line 515, in parse
    raise self.error(token, e)
  File "D:\ProgramFiles\Anaconda3\lib\site-packages\django-1.11.8-py3.6.egg\django\template\base.py", line 513, in parse
    compiled_result = compile_func(self, token)
  File "D:\ProgramFiles\Anaconda3\lib\site-packages\django-1.11.8-py3.6.egg\django\template\loader_tags.py", line 255, in do_block
    nodelist = parser.parse(('endblock',))
  File "D:\ProgramFiles\Anaconda3\lib\site-packages\django-1.11.8-py3.6.egg\django\template\base.py", line 515, in parse
    raise self.error(token, e)
  File "D:\ProgramFiles\Anaconda3\lib\site-packages\django-1.11.8-py3.6.egg\django\template\base.py", line 513, in parse
    compiled_result = compile_func(self, token)
  File "D:\ProgramFiles\Anaconda3\lib\site-packages\django-1.11.8-py3.6.egg\django\template\defaulttags.py", line 977, in do_if
    nodelist = parser.parse(('elif', 'else', 'endif'))
  File "D:\ProgramFiles\Anaconda3\lib\site-packages\django-1.11.8-py3.6.egg\django\template\base.py", line 515, in parse
    raise self.error(token, e)
  File "D:\ProgramFiles\Anaconda3\lib\site-packages\django-1.11.8-py3.6.egg\django\template\base.py", line 513, in parse
    compiled_result = compile_func(self, token)
  File "D:\ProgramFiles\Anaconda3\lib\site-packages\django-1.11.8-py3.6.egg\django\template\defaulttags.py", line 1095, in load
    lib = find_library(parser, name)
  File "D:\ProgramFiles\Anaconda3\lib\site-packages\django-1.11.8-py3.6.egg\django\template\defaulttags.py", line 1042, in find_library
    name, "\n".join(sorted(parser.libraries.keys())),
django.template.exceptions.TemplateSyntaxError: 'mvote' is not a registered tag library. Must be one of:
admin_list
admin_modify
admin_static
admin_urls
cache
i18n
l10n
log
static
staticfiles
tz
exception.py[2018-03-12 19:33:31][ERROR]：Internal Server Error: /tj/4
Traceback (most recent call last):
  File "D:\ProgramFiles\Anaconda3\lib\site-packages\django-1.11.8-py3.6.egg\django\template\defaulttags.py", line 1038, in find_library
    return parser.libraries[name]
KeyError: 'mvote'

During handling of the above exception, another exception occurred:

Traceback (most recent call last):
  File "D:\ProgramFiles\Anaconda3\lib\site-packages\django-1.11.8-py3.6.egg\django\core\handlers\exception.py", line 41, in inner
    response = get_response(request)
  File "D:\ProgramFiles\Anaconda3\lib\site-packages\django-1.11.8-py3.6.egg\django\core\handlers\base.py", line 249, in _legacy_get_response
    response = self._get_response(request)
  File "D:\ProgramFiles\Anaconda3\lib\site-packages\django-1.11.8-py3.6.egg\django\core\handlers\base.py", line 187, in _get_response
    response = self.process_exception_by_middleware(e, request)
  File "D:\ProgramFiles\Anaconda3\lib\site-packages\django-1.11.8-py3.6.egg\django\core\handlers\base.py", line 185, in _get_response
    response = wrapped_callback(request, *callback_args, **callback_kwargs)
  File "D:\tools\Tools\2018年3月5日\Carry\mysite\views.py", line 374, in tongji
    return render(rq,'tongji.html',{'results':results,'dates':rq_date,'ids':HSD.IDS,'huizong':huizong,'id_name':id_name})
  File "D:\ProgramFiles\Anaconda3\lib\site-packages\django-1.11.8-py3.6.egg\django\shortcuts.py", line 30, in render
    content = loader.render_to_string(template_name, context, request, using=using)
  File "D:\ProgramFiles\Anaconda3\lib\site-packages\django-1.11.8-py3.6.egg\django\template\loader.py", line 67, in render_to_string
    template = get_template(template_name, using=using)
  File "D:\ProgramFiles\Anaconda3\lib\site-packages\django-1.11.8-py3.6.egg\django\template\loader.py", line 21, in get_template
    return engine.get_template(template_name)
  File "D:\ProgramFiles\Anaconda3\lib\site-packages\django-1.11.8-py3.6.egg\django\template\backends\django.py", line 39, in get_template
    return Template(self.engine.get_template(template_name), self)
  File "D:\ProgramFiles\Anaconda3\lib\site-packages\django-1.11.8-py3.6.egg\django\template\engine.py", line 162, in get_template
    template, origin = self.find_template(template_name)
  File "D:\ProgramFiles\Anaconda3\lib\site-packages\django-1.11.8-py3.6.egg\django\template\engine.py", line 136, in find_template
    name, template_dirs=dirs, skip=skip,
  File "D:\ProgramFiles\Anaconda3\lib\site-packages\django-1.11.8-py3.6.egg\django\template\loaders\base.py", line 44, in get_template
    contents, origin, origin.template_name, self.engine,
  File "D:\ProgramFiles\Anaconda3\lib\site-packages\django-1.11.8-py3.6.egg\django\template\base.py", line 191, in __init__
    self.nodelist = self.compile_nodelist()
  File "D:\ProgramFiles\Anaconda3\lib\site-packages\django-1.11.8-py3.6.egg\django\template\base.py", line 230, in compile_nodelist
    return parser.parse()
  File "D:\ProgramFiles\Anaconda3\lib\site-packages\django-1.11.8-py3.6.egg\django\template\base.py", line 515, in parse
    raise self.error(token, e)
  File "D:\ProgramFiles\Anaconda3\lib\site-packages\django-1.11.8-py3.6.egg\django\template\base.py", line 513, in parse
    compiled_result = compile_func(self, token)
  File "D:\ProgramFiles\Anaconda3\lib\site-packages\django-1.11.8-py3.6.egg\django\template\loader_tags.py", line 312, in do_extends
    nodelist = parser.parse()
  File "D:\ProgramFiles\Anaconda3\lib\site-packages\django-1.11.8-py3.6.egg\django\template\base.py", line 515, in parse
    raise self.error(token, e)
  File "D:\ProgramFiles\Anaconda3\lib\site-packages\django-1.11.8-py3.6.egg\django\template\base.py", line 513, in parse
    compiled_result = compile_func(self, token)
  File "D:\ProgramFiles\Anaconda3\lib\site-packages\django-1.11.8-py3.6.egg\django\template\loader_tags.py", line 255, in do_block
    nodelist = parser.parse(('endblock',))
  File "D:\ProgramFiles\Anaconda3\lib\site-packages\django-1.11.8-py3.6.egg\django\template\base.py", line 515, in parse
    raise self.error(token, e)
  File "D:\ProgramFiles\Anaconda3\lib\site-packages\django-1.11.8-py3.6.egg\django\template\base.py", line 513, in parse
    compiled_result = compile_func(self, token)
  File "D:\ProgramFiles\Anaconda3\lib\site-packages\django-1.11.8-py3.6.egg\django\template\defaulttags.py", line 977, in do_if
    nodelist = parser.parse(('elif', 'else', 'endif'))
  File "D:\ProgramFiles\Anaconda3\lib\site-packages\django-1.11.8-py3.6.egg\django\template\base.py", line 515, in parse
    raise self.error(token, e)
  File "D:\ProgramFiles\Anaconda3\lib\site-packages\django-1.11.8-py3.6.egg\django\template\base.py", line 513, in parse
    compiled_result = compile_func(self, token)
  File "D:\ProgramFiles\Anaconda3\lib\site-packages\django-1.11.8-py3.6.egg\django\template\defaulttags.py", line 1095, in load
    lib = find_library(parser, name)
  File "D:\ProgramFiles\Anaconda3\lib\site-packages\django-1.11.8-py3.6.egg\django\template\defaulttags.py", line 1042, in find_library
    name, "\n".join(sorted(parser.libraries.keys())),
django.template.exceptions.TemplateSyntaxError: 'mvote' is not a registered tag library. Must be one of:
admin_list
admin_modify
admin_static
admin_urls
cache
i18n
l10n
log
static
staticfiles
tz
exception.py[2018-03-12 19:33:42][ERROR]：Internal Server Error: /tj/4
Traceback (most recent call last):
  File "D:\ProgramFiles\Anaconda3\lib\site-packages\django-1.11.8-py3.6.egg\django\template\defaulttags.py", line 1038, in find_library
    return parser.libraries[name]
KeyError: 'mvote'

During handling of the above exception, another exception occurred:

Traceback (most recent call last):
  File "D:\ProgramFiles\Anaconda3\lib\site-packages\django-1.11.8-py3.6.egg\django\core\handlers\exception.py", line 41, in inner
    response = get_response(request)
  File "D:\ProgramFiles\Anaconda3\lib\site-packages\django-1.11.8-py3.6.egg\django\core\handlers\base.py", line 249, in _legacy_get_response
    response = self._get_response(request)
  File "D:\ProgramFiles\Anaconda3\lib\site-packages\django-1.11.8-py3.6.egg\django\core\handlers\base.py", line 187, in _get_response
    response = self.process_exception_by_middleware(e, request)
  File "D:\ProgramFiles\Anaconda3\lib\site-packages\django-1.11.8-py3.6.egg\django\core\handlers\base.py", line 185, in _get_response
    response = wrapped_callback(request, *callback_args, **callback_kwargs)
  File "D:\tools\Tools\2018年3月5日\Carry\mysite\views.py", line 374, in tongji
    return render(rq,'tongji.html',{'results':results,'dates':rq_date,'ids':HSD.IDS,'huizong':huizong,'id_name':id_name})
  File "D:\ProgramFiles\Anaconda3\lib\site-packages\django-1.11.8-py3.6.egg\django\shortcuts.py", line 30, in render
    content = loader.render_to_string(template_name, context, request, using=using)
  File "D:\ProgramFiles\Anaconda3\lib\site-packages\django-1.11.8-py3.6.egg\django\template\loader.py", line 67, in render_to_string
    template = get_template(template_name, using=using)
  File "D:\ProgramFiles\Anaconda3\lib\site-packages\django-1.11.8-py3.6.egg\django\template\loader.py", line 21, in get_template
    return engine.get_template(template_name)
  File "D:\ProgramFiles\Anaconda3\lib\site-packages\django-1.11.8-py3.6.egg\django\template\backends\django.py", line 39, in get_template
    return Template(self.engine.get_template(template_name), self)
  File "D:\ProgramFiles\Anaconda3\lib\site-packages\django-1.11.8-py3.6.egg\django\template\engine.py", line 162, in get_template
    template, origin = self.find_template(template_name)
  File "D:\ProgramFiles\Anaconda3\lib\site-packages\django-1.11.8-py3.6.egg\django\template\engine.py", line 136, in find_template
    name, template_dirs=dirs, skip=skip,
  File "D:\ProgramFiles\Anaconda3\lib\site-packages\django-1.11.8-py3.6.egg\django\template\loaders\base.py", line 44, in get_template
    contents, origin, origin.template_name, self.engine,
  File "D:\ProgramFiles\Anaconda3\lib\site-packages\django-1.11.8-py3.6.egg\django\template\base.py", line 191, in __init__
    self.nodelist = self.compile_nodelist()
  File "D:\ProgramFiles\Anaconda3\lib\site-packages\django-1.11.8-py3.6.egg\django\template\base.py", line 230, in compile_nodelist
    return parser.parse()
  File "D:\ProgramFiles\Anaconda3\lib\site-packages\django-1.11.8-py3.6.egg\django\template\base.py", line 515, in parse
    raise self.error(token, e)
  File "D:\ProgramFiles\Anaconda3\lib\site-packages\django-1.11.8-py3.6.egg\django\template\base.py", line 513, in parse
    compiled_result = compile_func(self, token)
  File "D:\ProgramFiles\Anaconda3\lib\site-packages\django-1.11.8-py3.6.egg\django\template\loader_tags.py", line 312, in do_extends
    nodelist = parser.parse()
  File "D:\ProgramFiles\Anaconda3\lib\site-packages\django-1.11.8-py3.6.egg\django\template\base.py", line 515, in parse
    raise self.error(token, e)
  File "D:\ProgramFiles\Anaconda3\lib\site-packages\django-1.11.8-py3.6.egg\django\template\base.py", line 513, in parse
    compiled_result = compile_func(self, token)
  File "D:\ProgramFiles\Anaconda3\lib\site-packages\django-1.11.8-py3.6.egg\django\template\loader_tags.py", line 255, in do_block
    nodelist = parser.parse(('endblock',))
  File "D:\ProgramFiles\Anaconda3\lib\site-packages\django-1.11.8-py3.6.egg\django\template\base.py", line 515, in parse
    raise self.error(token, e)
  File "D:\ProgramFiles\Anaconda3\lib\site-packages\django-1.11.8-py3.6.egg\django\template\base.py", line 513, in parse
    compiled_result = compile_func(self, token)
  File "D:\ProgramFiles\Anaconda3\lib\site-packages\django-1.11.8-py3.6.egg\django\template\defaulttags.py", line 977, in do_if
    nodelist = parser.parse(('elif', 'else', 'endif'))
  File "D:\ProgramFiles\Anaconda3\lib\site-packages\django-1.11.8-py3.6.egg\django\template\base.py", line 515, in parse
    raise self.error(token, e)
  File "D:\ProgramFiles\Anaconda3\lib\site-packages\django-1.11.8-py3.6.egg\django\template\base.py", line 513, in parse
    compiled_result = compile_func(self, token)
  File "D:\ProgramFiles\Anaconda3\lib\site-packages\django-1.11.8-py3.6.egg\django\template\defaulttags.py", line 1095, in load
    lib = find_library(parser, name)
  File "D:\ProgramFiles\Anaconda3\lib\site-packages\django-1.11.8-py3.6.egg\django\template\defaulttags.py", line 1042, in find_library
    name, "\n".join(sorted(parser.libraries.keys())),
django.template.exceptions.TemplateSyntaxError: 'mvote' is not a registered tag library. Must be one of:
admin_list
admin_modify
admin_static
admin_urls
cache
i18n
l10n
log
static
staticfiles
tz
exception.py[2018-03-12 19:35:27][ERROR]：Internal Server Error: /tj/1
Traceback (most recent call last):
  File "D:\ProgramFiles\Anaconda3\lib\site-packages\django-1.11.8-py3.6.egg\django\template\defaulttags.py", line 1038, in find_library
    return parser.libraries[name]
KeyError: 'mvote'

During handling of the above exception, another exception occurred:

Traceback (most recent call last):
  File "D:\ProgramFiles\Anaconda3\lib\site-packages\django-1.11.8-py3.6.egg\django\core\handlers\exception.py", line 41, in inner
    response = get_response(request)
  File "D:\ProgramFiles\Anaconda3\lib\site-packages\django-1.11.8-py3.6.egg\django\core\handlers\base.py", line 249, in _legacy_get_response
    response = self._get_response(request)
  File "D:\ProgramFiles\Anaconda3\lib\site-packages\django-1.11.8-py3.6.egg\django\core\handlers\base.py", line 187, in _get_response
    response = self.process_exception_by_middleware(e, request)
  File "D:\ProgramFiles\Anaconda3\lib\site-packages\django-1.11.8-py3.6.egg\django\core\handlers\base.py", line 185, in _get_response
    response = wrapped_callback(request, *callback_args, **callback_kwargs)
  File "D:\tools\Tools\2018年3月5日\Carry\mysite\views.py", line 393, in tongji
    return render(rq, 'tongji.html', {'herys': herys.to_html(), 'xz': xz,'dates':dates,'ids':HSD.IDS})
  File "D:\ProgramFiles\Anaconda3\lib\site-packages\django-1.11.8-py3.6.egg\django\shortcuts.py", line 30, in render
    content = loader.render_to_string(template_name, context, request, using=using)
  File "D:\ProgramFiles\Anaconda3\lib\site-packages\django-1.11.8-py3.6.egg\django\template\loader.py", line 67, in render_to_string
    template = get_template(template_name, using=using)
  File "D:\ProgramFiles\Anaconda3\lib\site-packages\django-1.11.8-py3.6.egg\django\template\loader.py", line 21, in get_template
    return engine.get_template(template_name)
  File "D:\ProgramFiles\Anaconda3\lib\site-packages\django-1.11.8-py3.6.egg\django\template\backends\django.py", line 39, in get_template
    return Template(self.engine.get_template(template_name), self)
  File "D:\ProgramFiles\Anaconda3\lib\site-packages\django-1.11.8-py3.6.egg\django\template\engine.py", line 162, in get_template
    template, origin = self.find_template(template_name)
  File "D:\ProgramFiles\Anaconda3\lib\site-packages\django-1.11.8-py3.6.egg\django\template\engine.py", line 136, in find_template
    name, template_dirs=dirs, skip=skip,
  File "D:\ProgramFiles\Anaconda3\lib\site-packages\django-1.11.8-py3.6.egg\django\template\loaders\base.py", line 44, in get_template
    contents, origin, origin.template_name, self.engine,
  File "D:\ProgramFiles\Anaconda3\lib\site-packages\django-1.11.8-py3.6.egg\django\template\base.py", line 191, in __init__
    self.nodelist = self.compile_nodelist()
  File "D:\ProgramFiles\Anaconda3\lib\site-packages\django-1.11.8-py3.6.egg\django\template\base.py", line 230, in compile_nodelist
    return parser.parse()
  File "D:\ProgramFiles\Anaconda3\lib\site-packages\django-1.11.8-py3.6.egg\django\template\base.py", line 515, in parse
    raise self.error(token, e)
  File "D:\ProgramFiles\Anaconda3\lib\site-packages\django-1.11.8-py3.6.egg\django\template\base.py", line 513, in parse
    compiled_result = compile_func(self, token)
  File "D:\ProgramFiles\Anaconda3\lib\site-packages\django-1.11.8-py3.6.egg\django\template\loader_tags.py", line 312, in do_extends
    nodelist = parser.parse()
  File "D:\ProgramFiles\Anaconda3\lib\site-packages\django-1.11.8-py3.6.egg\django\template\base.py", line 515, in parse
    raise self.error(token, e)
  File "D:\ProgramFiles\Anaconda3\lib\site-packages\django-1.11.8-py3.6.egg\django\template\base.py", line 513, in parse
    compiled_result = compile_func(self, token)
  File "D:\ProgramFiles\Anaconda3\lib\site-packages\django-1.11.8-py3.6.egg\django\template\loader_tags.py", line 255, in do_block
    nodelist = parser.parse(('endblock',))
  File "D:\ProgramFiles\Anaconda3\lib\site-packages\django-1.11.8-py3.6.egg\django\template\base.py", line 515, in parse
    raise self.error(token, e)
  File "D:\ProgramFiles\Anaconda3\lib\site-packages\django-1.11.8-py3.6.egg\django\template\base.py", line 513, in parse
    compiled_result = compile_func(self, token)
  File "D:\ProgramFiles\Anaconda3\lib\site-packages\django-1.11.8-py3.6.egg\django\template\defaulttags.py", line 977, in do_if
    nodelist = parser.parse(('elif', 'else', 'endif'))
  File "D:\ProgramFiles\Anaconda3\lib\site-packages\django-1.11.8-py3.6.egg\django\template\base.py", line 515, in parse
    raise self.error(token, e)
  File "D:\ProgramFiles\Anaconda3\lib\site-packages\django-1.11.8-py3.6.egg\django\template\base.py", line 513, in parse
    compiled_result = compile_func(self, token)
  File "D:\ProgramFiles\Anaconda3\lib\site-packages\django-1.11.8-py3.6.egg\django\template\defaulttags.py", line 1095, in load
    lib = find_library(parser, name)
  File "D:\ProgramFiles\Anaconda3\lib\site-packages\django-1.11.8-py3.6.egg\django\template\defaulttags.py", line 1042, in find_library
    name, "\n".join(sorted(parser.libraries.keys())),
django.template.exceptions.TemplateSyntaxError: 'mvote' is not a registered tag library. Must be one of:
admin_list
admin_modify
admin_static
admin_urls
cache
i18n
l10n
log
static
staticfiles
tz
exception.py[2018-03-12 19:35:54][ERROR]：Internal Server Error: /tj/1
Traceback (most recent call last):
  File "D:\ProgramFiles\Anaconda3\lib\site-packages\django-1.11.8-py3.6.egg\django\template\defaulttags.py", line 1038, in find_library
    return parser.libraries[name]
KeyError: 'mvote'

During handling of the above exception, another exception occurred:

Traceback (most recent call last):
  File "D:\ProgramFiles\Anaconda3\lib\site-packages\django-1.11.8-py3.6.egg\django\core\handlers\exception.py", line 41, in inner
    response = get_response(request)
  File "D:\ProgramFiles\Anaconda3\lib\site-packages\django-1.11.8-py3.6.egg\django\core\handlers\base.py", line 249, in _legacy_get_response
    response = self._get_response(request)
  File "D:\ProgramFiles\Anaconda3\lib\site-packages\django-1.11.8-py3.6.egg\django\core\handlers\base.py", line 187, in _get_response
    response = self.process_exception_by_middleware(e, request)
  File "D:\ProgramFiles\Anaconda3\lib\site-packages\django-1.11.8-py3.6.egg\django\core\handlers\base.py", line 185, in _get_response
    response = wrapped_callback(request, *callback_args, **callback_kwargs)
  File "D:\tools\Tools\2018年3月5日\Carry\mysite\views.py", line 393, in tongji
    return render(rq, 'tongji.html', {'herys': herys.to_html(), 'xz': xz,'dates':dates,'ids':HSD.IDS})
  File "D:\ProgramFiles\Anaconda3\lib\site-packages\django-1.11.8-py3.6.egg\django\shortcuts.py", line 30, in render
    content = loader.render_to_string(template_name, context, request, using=using)
  File "D:\ProgramFiles\Anaconda3\lib\site-packages\django-1.11.8-py3.6.egg\django\template\loader.py", line 67, in render_to_string
    template = get_template(template_name, using=using)
  File "D:\ProgramFiles\Anaconda3\lib\site-packages\django-1.11.8-py3.6.egg\django\template\loader.py", line 21, in get_template
    return engine.get_template(template_name)
  File "D:\ProgramFiles\Anaconda3\lib\site-packages\django-1.11.8-py3.6.egg\django\template\backends\django.py", line 39, in get_template
    return Template(self.engine.get_template(template_name), self)
  File "D:\ProgramFiles\Anaconda3\lib\site-packages\django-1.11.8-py3.6.egg\django\template\engine.py", line 162, in get_template
    template, origin = self.find_template(template_name)
  File "D:\ProgramFiles\Anaconda3\lib\site-packages\django-1.11.8-py3.6.egg\django\template\engine.py", line 136, in find_template
    name, template_dirs=dirs, skip=skip,
  File "D:\ProgramFiles\Anaconda3\lib\site-packages\django-1.11.8-py3.6.egg\django\template\loaders\base.py", line 44, in get_template
    contents, origin, origin.template_name, self.engine,
  File "D:\ProgramFiles\Anaconda3\lib\site-packages\django-1.11.8-py3.6.egg\django\template\base.py", line 191, in __init__
    self.nodelist = self.compile_nodelist()
  File "D:\ProgramFiles\Anaconda3\lib\site-packages\django-1.11.8-py3.6.egg\django\template\base.py", line 230, in compile_nodelist
    return parser.parse()
  File "D:\ProgramFiles\Anaconda3\lib\site-packages\django-1.11.8-py3.6.egg\django\template\base.py", line 515, in parse
    raise self.error(token, e)
  File "D:\ProgramFiles\Anaconda3\lib\site-packages\django-1.11.8-py3.6.egg\django\template\base.py", line 513, in parse
    compiled_result = compile_func(self, token)
  File "D:\ProgramFiles\Anaconda3\lib\site-packages\django-1.11.8-py3.6.egg\django\template\loader_tags.py", line 312, in do_extends
    nodelist = parser.parse()
  File "D:\ProgramFiles\Anaconda3\lib\site-packages\django-1.11.8-py3.6.egg\django\template\base.py", line 515, in parse
    raise self.error(token, e)
  File "D:\ProgramFiles\Anaconda3\lib\site-packages\django-1.11.8-py3.6.egg\django\template\base.py", line 513, in parse
    compiled_result = compile_func(self, token)
  File "D:\ProgramFiles\Anaconda3\lib\site-packages\django-1.11.8-py3.6.egg\django\template\loader_tags.py", line 255, in do_block
    nodelist = parser.parse(('endblock',))
  File "D:\ProgramFiles\Anaconda3\lib\site-packages\django-1.11.8-py3.6.egg\django\template\base.py", line 515, in parse
    raise self.error(token, e)
  File "D:\ProgramFiles\Anaconda3\lib\site-packages\django-1.11.8-py3.6.egg\django\template\base.py", line 513, in parse
    compiled_result = compile_func(self, token)
  File "D:\ProgramFiles\Anaconda3\lib\site-packages\django-1.11.8-py3.6.egg\django\template\defaulttags.py", line 977, in do_if
    nodelist = parser.parse(('elif', 'else', 'endif'))
  File "D:\ProgramFiles\Anaconda3\lib\site-packages\django-1.11.8-py3.6.egg\django\template\base.py", line 515, in parse
    raise self.error(token, e)
  File "D:\ProgramFiles\Anaconda3\lib\site-packages\django-1.11.8-py3.6.egg\django\template\base.py", line 513, in parse
    compiled_result = compile_func(self, token)
  File "D:\ProgramFiles\Anaconda3\lib\site-packages\django-1.11.8-py3.6.egg\django\template\defaulttags.py", line 1095, in load
    lib = find_library(parser, name)
  File "D:\ProgramFiles\Anaconda3\lib\site-packages\django-1.11.8-py3.6.egg\django\template\defaulttags.py", line 1042, in find_library
    name, "\n".join(sorted(parser.libraries.keys())),
django.template.exceptions.TemplateSyntaxError: 'mvote' is not a registered tag library. Must be one of:
admin_list
admin_modify
admin_static
admin_urls
cache
i18n
l10n
log
static
staticfiles
tz
exception.py[2018-03-12 19:38:18][ERROR]：Internal Server Error: /tj/1
Traceback (most recent call last):
  File "D:\ProgramFiles\Anaconda3\lib\site-packages\django-1.11.8-py3.6.egg\django\template\defaulttags.py", line 1038, in find_library
    return parser.libraries[name]
KeyError: 'mvote'

During handling of the above exception, another exception occurred:

Traceback (most recent call last):
  File "D:\ProgramFiles\Anaconda3\lib\site-packages\django-1.11.8-py3.6.egg\django\core\handlers\exception.py", line 41, in inner
    response = get_response(request)
  File "D:\ProgramFiles\Anaconda3\lib\site-packages\django-1.11.8-py3.6.egg\django\core\handlers\base.py", line 249, in _legacy_get_response
    response = self._get_response(request)
  File "D:\ProgramFiles\Anaconda3\lib\site-packages\django-1.11.8-py3.6.egg\django\core\handlers\base.py", line 187, in _get_response
    response = self.process_exception_by_middleware(e, request)
  File "D:\ProgramFiles\Anaconda3\lib\site-packages\django-1.11.8-py3.6.egg\django\core\handlers\base.py", line 185, in _get_response
    response = wrapped_callback(request, *callback_args, **callback_kwargs)
  File "D:\tools\Tools\2018年3月5日\Carry\mysite\views.py", line 393, in tongji
    return render(rq, 'tongji.html', {'herys': herys.to_html(), 'xz': xz,'dates':dates,'ids':HSD.IDS})
  File "D:\ProgramFiles\Anaconda3\lib\site-packages\django-1.11.8-py3.6.egg\django\shortcuts.py", line 30, in render
    content = loader.render_to_string(template_name, context, request, using=using)
  File "D:\ProgramFiles\Anaconda3\lib\site-packages\django-1.11.8-py3.6.egg\django\template\loader.py", line 67, in render_to_string
    template = get_template(template_name, using=using)
  File "D:\ProgramFiles\Anaconda3\lib\site-packages\django-1.11.8-py3.6.egg\django\template\loader.py", line 21, in get_template
    return engine.get_template(template_name)
  File "D:\ProgramFiles\Anaconda3\lib\site-packages\django-1.11.8-py3.6.egg\django\template\backends\django.py", line 39, in get_template
    return Template(self.engine.get_template(template_name), self)
  File "D:\ProgramFiles\Anaconda3\lib\site-packages\django-1.11.8-py3.6.egg\django\template\engine.py", line 162, in get_template
    template, origin = self.find_template(template_name)
  File "D:\ProgramFiles\Anaconda3\lib\site-packages\django-1.11.8-py3.6.egg\django\template\engine.py", line 136, in find_template
    name, template_dirs=dirs, skip=skip,
  File "D:\ProgramFiles\Anaconda3\lib\site-packages\django-1.11.8-py3.6.egg\django\template\loaders\base.py", line 44, in get_template
    contents, origin, origin.template_name, self.engine,
  File "D:\ProgramFiles\Anaconda3\lib\site-packages\django-1.11.8-py3.6.egg\django\template\base.py", line 191, in __init__
    self.nodelist = self.compile_nodelist()
  File "D:\ProgramFiles\Anaconda3\lib\site-packages\django-1.11.8-py3.6.egg\django\template\base.py", line 230, in compile_nodelist
    return parser.parse()
  File "D:\ProgramFiles\Anaconda3\lib\site-packages\django-1.11.8-py3.6.egg\django\template\base.py", line 515, in parse
    raise self.error(token, e)
  File "D:\ProgramFiles\Anaconda3\lib\site-packages\django-1.11.8-py3.6.egg\django\template\base.py", line 513, in parse
    compiled_result = compile_func(self, token)
  File "D:\ProgramFiles\Anaconda3\lib\site-packages\django-1.11.8-py3.6.egg\django\template\loader_tags.py", line 312, in do_extends
    nodelist = parser.parse()
  File "D:\ProgramFiles\Anaconda3\lib\site-packages\django-1.11.8-py3.6.egg\django\template\base.py", line 515, in parse
    raise self.error(token, e)
  File "D:\ProgramFiles\Anaconda3\lib\site-packages\django-1.11.8-py3.6.egg\django\template\base.py", line 513, in parse
    compiled_result = compile_func(self, token)
  File "D:\ProgramFiles\Anaconda3\lib\site-packages\django-1.11.8-py3.6.egg\django\template\loader_tags.py", line 255, in do_block
    nodelist = parser.parse(('endblock',))
  File "D:\ProgramFiles\Anaconda3\lib\site-packages\django-1.11.8-py3.6.egg\django\template\base.py", line 515, in parse
    raise self.error(token, e)
  File "D:\ProgramFiles\Anaconda3\lib\site-packages\django-1.11.8-py3.6.egg\django\template\base.py", line 513, in parse
    compiled_result = compile_func(self, token)
  File "D:\ProgramFiles\Anaconda3\lib\site-packages\django-1.11.8-py3.6.egg\django\template\defaulttags.py", line 977, in do_if
    nodelist = parser.parse(('elif', 'else', 'endif'))
  File "D:\ProgramFiles\Anaconda3\lib\site-packages\django-1.11.8-py3.6.egg\django\template\base.py", line 515, in parse
    raise self.error(token, e)
  File "D:\ProgramFiles\Anaconda3\lib\site-packages\django-1.11.8-py3.6.egg\django\template\base.py", line 513, in parse
    compiled_result = compile_func(self, token)
  File "D:\ProgramFiles\Anaconda3\lib\site-packages\django-1.11.8-py3.6.egg\django\template\defaulttags.py", line 1095, in load
    lib = find_library(parser, name)
  File "D:\ProgramFiles\Anaconda3\lib\site-packages\django-1.11.8-py3.6.egg\django\template\defaulttags.py", line 1042, in find_library
    name, "\n".join(sorted(parser.libraries.keys())),
django.template.exceptions.TemplateSyntaxError: 'mvote' is not a registered tag library. Must be one of:
admin_list
admin_modify
admin_static
admin_urls
cache
i18n
l10n
log
static
staticfiles
tz
exception.py[2018-03-12 19:45:06][ERROR]：Internal Server Error: /tj/1
Traceback (most recent call last):
  File "D:\ProgramFiles\Anaconda3\lib\site-packages\django-1.11.8-py3.6.egg\django\core\handlers\exception.py", line 41, in inner
    response = get_response(request)
  File "D:\ProgramFiles\Anaconda3\lib\site-packages\django-1.11.8-py3.6.egg\django\core\handlers\base.py", line 249, in _legacy_get_response
    response = self._get_response(request)
  File "D:\ProgramFiles\Anaconda3\lib\site-packages\django-1.11.8-py3.6.egg\django\core\handlers\base.py", line 187, in _get_response
    response = self.process_exception_by_middleware(e, request)
  File "D:\ProgramFiles\Anaconda3\lib\site-packages\django-1.11.8-py3.6.egg\django\core\handlers\base.py", line 185, in _get_response
    response = wrapped_callback(request, *callback_args, **callback_kwargs)
  File "D:\tools\Tools\2018年3月5日\Carry\mysite\views.py", line 374, in tongji
    return render(rq,'tongji.html',{'results':results,'dates':rq_date,'ids':HSD.IDS,'huizong':huizong,'id_name':id_name})
  File "D:\ProgramFiles\Anaconda3\lib\site-packages\django-1.11.8-py3.6.egg\django\shortcuts.py", line 30, in render
    content = loader.render_to_string(template_name, context, request, using=using)
  File "D:\ProgramFiles\Anaconda3\lib\site-packages\django-1.11.8-py3.6.egg\django\template\loader.py", line 67, in render_to_string
    template = get_template(template_name, using=using)
  File "D:\ProgramFiles\Anaconda3\lib\site-packages\django-1.11.8-py3.6.egg\django\template\loader.py", line 21, in get_template
    return engine.get_template(template_name)
  File "D:\ProgramFiles\Anaconda3\lib\site-packages\django-1.11.8-py3.6.egg\django\template\backends\django.py", line 39, in get_template
    return Template(self.engine.get_template(template_name), self)
  File "D:\ProgramFiles\Anaconda3\lib\site-packages\django-1.11.8-py3.6.egg\django\template\engine.py", line 162, in get_template
    template, origin = self.find_template(template_name)
  File "D:\ProgramFiles\Anaconda3\lib\site-packages\django-1.11.8-py3.6.egg\django\template\engine.py", line 136, in find_template
    name, template_dirs=dirs, skip=skip,
  File "D:\ProgramFiles\Anaconda3\lib\site-packages\django-1.11.8-py3.6.egg\django\template\loaders\base.py", line 44, in get_template
    contents, origin, origin.template_name, self.engine,
  File "D:\ProgramFiles\Anaconda3\lib\site-packages\django-1.11.8-py3.6.egg\django\template\base.py", line 191, in __init__
    self.nodelist = self.compile_nodelist()
  File "D:\ProgramFiles\Anaconda3\lib\site-packages\django-1.11.8-py3.6.egg\django\template\base.py", line 230, in compile_nodelist
    return parser.parse()
  File "D:\ProgramFiles\Anaconda3\lib\site-packages\django-1.11.8-py3.6.egg\django\template\base.py", line 515, in parse
    raise self.error(token, e)
  File "D:\ProgramFiles\Anaconda3\lib\site-packages\django-1.11.8-py3.6.egg\django\template\base.py", line 513, in parse
    compiled_result = compile_func(self, token)
  File "D:\ProgramFiles\Anaconda3\lib\site-packages\django-1.11.8-py3.6.egg\django\template\loader_tags.py", line 312, in do_extends
    nodelist = parser.parse()
  File "D:\ProgramFiles\Anaconda3\lib\site-packages\django-1.11.8-py3.6.egg\django\template\base.py", line 515, in parse
    raise self.error(token, e)
  File "D:\ProgramFiles\Anaconda3\lib\site-packages\django-1.11.8-py3.6.egg\django\template\base.py", line 513, in parse
    compiled_result = compile_func(self, token)
  File "D:\ProgramFiles\Anaconda3\lib\site-packages\django-1.11.8-py3.6.egg\django\template\loader_tags.py", line 255, in do_block
    nodelist = parser.parse(('endblock',))
  File "D:\ProgramFiles\Anaconda3\lib\site-packages\django-1.11.8-py3.6.egg\django\template\base.py", line 515, in parse
    raise self.error(token, e)
  File "D:\ProgramFiles\Anaconda3\lib\site-packages\django-1.11.8-py3.6.egg\django\template\base.py", line 513, in parse
    compiled_result = compile_func(self, token)
  File "D:\ProgramFiles\Anaconda3\lib\site-packages\django-1.11.8-py3.6.egg\django\template\defaulttags.py", line 977, in do_if
    nodelist = parser.parse(('elif', 'else', 'endif'))
  File "D:\ProgramFiles\Anaconda3\lib\site-packages\django-1.11.8-py3.6.egg\django\template\base.py", line 515, in parse
    raise self.error(token, e)
  File "D:\ProgramFiles\Anaconda3\lib\site-packages\django-1.11.8-py3.6.egg\django\template\base.py", line 513, in parse
    compiled_result = compile_func(self, token)
  File "D:\ProgramFiles\Anaconda3\lib\site-packages\django-1.11.8-py3.6.egg\django\template\defaulttags.py", line 827, in do_for
    nodelist_loop = parser.parse(('empty', 'endfor',))
  File "D:\ProgramFiles\Anaconda3\lib\site-packages\django-1.11.8-py3.6.egg\django\template\base.py", line 486, in parse
    raise self.error(token, e)
  File "D:\ProgramFiles\Anaconda3\lib\site-packages\django-1.11.8-py3.6.egg\django\template\base.py", line 484, in parse
    filter_expression = self.compile_filter(token.contents)
  File "D:\ProgramFiles\Anaconda3\lib\site-packages\django-1.11.8-py3.6.egg\django\template\base.py", line 600, in compile_filter
    return FilterExpression(token, self)
  File "D:\ProgramFiles\Anaconda3\lib\site-packages\django-1.11.8-py3.6.egg\django\template\base.py", line 694, in __init__
    filter_func = parser.find_filter(filter_name)
  File "D:\ProgramFiles\Anaconda3\lib\site-packages\django-1.11.8-py3.6.egg\django\template\base.py", line 606, in find_filter
    raise TemplateSyntaxError("Invalid filter: '%s'" % filter_name)
django.template.exceptions.TemplateSyntaxError: Invalid filter: 'names'
exception.py[2018-03-12 20:04:47][ERROR]：Internal Server Error: /tj/1
Traceback (most recent call last):
  File "D:\ProgramFiles\Anaconda3\lib\site-packages\django-1.11.8-py3.6.egg\django\core\handlers\exception.py", line 41, in inner
    response = get_response(request)
  File "D:\ProgramFiles\Anaconda3\lib\site-packages\django-1.11.8-py3.6.egg\django\core\handlers\base.py", line 249, in _legacy_get_response
    response = self._get_response(request)
  File "D:\ProgramFiles\Anaconda3\lib\site-packages\django-1.11.8-py3.6.egg\django\core\handlers\base.py", line 187, in _get_response
    response = self.process_exception_by_middleware(e, request)
  File "D:\ProgramFiles\Anaconda3\lib\site-packages\django-1.11.8-py3.6.egg\django\core\handlers\base.py", line 185, in _get_response
    response = wrapped_callback(request, *callback_args, **callback_kwargs)
  File "D:\tools\Tools\2018年3月5日\Carry\mysite\views.py", line 371, in tongji
    return render(rq,'tongji.html',{'results':results,'dates':rq_date,'ids':HSD.IDS,'huizong':huizong,'id_name':id_name})
  File "D:\ProgramFiles\Anaconda3\lib\site-packages\django-1.11.8-py3.6.egg\django\shortcuts.py", line 30, in render
    content = loader.render_to_string(template_name, context, request, using=using)
  File "D:\ProgramFiles\Anaconda3\lib\site-packages\django-1.11.8-py3.6.egg\django\template\loader.py", line 68, in render_to_string
    return template.render(context, request)
  File "D:\ProgramFiles\Anaconda3\lib\site-packages\django-1.11.8-py3.6.egg\django\template\backends\django.py", line 66, in render
    return self.template.render(context)
  File "D:\ProgramFiles\Anaconda3\lib\site-packages\django-1.11.8-py3.6.egg\django\template\base.py", line 207, in render
    return self._render(context)
  File "D:\ProgramFiles\Anaconda3\lib\site-packages\django-1.11.8-py3.6.egg\django\template\base.py", line 199, in _render
    return self.nodelist.render(context)
  File "D:\ProgramFiles\Anaconda3\lib\site-packages\django-1.11.8-py3.6.egg\django\template\base.py", line 990, in render
    bit = node.render_annotated(context)
  File "D:\ProgramFiles\Anaconda3\lib\site-packages\django-1.11.8-py3.6.egg\django\template\base.py", line 957, in render_annotated
    return self.render(context)
  File "D:\ProgramFiles\Anaconda3\lib\site-packages\django-1.11.8-py3.6.egg\django\template\loader_tags.py", line 177, in render
    return compiled_parent._render(context)
  File "D:\ProgramFiles\Anaconda3\lib\site-packages\django-1.11.8-py3.6.egg\django\template\base.py", line 199, in _render
    return self.nodelist.render(context)
  File "D:\ProgramFiles\Anaconda3\lib\site-packages\django-1.11.8-py3.6.egg\django\template\base.py", line 990, in render
    bit = node.render_annotated(context)
  File "D:\ProgramFiles\Anaconda3\lib\site-packages\django-1.11.8-py3.6.egg\django\template\base.py", line 957, in render_annotated
    return self.render(context)
  File "D:\ProgramFiles\Anaconda3\lib\site-packages\django-1.11.8-py3.6.egg\django\template\loader_tags.py", line 72, in render
    result = block.nodelist.render(context)
  File "D:\ProgramFiles\Anaconda3\lib\site-packages\django-1.11.8-py3.6.egg\django\template\base.py", line 990, in render
    bit = node.render_annotated(context)
  File "D:\ProgramFiles\Anaconda3\lib\site-packages\django-1.11.8-py3.6.egg\django\template\base.py", line 957, in render_annotated
    return self.render(context)
  File "D:\ProgramFiles\Anaconda3\lib\site-packages\django-1.11.8-py3.6.egg\django\template\loader_tags.py", line 72, in render
    result = block.nodelist.render(context)
  File "D:\ProgramFiles\Anaconda3\lib\site-packages\django-1.11.8-py3.6.egg\django\template\base.py", line 990, in render
    bit = node.render_annotated(context)
  File "D:\ProgramFiles\Anaconda3\lib\site-packages\django-1.11.8-py3.6.egg\django\template\base.py", line 957, in render_annotated
    return self.render(context)
  File "D:\ProgramFiles\Anaconda3\lib\site-packages\django-1.11.8-py3.6.egg\django\template\defaulttags.py", line 322, in render
    return nodelist.render(context)
  File "D:\ProgramFiles\Anaconda3\lib\site-packages\django-1.11.8-py3.6.egg\django\template\base.py", line 990, in render
    bit = node.render_annotated(context)
  File "D:\ProgramFiles\Anaconda3\lib\site-packages\django-1.11.8-py3.6.egg\django\template\base.py", line 957, in render_annotated
    return self.render(context)
  File "D:\ProgramFiles\Anaconda3\lib\site-packages\django-1.11.8-py3.6.egg\django\template\defaulttags.py", line 207, in render
    .format(num_loopvars, len_item),
ValueError: Need 2 values to unpack in for loop; got 1. 
base.py[2018-03-13 09:54:40][WARNING]：Not Found: /favicon.ico
exception.py[2018-03-13 10:16:41][ERROR]：Internal Server Error: /getkline
Traceback (most recent call last):
  File "D:\ProgramFiles\Anaconda3\lib\site-packages\django-1.11.8-py3.6.egg\django\core\handlers\exception.py", line 41, in inner
    response = get_response(request)
  File "D:\ProgramFiles\Anaconda3\lib\site-packages\django-1.11.8-py3.6.egg\django\core\handlers\base.py", line 249, in _legacy_get_response
    response = self._get_response(request)
  File "D:\ProgramFiles\Anaconda3\lib\site-packages\django-1.11.8-py3.6.egg\django\core\handlers\base.py", line 187, in _get_response
    response = self.process_exception_by_middleware(e, request)
  File "D:\ProgramFiles\Anaconda3\lib\site-packages\django-1.11.8-py3.6.egg\django\core\handlers\base.py", line 185, in _get_response
    response = wrapped_callback(request, *callback_args, **callback_kwargs)
  File "D:\ProgramFiles\Anaconda3\lib\site-packages\django-1.11.8-py3.6.egg\django\utils\decorators.py", line 149, in _wrapped_view
    response = view_func(request, *args, **kwargs)
  File "D:\ProgramFiles\Anaconda3\lib\site-packages\dwebsocket\decorators.py", line 16, in new_func
    response = func(request, *args, **kwargs)
  File "D:\ProgramFiles\Anaconda3\lib\site-packages\django-1.11.8-py3.6.egg\django\views\decorators\csrf.py", line 58, in wrapped_view
    return view_func(*args, **kwargs)
  File "D:\tools\Tools\2018年3月5日\Carry\mysite\views.py", line 510, in getkline
    ticker=sub_socket.recv_pyobj()
  File "D:\ProgramFiles\Anaconda3\lib\site-packages\zmq\sugar\socket.py", line 492, in recv_pyobj
    return self._deserialize(msg, pickle.loads)
  File "D:\ProgramFiles\Anaconda3\lib\site-packages\zmq\sugar\socket.py", line 419, in _deserialize
    return load(recvd)
AttributeError: Can't get attribute 'SPApiTicker' on <module 'sp_struct' from 'D:\\tools\\Tools\\2018年3月5日\\Carry\\sp_struct.py'>
exception.py[2018-03-13 10:16:41][ERROR]：Internal Server Error: /getkline
Traceback (most recent call last):
  File "D:\ProgramFiles\Anaconda3\lib\site-packages\django-1.11.8-py3.6.egg\django\core\handlers\exception.py", line 41, in inner
    response = get_response(request)
  File "D:\ProgramFiles\Anaconda3\lib\site-packages\django-1.11.8-py3.6.egg\django\core\handlers\base.py", line 249, in _legacy_get_response
    response = self._get_response(request)
  File "D:\ProgramFiles\Anaconda3\lib\site-packages\django-1.11.8-py3.6.egg\django\core\handlers\base.py", line 187, in _get_response
    response = self.process_exception_by_middleware(e, request)
  File "D:\ProgramFiles\Anaconda3\lib\site-packages\django-1.11.8-py3.6.egg\django\core\handlers\base.py", line 185, in _get_response
    response = wrapped_callback(request, *callback_args, **callback_kwargs)
  File "D:\ProgramFiles\Anaconda3\lib\site-packages\django-1.11.8-py3.6.egg\django\utils\decorators.py", line 149, in _wrapped_view
    response = view_func(request, *args, **kwargs)
  File "D:\ProgramFiles\Anaconda3\lib\site-packages\dwebsocket\decorators.py", line 16, in new_func
    response = func(request, *args, **kwargs)
  File "D:\ProgramFiles\Anaconda3\lib\site-packages\django-1.11.8-py3.6.egg\django\views\decorators\csrf.py", line 58, in wrapped_view
    return view_func(*args, **kwargs)
  File "D:\tools\Tools\2018年3月5日\Carry\mysite\views.py", line 510, in getkline
    ticker=sub_socket.recv_pyobj()
  File "D:\ProgramFiles\Anaconda3\lib\site-packages\zmq\sugar\socket.py", line 492, in recv_pyobj
    return self._deserialize(msg, pickle.loads)
  File "D:\ProgramFiles\Anaconda3\lib\site-packages\zmq\sugar\socket.py", line 419, in _deserialize
    return load(recvd)
AttributeError: Can't get attribute 'SPApiTicker' on <module 'sp_struct' from 'D:\\tools\\Tools\\2018年3月5日\\Carry\\sp_struct.py'>
exception.py[2018-03-13 10:16:41][ERROR]：Internal Server Error: /getkline
Traceback (most recent call last):
  File "D:\ProgramFiles\Anaconda3\lib\site-packages\django-1.11.8-py3.6.egg\django\core\handlers\exception.py", line 41, in inner
    response = get_response(request)
  File "D:\ProgramFiles\Anaconda3\lib\site-packages\django-1.11.8-py3.6.egg\django\core\handlers\base.py", line 249, in _legacy_get_response
    response = self._get_response(request)
  File "D:\ProgramFiles\Anaconda3\lib\site-packages\django-1.11.8-py3.6.egg\django\core\handlers\base.py", line 187, in _get_response
    response = self.process_exception_by_middleware(e, request)
  File "D:\ProgramFiles\Anaconda3\lib\site-packages\django-1.11.8-py3.6.egg\django\core\handlers\base.py", line 185, in _get_response
    response = wrapped_callback(request, *callback_args, **callback_kwargs)
  File "D:\ProgramFiles\Anaconda3\lib\site-packages\django-1.11.8-py3.6.egg\django\utils\decorators.py", line 149, in _wrapped_view
    response = view_func(request, *args, **kwargs)
  File "D:\ProgramFiles\Anaconda3\lib\site-packages\dwebsocket\decorators.py", line 16, in new_func
    response = func(request, *args, **kwargs)
  File "D:\ProgramFiles\Anaconda3\lib\site-packages\django-1.11.8-py3.6.egg\django\views\decorators\csrf.py", line 58, in wrapped_view
    return view_func(*args, **kwargs)
  File "D:\tools\Tools\2018年3月5日\Carry\mysite\views.py", line 510, in getkline
    ticker=sub_socket.recv_pyobj()
  File "D:\ProgramFiles\Anaconda3\lib\site-packages\zmq\sugar\socket.py", line 492, in recv_pyobj
    return self._deserialize(msg, pickle.loads)
  File "D:\ProgramFiles\Anaconda3\lib\site-packages\zmq\sugar\socket.py", line 419, in _deserialize
    return load(recvd)
AttributeError: Can't get attribute 'SPApiTicker' on <module 'sp_struct' from 'D:\\tools\\Tools\\2018年3月5日\\Carry\\sp_struct.py'>
exception.py[2018-03-13 10:16:41][ERROR]：Internal Server Error: /getkline
Traceback (most recent call last):
  File "D:\ProgramFiles\Anaconda3\lib\site-packages\django-1.11.8-py3.6.egg\django\core\handlers\exception.py", line 41, in inner
    response = get_response(request)
  File "D:\ProgramFiles\Anaconda3\lib\site-packages\django-1.11.8-py3.6.egg\django\core\handlers\base.py", line 249, in _legacy_get_response
    response = self._get_response(request)
  File "D:\ProgramFiles\Anaconda3\lib\site-packages\django-1.11.8-py3.6.egg\django\core\handlers\base.py", line 187, in _get_response
    response = self.process_exception_by_middleware(e, request)
  File "D:\ProgramFiles\Anaconda3\lib\site-packages\django-1.11.8-py3.6.egg\django\core\handlers\base.py", line 185, in _get_response
    response = wrapped_callback(request, *callback_args, **callback_kwargs)
  File "D:\ProgramFiles\Anaconda3\lib\site-packages\django-1.11.8-py3.6.egg\django\utils\decorators.py", line 149, in _wrapped_view
    response = view_func(request, *args, **kwargs)
  File "D:\ProgramFiles\Anaconda3\lib\site-packages\dwebsocket\decorators.py", line 16, in new_func
    response = func(request, *args, **kwargs)
  File "D:\ProgramFiles\Anaconda3\lib\site-packages\django-1.11.8-py3.6.egg\django\views\decorators\csrf.py", line 58, in wrapped_view
    return view_func(*args, **kwargs)
  File "D:\tools\Tools\2018年3月5日\Carry\mysite\views.py", line 510, in getkline
    ticker=sub_socket.recv_pyobj()
  File "D:\ProgramFiles\Anaconda3\lib\site-packages\zmq\sugar\socket.py", line 492, in recv_pyobj
    return self._deserialize(msg, pickle.loads)
  File "D:\ProgramFiles\Anaconda3\lib\site-packages\zmq\sugar\socket.py", line 419, in _deserialize
    return load(recvd)
AttributeError: Can't get attribute 'SPApiTicker' on <module 'sp_struct' from 'D:\\tools\\Tools\\2018年3月5日\\Carry\\sp_struct.py'>
exception.py[2018-03-13 10:16:41][ERROR]：Internal Server Error: /getkline
Traceback (most recent call last):
  File "D:\ProgramFiles\Anaconda3\lib\site-packages\django-1.11.8-py3.6.egg\django\core\handlers\exception.py", line 41, in inner
    response = get_response(request)
  File "D:\ProgramFiles\Anaconda3\lib\site-packages\django-1.11.8-py3.6.egg\django\core\handlers\base.py", line 249, in _legacy_get_response
    response = self._get_response(request)
  File "D:\ProgramFiles\Anaconda3\lib\site-packages\django-1.11.8-py3.6.egg\django\core\handlers\base.py", line 187, in _get_response
    response = self.process_exception_by_middleware(e, request)
  File "D:\ProgramFiles\Anaconda3\lib\site-packages\django-1.11.8-py3.6.egg\django\core\handlers\base.py", line 185, in _get_response
    response = wrapped_callback(request, *callback_args, **callback_kwargs)
  File "D:\ProgramFiles\Anaconda3\lib\site-packages\django-1.11.8-py3.6.egg\django\utils\decorators.py", line 149, in _wrapped_view
    response = view_func(request, *args, **kwargs)
  File "D:\ProgramFiles\Anaconda3\lib\site-packages\dwebsocket\decorators.py", line 16, in new_func
    response = func(request, *args, **kwargs)
  File "D:\ProgramFiles\Anaconda3\lib\site-packages\django-1.11.8-py3.6.egg\django\views\decorators\csrf.py", line 58, in wrapped_view
    return view_func(*args, **kwargs)
  File "D:\tools\Tools\2018年3月5日\Carry\mysite\views.py", line 510, in getkline
    ticker=sub_socket.recv_pyobj()
  File "D:\ProgramFiles\Anaconda3\lib\site-packages\zmq\sugar\socket.py", line 492, in recv_pyobj
    return self._deserialize(msg, pickle.loads)
  File "D:\ProgramFiles\Anaconda3\lib\site-packages\zmq\sugar\socket.py", line 419, in _deserialize
    return load(recvd)
AttributeError: Can't get attribute 'SPApiTicker' on <module 'sp_struct' from 'D:\\tools\\Tools\\2018年3月5日\\Carry\\sp_struct.py'>
exception.py[2018-03-13 10:16:41][ERROR]：Internal Server Error: /getkline
Traceback (most recent call last):
  File "D:\ProgramFiles\Anaconda3\lib\site-packages\django-1.11.8-py3.6.egg\django\core\handlers\exception.py", line 41, in inner
    response = get_response(request)
  File "D:\ProgramFiles\Anaconda3\lib\site-packages\django-1.11.8-py3.6.egg\django\core\handlers\base.py", line 249, in _legacy_get_response
    response = self._get_response(request)
  File "D:\ProgramFiles\Anaconda3\lib\site-packages\django-1.11.8-py3.6.egg\django\core\handlers\base.py", line 187, in _get_response
    response = self.process_exception_by_middleware(e, request)
  File "D:\ProgramFiles\Anaconda3\lib\site-packages\django-1.11.8-py3.6.egg\django\core\handlers\base.py", line 185, in _get_response
    response = wrapped_callback(request, *callback_args, **callback_kwargs)
  File "D:\ProgramFiles\Anaconda3\lib\site-packages\django-1.11.8-py3.6.egg\django\utils\decorators.py", line 149, in _wrapped_view
    response = view_func(request, *args, **kwargs)
  File "D:\ProgramFiles\Anaconda3\lib\site-packages\dwebsocket\decorators.py", line 16, in new_func
    response = func(request, *args, **kwargs)
  File "D:\ProgramFiles\Anaconda3\lib\site-packages\django-1.11.8-py3.6.egg\django\views\decorators\csrf.py", line 58, in wrapped_view
    return view_func(*args, **kwargs)
  File "D:\tools\Tools\2018年3月5日\Carry\mysite\views.py", line 510, in getkline
    ticker=sub_socket.recv_pyobj()
  File "D:\ProgramFiles\Anaconda3\lib\site-packages\zmq\sugar\socket.py", line 492, in recv_pyobj
    return self._deserialize(msg, pickle.loads)
  File "D:\ProgramFiles\Anaconda3\lib\site-packages\zmq\sugar\socket.py", line 419, in _deserialize
    return load(recvd)
AttributeError: Can't get attribute 'SPApiTicker' on <module 'sp_struct' from 'D:\\tools\\Tools\\2018年3月5日\\Carry\\sp_struct.py'>
exception.py[2018-03-13 10:16:41][ERROR]：Internal Server Error: /getkline
Traceback (most recent call last):
  File "D:\ProgramFiles\Anaconda3\lib\site-packages\django-1.11.8-py3.6.egg\django\core\handlers\exception.py", line 41, in inner
    response = get_response(request)
  File "D:\ProgramFiles\Anaconda3\lib\site-packages\django-1.11.8-py3.6.egg\django\core\handlers\base.py", line 249, in _legacy_get_response
    response = self._get_response(request)
  File "D:\ProgramFiles\Anaconda3\lib\site-packages\django-1.11.8-py3.6.egg\django\core\handlers\base.py", line 187, in _get_response
    response = self.process_exception_by_middleware(e, request)
  File "D:\ProgramFiles\Anaconda3\lib\site-packages\django-1.11.8-py3.6.egg\django\core\handlers\base.py", line 185, in _get_response
    response = wrapped_callback(request, *callback_args, **callback_kwargs)
  File "D:\ProgramFiles\Anaconda3\lib\site-packages\django-1.11.8-py3.6.egg\django\utils\decorators.py", line 149, in _wrapped_view
    response = view_func(request, *args, **kwargs)
  File "D:\ProgramFiles\Anaconda3\lib\site-packages\dwebsocket\decorators.py", line 16, in new_func
    response = func(request, *args, **kwargs)
  File "D:\ProgramFiles\Anaconda3\lib\site-packages\django-1.11.8-py3.6.egg\django\views\decorators\csrf.py", line 58, in wrapped_view
    return view_func(*args, **kwargs)
  File "D:\tools\Tools\2018年3月5日\Carry\mysite\views.py", line 510, in getkline
    ticker=sub_socket.recv_pyobj()
  File "D:\ProgramFiles\Anaconda3\lib\site-packages\zmq\sugar\socket.py", line 492, in recv_pyobj
    return self._deserialize(msg, pickle.loads)
  File "D:\ProgramFiles\Anaconda3\lib\site-packages\zmq\sugar\socket.py", line 419, in _deserialize
    return load(recvd)
AttributeError: Can't get attribute 'SPApiTicker' on <module 'sp_struct' from 'D:\\tools\\Tools\\2018年3月5日\\Carry\\sp_struct.py'>
views.py[2018-03-13 10:45:40][ERROR]：Object of type 'datetime' is not JSON serializable
exception.py[2018-03-13 11:55:31][ERROR]：Internal Server Error: /tj/4
Traceback (most recent call last):
  File "D:\ProgramFiles\Anaconda3\lib\site-packages\django-1.11.8-py3.6.egg\django\core\handlers\exception.py", line 41, in inner
    response = get_response(request)
  File "D:\ProgramFiles\Anaconda3\lib\site-packages\django-1.11.8-py3.6.egg\django\core\handlers\base.py", line 249, in _legacy_get_response
    response = self._get_response(request)
  File "D:\ProgramFiles\Anaconda3\lib\site-packages\django-1.11.8-py3.6.egg\django\core\handlers\base.py", line 187, in _get_response
    response = self.process_exception_by_middleware(e, request)
  File "D:\ProgramFiles\Anaconda3\lib\site-packages\django-1.11.8-py3.6.egg\django\core\handlers\base.py", line 185, in _get_response
    response = wrapped_callback(request, *callback_args, **callback_kwargs)
  File "D:\tools\Tools\2018年3月5日\Carry\mysite\views.py", line 376, in tongji
    return render(rq,'tongji.html',{'results':results,'dates':rq_date,'ids':HSD.IDS,'huizong':huizong,'id_name':id_name,'id_count':id_count})
  File "D:\ProgramFiles\Anaconda3\lib\site-packages\django-1.11.8-py3.6.egg\django\shortcuts.py", line 30, in render
    content = loader.render_to_string(template_name, context, request, using=using)
  File "D:\ProgramFiles\Anaconda3\lib\site-packages\django-1.11.8-py3.6.egg\django\template\loader.py", line 68, in render_to_string
    return template.render(context, request)
  File "D:\ProgramFiles\Anaconda3\lib\site-packages\django-1.11.8-py3.6.egg\django\template\backends\django.py", line 66, in render
    return self.template.render(context)
  File "D:\ProgramFiles\Anaconda3\lib\site-packages\django-1.11.8-py3.6.egg\django\template\base.py", line 207, in render
    return self._render(context)
  File "D:\ProgramFiles\Anaconda3\lib\site-packages\django-1.11.8-py3.6.egg\django\template\base.py", line 199, in _render
    return self.nodelist.render(context)
  File "D:\ProgramFiles\Anaconda3\lib\site-packages\django-1.11.8-py3.6.egg\django\template\base.py", line 990, in render
    bit = node.render_annotated(context)
  File "D:\ProgramFiles\Anaconda3\lib\site-packages\django-1.11.8-py3.6.egg\django\template\base.py", line 957, in render_annotated
    return self.render(context)
  File "D:\ProgramFiles\Anaconda3\lib\site-packages\django-1.11.8-py3.6.egg\django\template\loader_tags.py", line 177, in render
    return compiled_parent._render(context)
  File "D:\ProgramFiles\Anaconda3\lib\site-packages\django-1.11.8-py3.6.egg\django\template\base.py", line 199, in _render
    return self.nodelist.render(context)
  File "D:\ProgramFiles\Anaconda3\lib\site-packages\django-1.11.8-py3.6.egg\django\template\base.py", line 990, in render
    bit = node.render_annotated(context)
  File "D:\ProgramFiles\Anaconda3\lib\site-packages\django-1.11.8-py3.6.egg\django\template\base.py", line 957, in render_annotated
    return self.render(context)
  File "D:\ProgramFiles\Anaconda3\lib\site-packages\django-1.11.8-py3.6.egg\django\template\loader_tags.py", line 72, in render
    result = block.nodelist.render(context)
  File "D:\ProgramFiles\Anaconda3\lib\site-packages\django-1.11.8-py3.6.egg\django\template\base.py", line 990, in render
    bit = node.render_annotated(context)
  File "D:\ProgramFiles\Anaconda3\lib\site-packages\django-1.11.8-py3.6.egg\django\template\base.py", line 957, in render_annotated
    return self.render(context)
  File "D:\ProgramFiles\Anaconda3\lib\site-packages\django-1.11.8-py3.6.egg\django\template\loader_tags.py", line 72, in render
    result = block.nodelist.render(context)
  File "D:\ProgramFiles\Anaconda3\lib\site-packages\django-1.11.8-py3.6.egg\django\template\base.py", line 990, in render
    bit = node.render_annotated(context)
  File "D:\ProgramFiles\Anaconda3\lib\site-packages\django-1.11.8-py3.6.egg\django\template\base.py", line 957, in render_annotated
    return self.render(context)
  File "D:\ProgramFiles\Anaconda3\lib\site-packages\django-1.11.8-py3.6.egg\django\template\defaulttags.py", line 321, in render
    if match:
ValueError: The truth value of an array with more than one element is ambiguous. Use a.any() or a.all()
exception.py[2018-03-13 13:28:01][ERROR]：Internal Server Error: /tj/4
Traceback (most recent call last):
  File "D:\ProgramFiles\Anaconda3\lib\site-packages\django-1.11.8-py3.6.egg\django\core\handlers\exception.py", line 41, in inner
    response = get_response(request)
  File "D:\ProgramFiles\Anaconda3\lib\site-packages\django-1.11.8-py3.6.egg\django\core\handlers\base.py", line 249, in _legacy_get_response
    response = self._get_response(request)
  File "D:\ProgramFiles\Anaconda3\lib\site-packages\django-1.11.8-py3.6.egg\django\core\handlers\base.py", line 187, in _get_response
    response = self.process_exception_by_middleware(e, request)
  File "D:\ProgramFiles\Anaconda3\lib\site-packages\django-1.11.8-py3.6.egg\django\core\handlers\base.py", line 185, in _get_response
    response = wrapped_callback(request, *callback_args, **callback_kwargs)
  File "D:\tools\Tools\2018年3月5日\Carry\mysite\views.py", line 373, in tongji
    id_count={i:len(results[np.where(results[:,2]==i)]) for i in HSD.IDS}
  File "D:\tools\Tools\2018年3月5日\Carry\mysite\views.py", line 373, in <dictcomp>
    id_count={i:len(results[np.where(results[:,2]==i)]) for i in HSD.IDS}
IndexError: too many indices for array
exception.py[2018-03-13 13:28:22][ERROR]：Internal Server Error: /tj/1
Traceback (most recent call last):
  File "D:\ProgramFiles\Anaconda3\lib\site-packages\django-1.11.8-py3.6.egg\django\core\handlers\exception.py", line 41, in inner
    response = get_response(request)
  File "D:\ProgramFiles\Anaconda3\lib\site-packages\django-1.11.8-py3.6.egg\django\core\handlers\base.py", line 249, in _legacy_get_response
    response = self._get_response(request)
  File "D:\ProgramFiles\Anaconda3\lib\site-packages\django-1.11.8-py3.6.egg\django\core\handlers\base.py", line 187, in _get_response
    response = self.process_exception_by_middleware(e, request)
  File "D:\ProgramFiles\Anaconda3\lib\site-packages\django-1.11.8-py3.6.egg\django\core\handlers\base.py", line 185, in _get_response
    response = wrapped_callback(request, *callback_args, **callback_kwargs)
  File "D:\tools\Tools\2018年3月5日\Carry\mysite\views.py", line 373, in tongji
    id_count={i:len(results[np.where(results[:,2]==i)]) for i in HSD.IDS}
  File "D:\tools\Tools\2018年3月5日\Carry\mysite\views.py", line 373, in <dictcomp>
    id_count={i:len(results[np.where(results[:,2]==i)]) for i in HSD.IDS}
IndexError: too many indices for array
exception.py[2018-03-13 13:28:31][ERROR]：Internal Server Error: /tj/1
Traceback (most recent call last):
  File "D:\ProgramFiles\Anaconda3\lib\site-packages\django-1.11.8-py3.6.egg\django\core\handlers\exception.py", line 41, in inner
    response = get_response(request)
  File "D:\ProgramFiles\Anaconda3\lib\site-packages\django-1.11.8-py3.6.egg\django\core\handlers\base.py", line 249, in _legacy_get_response
    response = self._get_response(request)
  File "D:\ProgramFiles\Anaconda3\lib\site-packages\django-1.11.8-py3.6.egg\django\core\handlers\base.py", line 187, in _get_response
    response = self.process_exception_by_middleware(e, request)
  File "D:\ProgramFiles\Anaconda3\lib\site-packages\django-1.11.8-py3.6.egg\django\core\handlers\base.py", line 185, in _get_response
    response = wrapped_callback(request, *callback_args, **callback_kwargs)
  File "D:\tools\Tools\2018年3月5日\Carry\mysite\views.py", line 373, in tongji
    id_count={i:len(results[np.where(results[:,2]==i)]) for i in HSD.IDS}
  File "D:\tools\Tools\2018年3月5日\Carry\mysite\views.py", line 373, in <dictcomp>
    id_count={i:len(results[np.where(results[:,2]==i)]) for i in HSD.IDS}
IndexError: too many indices for array
exception.py[2018-03-13 13:28:48][ERROR]：Internal Server Error: /tj/1
Traceback (most recent call last):
  File "D:\ProgramFiles\Anaconda3\lib\site-packages\django-1.11.8-py3.6.egg\django\core\handlers\exception.py", line 41, in inner
    response = get_response(request)
  File "D:\ProgramFiles\Anaconda3\lib\site-packages\django-1.11.8-py3.6.egg\django\core\handlers\base.py", line 249, in _legacy_get_response
    response = self._get_response(request)
  File "D:\ProgramFiles\Anaconda3\lib\site-packages\django-1.11.8-py3.6.egg\django\core\handlers\base.py", line 187, in _get_response
    response = self.process_exception_by_middleware(e, request)
  File "D:\ProgramFiles\Anaconda3\lib\site-packages\django-1.11.8-py3.6.egg\django\core\handlers\base.py", line 185, in _get_response
    response = wrapped_callback(request, *callback_args, **callback_kwargs)
  File "D:\tools\Tools\2018年3月5日\Carry\mysite\views.py", line 373, in tongji
    id_count={i:len(results[np.where(results[:,2]==i)]) for i in HSD.IDS}
  File "D:\tools\Tools\2018年3月5日\Carry\mysite\views.py", line 373, in <dictcomp>
    id_count={i:len(results[np.where(results[:,2]==i)]) for i in HSD.IDS}
IndexError: too many indices for array
exception.py[2018-03-13 13:30:39][ERROR]：Internal Server Error: /tj/1
Traceback (most recent call last):
  File "D:\ProgramFiles\Anaconda3\lib\site-packages\django-1.11.8-py3.6.egg\django\core\handlers\exception.py", line 41, in inner
    response = get_response(request)
  File "D:\ProgramFiles\Anaconda3\lib\site-packages\django-1.11.8-py3.6.egg\django\core\handlers\base.py", line 249, in _legacy_get_response
    response = self._get_response(request)
  File "D:\ProgramFiles\Anaconda3\lib\site-packages\django-1.11.8-py3.6.egg\django\core\handlers\base.py", line 187, in _get_response
    response = self.process_exception_by_middleware(e, request)
  File "D:\ProgramFiles\Anaconda3\lib\site-packages\django-1.11.8-py3.6.egg\django\core\handlers\base.py", line 185, in _get_response
    response = wrapped_callback(request, *callback_args, **callback_kwargs)
  File "D:\tools\Tools\2018年3月5日\Carry\mysite\views.py", line 371, in tongji
    results.remove(results[ind1])
ValueError: The truth value of an array with more than one element is ambiguous. Use a.any() or a.all()
exception.py[2018-03-13 13:35:07][ERROR]：Internal Server Error: /tj/1
Traceback (most recent call last):
  File "D:\ProgramFiles\Anaconda3\lib\site-packages\django-1.11.8-py3.6.egg\django\core\handlers\exception.py", line 41, in inner
    response = get_response(request)
  File "D:\ProgramFiles\Anaconda3\lib\site-packages\django-1.11.8-py3.6.egg\django\core\handlers\base.py", line 249, in _legacy_get_response
    response = self._get_response(request)
  File "D:\ProgramFiles\Anaconda3\lib\site-packages\django-1.11.8-py3.6.egg\django\core\handlers\base.py", line 187, in _get_response
    response = self.process_exception_by_middleware(e, request)
  File "D:\ProgramFiles\Anaconda3\lib\site-packages\django-1.11.8-py3.6.egg\django\core\handlers\base.py", line 185, in _get_response
    response = wrapped_callback(request, *callback_args, **callback_kwargs)
  File "D:\tools\Tools\2018年3月5日\Carry\mysite\views.py", line 373, in tongji
    results.remove(results[ind1])
ValueError: The truth value of an array with more than one element is ambiguous. Use a.any() or a.all()
exception.py[2018-03-13 13:35:10][ERROR]：Internal Server Error: /tj/1
Traceback (most recent call last):
  File "D:\ProgramFiles\Anaconda3\lib\site-packages\django-1.11.8-py3.6.egg\django\core\handlers\exception.py", line 41, in inner
    response = get_response(request)
  File "D:\ProgramFiles\Anaconda3\lib\site-packages\django-1.11.8-py3.6.egg\django\core\handlers\base.py", line 249, in _legacy_get_response
    response = self._get_response(request)
  File "D:\ProgramFiles\Anaconda3\lib\site-packages\django-1.11.8-py3.6.egg\django\core\handlers\base.py", line 187, in _get_response
    response = self.process_exception_by_middleware(e, request)
  File "D:\ProgramFiles\Anaconda3\lib\site-packages\django-1.11.8-py3.6.egg\django\core\handlers\base.py", line 185, in _get_response
    response = wrapped_callback(request, *callback_args, **callback_kwargs)
  File "D:\tools\Tools\2018年3月5日\Carry\mysite\views.py", line 373, in tongji
    results.remove(results[ind1])
ValueError: The truth value of an array with more than one element is ambiguous. Use a.any() or a.all()
exception.py[2018-03-13 13:36:56][ERROR]：Internal Server Error: /tj/1
Traceback (most recent call last):
  File "D:\ProgramFiles\Anaconda3\lib\site-packages\django-1.11.8-py3.6.egg\django\core\handlers\exception.py", line 41, in inner
    response = get_response(request)
  File "D:\ProgramFiles\Anaconda3\lib\site-packages\django-1.11.8-py3.6.egg\django\core\handlers\base.py", line 249, in _legacy_get_response
    response = self._get_response(request)
  File "D:\ProgramFiles\Anaconda3\lib\site-packages\django-1.11.8-py3.6.egg\django\core\handlers\base.py", line 187, in _get_response
    response = self.process_exception_by_middleware(e, request)
  File "D:\ProgramFiles\Anaconda3\lib\site-packages\django-1.11.8-py3.6.egg\django\core\handlers\base.py", line 185, in _get_response
    response = wrapped_callback(request, *callback_args, **callback_kwargs)
  File "D:\tools\Tools\2018年3月5日\Carry\mysite\views.py", line 370, in tongji
    if results[ind1] in results and rq_id != results[ind1][2]:
ValueError: The truth value of an array with more than one element is ambiguous. Use a.any() or a.all()
exception.py[2018-03-13 13:37:19][ERROR]：Internal Server Error: /tj/1
Traceback (most recent call last):
  File "D:\ProgramFiles\Anaconda3\lib\site-packages\django-1.11.8-py3.6.egg\django\core\handlers\exception.py", line 41, in inner
    response = get_response(request)
  File "D:\ProgramFiles\Anaconda3\lib\site-packages\django-1.11.8-py3.6.egg\django\core\handlers\base.py", line 249, in _legacy_get_response
    response = self._get_response(request)
  File "D:\ProgramFiles\Anaconda3\lib\site-packages\django-1.11.8-py3.6.egg\django\core\handlers\base.py", line 187, in _get_response
    response = self.process_exception_by_middleware(e, request)
  File "D:\ProgramFiles\Anaconda3\lib\site-packages\django-1.11.8-py3.6.egg\django\core\handlers\base.py", line 185, in _get_response
    response = wrapped_callback(request, *callback_args, **callback_kwargs)
  File "D:\tools\Tools\2018年3月5日\Carry\mysite\views.py", line 372, in tongji
    results.remove(results[ind1])
ValueError: The truth value of an array with more than one element is ambiguous. Use a.any() or a.all()
