base.py[2018-03-07 16:35:00][WARNING]：Not Found: /favicon.ico
base.py[2018-03-07 18:16:24][WARNING]：Not Found: /favicon.ico
HSD.py[2018-03-08 11:47:49][ERROR]：list index out of range
HSD.py[2018-03-08 11:48:01][ERROR]：list index out of range
HSD.py[2018-03-08 11:48:11][ERROR]：list index out of range
HSD.py[2018-03-08 11:48:14][ERROR]：list indices must be integers or slices, not str
HSD.py[2018-03-08 11:48:33][ERROR]：list index out of range
HSD.py[2018-03-08 11:48:34][ERROR]：list index out of range
HSD.py[2018-03-08 11:48:36][ERROR]：list index out of range
HSD.py[2018-03-08 11:48:44][ERROR]：list index out of range
HSD.py[2018-03-08 11:48:50][ERROR]：list indices must be integers or slices, not str
HSD.py[2018-03-08 11:48:50][ERROR]：list index out of range
HSD.py[2018-03-08 11:48:57][ERROR]：list index out of range
exception.py[2018-03-08 11:48:57][ERROR]：Internal Server Error: /jyzt/
Traceback (most recent call last):
  File "D:\ProgramFiles\Anaconda3\lib\site-packages\django-1.11.8-py3.6.egg\django\core\handlers\exception.py", line 41, in inner
    response = get_response(request)
  File "D:\ProgramFiles\Anaconda3\lib\site-packages\django-1.11.8-py3.6.egg\django\core\handlers\base.py", line 249, in _legacy_get_response
    response = self._get_response(request)
  File "D:\ProgramFiles\Anaconda3\lib\site-packages\django-1.11.8-py3.6.egg\django\core\handlers\base.py", line 187, in _get_response
    response = self.process_exception_by_middleware(e, request)
  File "D:\ProgramFiles\Anaconda3\lib\site-packages\django-1.11.8-py3.6.egg\django\core\handlers\base.py", line 185, in _get_response
    response = wrapped_callback(request, *callback_args, **callback_kwargs)
  File "D:\tools\Tools\2018年3月5日\Carry\mysite\views.py", line 530, in jyzt
    zt = ZT.yanzen()
  File "D:\tools\Tools\2018年3月5日\Carry\mysite\HSD.py", line 495, in yanzen
    with open('log\\jyzt_gp.txt') as f: # 保存
FileNotFoundError: [Errno 2] No such file or directory: 'log\\jyzt_gp.txt'
HSD.py[2018-03-08 11:50:58][ERROR]：list index out of range
HSD.py[2018-03-08 11:51:06][ERROR]：list index out of range
HSD.py[2018-03-08 11:51:16][ERROR]：list index out of range
HSD.py[2018-03-08 11:51:19][ERROR]：list indices must be integers or slices, not str
HSD.py[2018-03-08 11:51:33][ERROR]：list index out of range
HSD.py[2018-03-08 11:51:35][ERROR]：list index out of range
HSD.py[2018-03-08 11:51:37][ERROR]：list index out of range
HSD.py[2018-03-08 11:51:45][ERROR]：list index out of range
HSD.py[2018-03-08 11:51:50][ERROR]：list indices must be integers or slices, not str
HSD.py[2018-03-08 11:51:50][ERROR]：list index out of range
HSD.py[2018-03-08 11:51:55][ERROR]：list index out of range
base.py[2018-03-08 12:05:45][WARNING]：Not Found: /zhangting/jyzt
base.py[2018-03-08 12:05:57][WARNING]：Not Found: /zyzt
base.py[2018-03-08 12:06:11][WARNING]：Not Found: /zyzt/
base.py[2018-03-08 12:06:16][WARNING]：Not Found: /zyzt
base.py[2018-03-08 13:33:22][WARNING]：Not Found: /jyzt/
base.py[2018-03-08 15:20:08][WARNING]：Not Found: /favicon.ico
base.py[2018-03-08 15:20:09][WARNING]：Not Found: /favicon.ico
base.py[2018-03-08 15:20:09][WARNING]：Not Found: /favicon.ico
views.py[2018-03-08 15:28:48][ERROR]：Object of type 'datetime' is not JSON serializable
views.py[2018-03-08 15:45:50][ERROR]：name 'cache' is not defined
views.py[2018-03-08 15:45:50][ERROR]：name 'cache' is not defined
views.py[2018-03-08 15:45:50][ERROR]：name 'cache' is not defined
views.py[2018-03-08 15:45:50][ERROR]：name 'cache' is not defined
views.py[2018-03-08 15:46:04][ERROR]：name 'cache' is not defined
views.py[2018-03-08 15:46:04][ERROR]：name 'cache' is not defined
views.py[2018-03-08 15:46:04][ERROR]：name 'cache' is not defined
views.py[2018-03-08 15:46:04][ERROR]：name 'cache' is not defined
views.py[2018-03-08 15:46:04][ERROR]：name 'cache' is not defined
views.py[2018-03-08 15:46:04][ERROR]：name 'cache' is not defined
exception.py[2018-03-08 15:46:04][ERROR]：Internal Server Error: /getkline
Traceback (most recent call last):
  File "D:\ProgramFiles\Anaconda3\lib\site-packages\django-1.11.8-py3.6.egg\django\core\handlers\exception.py", line 41, in inner
    response = get_response(request)
  File "D:\ProgramFiles\Anaconda3\lib\site-packages\django-1.11.8-py3.6.egg\django\core\handlers\base.py", line 249, in _legacy_get_response
    response = self._get_response(request)
  File "D:\ProgramFiles\Anaconda3\lib\site-packages\django-1.11.8-py3.6.egg\django\core\handlers\base.py", line 187, in _get_response
    response = self.process_exception_by_middleware(e, request)
  File "D:\ProgramFiles\Anaconda3\lib\site-packages\django-1.11.8-py3.6.egg\django\core\handlers\base.py", line 185, in _get_response
    response = wrapped_callback(request, *callback_args, **callback_kwargs)
  File "D:\ProgramFiles\Anaconda3\lib\site-packages\django-1.11.8-py3.6.egg\django\utils\decorators.py", line 149, in _wrapped_view
    response = view_func(request, *args, **kwargs)
  File "D:\ProgramFiles\Anaconda3\lib\site-packages\dwebsocket\decorators.py", line 16, in new_func
    response = func(request, *args, **kwargs)
  File "D:\ProgramFiles\Anaconda3\lib\site-packages\django-1.11.8-py3.6.egg\django\views\decorators\csrf.py", line 58, in wrapped_view
    return view_func(*args, **kwargs)
  File "D:\tools\Tools\2018年3月5日\Carry\mysite\views.py", line 526, in getkline
    times,opens,high,low,close,vol=objArr #if objArr else (ticker.TickerTime*1000,ticker.Price,ticker.Price,ticker.Price,ticker.Price,ticker.Qty)
TypeError: 'NoneType' object is not iterable
views.py[2018-03-08 15:46:16][ERROR]：name 'cache' is not defined
views.py[2018-03-08 15:46:17][ERROR]：name 'cache' is not defined
views.py[2018-03-08 15:46:17][ERROR]：name 'cache' is not defined
views.py[2018-03-08 15:46:17][ERROR]：name 'cache' is not defined
views.py[2018-03-08 15:46:17][ERROR]：name 'cache' is not defined
views.py[2018-03-08 15:46:17][ERROR]：name 'cache' is not defined
exception.py[2018-03-08 15:46:17][ERROR]：Internal Server Error: /getkline
Traceback (most recent call last):
  File "D:\ProgramFiles\Anaconda3\lib\site-packages\django-1.11.8-py3.6.egg\django\core\handlers\exception.py", line 41, in inner
    response = get_response(request)
  File "D:\ProgramFiles\Anaconda3\lib\site-packages\django-1.11.8-py3.6.egg\django\core\handlers\base.py", line 249, in _legacy_get_response
    response = self._get_response(request)
  File "D:\ProgramFiles\Anaconda3\lib\site-packages\django-1.11.8-py3.6.egg\django\core\handlers\base.py", line 187, in _get_response
    response = self.process_exception_by_middleware(e, request)
  File "D:\ProgramFiles\Anaconda3\lib\site-packages\django-1.11.8-py3.6.egg\django\core\handlers\base.py", line 185, in _get_response
    response = wrapped_callback(request, *callback_args, **callback_kwargs)
  File "D:\ProgramFiles\Anaconda3\lib\site-packages\django-1.11.8-py3.6.egg\django\utils\decorators.py", line 149, in _wrapped_view
    response = view_func(request, *args, **kwargs)
  File "D:\ProgramFiles\Anaconda3\lib\site-packages\dwebsocket\decorators.py", line 16, in new_func
    response = func(request, *args, **kwargs)
  File "D:\ProgramFiles\Anaconda3\lib\site-packages\django-1.11.8-py3.6.egg\django\views\decorators\csrf.py", line 58, in wrapped_view
    return view_func(*args, **kwargs)
  File "D:\tools\Tools\2018年3月5日\Carry\mysite\views.py", line 526, in getkline
    times,opens,high,low,close,vol=objArr #if objArr else (ticker.TickerTime*1000,ticker.Price,ticker.Price,ticker.Price,ticker.Price,ticker.Qty)
TypeError: 'NoneType' object is not iterable
views.py[2018-03-08 15:47:05][ERROR]：name 'cache' is not defined
views.py[2018-03-08 15:47:05][ERROR]：name 'cache' is not defined
views.py[2018-03-08 15:47:05][ERROR]：name 'cache' is not defined
views.py[2018-03-08 15:47:05][ERROR]：name 'cache' is not defined
views.py[2018-03-08 15:47:08][ERROR]：name 'cache' is not defined
views.py[2018-03-08 15:47:09][ERROR]：name 'cache' is not defined
views.py[2018-03-08 15:47:09][ERROR]：name 'cache' is not defined
views.py[2018-03-08 15:47:09][ERROR]：name 'cache' is not defined
views.py[2018-03-08 15:47:09][ERROR]：name 'cache' is not defined
views.py[2018-03-08 15:47:09][ERROR]：name 'cache' is not defined
exception.py[2018-03-08 15:47:09][ERROR]：Internal Server Error: /getkline
Traceback (most recent call last):
  File "D:\ProgramFiles\Anaconda3\lib\site-packages\django-1.11.8-py3.6.egg\django\core\handlers\exception.py", line 41, in inner
    response = get_response(request)
  File "D:\ProgramFiles\Anaconda3\lib\site-packages\django-1.11.8-py3.6.egg\django\core\handlers\base.py", line 249, in _legacy_get_response
    response = self._get_response(request)
  File "D:\ProgramFiles\Anaconda3\lib\site-packages\django-1.11.8-py3.6.egg\django\core\handlers\base.py", line 187, in _get_response
    response = self.process_exception_by_middleware(e, request)
  File "D:\ProgramFiles\Anaconda3\lib\site-packages\django-1.11.8-py3.6.egg\django\core\handlers\base.py", line 185, in _get_response
    response = wrapped_callback(request, *callback_args, **callback_kwargs)
  File "D:\ProgramFiles\Anaconda3\lib\site-packages\django-1.11.8-py3.6.egg\django\utils\decorators.py", line 149, in _wrapped_view
    response = view_func(request, *args, **kwargs)
  File "D:\ProgramFiles\Anaconda3\lib\site-packages\dwebsocket\decorators.py", line 16, in new_func
    response = func(request, *args, **kwargs)
  File "D:\ProgramFiles\Anaconda3\lib\site-packages\django-1.11.8-py3.6.egg\django\views\decorators\csrf.py", line 58, in wrapped_view
    return view_func(*args, **kwargs)
  File "D:\tools\Tools\2018年3月5日\Carry\mysite\views.py", line 527, in getkline
    times,opens,high,low,close,vol=objArr #if objArr else (ticker.TickerTime*1000,ticker.Price,ticker.Price,ticker.Price,ticker.Price,ticker.Qty)
TypeError: 'NoneType' object is not iterable
base.py[2018-03-08 17:44:08][WARNING]：Not Found: /favicon.ico
base.py[2018-03-09 09:54:06][WARNING]：Not Found: /favicon.ico
base.py[2018-03-12 09:04:42][WARNING]：Not Found: /favicon.ico
exception.py[2018-03-12 13:26:00][ERROR]：Internal Server Error: /getkline
Traceback (most recent call last):
  File "D:\ProgramFiles\Anaconda3\lib\site-packages\django-1.11.8-py3.6.egg\django\core\handlers\exception.py", line 41, in inner
    response = get_response(request)
  File "D:\ProgramFiles\Anaconda3\lib\site-packages\django-1.11.8-py3.6.egg\django\core\handlers\base.py", line 249, in _legacy_get_response
    response = self._get_response(request)
  File "D:\ProgramFiles\Anaconda3\lib\site-packages\django-1.11.8-py3.6.egg\django\core\handlers\base.py", line 187, in _get_response
    response = self.process_exception_by_middleware(e, request)
  File "D:\ProgramFiles\Anaconda3\lib\site-packages\django-1.11.8-py3.6.egg\django\core\handlers\base.py", line 185, in _get_response
    response = wrapped_callback(request, *callback_args, **callback_kwargs)
  File "D:\ProgramFiles\Anaconda3\lib\site-packages\django-1.11.8-py3.6.egg\django\utils\decorators.py", line 149, in _wrapped_view
    response = view_func(request, *args, **kwargs)
  File "D:\ProgramFiles\Anaconda3\lib\site-packages\dwebsocket\decorators.py", line 16, in new_func
    response = func(request, *args, **kwargs)
  File "D:\ProgramFiles\Anaconda3\lib\site-packages\django-1.11.8-py3.6.egg\django\views\decorators\csrf.py", line 58, in wrapped_view
    return view_func(*args, **kwargs)
  File "D:\tools\Tools\2018年3月5日\Carry\mysite\views.py", line 523, in getkline
    if is_time and int(times/60)==int(is_time/60): #若不满一分钟,修改数据
OverflowError: integer division result too large for a float
exception.py[2018-03-12 13:28:08][ERROR]：Internal Server Error: /getkline
Traceback (most recent call last):
  File "D:\ProgramFiles\Anaconda3\lib\site-packages\django-1.11.8-py3.6.egg\django\core\handlers\exception.py", line 41, in inner
    response = get_response(request)
  File "D:\ProgramFiles\Anaconda3\lib\site-packages\django-1.11.8-py3.6.egg\django\core\handlers\base.py", line 249, in _legacy_get_response
    response = self._get_response(request)
  File "D:\ProgramFiles\Anaconda3\lib\site-packages\django-1.11.8-py3.6.egg\django\core\handlers\base.py", line 187, in _get_response
    response = self.process_exception_by_middleware(e, request)
  File "D:\ProgramFiles\Anaconda3\lib\site-packages\django-1.11.8-py3.6.egg\django\core\handlers\base.py", line 185, in _get_response
    response = wrapped_callback(request, *callback_args, **callback_kwargs)
  File "D:\ProgramFiles\Anaconda3\lib\site-packages\django-1.11.8-py3.6.egg\django\utils\decorators.py", line 149, in _wrapped_view
    response = view_func(request, *args, **kwargs)
  File "D:\ProgramFiles\Anaconda3\lib\site-packages\dwebsocket\decorators.py", line 16, in new_func
    response = func(request, *args, **kwargs)
  File "D:\ProgramFiles\Anaconda3\lib\site-packages\django-1.11.8-py3.6.egg\django\views\decorators\csrf.py", line 58, in wrapped_view
    return view_func(*args, **kwargs)
  File "D:\tools\Tools\2018年3月5日\Carry\mysite\views.py", line 524, in getkline
    if is_time and int(times/60)==int(is_time/60): #若不满一分钟,修改数据
OverflowError: integer division result too large for a float
exception.py[2018-03-12 13:29:36][ERROR]：Internal Server Error: /getkline
Traceback (most recent call last):
  File "D:\ProgramFiles\Anaconda3\lib\site-packages\django-1.11.8-py3.6.egg\django\core\handlers\exception.py", line 41, in inner
    response = get_response(request)
  File "D:\ProgramFiles\Anaconda3\lib\site-packages\django-1.11.8-py3.6.egg\django\core\handlers\base.py", line 249, in _legacy_get_response
    response = self._get_response(request)
  File "D:\ProgramFiles\Anaconda3\lib\site-packages\django-1.11.8-py3.6.egg\django\core\handlers\base.py", line 187, in _get_response
    response = self.process_exception_by_middleware(e, request)
  File "D:\ProgramFiles\Anaconda3\lib\site-packages\django-1.11.8-py3.6.egg\django\core\handlers\base.py", line 185, in _get_response
    response = wrapped_callback(request, *callback_args, **callback_kwargs)
  File "D:\ProgramFiles\Anaconda3\lib\site-packages\django-1.11.8-py3.6.egg\django\utils\decorators.py", line 149, in _wrapped_view
    response = view_func(request, *args, **kwargs)
  File "D:\ProgramFiles\Anaconda3\lib\site-packages\dwebsocket\decorators.py", line 16, in new_func
    response = func(request, *args, **kwargs)
  File "D:\ProgramFiles\Anaconda3\lib\site-packages\django-1.11.8-py3.6.egg\django\views\decorators\csrf.py", line 58, in wrapped_view
    return view_func(*args, **kwargs)
  File "D:\tools\Tools\2018年3月5日\Carry\mysite\views.py", line 523, in getkline
    print('times......',int(times),int(is_time))
TypeError: int() argument must be a string, a bytes-like object or a number, not 'NoneType'
exception.py[2018-03-12 19:32:41][ERROR]：Internal Server Error: /tj/4
Traceback (most recent call last):
  File "D:\ProgramFiles\Anaconda3\lib\site-packages\django-1.11.8-py3.6.egg\django\template\defaulttags.py", line 1038, in find_library
    return parser.libraries[name]
KeyError: 'mvote'

During handling of the above exception, another exception occurred:

Traceback (most recent call last):
  File "D:\ProgramFiles\Anaconda3\lib\site-packages\django-1.11.8-py3.6.egg\django\core\handlers\exception.py", line 41, in inner
    response = get_response(request)
  File "D:\ProgramFiles\Anaconda3\lib\site-packages\django-1.11.8-py3.6.egg\django\core\handlers\base.py", line 249, in _legacy_get_response
    response = self._get_response(request)
  File "D:\ProgramFiles\Anaconda3\lib\site-packages\django-1.11.8-py3.6.egg\django\core\handlers\base.py", line 187, in _get_response
    response = self.process_exception_by_middleware(e, request)
  File "D:\ProgramFiles\Anaconda3\lib\site-packages\django-1.11.8-py3.6.egg\django\core\handlers\base.py", line 185, in _get_response
    response = wrapped_callback(request, *callback_args, **callback_kwargs)
  File "D:\tools\Tools\2018年3月5日\Carry\mysite\views.py", line 374, in tongji
    return render(rq,'tongji.html',{'results':results,'dates':rq_date,'ids':HSD.IDS,'huizong':huizong,'id_name':id_name})
  File "D:\ProgramFiles\Anaconda3\lib\site-packages\django-1.11.8-py3.6.egg\django\shortcuts.py", line 30, in render
    content = loader.render_to_string(template_name, context, request, using=using)
  File "D:\ProgramFiles\Anaconda3\lib\site-packages\django-1.11.8-py3.6.egg\django\template\loader.py", line 67, in render_to_string
    template = get_template(template_name, using=using)
  File "D:\ProgramFiles\Anaconda3\lib\site-packages\django-1.11.8-py3.6.egg\django\template\loader.py", line 21, in get_template
    return engine.get_template(template_name)
  File "D:\ProgramFiles\Anaconda3\lib\site-packages\django-1.11.8-py3.6.egg\django\template\backends\django.py", line 39, in get_template
    return Template(self.engine.get_template(template_name), self)
  File "D:\ProgramFiles\Anaconda3\lib\site-packages\django-1.11.8-py3.6.egg\django\template\engine.py", line 162, in get_template
    template, origin = self.find_template(template_name)
  File "D:\ProgramFiles\Anaconda3\lib\site-packages\django-1.11.8-py3.6.egg\django\template\engine.py", line 136, in find_template
    name, template_dirs=dirs, skip=skip,
  File "D:\ProgramFiles\Anaconda3\lib\site-packages\django-1.11.8-py3.6.egg\django\template\loaders\base.py", line 44, in get_template
    contents, origin, origin.template_name, self.engine,
  File "D:\ProgramFiles\Anaconda3\lib\site-packages\django-1.11.8-py3.6.egg\django\template\base.py", line 191, in __init__
    self.nodelist = self.compile_nodelist()
  File "D:\ProgramFiles\Anaconda3\lib\site-packages\django-1.11.8-py3.6.egg\django\template\base.py", line 230, in compile_nodelist
    return parser.parse()
  File "D:\ProgramFiles\Anaconda3\lib\site-packages\django-1.11.8-py3.6.egg\django\template\base.py", line 515, in parse
    raise self.error(token, e)
  File "D:\ProgramFiles\Anaconda3\lib\site-packages\django-1.11.8-py3.6.egg\django\template\base.py", line 513, in parse
    compiled_result = compile_func(self, token)
  File "D:\ProgramFiles\Anaconda3\lib\site-packages\django-1.11.8-py3.6.egg\django\template\loader_tags.py", line 312, in do_extends
    nodelist = parser.parse()
  File "D:\ProgramFiles\Anaconda3\lib\site-packages\django-1.11.8-py3.6.egg\django\template\base.py", line 515, in parse
    raise self.error(token, e)
  File "D:\ProgramFiles\Anaconda3\lib\site-packages\django-1.11.8-py3.6.egg\django\template\base.py", line 513, in parse
    compiled_result = compile_func(self, token)
  File "D:\ProgramFiles\Anaconda3\lib\site-packages\django-1.11.8-py3.6.egg\django\template\loader_tags.py", line 255, in do_block
    nodelist = parser.parse(('endblock',))
  File "D:\ProgramFiles\Anaconda3\lib\site-packages\django-1.11.8-py3.6.egg\django\template\base.py", line 515, in parse
    raise self.error(token, e)
  File "D:\ProgramFiles\Anaconda3\lib\site-packages\django-1.11.8-py3.6.egg\django\template\base.py", line 513, in parse
    compiled_result = compile_func(self, token)
  File "D:\ProgramFiles\Anaconda3\lib\site-packages\django-1.11.8-py3.6.egg\django\template\defaulttags.py", line 977, in do_if
    nodelist = parser.parse(('elif', 'else', 'endif'))
  File "D:\ProgramFiles\Anaconda3\lib\site-packages\django-1.11.8-py3.6.egg\django\template\base.py", line 515, in parse
    raise self.error(token, e)
  File "D:\ProgramFiles\Anaconda3\lib\site-packages\django-1.11.8-py3.6.egg\django\template\base.py", line 513, in parse
    compiled_result = compile_func(self, token)
  File "D:\ProgramFiles\Anaconda3\lib\site-packages\django-1.11.8-py3.6.egg\django\template\defaulttags.py", line 1095, in load
    lib = find_library(parser, name)
  File "D:\ProgramFiles\Anaconda3\lib\site-packages\django-1.11.8-py3.6.egg\django\template\defaulttags.py", line 1042, in find_library
    name, "\n".join(sorted(parser.libraries.keys())),
django.template.exceptions.TemplateSyntaxError: 'mvote' is not a registered tag library. Must be one of:
admin_list
admin_modify
admin_static
admin_urls
cache
i18n
l10n
log
static
staticfiles
tz
exception.py[2018-03-12 19:33:31][ERROR]：Internal Server Error: /tj/4
Traceback (most recent call last):
  File "D:\ProgramFiles\Anaconda3\lib\site-packages\django-1.11.8-py3.6.egg\django\template\defaulttags.py", line 1038, in find_library
    return parser.libraries[name]
KeyError: 'mvote'

During handling of the above exception, another exception occurred:

Traceback (most recent call last):
  File "D:\ProgramFiles\Anaconda3\lib\site-packages\django-1.11.8-py3.6.egg\django\core\handlers\exception.py", line 41, in inner
    response = get_response(request)
  File "D:\ProgramFiles\Anaconda3\lib\site-packages\django-1.11.8-py3.6.egg\django\core\handlers\base.py", line 249, in _legacy_get_response
    response = self._get_response(request)
  File "D:\ProgramFiles\Anaconda3\lib\site-packages\django-1.11.8-py3.6.egg\django\core\handlers\base.py", line 187, in _get_response
    response = self.process_exception_by_middleware(e, request)
  File "D:\ProgramFiles\Anaconda3\lib\site-packages\django-1.11.8-py3.6.egg\django\core\handlers\base.py", line 185, in _get_response
    response = wrapped_callback(request, *callback_args, **callback_kwargs)
  File "D:\tools\Tools\2018年3月5日\Carry\mysite\views.py", line 374, in tongji
    return render(rq,'tongji.html',{'results':results,'dates':rq_date,'ids':HSD.IDS,'huizong':huizong,'id_name':id_name})
  File "D:\ProgramFiles\Anaconda3\lib\site-packages\django-1.11.8-py3.6.egg\django\shortcuts.py", line 30, in render
    content = loader.render_to_string(template_name, context, request, using=using)
  File "D:\ProgramFiles\Anaconda3\lib\site-packages\django-1.11.8-py3.6.egg\django\template\loader.py", line 67, in render_to_string
    template = get_template(template_name, using=using)
  File "D:\ProgramFiles\Anaconda3\lib\site-packages\django-1.11.8-py3.6.egg\django\template\loader.py", line 21, in get_template
    return engine.get_template(template_name)
  File "D:\ProgramFiles\Anaconda3\lib\site-packages\django-1.11.8-py3.6.egg\django\template\backends\django.py", line 39, in get_template
    return Template(self.engine.get_template(template_name), self)
  File "D:\ProgramFiles\Anaconda3\lib\site-packages\django-1.11.8-py3.6.egg\django\template\engine.py", line 162, in get_template
    template, origin = self.find_template(template_name)
  File "D:\ProgramFiles\Anaconda3\lib\site-packages\django-1.11.8-py3.6.egg\django\template\engine.py", line 136, in find_template
    name, template_dirs=dirs, skip=skip,
  File "D:\ProgramFiles\Anaconda3\lib\site-packages\django-1.11.8-py3.6.egg\django\template\loaders\base.py", line 44, in get_template
    contents, origin, origin.template_name, self.engine,
  File "D:\ProgramFiles\Anaconda3\lib\site-packages\django-1.11.8-py3.6.egg\django\template\base.py", line 191, in __init__
    self.nodelist = self.compile_nodelist()
  File "D:\ProgramFiles\Anaconda3\lib\site-packages\django-1.11.8-py3.6.egg\django\template\base.py", line 230, in compile_nodelist
    return parser.parse()
  File "D:\ProgramFiles\Anaconda3\lib\site-packages\django-1.11.8-py3.6.egg\django\template\base.py", line 515, in parse
    raise self.error(token, e)
  File "D:\ProgramFiles\Anaconda3\lib\site-packages\django-1.11.8-py3.6.egg\django\template\base.py", line 513, in parse
    compiled_result = compile_func(self, token)
  File "D:\ProgramFiles\Anaconda3\lib\site-packages\django-1.11.8-py3.6.egg\django\template\loader_tags.py", line 312, in do_extends
    nodelist = parser.parse()
  File "D:\ProgramFiles\Anaconda3\lib\site-packages\django-1.11.8-py3.6.egg\django\template\base.py", line 515, in parse
    raise self.error(token, e)
  File "D:\ProgramFiles\Anaconda3\lib\site-packages\django-1.11.8-py3.6.egg\django\template\base.py", line 513, in parse
    compiled_result = compile_func(self, token)
  File "D:\ProgramFiles\Anaconda3\lib\site-packages\django-1.11.8-py3.6.egg\django\template\loader_tags.py", line 255, in do_block
    nodelist = parser.parse(('endblock',))
  File "D:\ProgramFiles\Anaconda3\lib\site-packages\django-1.11.8-py3.6.egg\django\template\base.py", line 515, in parse
    raise self.error(token, e)
  File "D:\ProgramFiles\Anaconda3\lib\site-packages\django-1.11.8-py3.6.egg\django\template\base.py", line 513, in parse
    compiled_result = compile_func(self, token)
  File "D:\ProgramFiles\Anaconda3\lib\site-packages\django-1.11.8-py3.6.egg\django\template\defaulttags.py", line 977, in do_if
    nodelist = parser.parse(('elif', 'else', 'endif'))
  File "D:\ProgramFiles\Anaconda3\lib\site-packages\django-1.11.8-py3.6.egg\django\template\base.py", line 515, in parse
    raise self.error(token, e)
  File "D:\ProgramFiles\Anaconda3\lib\site-packages\django-1.11.8-py3.6.egg\django\template\base.py", line 513, in parse
    compiled_result = compile_func(self, token)
  File "D:\ProgramFiles\Anaconda3\lib\site-packages\django-1.11.8-py3.6.egg\django\template\defaulttags.py", line 1095, in load
    lib = find_library(parser, name)
  File "D:\ProgramFiles\Anaconda3\lib\site-packages\django-1.11.8-py3.6.egg\django\template\defaulttags.py", line 1042, in find_library
    name, "\n".join(sorted(parser.libraries.keys())),
django.template.exceptions.TemplateSyntaxError: 'mvote' is not a registered tag library. Must be one of:
admin_list
admin_modify
admin_static
admin_urls
cache
i18n
l10n
log
static
staticfiles
tz
exception.py[2018-03-12 19:33:42][ERROR]：Internal Server Error: /tj/4
Traceback (most recent call last):
  File "D:\ProgramFiles\Anaconda3\lib\site-packages\django-1.11.8-py3.6.egg\django\template\defaulttags.py", line 1038, in find_library
    return parser.libraries[name]
KeyError: 'mvote'

During handling of the above exception, another exception occurred:

Traceback (most recent call last):
  File "D:\ProgramFiles\Anaconda3\lib\site-packages\django-1.11.8-py3.6.egg\django\core\handlers\exception.py", line 41, in inner
    response = get_response(request)
  File "D:\ProgramFiles\Anaconda3\lib\site-packages\django-1.11.8-py3.6.egg\django\core\handlers\base.py", line 249, in _legacy_get_response
    response = self._get_response(request)
  File "D:\ProgramFiles\Anaconda3\lib\site-packages\django-1.11.8-py3.6.egg\django\core\handlers\base.py", line 187, in _get_response
    response = self.process_exception_by_middleware(e, request)
  File "D:\ProgramFiles\Anaconda3\lib\site-packages\django-1.11.8-py3.6.egg\django\core\handlers\base.py", line 185, in _get_response
    response = wrapped_callback(request, *callback_args, **callback_kwargs)
  File "D:\tools\Tools\2018年3月5日\Carry\mysite\views.py", line 374, in tongji
    return render(rq,'tongji.html',{'results':results,'dates':rq_date,'ids':HSD.IDS,'huizong':huizong,'id_name':id_name})
  File "D:\ProgramFiles\Anaconda3\lib\site-packages\django-1.11.8-py3.6.egg\django\shortcuts.py", line 30, in render
    content = loader.render_to_string(template_name, context, request, using=using)
  File "D:\ProgramFiles\Anaconda3\lib\site-packages\django-1.11.8-py3.6.egg\django\template\loader.py", line 67, in render_to_string
    template = get_template(template_name, using=using)
  File "D:\ProgramFiles\Anaconda3\lib\site-packages\django-1.11.8-py3.6.egg\django\template\loader.py", line 21, in get_template
    return engine.get_template(template_name)
  File "D:\ProgramFiles\Anaconda3\lib\site-packages\django-1.11.8-py3.6.egg\django\template\backends\django.py", line 39, in get_template
    return Template(self.engine.get_template(template_name), self)
  File "D:\ProgramFiles\Anaconda3\lib\site-packages\django-1.11.8-py3.6.egg\django\template\engine.py", line 162, in get_template
    template, origin = self.find_template(template_name)
  File "D:\ProgramFiles\Anaconda3\lib\site-packages\django-1.11.8-py3.6.egg\django\template\engine.py", line 136, in find_template
    name, template_dirs=dirs, skip=skip,
  File "D:\ProgramFiles\Anaconda3\lib\site-packages\django-1.11.8-py3.6.egg\django\template\loaders\base.py", line 44, in get_template
    contents, origin, origin.template_name, self.engine,
  File "D:\ProgramFiles\Anaconda3\lib\site-packages\django-1.11.8-py3.6.egg\django\template\base.py", line 191, in __init__
    self.nodelist = self.compile_nodelist()
  File "D:\ProgramFiles\Anaconda3\lib\site-packages\django-1.11.8-py3.6.egg\django\template\base.py", line 230, in compile_nodelist
    return parser.parse()
  File "D:\ProgramFiles\Anaconda3\lib\site-packages\django-1.11.8-py3.6.egg\django\template\base.py", line 515, in parse
    raise self.error(token, e)
  File "D:\ProgramFiles\Anaconda3\lib\site-packages\django-1.11.8-py3.6.egg\django\template\base.py", line 513, in parse
    compiled_result = compile_func(self, token)
  File "D:\ProgramFiles\Anaconda3\lib\site-packages\django-1.11.8-py3.6.egg\django\template\loader_tags.py", line 312, in do_extends
    nodelist = parser.parse()
  File "D:\ProgramFiles\Anaconda3\lib\site-packages\django-1.11.8-py3.6.egg\django\template\base.py", line 515, in parse
    raise self.error(token, e)
  File "D:\ProgramFiles\Anaconda3\lib\site-packages\django-1.11.8-py3.6.egg\django\template\base.py", line 513, in parse
    compiled_result = compile_func(self, token)
  File "D:\ProgramFiles\Anaconda3\lib\site-packages\django-1.11.8-py3.6.egg\django\template\loader_tags.py", line 255, in do_block
    nodelist = parser.parse(('endblock',))
  File "D:\ProgramFiles\Anaconda3\lib\site-packages\django-1.11.8-py3.6.egg\django\template\base.py", line 515, in parse
    raise self.error(token, e)
  File "D:\ProgramFiles\Anaconda3\lib\site-packages\django-1.11.8-py3.6.egg\django\template\base.py", line 513, in parse
    compiled_result = compile_func(self, token)
  File "D:\ProgramFiles\Anaconda3\lib\site-packages\django-1.11.8-py3.6.egg\django\template\defaulttags.py", line 977, in do_if
    nodelist = parser.parse(('elif', 'else', 'endif'))
  File "D:\ProgramFiles\Anaconda3\lib\site-packages\django-1.11.8-py3.6.egg\django\template\base.py", line 515, in parse
    raise self.error(token, e)
  File "D:\ProgramFiles\Anaconda3\lib\site-packages\django-1.11.8-py3.6.egg\django\template\base.py", line 513, in parse
    compiled_result = compile_func(self, token)
  File "D:\ProgramFiles\Anaconda3\lib\site-packages\django-1.11.8-py3.6.egg\django\template\defaulttags.py", line 1095, in load
    lib = find_library(parser, name)
  File "D:\ProgramFiles\Anaconda3\lib\site-packages\django-1.11.8-py3.6.egg\django\template\defaulttags.py", line 1042, in find_library
    name, "\n".join(sorted(parser.libraries.keys())),
django.template.exceptions.TemplateSyntaxError: 'mvote' is not a registered tag library. Must be one of:
admin_list
admin_modify
admin_static
admin_urls
cache
i18n
l10n
log
static
staticfiles
tz
exception.py[2018-03-12 19:35:27][ERROR]：Internal Server Error: /tj/1
Traceback (most recent call last):
  File "D:\ProgramFiles\Anaconda3\lib\site-packages\django-1.11.8-py3.6.egg\django\template\defaulttags.py", line 1038, in find_library
    return parser.libraries[name]
KeyError: 'mvote'

During handling of the above exception, another exception occurred:

Traceback (most recent call last):
  File "D:\ProgramFiles\Anaconda3\lib\site-packages\django-1.11.8-py3.6.egg\django\core\handlers\exception.py", line 41, in inner
    response = get_response(request)
  File "D:\ProgramFiles\Anaconda3\lib\site-packages\django-1.11.8-py3.6.egg\django\core\handlers\base.py", line 249, in _legacy_get_response
    response = self._get_response(request)
  File "D:\ProgramFiles\Anaconda3\lib\site-packages\django-1.11.8-py3.6.egg\django\core\handlers\base.py", line 187, in _get_response
    response = self.process_exception_by_middleware(e, request)
  File "D:\ProgramFiles\Anaconda3\lib\site-packages\django-1.11.8-py3.6.egg\django\core\handlers\base.py", line 185, in _get_response
    response = wrapped_callback(request, *callback_args, **callback_kwargs)
  File "D:\tools\Tools\2018年3月5日\Carry\mysite\views.py", line 393, in tongji
    return render(rq, 'tongji.html', {'herys': herys.to_html(), 'xz': xz,'dates':dates,'ids':HSD.IDS})
  File "D:\ProgramFiles\Anaconda3\lib\site-packages\django-1.11.8-py3.6.egg\django\shortcuts.py", line 30, in render
    content = loader.render_to_string(template_name, context, request, using=using)
  File "D:\ProgramFiles\Anaconda3\lib\site-packages\django-1.11.8-py3.6.egg\django\template\loader.py", line 67, in render_to_string
    template = get_template(template_name, using=using)
  File "D:\ProgramFiles\Anaconda3\lib\site-packages\django-1.11.8-py3.6.egg\django\template\loader.py", line 21, in get_template
    return engine.get_template(template_name)
  File "D:\ProgramFiles\Anaconda3\lib\site-packages\django-1.11.8-py3.6.egg\django\template\backends\django.py", line 39, in get_template
    return Template(self.engine.get_template(template_name), self)
  File "D:\ProgramFiles\Anaconda3\lib\site-packages\django-1.11.8-py3.6.egg\django\template\engine.py", line 162, in get_template
    template, origin = self.find_template(template_name)
  File "D:\ProgramFiles\Anaconda3\lib\site-packages\django-1.11.8-py3.6.egg\django\template\engine.py", line 136, in find_template
    name, template_dirs=dirs, skip=skip,
  File "D:\ProgramFiles\Anaconda3\lib\site-packages\django-1.11.8-py3.6.egg\django\template\loaders\base.py", line 44, in get_template
    contents, origin, origin.template_name, self.engine,
  File "D:\ProgramFiles\Anaconda3\lib\site-packages\django-1.11.8-py3.6.egg\django\template\base.py", line 191, in __init__
    self.nodelist = self.compile_nodelist()
  File "D:\ProgramFiles\Anaconda3\lib\site-packages\django-1.11.8-py3.6.egg\django\template\base.py", line 230, in compile_nodelist
    return parser.parse()
  File "D:\ProgramFiles\Anaconda3\lib\site-packages\django-1.11.8-py3.6.egg\django\template\base.py", line 515, in parse
    raise self.error(token, e)
  File "D:\ProgramFiles\Anaconda3\lib\site-packages\django-1.11.8-py3.6.egg\django\template\base.py", line 513, in parse
    compiled_result = compile_func(self, token)
  File "D:\ProgramFiles\Anaconda3\lib\site-packages\django-1.11.8-py3.6.egg\django\template\loader_tags.py", line 312, in do_extends
    nodelist = parser.parse()
  File "D:\ProgramFiles\Anaconda3\lib\site-packages\django-1.11.8-py3.6.egg\django\template\base.py", line 515, in parse
    raise self.error(token, e)
  File "D:\ProgramFiles\Anaconda3\lib\site-packages\django-1.11.8-py3.6.egg\django\template\base.py", line 513, in parse
    compiled_result = compile_func(self, token)
  File "D:\ProgramFiles\Anaconda3\lib\site-packages\django-1.11.8-py3.6.egg\django\template\loader_tags.py", line 255, in do_block
    nodelist = parser.parse(('endblock',))
  File "D:\ProgramFiles\Anaconda3\lib\site-packages\django-1.11.8-py3.6.egg\django\template\base.py", line 515, in parse
    raise self.error(token, e)
  File "D:\ProgramFiles\Anaconda3\lib\site-packages\django-1.11.8-py3.6.egg\django\template\base.py", line 513, in parse
    compiled_result = compile_func(self, token)
  File "D:\ProgramFiles\Anaconda3\lib\site-packages\django-1.11.8-py3.6.egg\django\template\defaulttags.py", line 977, in do_if
    nodelist = parser.parse(('elif', 'else', 'endif'))
  File "D:\ProgramFiles\Anaconda3\lib\site-packages\django-1.11.8-py3.6.egg\django\template\base.py", line 515, in parse
    raise self.error(token, e)
  File "D:\ProgramFiles\Anaconda3\lib\site-packages\django-1.11.8-py3.6.egg\django\template\base.py", line 513, in parse
    compiled_result = compile_func(self, token)
  File "D:\ProgramFiles\Anaconda3\lib\site-packages\django-1.11.8-py3.6.egg\django\template\defaulttags.py", line 1095, in load
    lib = find_library(parser, name)
  File "D:\ProgramFiles\Anaconda3\lib\site-packages\django-1.11.8-py3.6.egg\django\template\defaulttags.py", line 1042, in find_library
    name, "\n".join(sorted(parser.libraries.keys())),
django.template.exceptions.TemplateSyntaxError: 'mvote' is not a registered tag library. Must be one of:
admin_list
admin_modify
admin_static
admin_urls
cache
i18n
l10n
log
static
staticfiles
tz
exception.py[2018-03-12 19:35:54][ERROR]：Internal Server Error: /tj/1
Traceback (most recent call last):
  File "D:\ProgramFiles\Anaconda3\lib\site-packages\django-1.11.8-py3.6.egg\django\template\defaulttags.py", line 1038, in find_library
    return parser.libraries[name]
KeyError: 'mvote'

During handling of the above exception, another exception occurred:

Traceback (most recent call last):
  File "D:\ProgramFiles\Anaconda3\lib\site-packages\django-1.11.8-py3.6.egg\django\core\handlers\exception.py", line 41, in inner
    response = get_response(request)
  File "D:\ProgramFiles\Anaconda3\lib\site-packages\django-1.11.8-py3.6.egg\django\core\handlers\base.py", line 249, in _legacy_get_response
    response = self._get_response(request)
  File "D:\ProgramFiles\Anaconda3\lib\site-packages\django-1.11.8-py3.6.egg\django\core\handlers\base.py", line 187, in _get_response
    response = self.process_exception_by_middleware(e, request)
  File "D:\ProgramFiles\Anaconda3\lib\site-packages\django-1.11.8-py3.6.egg\django\core\handlers\base.py", line 185, in _get_response
    response = wrapped_callback(request, *callback_args, **callback_kwargs)
  File "D:\tools\Tools\2018年3月5日\Carry\mysite\views.py", line 393, in tongji
    return render(rq, 'tongji.html', {'herys': herys.to_html(), 'xz': xz,'dates':dates,'ids':HSD.IDS})
  File "D:\ProgramFiles\Anaconda3\lib\site-packages\django-1.11.8-py3.6.egg\django\shortcuts.py", line 30, in render
    content = loader.render_to_string(template_name, context, request, using=using)
  File "D:\ProgramFiles\Anaconda3\lib\site-packages\django-1.11.8-py3.6.egg\django\template\loader.py", line 67, in render_to_string
    template = get_template(template_name, using=using)
  File "D:\ProgramFiles\Anaconda3\lib\site-packages\django-1.11.8-py3.6.egg\django\template\loader.py", line 21, in get_template
    return engine.get_template(template_name)
  File "D:\ProgramFiles\Anaconda3\lib\site-packages\django-1.11.8-py3.6.egg\django\template\backends\django.py", line 39, in get_template
    return Template(self.engine.get_template(template_name), self)
  File "D:\ProgramFiles\Anaconda3\lib\site-packages\django-1.11.8-py3.6.egg\django\template\engine.py", line 162, in get_template
    template, origin = self.find_template(template_name)
  File "D:\ProgramFiles\Anaconda3\lib\site-packages\django-1.11.8-py3.6.egg\django\template\engine.py", line 136, in find_template
    name, template_dirs=dirs, skip=skip,
  File "D:\ProgramFiles\Anaconda3\lib\site-packages\django-1.11.8-py3.6.egg\django\template\loaders\base.py", line 44, in get_template
    contents, origin, origin.template_name, self.engine,
  File "D:\ProgramFiles\Anaconda3\lib\site-packages\django-1.11.8-py3.6.egg\django\template\base.py", line 191, in __init__
    self.nodelist = self.compile_nodelist()
  File "D:\ProgramFiles\Anaconda3\lib\site-packages\django-1.11.8-py3.6.egg\django\template\base.py", line 230, in compile_nodelist
    return parser.parse()
  File "D:\ProgramFiles\Anaconda3\lib\site-packages\django-1.11.8-py3.6.egg\django\template\base.py", line 515, in parse
    raise self.error(token, e)
  File "D:\ProgramFiles\Anaconda3\lib\site-packages\django-1.11.8-py3.6.egg\django\template\base.py", line 513, in parse
    compiled_result = compile_func(self, token)
  File "D:\ProgramFiles\Anaconda3\lib\site-packages\django-1.11.8-py3.6.egg\django\template\loader_tags.py", line 312, in do_extends
    nodelist = parser.parse()
  File "D:\ProgramFiles\Anaconda3\lib\site-packages\django-1.11.8-py3.6.egg\django\template\base.py", line 515, in parse
    raise self.error(token, e)
  File "D:\ProgramFiles\Anaconda3\lib\site-packages\django-1.11.8-py3.6.egg\django\template\base.py", line 513, in parse
    compiled_result = compile_func(self, token)
  File "D:\ProgramFiles\Anaconda3\lib\site-packages\django-1.11.8-py3.6.egg\django\template\loader_tags.py", line 255, in do_block
    nodelist = parser.parse(('endblock',))
  File "D:\ProgramFiles\Anaconda3\lib\site-packages\django-1.11.8-py3.6.egg\django\template\base.py", line 515, in parse
    raise self.error(token, e)
  File "D:\ProgramFiles\Anaconda3\lib\site-packages\django-1.11.8-py3.6.egg\django\template\base.py", line 513, in parse
    compiled_result = compile_func(self, token)
  File "D:\ProgramFiles\Anaconda3\lib\site-packages\django-1.11.8-py3.6.egg\django\template\defaulttags.py", line 977, in do_if
    nodelist = parser.parse(('elif', 'else', 'endif'))
  File "D:\ProgramFiles\Anaconda3\lib\site-packages\django-1.11.8-py3.6.egg\django\template\base.py", line 515, in parse
    raise self.error(token, e)
  File "D:\ProgramFiles\Anaconda3\lib\site-packages\django-1.11.8-py3.6.egg\django\template\base.py", line 513, in parse
    compiled_result = compile_func(self, token)
  File "D:\ProgramFiles\Anaconda3\lib\site-packages\django-1.11.8-py3.6.egg\django\template\defaulttags.py", line 1095, in load
    lib = find_library(parser, name)
  File "D:\ProgramFiles\Anaconda3\lib\site-packages\django-1.11.8-py3.6.egg\django\template\defaulttags.py", line 1042, in find_library
    name, "\n".join(sorted(parser.libraries.keys())),
django.template.exceptions.TemplateSyntaxError: 'mvote' is not a registered tag library. Must be one of:
admin_list
admin_modify
admin_static
admin_urls
cache
i18n
l10n
log
static
staticfiles
tz
exception.py[2018-03-12 19:38:18][ERROR]：Internal Server Error: /tj/1
Traceback (most recent call last):
  File "D:\ProgramFiles\Anaconda3\lib\site-packages\django-1.11.8-py3.6.egg\django\template\defaulttags.py", line 1038, in find_library
    return parser.libraries[name]
KeyError: 'mvote'

During handling of the above exception, another exception occurred:

Traceback (most recent call last):
  File "D:\ProgramFiles\Anaconda3\lib\site-packages\django-1.11.8-py3.6.egg\django\core\handlers\exception.py", line 41, in inner
    response = get_response(request)
  File "D:\ProgramFiles\Anaconda3\lib\site-packages\django-1.11.8-py3.6.egg\django\core\handlers\base.py", line 249, in _legacy_get_response
    response = self._get_response(request)
  File "D:\ProgramFiles\Anaconda3\lib\site-packages\django-1.11.8-py3.6.egg\django\core\handlers\base.py", line 187, in _get_response
    response = self.process_exception_by_middleware(e, request)
  File "D:\ProgramFiles\Anaconda3\lib\site-packages\django-1.11.8-py3.6.egg\django\core\handlers\base.py", line 185, in _get_response
    response = wrapped_callback(request, *callback_args, **callback_kwargs)
  File "D:\tools\Tools\2018年3月5日\Carry\mysite\views.py", line 393, in tongji
    return render(rq, 'tongji.html', {'herys': herys.to_html(), 'xz': xz,'dates':dates,'ids':HSD.IDS})
  File "D:\ProgramFiles\Anaconda3\lib\site-packages\django-1.11.8-py3.6.egg\django\shortcuts.py", line 30, in render
    content = loader.render_to_string(template_name, context, request, using=using)
  File "D:\ProgramFiles\Anaconda3\lib\site-packages\django-1.11.8-py3.6.egg\django\template\loader.py", line 67, in render_to_string
    template = get_template(template_name, using=using)
  File "D:\ProgramFiles\Anaconda3\lib\site-packages\django-1.11.8-py3.6.egg\django\template\loader.py", line 21, in get_template
    return engine.get_template(template_name)
  File "D:\ProgramFiles\Anaconda3\lib\site-packages\django-1.11.8-py3.6.egg\django\template\backends\django.py", line 39, in get_template
    return Template(self.engine.get_template(template_name), self)
  File "D:\ProgramFiles\Anaconda3\lib\site-packages\django-1.11.8-py3.6.egg\django\template\engine.py", line 162, in get_template
    template, origin = self.find_template(template_name)
  File "D:\ProgramFiles\Anaconda3\lib\site-packages\django-1.11.8-py3.6.egg\django\template\engine.py", line 136, in find_template
    name, template_dirs=dirs, skip=skip,
  File "D:\ProgramFiles\Anaconda3\lib\site-packages\django-1.11.8-py3.6.egg\django\template\loaders\base.py", line 44, in get_template
    contents, origin, origin.template_name, self.engine,
  File "D:\ProgramFiles\Anaconda3\lib\site-packages\django-1.11.8-py3.6.egg\django\template\base.py", line 191, in __init__
    self.nodelist = self.compile_nodelist()
  File "D:\ProgramFiles\Anaconda3\lib\site-packages\django-1.11.8-py3.6.egg\django\template\base.py", line 230, in compile_nodelist
    return parser.parse()
  File "D:\ProgramFiles\Anaconda3\lib\site-packages\django-1.11.8-py3.6.egg\django\template\base.py", line 515, in parse
    raise self.error(token, e)
  File "D:\ProgramFiles\Anaconda3\lib\site-packages\django-1.11.8-py3.6.egg\django\template\base.py", line 513, in parse
    compiled_result = compile_func(self, token)
  File "D:\ProgramFiles\Anaconda3\lib\site-packages\django-1.11.8-py3.6.egg\django\template\loader_tags.py", line 312, in do_extends
    nodelist = parser.parse()
  File "D:\ProgramFiles\Anaconda3\lib\site-packages\django-1.11.8-py3.6.egg\django\template\base.py", line 515, in parse
    raise self.error(token, e)
  File "D:\ProgramFiles\Anaconda3\lib\site-packages\django-1.11.8-py3.6.egg\django\template\base.py", line 513, in parse
    compiled_result = compile_func(self, token)
  File "D:\ProgramFiles\Anaconda3\lib\site-packages\django-1.11.8-py3.6.egg\django\template\loader_tags.py", line 255, in do_block
    nodelist = parser.parse(('endblock',))
  File "D:\ProgramFiles\Anaconda3\lib\site-packages\django-1.11.8-py3.6.egg\django\template\base.py", line 515, in parse
    raise self.error(token, e)
  File "D:\ProgramFiles\Anaconda3\lib\site-packages\django-1.11.8-py3.6.egg\django\template\base.py", line 513, in parse
    compiled_result = compile_func(self, token)
  File "D:\ProgramFiles\Anaconda3\lib\site-packages\django-1.11.8-py3.6.egg\django\template\defaulttags.py", line 977, in do_if
    nodelist = parser.parse(('elif', 'else', 'endif'))
  File "D:\ProgramFiles\Anaconda3\lib\site-packages\django-1.11.8-py3.6.egg\django\template\base.py", line 515, in parse
    raise self.error(token, e)
  File "D:\ProgramFiles\Anaconda3\lib\site-packages\django-1.11.8-py3.6.egg\django\template\base.py", line 513, in parse
    compiled_result = compile_func(self, token)
  File "D:\ProgramFiles\Anaconda3\lib\site-packages\django-1.11.8-py3.6.egg\django\template\defaulttags.py", line 1095, in load
    lib = find_library(parser, name)
  File "D:\ProgramFiles\Anaconda3\lib\site-packages\django-1.11.8-py3.6.egg\django\template\defaulttags.py", line 1042, in find_library
    name, "\n".join(sorted(parser.libraries.keys())),
django.template.exceptions.TemplateSyntaxError: 'mvote' is not a registered tag library. Must be one of:
admin_list
admin_modify
admin_static
admin_urls
cache
i18n
l10n
log
static
staticfiles
tz
exception.py[2018-03-12 19:45:06][ERROR]：Internal Server Error: /tj/1
Traceback (most recent call last):
  File "D:\ProgramFiles\Anaconda3\lib\site-packages\django-1.11.8-py3.6.egg\django\core\handlers\exception.py", line 41, in inner
    response = get_response(request)
  File "D:\ProgramFiles\Anaconda3\lib\site-packages\django-1.11.8-py3.6.egg\django\core\handlers\base.py", line 249, in _legacy_get_response
    response = self._get_response(request)
  File "D:\ProgramFiles\Anaconda3\lib\site-packages\django-1.11.8-py3.6.egg\django\core\handlers\base.py", line 187, in _get_response
    response = self.process_exception_by_middleware(e, request)
  File "D:\ProgramFiles\Anaconda3\lib\site-packages\django-1.11.8-py3.6.egg\django\core\handlers\base.py", line 185, in _get_response
    response = wrapped_callback(request, *callback_args, **callback_kwargs)
  File "D:\tools\Tools\2018年3月5日\Carry\mysite\views.py", line 374, in tongji
    return render(rq,'tongji.html',{'results':results,'dates':rq_date,'ids':HSD.IDS,'huizong':huizong,'id_name':id_name})
  File "D:\ProgramFiles\Anaconda3\lib\site-packages\django-1.11.8-py3.6.egg\django\shortcuts.py", line 30, in render
    content = loader.render_to_string(template_name, context, request, using=using)
  File "D:\ProgramFiles\Anaconda3\lib\site-packages\django-1.11.8-py3.6.egg\django\template\loader.py", line 67, in render_to_string
    template = get_template(template_name, using=using)
  File "D:\ProgramFiles\Anaconda3\lib\site-packages\django-1.11.8-py3.6.egg\django\template\loader.py", line 21, in get_template
    return engine.get_template(template_name)
  File "D:\ProgramFiles\Anaconda3\lib\site-packages\django-1.11.8-py3.6.egg\django\template\backends\django.py", line 39, in get_template
    return Template(self.engine.get_template(template_name), self)
  File "D:\ProgramFiles\Anaconda3\lib\site-packages\django-1.11.8-py3.6.egg\django\template\engine.py", line 162, in get_template
    template, origin = self.find_template(template_name)
  File "D:\ProgramFiles\Anaconda3\lib\site-packages\django-1.11.8-py3.6.egg\django\template\engine.py", line 136, in find_template
    name, template_dirs=dirs, skip=skip,
  File "D:\ProgramFiles\Anaconda3\lib\site-packages\django-1.11.8-py3.6.egg\django\template\loaders\base.py", line 44, in get_template
    contents, origin, origin.template_name, self.engine,
  File "D:\ProgramFiles\Anaconda3\lib\site-packages\django-1.11.8-py3.6.egg\django\template\base.py", line 191, in __init__
    self.nodelist = self.compile_nodelist()
  File "D:\ProgramFiles\Anaconda3\lib\site-packages\django-1.11.8-py3.6.egg\django\template\base.py", line 230, in compile_nodelist
    return parser.parse()
  File "D:\ProgramFiles\Anaconda3\lib\site-packages\django-1.11.8-py3.6.egg\django\template\base.py", line 515, in parse
    raise self.error(token, e)
  File "D:\ProgramFiles\Anaconda3\lib\site-packages\django-1.11.8-py3.6.egg\django\template\base.py", line 513, in parse
    compiled_result = compile_func(self, token)
  File "D:\ProgramFiles\Anaconda3\lib\site-packages\django-1.11.8-py3.6.egg\django\template\loader_tags.py", line 312, in do_extends
    nodelist = parser.parse()
  File "D:\ProgramFiles\Anaconda3\lib\site-packages\django-1.11.8-py3.6.egg\django\template\base.py", line 515, in parse
    raise self.error(token, e)
  File "D:\ProgramFiles\Anaconda3\lib\site-packages\django-1.11.8-py3.6.egg\django\template\base.py", line 513, in parse
    compiled_result = compile_func(self, token)
  File "D:\ProgramFiles\Anaconda3\lib\site-packages\django-1.11.8-py3.6.egg\django\template\loader_tags.py", line 255, in do_block
    nodelist = parser.parse(('endblock',))
  File "D:\ProgramFiles\Anaconda3\lib\site-packages\django-1.11.8-py3.6.egg\django\template\base.py", line 515, in parse
    raise self.error(token, e)
  File "D:\ProgramFiles\Anaconda3\lib\site-packages\django-1.11.8-py3.6.egg\django\template\base.py", line 513, in parse
    compiled_result = compile_func(self, token)
  File "D:\ProgramFiles\Anaconda3\lib\site-packages\django-1.11.8-py3.6.egg\django\template\defaulttags.py", line 977, in do_if
    nodelist = parser.parse(('elif', 'else', 'endif'))
  File "D:\ProgramFiles\Anaconda3\lib\site-packages\django-1.11.8-py3.6.egg\django\template\base.py", line 515, in parse
    raise self.error(token, e)
  File "D:\ProgramFiles\Anaconda3\lib\site-packages\django-1.11.8-py3.6.egg\django\template\base.py", line 513, in parse
    compiled_result = compile_func(self, token)
  File "D:\ProgramFiles\Anaconda3\lib\site-packages\django-1.11.8-py3.6.egg\django\template\defaulttags.py", line 827, in do_for
    nodelist_loop = parser.parse(('empty', 'endfor',))
  File "D:\ProgramFiles\Anaconda3\lib\site-packages\django-1.11.8-py3.6.egg\django\template\base.py", line 486, in parse
    raise self.error(token, e)
  File "D:\ProgramFiles\Anaconda3\lib\site-packages\django-1.11.8-py3.6.egg\django\template\base.py", line 484, in parse
    filter_expression = self.compile_filter(token.contents)
  File "D:\ProgramFiles\Anaconda3\lib\site-packages\django-1.11.8-py3.6.egg\django\template\base.py", line 600, in compile_filter
    return FilterExpression(token, self)
  File "D:\ProgramFiles\Anaconda3\lib\site-packages\django-1.11.8-py3.6.egg\django\template\base.py", line 694, in __init__
    filter_func = parser.find_filter(filter_name)
  File "D:\ProgramFiles\Anaconda3\lib\site-packages\django-1.11.8-py3.6.egg\django\template\base.py", line 606, in find_filter
    raise TemplateSyntaxError("Invalid filter: '%s'" % filter_name)
django.template.exceptions.TemplateSyntaxError: Invalid filter: 'names'
exception.py[2018-03-12 20:04:47][ERROR]：Internal Server Error: /tj/1
Traceback (most recent call last):
  File "D:\ProgramFiles\Anaconda3\lib\site-packages\django-1.11.8-py3.6.egg\django\core\handlers\exception.py", line 41, in inner
    response = get_response(request)
  File "D:\ProgramFiles\Anaconda3\lib\site-packages\django-1.11.8-py3.6.egg\django\core\handlers\base.py", line 249, in _legacy_get_response
    response = self._get_response(request)
  File "D:\ProgramFiles\Anaconda3\lib\site-packages\django-1.11.8-py3.6.egg\django\core\handlers\base.py", line 187, in _get_response
    response = self.process_exception_by_middleware(e, request)
  File "D:\ProgramFiles\Anaconda3\lib\site-packages\django-1.11.8-py3.6.egg\django\core\handlers\base.py", line 185, in _get_response
    response = wrapped_callback(request, *callback_args, **callback_kwargs)
  File "D:\tools\Tools\2018年3月5日\Carry\mysite\views.py", line 371, in tongji
    return render(rq,'tongji.html',{'results':results,'dates':rq_date,'ids':HSD.IDS,'huizong':huizong,'id_name':id_name})
  File "D:\ProgramFiles\Anaconda3\lib\site-packages\django-1.11.8-py3.6.egg\django\shortcuts.py", line 30, in render
    content = loader.render_to_string(template_name, context, request, using=using)
  File "D:\ProgramFiles\Anaconda3\lib\site-packages\django-1.11.8-py3.6.egg\django\template\loader.py", line 68, in render_to_string
    return template.render(context, request)
  File "D:\ProgramFiles\Anaconda3\lib\site-packages\django-1.11.8-py3.6.egg\django\template\backends\django.py", line 66, in render
    return self.template.render(context)
  File "D:\ProgramFiles\Anaconda3\lib\site-packages\django-1.11.8-py3.6.egg\django\template\base.py", line 207, in render
    return self._render(context)
  File "D:\ProgramFiles\Anaconda3\lib\site-packages\django-1.11.8-py3.6.egg\django\template\base.py", line 199, in _render
    return self.nodelist.render(context)
  File "D:\ProgramFiles\Anaconda3\lib\site-packages\django-1.11.8-py3.6.egg\django\template\base.py", line 990, in render
    bit = node.render_annotated(context)
  File "D:\ProgramFiles\Anaconda3\lib\site-packages\django-1.11.8-py3.6.egg\django\template\base.py", line 957, in render_annotated
    return self.render(context)
  File "D:\ProgramFiles\Anaconda3\lib\site-packages\django-1.11.8-py3.6.egg\django\template\loader_tags.py", line 177, in render
    return compiled_parent._render(context)
  File "D:\ProgramFiles\Anaconda3\lib\site-packages\django-1.11.8-py3.6.egg\django\template\base.py", line 199, in _render
    return self.nodelist.render(context)
  File "D:\ProgramFiles\Anaconda3\lib\site-packages\django-1.11.8-py3.6.egg\django\template\base.py", line 990, in render
    bit = node.render_annotated(context)
  File "D:\ProgramFiles\Anaconda3\lib\site-packages\django-1.11.8-py3.6.egg\django\template\base.py", line 957, in render_annotated
    return self.render(context)
  File "D:\ProgramFiles\Anaconda3\lib\site-packages\django-1.11.8-py3.6.egg\django\template\loader_tags.py", line 72, in render
    result = block.nodelist.render(context)
  File "D:\ProgramFiles\Anaconda3\lib\site-packages\django-1.11.8-py3.6.egg\django\template\base.py", line 990, in render
    bit = node.render_annotated(context)
  File "D:\ProgramFiles\Anaconda3\lib\site-packages\django-1.11.8-py3.6.egg\django\template\base.py", line 957, in render_annotated
    return self.render(context)
  File "D:\ProgramFiles\Anaconda3\lib\site-packages\django-1.11.8-py3.6.egg\django\template\loader_tags.py", line 72, in render
    result = block.nodelist.render(context)
  File "D:\ProgramFiles\Anaconda3\lib\site-packages\django-1.11.8-py3.6.egg\django\template\base.py", line 990, in render
    bit = node.render_annotated(context)
  File "D:\ProgramFiles\Anaconda3\lib\site-packages\django-1.11.8-py3.6.egg\django\template\base.py", line 957, in render_annotated
    return self.render(context)
  File "D:\ProgramFiles\Anaconda3\lib\site-packages\django-1.11.8-py3.6.egg\django\template\defaulttags.py", line 322, in render
    return nodelist.render(context)
  File "D:\ProgramFiles\Anaconda3\lib\site-packages\django-1.11.8-py3.6.egg\django\template\base.py", line 990, in render
    bit = node.render_annotated(context)
  File "D:\ProgramFiles\Anaconda3\lib\site-packages\django-1.11.8-py3.6.egg\django\template\base.py", line 957, in render_annotated
    return self.render(context)
  File "D:\ProgramFiles\Anaconda3\lib\site-packages\django-1.11.8-py3.6.egg\django\template\defaulttags.py", line 207, in render
    .format(num_loopvars, len_item),
ValueError: Need 2 values to unpack in for loop; got 1. 
base.py[2018-03-13 09:54:40][WARNING]：Not Found: /favicon.ico
exception.py[2018-03-13 10:16:41][ERROR]：Internal Server Error: /getkline
Traceback (most recent call last):
  File "D:\ProgramFiles\Anaconda3\lib\site-packages\django-1.11.8-py3.6.egg\django\core\handlers\exception.py", line 41, in inner
    response = get_response(request)
  File "D:\ProgramFiles\Anaconda3\lib\site-packages\django-1.11.8-py3.6.egg\django\core\handlers\base.py", line 249, in _legacy_get_response
    response = self._get_response(request)
  File "D:\ProgramFiles\Anaconda3\lib\site-packages\django-1.11.8-py3.6.egg\django\core\handlers\base.py", line 187, in _get_response
    response = self.process_exception_by_middleware(e, request)
  File "D:\ProgramFiles\Anaconda3\lib\site-packages\django-1.11.8-py3.6.egg\django\core\handlers\base.py", line 185, in _get_response
    response = wrapped_callback(request, *callback_args, **callback_kwargs)
  File "D:\ProgramFiles\Anaconda3\lib\site-packages\django-1.11.8-py3.6.egg\django\utils\decorators.py", line 149, in _wrapped_view
    response = view_func(request, *args, **kwargs)
  File "D:\ProgramFiles\Anaconda3\lib\site-packages\dwebsocket\decorators.py", line 16, in new_func
    response = func(request, *args, **kwargs)
  File "D:\ProgramFiles\Anaconda3\lib\site-packages\django-1.11.8-py3.6.egg\django\views\decorators\csrf.py", line 58, in wrapped_view
    return view_func(*args, **kwargs)
  File "D:\tools\Tools\2018年3月5日\Carry\mysite\views.py", line 510, in getkline
    ticker=sub_socket.recv_pyobj()
  File "D:\ProgramFiles\Anaconda3\lib\site-packages\zmq\sugar\socket.py", line 492, in recv_pyobj
    return self._deserialize(msg, pickle.loads)
  File "D:\ProgramFiles\Anaconda3\lib\site-packages\zmq\sugar\socket.py", line 419, in _deserialize
    return load(recvd)
AttributeError: Can't get attribute 'SPApiTicker' on <module 'sp_struct' from 'D:\\tools\\Tools\\2018年3月5日\\Carry\\sp_struct.py'>
exception.py[2018-03-13 10:16:41][ERROR]：Internal Server Error: /getkline
Traceback (most recent call last):
  File "D:\ProgramFiles\Anaconda3\lib\site-packages\django-1.11.8-py3.6.egg\django\core\handlers\exception.py", line 41, in inner
    response = get_response(request)
  File "D:\ProgramFiles\Anaconda3\lib\site-packages\django-1.11.8-py3.6.egg\django\core\handlers\base.py", line 249, in _legacy_get_response
    response = self._get_response(request)
  File "D:\ProgramFiles\Anaconda3\lib\site-packages\django-1.11.8-py3.6.egg\django\core\handlers\base.py", line 187, in _get_response
    response = self.process_exception_by_middleware(e, request)
  File "D:\ProgramFiles\Anaconda3\lib\site-packages\django-1.11.8-py3.6.egg\django\core\handlers\base.py", line 185, in _get_response
    response = wrapped_callback(request, *callback_args, **callback_kwargs)
  File "D:\ProgramFiles\Anaconda3\lib\site-packages\django-1.11.8-py3.6.egg\django\utils\decorators.py", line 149, in _wrapped_view
    response = view_func(request, *args, **kwargs)
  File "D:\ProgramFiles\Anaconda3\lib\site-packages\dwebsocket\decorators.py", line 16, in new_func
    response = func(request, *args, **kwargs)
  File "D:\ProgramFiles\Anaconda3\lib\site-packages\django-1.11.8-py3.6.egg\django\views\decorators\csrf.py", line 58, in wrapped_view
    return view_func(*args, **kwargs)
  File "D:\tools\Tools\2018年3月5日\Carry\mysite\views.py", line 510, in getkline
    ticker=sub_socket.recv_pyobj()
  File "D:\ProgramFiles\Anaconda3\lib\site-packages\zmq\sugar\socket.py", line 492, in recv_pyobj
    return self._deserialize(msg, pickle.loads)
  File "D:\ProgramFiles\Anaconda3\lib\site-packages\zmq\sugar\socket.py", line 419, in _deserialize
    return load(recvd)
AttributeError: Can't get attribute 'SPApiTicker' on <module 'sp_struct' from 'D:\\tools\\Tools\\2018年3月5日\\Carry\\sp_struct.py'>
exception.py[2018-03-13 10:16:41][ERROR]：Internal Server Error: /getkline
Traceback (most recent call last):
  File "D:\ProgramFiles\Anaconda3\lib\site-packages\django-1.11.8-py3.6.egg\django\core\handlers\exception.py", line 41, in inner
    response = get_response(request)
  File "D:\ProgramFiles\Anaconda3\lib\site-packages\django-1.11.8-py3.6.egg\django\core\handlers\base.py", line 249, in _legacy_get_response
    response = self._get_response(request)
  File "D:\ProgramFiles\Anaconda3\lib\site-packages\django-1.11.8-py3.6.egg\django\core\handlers\base.py", line 187, in _get_response
    response = self.process_exception_by_middleware(e, request)
  File "D:\ProgramFiles\Anaconda3\lib\site-packages\django-1.11.8-py3.6.egg\django\core\handlers\base.py", line 185, in _get_response
    response = wrapped_callback(request, *callback_args, **callback_kwargs)
  File "D:\ProgramFiles\Anaconda3\lib\site-packages\django-1.11.8-py3.6.egg\django\utils\decorators.py", line 149, in _wrapped_view
    response = view_func(request, *args, **kwargs)
  File "D:\ProgramFiles\Anaconda3\lib\site-packages\dwebsocket\decorators.py", line 16, in new_func
    response = func(request, *args, **kwargs)
  File "D:\ProgramFiles\Anaconda3\lib\site-packages\django-1.11.8-py3.6.egg\django\views\decorators\csrf.py", line 58, in wrapped_view
    return view_func(*args, **kwargs)
  File "D:\tools\Tools\2018年3月5日\Carry\mysite\views.py", line 510, in getkline
    ticker=sub_socket.recv_pyobj()
  File "D:\ProgramFiles\Anaconda3\lib\site-packages\zmq\sugar\socket.py", line 492, in recv_pyobj
    return self._deserialize(msg, pickle.loads)
  File "D:\ProgramFiles\Anaconda3\lib\site-packages\zmq\sugar\socket.py", line 419, in _deserialize
    return load(recvd)
AttributeError: Can't get attribute 'SPApiTicker' on <module 'sp_struct' from 'D:\\tools\\Tools\\2018年3月5日\\Carry\\sp_struct.py'>
exception.py[2018-03-13 10:16:41][ERROR]：Internal Server Error: /getkline
Traceback (most recent call last):
  File "D:\ProgramFiles\Anaconda3\lib\site-packages\django-1.11.8-py3.6.egg\django\core\handlers\exception.py", line 41, in inner
    response = get_response(request)
  File "D:\ProgramFiles\Anaconda3\lib\site-packages\django-1.11.8-py3.6.egg\django\core\handlers\base.py", line 249, in _legacy_get_response
    response = self._get_response(request)
  File "D:\ProgramFiles\Anaconda3\lib\site-packages\django-1.11.8-py3.6.egg\django\core\handlers\base.py", line 187, in _get_response
    response = self.process_exception_by_middleware(e, request)
  File "D:\ProgramFiles\Anaconda3\lib\site-packages\django-1.11.8-py3.6.egg\django\core\handlers\base.py", line 185, in _get_response
    response = wrapped_callback(request, *callback_args, **callback_kwargs)
  File "D:\ProgramFiles\Anaconda3\lib\site-packages\django-1.11.8-py3.6.egg\django\utils\decorators.py", line 149, in _wrapped_view
    response = view_func(request, *args, **kwargs)
  File "D:\ProgramFiles\Anaconda3\lib\site-packages\dwebsocket\decorators.py", line 16, in new_func
    response = func(request, *args, **kwargs)
  File "D:\ProgramFiles\Anaconda3\lib\site-packages\django-1.11.8-py3.6.egg\django\views\decorators\csrf.py", line 58, in wrapped_view
    return view_func(*args, **kwargs)
  File "D:\tools\Tools\2018年3月5日\Carry\mysite\views.py", line 510, in getkline
    ticker=sub_socket.recv_pyobj()
  File "D:\ProgramFiles\Anaconda3\lib\site-packages\zmq\sugar\socket.py", line 492, in recv_pyobj
    return self._deserialize(msg, pickle.loads)
  File "D:\ProgramFiles\Anaconda3\lib\site-packages\zmq\sugar\socket.py", line 419, in _deserialize
    return load(recvd)
AttributeError: Can't get attribute 'SPApiTicker' on <module 'sp_struct' from 'D:\\tools\\Tools\\2018年3月5日\\Carry\\sp_struct.py'>
exception.py[2018-03-13 10:16:41][ERROR]：Internal Server Error: /getkline
Traceback (most recent call last):
  File "D:\ProgramFiles\Anaconda3\lib\site-packages\django-1.11.8-py3.6.egg\django\core\handlers\exception.py", line 41, in inner
    response = get_response(request)
  File "D:\ProgramFiles\Anaconda3\lib\site-packages\django-1.11.8-py3.6.egg\django\core\handlers\base.py", line 249, in _legacy_get_response
    response = self._get_response(request)
  File "D:\ProgramFiles\Anaconda3\lib\site-packages\django-1.11.8-py3.6.egg\django\core\handlers\base.py", line 187, in _get_response
    response = self.process_exception_by_middleware(e, request)
  File "D:\ProgramFiles\Anaconda3\lib\site-packages\django-1.11.8-py3.6.egg\django\core\handlers\base.py", line 185, in _get_response
    response = wrapped_callback(request, *callback_args, **callback_kwargs)
  File "D:\ProgramFiles\Anaconda3\lib\site-packages\django-1.11.8-py3.6.egg\django\utils\decorators.py", line 149, in _wrapped_view
    response = view_func(request, *args, **kwargs)
  File "D:\ProgramFiles\Anaconda3\lib\site-packages\dwebsocket\decorators.py", line 16, in new_func
    response = func(request, *args, **kwargs)
  File "D:\ProgramFiles\Anaconda3\lib\site-packages\django-1.11.8-py3.6.egg\django\views\decorators\csrf.py", line 58, in wrapped_view
    return view_func(*args, **kwargs)
  File "D:\tools\Tools\2018年3月5日\Carry\mysite\views.py", line 510, in getkline
    ticker=sub_socket.recv_pyobj()
  File "D:\ProgramFiles\Anaconda3\lib\site-packages\zmq\sugar\socket.py", line 492, in recv_pyobj
    return self._deserialize(msg, pickle.loads)
  File "D:\ProgramFiles\Anaconda3\lib\site-packages\zmq\sugar\socket.py", line 419, in _deserialize
    return load(recvd)
AttributeError: Can't get attribute 'SPApiTicker' on <module 'sp_struct' from 'D:\\tools\\Tools\\2018年3月5日\\Carry\\sp_struct.py'>
exception.py[2018-03-13 10:16:41][ERROR]：Internal Server Error: /getkline
Traceback (most recent call last):
  File "D:\ProgramFiles\Anaconda3\lib\site-packages\django-1.11.8-py3.6.egg\django\core\handlers\exception.py", line 41, in inner
    response = get_response(request)
  File "D:\ProgramFiles\Anaconda3\lib\site-packages\django-1.11.8-py3.6.egg\django\core\handlers\base.py", line 249, in _legacy_get_response
    response = self._get_response(request)
  File "D:\ProgramFiles\Anaconda3\lib\site-packages\django-1.11.8-py3.6.egg\django\core\handlers\base.py", line 187, in _get_response
    response = self.process_exception_by_middleware(e, request)
  File "D:\ProgramFiles\Anaconda3\lib\site-packages\django-1.11.8-py3.6.egg\django\core\handlers\base.py", line 185, in _get_response
    response = wrapped_callback(request, *callback_args, **callback_kwargs)
  File "D:\ProgramFiles\Anaconda3\lib\site-packages\django-1.11.8-py3.6.egg\django\utils\decorators.py", line 149, in _wrapped_view
    response = view_func(request, *args, **kwargs)
  File "D:\ProgramFiles\Anaconda3\lib\site-packages\dwebsocket\decorators.py", line 16, in new_func
    response = func(request, *args, **kwargs)
  File "D:\ProgramFiles\Anaconda3\lib\site-packages\django-1.11.8-py3.6.egg\django\views\decorators\csrf.py", line 58, in wrapped_view
    return view_func(*args, **kwargs)
  File "D:\tools\Tools\2018年3月5日\Carry\mysite\views.py", line 510, in getkline
    ticker=sub_socket.recv_pyobj()
  File "D:\ProgramFiles\Anaconda3\lib\site-packages\zmq\sugar\socket.py", line 492, in recv_pyobj
    return self._deserialize(msg, pickle.loads)
  File "D:\ProgramFiles\Anaconda3\lib\site-packages\zmq\sugar\socket.py", line 419, in _deserialize
    return load(recvd)
AttributeError: Can't get attribute 'SPApiTicker' on <module 'sp_struct' from 'D:\\tools\\Tools\\2018年3月5日\\Carry\\sp_struct.py'>
exception.py[2018-03-13 10:16:41][ERROR]：Internal Server Error: /getkline
Traceback (most recent call last):
  File "D:\ProgramFiles\Anaconda3\lib\site-packages\django-1.11.8-py3.6.egg\django\core\handlers\exception.py", line 41, in inner
    response = get_response(request)
  File "D:\ProgramFiles\Anaconda3\lib\site-packages\django-1.11.8-py3.6.egg\django\core\handlers\base.py", line 249, in _legacy_get_response
    response = self._get_response(request)
  File "D:\ProgramFiles\Anaconda3\lib\site-packages\django-1.11.8-py3.6.egg\django\core\handlers\base.py", line 187, in _get_response
    response = self.process_exception_by_middleware(e, request)
  File "D:\ProgramFiles\Anaconda3\lib\site-packages\django-1.11.8-py3.6.egg\django\core\handlers\base.py", line 185, in _get_response
    response = wrapped_callback(request, *callback_args, **callback_kwargs)
  File "D:\ProgramFiles\Anaconda3\lib\site-packages\django-1.11.8-py3.6.egg\django\utils\decorators.py", line 149, in _wrapped_view
    response = view_func(request, *args, **kwargs)
  File "D:\ProgramFiles\Anaconda3\lib\site-packages\dwebsocket\decorators.py", line 16, in new_func
    response = func(request, *args, **kwargs)
  File "D:\ProgramFiles\Anaconda3\lib\site-packages\django-1.11.8-py3.6.egg\django\views\decorators\csrf.py", line 58, in wrapped_view
    return view_func(*args, **kwargs)
  File "D:\tools\Tools\2018年3月5日\Carry\mysite\views.py", line 510, in getkline
    ticker=sub_socket.recv_pyobj()
  File "D:\ProgramFiles\Anaconda3\lib\site-packages\zmq\sugar\socket.py", line 492, in recv_pyobj
    return self._deserialize(msg, pickle.loads)
  File "D:\ProgramFiles\Anaconda3\lib\site-packages\zmq\sugar\socket.py", line 419, in _deserialize
    return load(recvd)
AttributeError: Can't get attribute 'SPApiTicker' on <module 'sp_struct' from 'D:\\tools\\Tools\\2018年3月5日\\Carry\\sp_struct.py'>
views.py[2018-03-13 10:45:40][ERROR]：Object of type 'datetime' is not JSON serializable
exception.py[2018-03-13 11:55:31][ERROR]：Internal Server Error: /tj/4
Traceback (most recent call last):
  File "D:\ProgramFiles\Anaconda3\lib\site-packages\django-1.11.8-py3.6.egg\django\core\handlers\exception.py", line 41, in inner
    response = get_response(request)
  File "D:\ProgramFiles\Anaconda3\lib\site-packages\django-1.11.8-py3.6.egg\django\core\handlers\base.py", line 249, in _legacy_get_response
    response = self._get_response(request)
  File "D:\ProgramFiles\Anaconda3\lib\site-packages\django-1.11.8-py3.6.egg\django\core\handlers\base.py", line 187, in _get_response
    response = self.process_exception_by_middleware(e, request)
  File "D:\ProgramFiles\Anaconda3\lib\site-packages\django-1.11.8-py3.6.egg\django\core\handlers\base.py", line 185, in _get_response
    response = wrapped_callback(request, *callback_args, **callback_kwargs)
  File "D:\tools\Tools\2018年3月5日\Carry\mysite\views.py", line 376, in tongji
    return render(rq,'tongji.html',{'results':results,'dates':rq_date,'ids':HSD.IDS,'huizong':huizong,'id_name':id_name,'id_count':id_count})
  File "D:\ProgramFiles\Anaconda3\lib\site-packages\django-1.11.8-py3.6.egg\django\shortcuts.py", line 30, in render
    content = loader.render_to_string(template_name, context, request, using=using)
  File "D:\ProgramFiles\Anaconda3\lib\site-packages\django-1.11.8-py3.6.egg\django\template\loader.py", line 68, in render_to_string
    return template.render(context, request)
  File "D:\ProgramFiles\Anaconda3\lib\site-packages\django-1.11.8-py3.6.egg\django\template\backends\django.py", line 66, in render
    return self.template.render(context)
  File "D:\ProgramFiles\Anaconda3\lib\site-packages\django-1.11.8-py3.6.egg\django\template\base.py", line 207, in render
    return self._render(context)
  File "D:\ProgramFiles\Anaconda3\lib\site-packages\django-1.11.8-py3.6.egg\django\template\base.py", line 199, in _render
    return self.nodelist.render(context)
  File "D:\ProgramFiles\Anaconda3\lib\site-packages\django-1.11.8-py3.6.egg\django\template\base.py", line 990, in render
    bit = node.render_annotated(context)
  File "D:\ProgramFiles\Anaconda3\lib\site-packages\django-1.11.8-py3.6.egg\django\template\base.py", line 957, in render_annotated
    return self.render(context)
  File "D:\ProgramFiles\Anaconda3\lib\site-packages\django-1.11.8-py3.6.egg\django\template\loader_tags.py", line 177, in render
    return compiled_parent._render(context)
  File "D:\ProgramFiles\Anaconda3\lib\site-packages\django-1.11.8-py3.6.egg\django\template\base.py", line 199, in _render
    return self.nodelist.render(context)
  File "D:\ProgramFiles\Anaconda3\lib\site-packages\django-1.11.8-py3.6.egg\django\template\base.py", line 990, in render
    bit = node.render_annotated(context)
  File "D:\ProgramFiles\Anaconda3\lib\site-packages\django-1.11.8-py3.6.egg\django\template\base.py", line 957, in render_annotated
    return self.render(context)
  File "D:\ProgramFiles\Anaconda3\lib\site-packages\django-1.11.8-py3.6.egg\django\template\loader_tags.py", line 72, in render
    result = block.nodelist.render(context)
  File "D:\ProgramFiles\Anaconda3\lib\site-packages\django-1.11.8-py3.6.egg\django\template\base.py", line 990, in render
    bit = node.render_annotated(context)
  File "D:\ProgramFiles\Anaconda3\lib\site-packages\django-1.11.8-py3.6.egg\django\template\base.py", line 957, in render_annotated
    return self.render(context)
  File "D:\ProgramFiles\Anaconda3\lib\site-packages\django-1.11.8-py3.6.egg\django\template\loader_tags.py", line 72, in render
    result = block.nodelist.render(context)
  File "D:\ProgramFiles\Anaconda3\lib\site-packages\django-1.11.8-py3.6.egg\django\template\base.py", line 990, in render
    bit = node.render_annotated(context)
  File "D:\ProgramFiles\Anaconda3\lib\site-packages\django-1.11.8-py3.6.egg\django\template\base.py", line 957, in render_annotated
    return self.render(context)
  File "D:\ProgramFiles\Anaconda3\lib\site-packages\django-1.11.8-py3.6.egg\django\template\defaulttags.py", line 321, in render
    if match:
ValueError: The truth value of an array with more than one element is ambiguous. Use a.any() or a.all()
exception.py[2018-03-13 13:28:01][ERROR]：Internal Server Error: /tj/4
Traceback (most recent call last):
  File "D:\ProgramFiles\Anaconda3\lib\site-packages\django-1.11.8-py3.6.egg\django\core\handlers\exception.py", line 41, in inner
    response = get_response(request)
  File "D:\ProgramFiles\Anaconda3\lib\site-packages\django-1.11.8-py3.6.egg\django\core\handlers\base.py", line 249, in _legacy_get_response
    response = self._get_response(request)
  File "D:\ProgramFiles\Anaconda3\lib\site-packages\django-1.11.8-py3.6.egg\django\core\handlers\base.py", line 187, in _get_response
    response = self.process_exception_by_middleware(e, request)
  File "D:\ProgramFiles\Anaconda3\lib\site-packages\django-1.11.8-py3.6.egg\django\core\handlers\base.py", line 185, in _get_response
    response = wrapped_callback(request, *callback_args, **callback_kwargs)
  File "D:\tools\Tools\2018年3月5日\Carry\mysite\views.py", line 373, in tongji
    id_count={i:len(results[np.where(results[:,2]==i)]) for i in HSD.IDS}
  File "D:\tools\Tools\2018年3月5日\Carry\mysite\views.py", line 373, in <dictcomp>
    id_count={i:len(results[np.where(results[:,2]==i)]) for i in HSD.IDS}
IndexError: too many indices for array
exception.py[2018-03-13 13:28:22][ERROR]：Internal Server Error: /tj/1
Traceback (most recent call last):
  File "D:\ProgramFiles\Anaconda3\lib\site-packages\django-1.11.8-py3.6.egg\django\core\handlers\exception.py", line 41, in inner
    response = get_response(request)
  File "D:\ProgramFiles\Anaconda3\lib\site-packages\django-1.11.8-py3.6.egg\django\core\handlers\base.py", line 249, in _legacy_get_response
    response = self._get_response(request)
  File "D:\ProgramFiles\Anaconda3\lib\site-packages\django-1.11.8-py3.6.egg\django\core\handlers\base.py", line 187, in _get_response
    response = self.process_exception_by_middleware(e, request)
  File "D:\ProgramFiles\Anaconda3\lib\site-packages\django-1.11.8-py3.6.egg\django\core\handlers\base.py", line 185, in _get_response
    response = wrapped_callback(request, *callback_args, **callback_kwargs)
  File "D:\tools\Tools\2018年3月5日\Carry\mysite\views.py", line 373, in tongji
    id_count={i:len(results[np.where(results[:,2]==i)]) for i in HSD.IDS}
  File "D:\tools\Tools\2018年3月5日\Carry\mysite\views.py", line 373, in <dictcomp>
    id_count={i:len(results[np.where(results[:,2]==i)]) for i in HSD.IDS}
IndexError: too many indices for array
exception.py[2018-03-13 13:28:31][ERROR]：Internal Server Error: /tj/1
Traceback (most recent call last):
  File "D:\ProgramFiles\Anaconda3\lib\site-packages\django-1.11.8-py3.6.egg\django\core\handlers\exception.py", line 41, in inner
    response = get_response(request)
  File "D:\ProgramFiles\Anaconda3\lib\site-packages\django-1.11.8-py3.6.egg\django\core\handlers\base.py", line 249, in _legacy_get_response
    response = self._get_response(request)
  File "D:\ProgramFiles\Anaconda3\lib\site-packages\django-1.11.8-py3.6.egg\django\core\handlers\base.py", line 187, in _get_response
    response = self.process_exception_by_middleware(e, request)
  File "D:\ProgramFiles\Anaconda3\lib\site-packages\django-1.11.8-py3.6.egg\django\core\handlers\base.py", line 185, in _get_response
    response = wrapped_callback(request, *callback_args, **callback_kwargs)
  File "D:\tools\Tools\2018年3月5日\Carry\mysite\views.py", line 373, in tongji
    id_count={i:len(results[np.where(results[:,2]==i)]) for i in HSD.IDS}
  File "D:\tools\Tools\2018年3月5日\Carry\mysite\views.py", line 373, in <dictcomp>
    id_count={i:len(results[np.where(results[:,2]==i)]) for i in HSD.IDS}
IndexError: too many indices for array
exception.py[2018-03-13 13:28:48][ERROR]：Internal Server Error: /tj/1
Traceback (most recent call last):
  File "D:\ProgramFiles\Anaconda3\lib\site-packages\django-1.11.8-py3.6.egg\django\core\handlers\exception.py", line 41, in inner
    response = get_response(request)
  File "D:\ProgramFiles\Anaconda3\lib\site-packages\django-1.11.8-py3.6.egg\django\core\handlers\base.py", line 249, in _legacy_get_response
    response = self._get_response(request)
  File "D:\ProgramFiles\Anaconda3\lib\site-packages\django-1.11.8-py3.6.egg\django\core\handlers\base.py", line 187, in _get_response
    response = self.process_exception_by_middleware(e, request)
  File "D:\ProgramFiles\Anaconda3\lib\site-packages\django-1.11.8-py3.6.egg\django\core\handlers\base.py", line 185, in _get_response
    response = wrapped_callback(request, *callback_args, **callback_kwargs)
  File "D:\tools\Tools\2018年3月5日\Carry\mysite\views.py", line 373, in tongji
    id_count={i:len(results[np.where(results[:,2]==i)]) for i in HSD.IDS}
  File "D:\tools\Tools\2018年3月5日\Carry\mysite\views.py", line 373, in <dictcomp>
    id_count={i:len(results[np.where(results[:,2]==i)]) for i in HSD.IDS}
IndexError: too many indices for array
exception.py[2018-03-13 13:30:39][ERROR]：Internal Server Error: /tj/1
Traceback (most recent call last):
  File "D:\ProgramFiles\Anaconda3\lib\site-packages\django-1.11.8-py3.6.egg\django\core\handlers\exception.py", line 41, in inner
    response = get_response(request)
  File "D:\ProgramFiles\Anaconda3\lib\site-packages\django-1.11.8-py3.6.egg\django\core\handlers\base.py", line 249, in _legacy_get_response
    response = self._get_response(request)
  File "D:\ProgramFiles\Anaconda3\lib\site-packages\django-1.11.8-py3.6.egg\django\core\handlers\base.py", line 187, in _get_response
    response = self.process_exception_by_middleware(e, request)
  File "D:\ProgramFiles\Anaconda3\lib\site-packages\django-1.11.8-py3.6.egg\django\core\handlers\base.py", line 185, in _get_response
    response = wrapped_callback(request, *callback_args, **callback_kwargs)
  File "D:\tools\Tools\2018年3月5日\Carry\mysite\views.py", line 371, in tongji
    results.remove(results[ind1])
ValueError: The truth value of an array with more than one element is ambiguous. Use a.any() or a.all()
exception.py[2018-03-13 13:35:07][ERROR]：Internal Server Error: /tj/1
Traceback (most recent call last):
  File "D:\ProgramFiles\Anaconda3\lib\site-packages\django-1.11.8-py3.6.egg\django\core\handlers\exception.py", line 41, in inner
    response = get_response(request)
  File "D:\ProgramFiles\Anaconda3\lib\site-packages\django-1.11.8-py3.6.egg\django\core\handlers\base.py", line 249, in _legacy_get_response
    response = self._get_response(request)
  File "D:\ProgramFiles\Anaconda3\lib\site-packages\django-1.11.8-py3.6.egg\django\core\handlers\base.py", line 187, in _get_response
    response = self.process_exception_by_middleware(e, request)
  File "D:\ProgramFiles\Anaconda3\lib\site-packages\django-1.11.8-py3.6.egg\django\core\handlers\base.py", line 185, in _get_response
    response = wrapped_callback(request, *callback_args, **callback_kwargs)
  File "D:\tools\Tools\2018年3月5日\Carry\mysite\views.py", line 373, in tongji
    results.remove(results[ind1])
ValueError: The truth value of an array with more than one element is ambiguous. Use a.any() or a.all()
exception.py[2018-03-13 13:35:10][ERROR]：Internal Server Error: /tj/1
Traceback (most recent call last):
  File "D:\ProgramFiles\Anaconda3\lib\site-packages\django-1.11.8-py3.6.egg\django\core\handlers\exception.py", line 41, in inner
    response = get_response(request)
  File "D:\ProgramFiles\Anaconda3\lib\site-packages\django-1.11.8-py3.6.egg\django\core\handlers\base.py", line 249, in _legacy_get_response
    response = self._get_response(request)
  File "D:\ProgramFiles\Anaconda3\lib\site-packages\django-1.11.8-py3.6.egg\django\core\handlers\base.py", line 187, in _get_response
    response = self.process_exception_by_middleware(e, request)
  File "D:\ProgramFiles\Anaconda3\lib\site-packages\django-1.11.8-py3.6.egg\django\core\handlers\base.py", line 185, in _get_response
    response = wrapped_callback(request, *callback_args, **callback_kwargs)
  File "D:\tools\Tools\2018年3月5日\Carry\mysite\views.py", line 373, in tongji
    results.remove(results[ind1])
ValueError: The truth value of an array with more than one element is ambiguous. Use a.any() or a.all()
exception.py[2018-03-13 13:36:56][ERROR]：Internal Server Error: /tj/1
Traceback (most recent call last):
  File "D:\ProgramFiles\Anaconda3\lib\site-packages\django-1.11.8-py3.6.egg\django\core\handlers\exception.py", line 41, in inner
    response = get_response(request)
  File "D:\ProgramFiles\Anaconda3\lib\site-packages\django-1.11.8-py3.6.egg\django\core\handlers\base.py", line 249, in _legacy_get_response
    response = self._get_response(request)
  File "D:\ProgramFiles\Anaconda3\lib\site-packages\django-1.11.8-py3.6.egg\django\core\handlers\base.py", line 187, in _get_response
    response = self.process_exception_by_middleware(e, request)
  File "D:\ProgramFiles\Anaconda3\lib\site-packages\django-1.11.8-py3.6.egg\django\core\handlers\base.py", line 185, in _get_response
    response = wrapped_callback(request, *callback_args, **callback_kwargs)
  File "D:\tools\Tools\2018年3月5日\Carry\mysite\views.py", line 370, in tongji
    if results[ind1] in results and rq_id != results[ind1][2]:
ValueError: The truth value of an array with more than one element is ambiguous. Use a.any() or a.all()
exception.py[2018-03-13 13:37:19][ERROR]：Internal Server Error: /tj/1
Traceback (most recent call last):
  File "D:\ProgramFiles\Anaconda3\lib\site-packages\django-1.11.8-py3.6.egg\django\core\handlers\exception.py", line 41, in inner
    response = get_response(request)
  File "D:\ProgramFiles\Anaconda3\lib\site-packages\django-1.11.8-py3.6.egg\django\core\handlers\base.py", line 249, in _legacy_get_response
    response = self._get_response(request)
  File "D:\ProgramFiles\Anaconda3\lib\site-packages\django-1.11.8-py3.6.egg\django\core\handlers\base.py", line 187, in _get_response
    response = self.process_exception_by_middleware(e, request)
  File "D:\ProgramFiles\Anaconda3\lib\site-packages\django-1.11.8-py3.6.egg\django\core\handlers\base.py", line 185, in _get_response
    response = wrapped_callback(request, *callback_args, **callback_kwargs)
  File "D:\tools\Tools\2018年3月5日\Carry\mysite\views.py", line 372, in tongji
    results.remove(results[ind1])
ValueError: The truth value of an array with more than one element is ambiguous. Use a.any() or a.all()
base.py[2018-03-13 17:08:27][WARNING]：Not Found: /favicon.ico
exception.py[2018-03-14 08:45:18][ERROR]：Internal Server Error: /tj/2
Traceback (most recent call last):
  File "D:\ProgramFiles\Anaconda3\lib\site-packages\django-1.11.8-py3.6.egg\django\core\handlers\exception.py", line 41, in inner
    response = get_response(request)
  File "D:\ProgramFiles\Anaconda3\lib\site-packages\django-1.11.8-py3.6.egg\django\core\handlers\base.py", line 249, in _legacy_get_response
    response = self._get_response(request)
  File "D:\ProgramFiles\Anaconda3\lib\site-packages\django-1.11.8-py3.6.egg\django\core\handlers\base.py", line 187, in _get_response
    response = self.process_exception_by_middleware(e, request)
  File "D:\ProgramFiles\Anaconda3\lib\site-packages\django-1.11.8-py3.6.egg\django\core\handlers\base.py", line 185, in _get_response
    response = wrapped_callback(request, *callback_args, **callback_kwargs)
  File "D:\tools\Tools\2018年3月5日\Carry\mysite\views.py", line 378, in tongji
    return render(rq,'tongji.html',{'results':results,'dates':rq_date,'ids':HSD.IDS,'huizong':huizong,'id_name':id_name,'id_count':id_count})
UnboundLocalError: local variable 'id_count' referenced before assignment
base.py[2018-03-14 08:45:18][WARNING]：Not Found: /favicon.ico
exception.py[2018-03-14 08:45:53][ERROR]：Internal Server Error: /tj/2
Traceback (most recent call last):
  File "D:\ProgramFiles\Anaconda3\lib\site-packages\django-1.11.8-py3.6.egg\django\core\handlers\exception.py", line 41, in inner
    response = get_response(request)
  File "D:\ProgramFiles\Anaconda3\lib\site-packages\django-1.11.8-py3.6.egg\django\core\handlers\base.py", line 249, in _legacy_get_response
    response = self._get_response(request)
  File "D:\ProgramFiles\Anaconda3\lib\site-packages\django-1.11.8-py3.6.egg\django\core\handlers\base.py", line 187, in _get_response
    response = self.process_exception_by_middleware(e, request)
  File "D:\ProgramFiles\Anaconda3\lib\site-packages\django-1.11.8-py3.6.egg\django\core\handlers\base.py", line 185, in _get_response
    response = wrapped_callback(request, *callback_args, **callback_kwargs)
  File "D:\tools\Tools\2018年3月5日\Carry\mysite\views.py", line 378, in tongji
    return render(rq,'tongji.html',{'results':results,'dates':rq_date,'ids':HSD.IDS,'huizong':huizong,'id_name':id_name,'id_count':id_count})
UnboundLocalError: local variable 'id_count' referenced before assignment
base.py[2018-03-14 08:49:22][WARNING]：Not Found: /favicon.ico
views.py[2018-03-14 09:19:14][ERROR]：name 'cache' is not defined
views.py[2018-03-14 09:19:15][ERROR]：name 'cache' is not defined
views.py[2018-03-14 09:19:15][ERROR]：name 'cache' is not defined
views.py[2018-03-14 09:19:15][ERROR]：name 'cache' is not defined
views.py[2018-03-14 09:21:03][ERROR]：name 'cache' is not defined
views.py[2018-03-14 09:21:03][ERROR]：name 'cache' is not defined
views.py[2018-03-14 09:28:56][ERROR]：Object of type 'datetime' is not JSON serializable
base.py[2018-03-14 10:06:28][WARNING]：Not Found: /tj/datetimes=2018-03-14
exception.py[2018-03-14 10:24:11][ERROR]：Internal Server Error: /tj/
Traceback (most recent call last):
  File "D:\ProgramFiles\Anaconda3\lib\site-packages\django-1.11.8-py3.6.egg\django\core\handlers\exception.py", line 41, in inner
    response = get_response(request)
  File "D:\ProgramFiles\Anaconda3\lib\site-packages\django-1.11.8-py3.6.egg\django\core\handlers\base.py", line 249, in _legacy_get_response
    response = self._get_response(request)
  File "D:\ProgramFiles\Anaconda3\lib\site-packages\django-1.11.8-py3.6.egg\django\core\handlers\base.py", line 187, in _get_response
    response = self.process_exception_by_middleware(e, request)
  File "D:\ProgramFiles\Anaconda3\lib\site-packages\django-1.11.8-py3.6.egg\django\core\handlers\base.py", line 185, in _get_response
    response = wrapped_callback(request, *callback_args, **callback_kwargs)
  File "D:\tools\Tools\2018年3月5日\Carry\mysite\views.py", line 378, in tongji
    return render(rq,'tongji.html',locals())
  File "D:\ProgramFiles\Anaconda3\lib\site-packages\django-1.11.8-py3.6.egg\django\shortcuts.py", line 30, in render
    content = loader.render_to_string(template_name, context, request, using=using)
  File "D:\ProgramFiles\Anaconda3\lib\site-packages\django-1.11.8-py3.6.egg\django\template\loader.py", line 68, in render_to_string
    return template.render(context, request)
  File "D:\ProgramFiles\Anaconda3\lib\site-packages\django-1.11.8-py3.6.egg\django\template\backends\django.py", line 66, in render
    return self.template.render(context)
  File "D:\ProgramFiles\Anaconda3\lib\site-packages\django-1.11.8-py3.6.egg\django\template\base.py", line 207, in render
    return self._render(context)
  File "D:\ProgramFiles\Anaconda3\lib\site-packages\django-1.11.8-py3.6.egg\django\template\base.py", line 199, in _render
    return self.nodelist.render(context)
  File "D:\ProgramFiles\Anaconda3\lib\site-packages\django-1.11.8-py3.6.egg\django\template\base.py", line 990, in render
    bit = node.render_annotated(context)
  File "D:\ProgramFiles\Anaconda3\lib\site-packages\django-1.11.8-py3.6.egg\django\template\base.py", line 957, in render_annotated
    return self.render(context)
  File "D:\ProgramFiles\Anaconda3\lib\site-packages\django-1.11.8-py3.6.egg\django\template\loader_tags.py", line 177, in render
    return compiled_parent._render(context)
  File "D:\ProgramFiles\Anaconda3\lib\site-packages\django-1.11.8-py3.6.egg\django\template\base.py", line 199, in _render
    return self.nodelist.render(context)
  File "D:\ProgramFiles\Anaconda3\lib\site-packages\django-1.11.8-py3.6.egg\django\template\base.py", line 990, in render
    bit = node.render_annotated(context)
  File "D:\ProgramFiles\Anaconda3\lib\site-packages\django-1.11.8-py3.6.egg\django\template\base.py", line 957, in render_annotated
    return self.render(context)
  File "D:\ProgramFiles\Anaconda3\lib\site-packages\django-1.11.8-py3.6.egg\django\template\loader_tags.py", line 72, in render
    result = block.nodelist.render(context)
  File "D:\ProgramFiles\Anaconda3\lib\site-packages\django-1.11.8-py3.6.egg\django\template\base.py", line 990, in render
    bit = node.render_annotated(context)
  File "D:\ProgramFiles\Anaconda3\lib\site-packages\django-1.11.8-py3.6.egg\django\template\base.py", line 957, in render_annotated
    return self.render(context)
  File "D:\ProgramFiles\Anaconda3\lib\site-packages\django-1.11.8-py3.6.egg\django\template\loader_tags.py", line 72, in render
    result = block.nodelist.render(context)
  File "D:\ProgramFiles\Anaconda3\lib\site-packages\django-1.11.8-py3.6.egg\django\template\base.py", line 990, in render
    bit = node.render_annotated(context)
  File "D:\ProgramFiles\Anaconda3\lib\site-packages\django-1.11.8-py3.6.egg\django\template\base.py", line 957, in render_annotated
    return self.render(context)
  File "D:\ProgramFiles\Anaconda3\lib\site-packages\django-1.11.8-py3.6.egg\django\template\loader_tags.py", line 204, in render
    template = context.template.engine.get_template(template_name)
  File "D:\ProgramFiles\Anaconda3\lib\site-packages\django-1.11.8-py3.6.egg\django\template\engine.py", line 162, in get_template
    template, origin = self.find_template(template_name)
  File "D:\ProgramFiles\Anaconda3\lib\site-packages\django-1.11.8-py3.6.egg\django\template\engine.py", line 136, in find_template
    name, template_dirs=dirs, skip=skip,
  File "D:\ProgramFiles\Anaconda3\lib\site-packages\django-1.11.8-py3.6.egg\django\template\loaders\base.py", line 44, in get_template
    contents, origin, origin.template_name, self.engine,
  File "D:\ProgramFiles\Anaconda3\lib\site-packages\django-1.11.8-py3.6.egg\django\template\base.py", line 191, in __init__
    self.nodelist = self.compile_nodelist()
  File "D:\ProgramFiles\Anaconda3\lib\site-packages\django-1.11.8-py3.6.egg\django\template\base.py", line 230, in compile_nodelist
    return parser.parse()
  File "D:\ProgramFiles\Anaconda3\lib\site-packages\django-1.11.8-py3.6.egg\django\template\base.py", line 515, in parse
    raise self.error(token, e)
  File "D:\ProgramFiles\Anaconda3\lib\site-packages\django-1.11.8-py3.6.egg\django\template\base.py", line 513, in parse
    compiled_result = compile_func(self, token)
  File "D:\ProgramFiles\Anaconda3\lib\site-packages\django-1.11.8-py3.6.egg\django\template\defaulttags.py", line 827, in do_for
    nodelist_loop = parser.parse(('empty', 'endfor',))
  File "D:\ProgramFiles\Anaconda3\lib\site-packages\django-1.11.8-py3.6.egg\django\template\base.py", line 486, in parse
    raise self.error(token, e)
  File "D:\ProgramFiles\Anaconda3\lib\site-packages\django-1.11.8-py3.6.egg\django\template\base.py", line 484, in parse
    filter_expression = self.compile_filter(token.contents)
  File "D:\ProgramFiles\Anaconda3\lib\site-packages\django-1.11.8-py3.6.egg\django\template\base.py", line 600, in compile_filter
    return FilterExpression(token, self)
  File "D:\ProgramFiles\Anaconda3\lib\site-packages\django-1.11.8-py3.6.egg\django\template\base.py", line 695, in __init__
    self.args_check(filter_name, filter_func, args)
  File "D:\ProgramFiles\Anaconda3\lib\site-packages\django-1.11.8-py3.6.egg\django\template\base.py", line 770, in args_check
    (name, alen - dlen, plen))
django.template.exceptions.TemplateSyntaxError: names requires 2 arguments, 1 provided
exception.py[2018-03-14 10:45:22][ERROR]：Internal Server Error: /tj/1
Traceback (most recent call last):
  File "D:\ProgramFiles\Anaconda3\lib\site-packages\django-1.11.8-py3.6.egg\django\core\handlers\exception.py", line 41, in inner
    response = get_response(request)
  File "D:\ProgramFiles\Anaconda3\lib\site-packages\django-1.11.8-py3.6.egg\django\core\handlers\base.py", line 249, in _legacy_get_response
    response = self._get_response(request)
  File "D:\ProgramFiles\Anaconda3\lib\site-packages\django-1.11.8-py3.6.egg\django\core\handlers\base.py", line 187, in _get_response
    response = self.process_exception_by_middleware(e, request)
  File "D:\ProgramFiles\Anaconda3\lib\site-packages\django-1.11.8-py3.6.egg\django\core\handlers\base.py", line 185, in _get_response
    response = wrapped_callback(request, *callback_args, **callback_kwargs)
  File "D:\tools\Tools\2018年3月5日\Carry\mysite\views.py", line 397, in tongji
    return render(rq, 'tongji.html', {'herys': herys,'dates':dates,'ids':HSD.IDS})
  File "D:\ProgramFiles\Anaconda3\lib\site-packages\django-1.11.8-py3.6.egg\django\shortcuts.py", line 30, in render
    content = loader.render_to_string(template_name, context, request, using=using)
  File "D:\ProgramFiles\Anaconda3\lib\site-packages\django-1.11.8-py3.6.egg\django\template\loader.py", line 68, in render_to_string
    return template.render(context, request)
  File "D:\ProgramFiles\Anaconda3\lib\site-packages\django-1.11.8-py3.6.egg\django\template\backends\django.py", line 66, in render
    return self.template.render(context)
  File "D:\ProgramFiles\Anaconda3\lib\site-packages\django-1.11.8-py3.6.egg\django\template\base.py", line 207, in render
    return self._render(context)
  File "D:\ProgramFiles\Anaconda3\lib\site-packages\django-1.11.8-py3.6.egg\django\template\base.py", line 199, in _render
    return self.nodelist.render(context)
  File "D:\ProgramFiles\Anaconda3\lib\site-packages\django-1.11.8-py3.6.egg\django\template\base.py", line 990, in render
    bit = node.render_annotated(context)
  File "D:\ProgramFiles\Anaconda3\lib\site-packages\django-1.11.8-py3.6.egg\django\template\base.py", line 957, in render_annotated
    return self.render(context)
  File "D:\ProgramFiles\Anaconda3\lib\site-packages\django-1.11.8-py3.6.egg\django\template\loader_tags.py", line 177, in render
    return compiled_parent._render(context)
  File "D:\ProgramFiles\Anaconda3\lib\site-packages\django-1.11.8-py3.6.egg\django\template\base.py", line 199, in _render
    return self.nodelist.render(context)
  File "D:\ProgramFiles\Anaconda3\lib\site-packages\django-1.11.8-py3.6.egg\django\template\base.py", line 990, in render
    bit = node.render_annotated(context)
  File "D:\ProgramFiles\Anaconda3\lib\site-packages\django-1.11.8-py3.6.egg\django\template\base.py", line 957, in render_annotated
    return self.render(context)
  File "D:\ProgramFiles\Anaconda3\lib\site-packages\django-1.11.8-py3.6.egg\django\template\loader_tags.py", line 72, in render
    result = block.nodelist.render(context)
  File "D:\ProgramFiles\Anaconda3\lib\site-packages\django-1.11.8-py3.6.egg\django\template\base.py", line 990, in render
    bit = node.render_annotated(context)
  File "D:\ProgramFiles\Anaconda3\lib\site-packages\django-1.11.8-py3.6.egg\django\template\base.py", line 957, in render_annotated
    return self.render(context)
  File "D:\ProgramFiles\Anaconda3\lib\site-packages\django-1.11.8-py3.6.egg\django\template\loader_tags.py", line 72, in render
    result = block.nodelist.render(context)
  File "D:\ProgramFiles\Anaconda3\lib\site-packages\django-1.11.8-py3.6.egg\django\template\base.py", line 990, in render
    bit = node.render_annotated(context)
  File "D:\ProgramFiles\Anaconda3\lib\site-packages\django-1.11.8-py3.6.egg\django\template\base.py", line 957, in render_annotated
    return self.render(context)
  File "D:\ProgramFiles\Anaconda3\lib\site-packages\django-1.11.8-py3.6.egg\django\template\loader_tags.py", line 216, in render
    return template.render(context)
  File "D:\ProgramFiles\Anaconda3\lib\site-packages\django-1.11.8-py3.6.egg\django\template\base.py", line 209, in render
    return self._render(context)
  File "D:\ProgramFiles\Anaconda3\lib\site-packages\django-1.11.8-py3.6.egg\django\template\base.py", line 199, in _render
    return self.nodelist.render(context)
  File "D:\ProgramFiles\Anaconda3\lib\site-packages\django-1.11.8-py3.6.egg\django\template\base.py", line 990, in render
    bit = node.render_annotated(context)
  File "D:\ProgramFiles\Anaconda3\lib\site-packages\django-1.11.8-py3.6.egg\django\template\base.py", line 957, in render_annotated
    return self.render(context)
  File "D:\ProgramFiles\Anaconda3\lib\site-packages\django-1.11.8-py3.6.egg\django\template\defaulttags.py", line 216, in render
    nodelist.append(node.render_annotated(context))
  File "D:\ProgramFiles\Anaconda3\lib\site-packages\django-1.11.8-py3.6.egg\django\template\base.py", line 957, in render_annotated
    return self.render(context)
  File "D:\ProgramFiles\Anaconda3\lib\site-packages\django-1.11.8-py3.6.egg\django\template\base.py", line 1040, in render
    output = self.filter_expression.resolve(context)
  File "D:\ProgramFiles\Anaconda3\lib\site-packages\django-1.11.8-py3.6.egg\django\template\base.py", line 736, in resolve
    new_obj = func(obj, *arg_vals)
  File "D:\tools\Tools\2018年3月5日\Carry\mysite\templatetags\mvote.py", line 20, in name_option
    name = d.get(i)
AttributeError: 'str' object has no attribute 'get'
exception.py[2018-03-14 10:46:53][ERROR]：Internal Server Error: /tj/3
Traceback (most recent call last):
  File "D:\ProgramFiles\Anaconda3\lib\site-packages\django-1.11.8-py3.6.egg\django\core\handlers\exception.py", line 41, in inner
    response = get_response(request)
  File "D:\ProgramFiles\Anaconda3\lib\site-packages\django-1.11.8-py3.6.egg\django\core\handlers\base.py", line 249, in _legacy_get_response
    response = self._get_response(request)
  File "D:\ProgramFiles\Anaconda3\lib\site-packages\django-1.11.8-py3.6.egg\django\core\handlers\base.py", line 187, in _get_response
    response = self.process_exception_by_middleware(e, request)
  File "D:\ProgramFiles\Anaconda3\lib\site-packages\django-1.11.8-py3.6.egg\django\core\handlers\base.py", line 185, in _get_response
    response = wrapped_callback(request, *callback_args, **callback_kwargs)
  File "D:\tools\Tools\2018年3月5日\Carry\mysite\views.py", line 397, in tongji
    return render(rq, 'tongji.html', {'herys': herys,'dates':dates,'ids':HSD.IDS})
  File "D:\ProgramFiles\Anaconda3\lib\site-packages\django-1.11.8-py3.6.egg\django\shortcuts.py", line 30, in render
    content = loader.render_to_string(template_name, context, request, using=using)
  File "D:\ProgramFiles\Anaconda3\lib\site-packages\django-1.11.8-py3.6.egg\django\template\loader.py", line 68, in render_to_string
    return template.render(context, request)
  File "D:\ProgramFiles\Anaconda3\lib\site-packages\django-1.11.8-py3.6.egg\django\template\backends\django.py", line 66, in render
    return self.template.render(context)
  File "D:\ProgramFiles\Anaconda3\lib\site-packages\django-1.11.8-py3.6.egg\django\template\base.py", line 207, in render
    return self._render(context)
  File "D:\ProgramFiles\Anaconda3\lib\site-packages\django-1.11.8-py3.6.egg\django\template\base.py", line 199, in _render
    return self.nodelist.render(context)
  File "D:\ProgramFiles\Anaconda3\lib\site-packages\django-1.11.8-py3.6.egg\django\template\base.py", line 990, in render
    bit = node.render_annotated(context)
  File "D:\ProgramFiles\Anaconda3\lib\site-packages\django-1.11.8-py3.6.egg\django\template\base.py", line 957, in render_annotated
    return self.render(context)
  File "D:\ProgramFiles\Anaconda3\lib\site-packages\django-1.11.8-py3.6.egg\django\template\loader_tags.py", line 177, in render
    return compiled_parent._render(context)
  File "D:\ProgramFiles\Anaconda3\lib\site-packages\django-1.11.8-py3.6.egg\django\template\base.py", line 199, in _render
    return self.nodelist.render(context)
  File "D:\ProgramFiles\Anaconda3\lib\site-packages\django-1.11.8-py3.6.egg\django\template\base.py", line 990, in render
    bit = node.render_annotated(context)
  File "D:\ProgramFiles\Anaconda3\lib\site-packages\django-1.11.8-py3.6.egg\django\template\base.py", line 957, in render_annotated
    return self.render(context)
  File "D:\ProgramFiles\Anaconda3\lib\site-packages\django-1.11.8-py3.6.egg\django\template\loader_tags.py", line 72, in render
    result = block.nodelist.render(context)
  File "D:\ProgramFiles\Anaconda3\lib\site-packages\django-1.11.8-py3.6.egg\django\template\base.py", line 990, in render
    bit = node.render_annotated(context)
  File "D:\ProgramFiles\Anaconda3\lib\site-packages\django-1.11.8-py3.6.egg\django\template\base.py", line 957, in render_annotated
    return self.render(context)
  File "D:\ProgramFiles\Anaconda3\lib\site-packages\django-1.11.8-py3.6.egg\django\template\loader_tags.py", line 72, in render
    result = block.nodelist.render(context)
  File "D:\ProgramFiles\Anaconda3\lib\site-packages\django-1.11.8-py3.6.egg\django\template\base.py", line 990, in render
    bit = node.render_annotated(context)
  File "D:\ProgramFiles\Anaconda3\lib\site-packages\django-1.11.8-py3.6.egg\django\template\base.py", line 957, in render_annotated
    return self.render(context)
  File "D:\ProgramFiles\Anaconda3\lib\site-packages\django-1.11.8-py3.6.egg\django\template\loader_tags.py", line 216, in render
    return template.render(context)
  File "D:\ProgramFiles\Anaconda3\lib\site-packages\django-1.11.8-py3.6.egg\django\template\base.py", line 209, in render
    return self._render(context)
  File "D:\ProgramFiles\Anaconda3\lib\site-packages\django-1.11.8-py3.6.egg\django\template\base.py", line 199, in _render
    return self.nodelist.render(context)
  File "D:\ProgramFiles\Anaconda3\lib\site-packages\django-1.11.8-py3.6.egg\django\template\base.py", line 990, in render
    bit = node.render_annotated(context)
  File "D:\ProgramFiles\Anaconda3\lib\site-packages\django-1.11.8-py3.6.egg\django\template\base.py", line 957, in render_annotated
    return self.render(context)
  File "D:\ProgramFiles\Anaconda3\lib\site-packages\django-1.11.8-py3.6.egg\django\template\defaulttags.py", line 216, in render
    nodelist.append(node.render_annotated(context))
  File "D:\ProgramFiles\Anaconda3\lib\site-packages\django-1.11.8-py3.6.egg\django\template\base.py", line 957, in render_annotated
    return self.render(context)
  File "D:\ProgramFiles\Anaconda3\lib\site-packages\django-1.11.8-py3.6.egg\django\template\base.py", line 1040, in render
    output = self.filter_expression.resolve(context)
  File "D:\ProgramFiles\Anaconda3\lib\site-packages\django-1.11.8-py3.6.egg\django\template\base.py", line 736, in resolve
    new_obj = func(obj, *arg_vals)
  File "D:\tools\Tools\2018年3月5日\Carry\mysite\templatetags\mvote.py", line 20, in name_option
    name = d.get(i)
AttributeError: 'str' object has no attribute 'get'
exception.py[2018-03-14 10:55:39][ERROR]：Internal Server Error: /tj/1
Traceback (most recent call last):
  File "D:\ProgramFiles\Anaconda3\lib\site-packages\django-1.11.8-py3.6.egg\django\core\handlers\exception.py", line 41, in inner
    response = get_response(request)
  File "D:\ProgramFiles\Anaconda3\lib\site-packages\django-1.11.8-py3.6.egg\django\core\handlers\base.py", line 249, in _legacy_get_response
    response = self._get_response(request)
  File "D:\ProgramFiles\Anaconda3\lib\site-packages\django-1.11.8-py3.6.egg\django\core\handlers\base.py", line 187, in _get_response
    response = self.process_exception_by_middleware(e, request)
  File "D:\ProgramFiles\Anaconda3\lib\site-packages\django-1.11.8-py3.6.egg\django\core\handlers\base.py", line 185, in _get_response
    response = wrapped_callback(request, *callback_args, **callback_kwargs)
  File "D:\tools\Tools\2018年3月5日\Carry\mysite\views.py", line 397, in tongji
    return render(rq, 'tongji.html', {'herys': herys,'dates':dates,'ids':HSD.IDS})
  File "D:\ProgramFiles\Anaconda3\lib\site-packages\django-1.11.8-py3.6.egg\django\shortcuts.py", line 30, in render
    content = loader.render_to_string(template_name, context, request, using=using)
  File "D:\ProgramFiles\Anaconda3\lib\site-packages\django-1.11.8-py3.6.egg\django\template\loader.py", line 68, in render_to_string
    return template.render(context, request)
  File "D:\ProgramFiles\Anaconda3\lib\site-packages\django-1.11.8-py3.6.egg\django\template\backends\django.py", line 66, in render
    return self.template.render(context)
  File "D:\ProgramFiles\Anaconda3\lib\site-packages\django-1.11.8-py3.6.egg\django\template\base.py", line 207, in render
    return self._render(context)
  File "D:\ProgramFiles\Anaconda3\lib\site-packages\django-1.11.8-py3.6.egg\django\template\base.py", line 199, in _render
    return self.nodelist.render(context)
  File "D:\ProgramFiles\Anaconda3\lib\site-packages\django-1.11.8-py3.6.egg\django\template\base.py", line 990, in render
    bit = node.render_annotated(context)
  File "D:\ProgramFiles\Anaconda3\lib\site-packages\django-1.11.8-py3.6.egg\django\template\base.py", line 957, in render_annotated
    return self.render(context)
  File "D:\ProgramFiles\Anaconda3\lib\site-packages\django-1.11.8-py3.6.egg\django\template\loader_tags.py", line 177, in render
    return compiled_parent._render(context)
  File "D:\ProgramFiles\Anaconda3\lib\site-packages\django-1.11.8-py3.6.egg\django\template\base.py", line 199, in _render
    return self.nodelist.render(context)
  File "D:\ProgramFiles\Anaconda3\lib\site-packages\django-1.11.8-py3.6.egg\django\template\base.py", line 990, in render
    bit = node.render_annotated(context)
  File "D:\ProgramFiles\Anaconda3\lib\site-packages\django-1.11.8-py3.6.egg\django\template\base.py", line 957, in render_annotated
    return self.render(context)
  File "D:\ProgramFiles\Anaconda3\lib\site-packages\django-1.11.8-py3.6.egg\django\template\loader_tags.py", line 72, in render
    result = block.nodelist.render(context)
  File "D:\ProgramFiles\Anaconda3\lib\site-packages\django-1.11.8-py3.6.egg\django\template\base.py", line 990, in render
    bit = node.render_annotated(context)
  File "D:\ProgramFiles\Anaconda3\lib\site-packages\django-1.11.8-py3.6.egg\django\template\base.py", line 957, in render_annotated
    return self.render(context)
  File "D:\ProgramFiles\Anaconda3\lib\site-packages\django-1.11.8-py3.6.egg\django\template\loader_tags.py", line 72, in render
    result = block.nodelist.render(context)
  File "D:\ProgramFiles\Anaconda3\lib\site-packages\django-1.11.8-py3.6.egg\django\template\base.py", line 990, in render
    bit = node.render_annotated(context)
  File "D:\ProgramFiles\Anaconda3\lib\site-packages\django-1.11.8-py3.6.egg\django\template\base.py", line 957, in render_annotated
    return self.render(context)
  File "D:\ProgramFiles\Anaconda3\lib\site-packages\django-1.11.8-py3.6.egg\django\template\loader_tags.py", line 216, in render
    return template.render(context)
  File "D:\ProgramFiles\Anaconda3\lib\site-packages\django-1.11.8-py3.6.egg\django\template\base.py", line 209, in render
    return self._render(context)
  File "D:\ProgramFiles\Anaconda3\lib\site-packages\django-1.11.8-py3.6.egg\django\template\base.py", line 199, in _render
    return self.nodelist.render(context)
  File "D:\ProgramFiles\Anaconda3\lib\site-packages\django-1.11.8-py3.6.egg\django\template\base.py", line 990, in render
    bit = node.render_annotated(context)
  File "D:\ProgramFiles\Anaconda3\lib\site-packages\django-1.11.8-py3.6.egg\django\template\base.py", line 957, in render_annotated
    return self.render(context)
  File "D:\ProgramFiles\Anaconda3\lib\site-packages\django-1.11.8-py3.6.egg\django\template\defaulttags.py", line 216, in render
    nodelist.append(node.render_annotated(context))
  File "D:\ProgramFiles\Anaconda3\lib\site-packages\django-1.11.8-py3.6.egg\django\template\base.py", line 957, in render_annotated
    return self.render(context)
  File "D:\ProgramFiles\Anaconda3\lib\site-packages\django-1.11.8-py3.6.egg\django\template\base.py", line 1040, in render
    output = self.filter_expression.resolve(context)
  File "D:\ProgramFiles\Anaconda3\lib\site-packages\django-1.11.8-py3.6.egg\django\template\base.py", line 736, in resolve
    new_obj = func(obj, *arg_vals)
  File "D:\tools\Tools\2018年3月5日\Carry\mysite\templatetags\mvote.py", line 20, in name_option
    name = d.get(i)
AttributeError: 'str' object has no attribute 'get'
exception.py[2018-03-14 11:14:32][ERROR]：Internal Server Error: /tj/
Traceback (most recent call last):
  File "D:\ProgramFiles\Anaconda3\lib\site-packages\django-1.11.8-py3.6.egg\django\core\handlers\exception.py", line 41, in inner
    response = get_response(request)
  File "D:\ProgramFiles\Anaconda3\lib\site-packages\django-1.11.8-py3.6.egg\django\core\handlers\base.py", line 249, in _legacy_get_response
    response = self._get_response(request)
  File "D:\ProgramFiles\Anaconda3\lib\site-packages\django-1.11.8-py3.6.egg\django\core\handlers\base.py", line 187, in _get_response
    response = self.process_exception_by_middleware(e, request)
  File "D:\ProgramFiles\Anaconda3\lib\site-packages\django-1.11.8-py3.6.egg\django\core\handlers\base.py", line 185, in _get_response
    response = wrapped_callback(request, *callback_args, **callback_kwargs)
  File "D:\tools\Tools\2018年3月5日\Carry\mysite\views.py", line 397, in tongji
    return render(rq, 'tongji.html', {'herys': herys,'dates':dates,'ids':HSD.IDS})
  File "D:\ProgramFiles\Anaconda3\lib\site-packages\django-1.11.8-py3.6.egg\django\shortcuts.py", line 30, in render
    content = loader.render_to_string(template_name, context, request, using=using)
  File "D:\ProgramFiles\Anaconda3\lib\site-packages\django-1.11.8-py3.6.egg\django\template\loader.py", line 68, in render_to_string
    return template.render(context, request)
  File "D:\ProgramFiles\Anaconda3\lib\site-packages\django-1.11.8-py3.6.egg\django\template\backends\django.py", line 66, in render
    return self.template.render(context)
  File "D:\ProgramFiles\Anaconda3\lib\site-packages\django-1.11.8-py3.6.egg\django\template\base.py", line 207, in render
    return self._render(context)
  File "D:\ProgramFiles\Anaconda3\lib\site-packages\django-1.11.8-py3.6.egg\django\template\base.py", line 199, in _render
    return self.nodelist.render(context)
  File "D:\ProgramFiles\Anaconda3\lib\site-packages\django-1.11.8-py3.6.egg\django\template\base.py", line 990, in render
    bit = node.render_annotated(context)
  File "D:\ProgramFiles\Anaconda3\lib\site-packages\django-1.11.8-py3.6.egg\django\template\base.py", line 957, in render_annotated
    return self.render(context)
  File "D:\ProgramFiles\Anaconda3\lib\site-packages\django-1.11.8-py3.6.egg\django\template\loader_tags.py", line 177, in render
    return compiled_parent._render(context)
  File "D:\ProgramFiles\Anaconda3\lib\site-packages\django-1.11.8-py3.6.egg\django\template\base.py", line 199, in _render
    return self.nodelist.render(context)
  File "D:\ProgramFiles\Anaconda3\lib\site-packages\django-1.11.8-py3.6.egg\django\template\base.py", line 990, in render
    bit = node.render_annotated(context)
  File "D:\ProgramFiles\Anaconda3\lib\site-packages\django-1.11.8-py3.6.egg\django\template\base.py", line 957, in render_annotated
    return self.render(context)
  File "D:\ProgramFiles\Anaconda3\lib\site-packages\django-1.11.8-py3.6.egg\django\template\loader_tags.py", line 72, in render
    result = block.nodelist.render(context)
  File "D:\ProgramFiles\Anaconda3\lib\site-packages\django-1.11.8-py3.6.egg\django\template\base.py", line 990, in render
    bit = node.render_annotated(context)
  File "D:\ProgramFiles\Anaconda3\lib\site-packages\django-1.11.8-py3.6.egg\django\template\base.py", line 957, in render_annotated
    return self.render(context)
  File "D:\ProgramFiles\Anaconda3\lib\site-packages\django-1.11.8-py3.6.egg\django\template\loader_tags.py", line 72, in render
    result = block.nodelist.render(context)
  File "D:\ProgramFiles\Anaconda3\lib\site-packages\django-1.11.8-py3.6.egg\django\template\base.py", line 990, in render
    bit = node.render_annotated(context)
  File "D:\ProgramFiles\Anaconda3\lib\site-packages\django-1.11.8-py3.6.egg\django\template\base.py", line 957, in render_annotated
    return self.render(context)
  File "D:\ProgramFiles\Anaconda3\lib\site-packages\django-1.11.8-py3.6.egg\django\template\loader_tags.py", line 216, in render
    return template.render(context)
  File "D:\ProgramFiles\Anaconda3\lib\site-packages\django-1.11.8-py3.6.egg\django\template\base.py", line 209, in render
    return self._render(context)
  File "D:\ProgramFiles\Anaconda3\lib\site-packages\django-1.11.8-py3.6.egg\django\template\base.py", line 199, in _render
    return self.nodelist.render(context)
  File "D:\ProgramFiles\Anaconda3\lib\site-packages\django-1.11.8-py3.6.egg\django\template\base.py", line 990, in render
    bit = node.render_annotated(context)
  File "D:\ProgramFiles\Anaconda3\lib\site-packages\django-1.11.8-py3.6.egg\django\template\base.py", line 957, in render_annotated
    return self.render(context)
  File "D:\ProgramFiles\Anaconda3\lib\site-packages\django-1.11.8-py3.6.egg\django\template\defaulttags.py", line 216, in render
    nodelist.append(node.render_annotated(context))
  File "D:\ProgramFiles\Anaconda3\lib\site-packages\django-1.11.8-py3.6.egg\django\template\base.py", line 957, in render_annotated
    return self.render(context)
  File "D:\ProgramFiles\Anaconda3\lib\site-packages\django-1.11.8-py3.6.egg\django\template\base.py", line 1040, in render
    output = self.filter_expression.resolve(context)
  File "D:\ProgramFiles\Anaconda3\lib\site-packages\django-1.11.8-py3.6.egg\django\template\base.py", line 736, in resolve
    new_obj = func(obj, *arg_vals)
  File "D:\tools\Tools\2018年3月5日\Carry\mysite\templatetags\mvote.py", line 22, in name_option
    if not name:
UnboundLocalError: local variable 'name' referenced before assignment
exception.py[2018-03-14 11:18:13][ERROR]：Internal Server Error: /tj/
Traceback (most recent call last):
  File "D:\ProgramFiles\Anaconda3\lib\site-packages\django-1.11.8-py3.6.egg\django\core\handlers\exception.py", line 41, in inner
    response = get_response(request)
  File "D:\ProgramFiles\Anaconda3\lib\site-packages\django-1.11.8-py3.6.egg\django\core\handlers\base.py", line 249, in _legacy_get_response
    response = self._get_response(request)
  File "D:\ProgramFiles\Anaconda3\lib\site-packages\django-1.11.8-py3.6.egg\django\core\handlers\base.py", line 187, in _get_response
    response = self.process_exception_by_middleware(e, request)
  File "D:\ProgramFiles\Anaconda3\lib\site-packages\django-1.11.8-py3.6.egg\django\core\handlers\base.py", line 185, in _get_response
    response = wrapped_callback(request, *callback_args, **callback_kwargs)
  File "D:\tools\Tools\2018年3月5日\Carry\mysite\views.py", line 396, in tongji
    return render(rq, 'tongji.html', {'herys': herys,'dates':dates,'ids':HSD.IDS})
  File "D:\ProgramFiles\Anaconda3\lib\site-packages\django-1.11.8-py3.6.egg\django\shortcuts.py", line 30, in render
    content = loader.render_to_string(template_name, context, request, using=using)
  File "D:\ProgramFiles\Anaconda3\lib\site-packages\django-1.11.8-py3.6.egg\django\template\loader.py", line 68, in render_to_string
    return template.render(context, request)
  File "D:\ProgramFiles\Anaconda3\lib\site-packages\django-1.11.8-py3.6.egg\django\template\backends\django.py", line 66, in render
    return self.template.render(context)
  File "D:\ProgramFiles\Anaconda3\lib\site-packages\django-1.11.8-py3.6.egg\django\template\base.py", line 207, in render
    return self._render(context)
  File "D:\ProgramFiles\Anaconda3\lib\site-packages\django-1.11.8-py3.6.egg\django\template\base.py", line 199, in _render
    return self.nodelist.render(context)
  File "D:\ProgramFiles\Anaconda3\lib\site-packages\django-1.11.8-py3.6.egg\django\template\base.py", line 990, in render
    bit = node.render_annotated(context)
  File "D:\ProgramFiles\Anaconda3\lib\site-packages\django-1.11.8-py3.6.egg\django\template\base.py", line 957, in render_annotated
    return self.render(context)
  File "D:\ProgramFiles\Anaconda3\lib\site-packages\django-1.11.8-py3.6.egg\django\template\loader_tags.py", line 177, in render
    return compiled_parent._render(context)
  File "D:\ProgramFiles\Anaconda3\lib\site-packages\django-1.11.8-py3.6.egg\django\template\base.py", line 199, in _render
    return self.nodelist.render(context)
  File "D:\ProgramFiles\Anaconda3\lib\site-packages\django-1.11.8-py3.6.egg\django\template\base.py", line 990, in render
    bit = node.render_annotated(context)
  File "D:\ProgramFiles\Anaconda3\lib\site-packages\django-1.11.8-py3.6.egg\django\template\base.py", line 957, in render_annotated
    return self.render(context)
  File "D:\ProgramFiles\Anaconda3\lib\site-packages\django-1.11.8-py3.6.egg\django\template\loader_tags.py", line 72, in render
    result = block.nodelist.render(context)
  File "D:\ProgramFiles\Anaconda3\lib\site-packages\django-1.11.8-py3.6.egg\django\template\base.py", line 990, in render
    bit = node.render_annotated(context)
  File "D:\ProgramFiles\Anaconda3\lib\site-packages\django-1.11.8-py3.6.egg\django\template\base.py", line 957, in render_annotated
    return self.render(context)
  File "D:\ProgramFiles\Anaconda3\lib\site-packages\django-1.11.8-py3.6.egg\django\template\loader_tags.py", line 72, in render
    result = block.nodelist.render(context)
  File "D:\ProgramFiles\Anaconda3\lib\site-packages\django-1.11.8-py3.6.egg\django\template\base.py", line 990, in render
    bit = node.render_annotated(context)
  File "D:\ProgramFiles\Anaconda3\lib\site-packages\django-1.11.8-py3.6.egg\django\template\base.py", line 957, in render_annotated
    return self.render(context)
  File "D:\ProgramFiles\Anaconda3\lib\site-packages\django-1.11.8-py3.6.egg\django\template\loader_tags.py", line 216, in render
    return template.render(context)
  File "D:\ProgramFiles\Anaconda3\lib\site-packages\django-1.11.8-py3.6.egg\django\template\base.py", line 209, in render
    return self._render(context)
  File "D:\ProgramFiles\Anaconda3\lib\site-packages\django-1.11.8-py3.6.egg\django\template\base.py", line 199, in _render
    return self.nodelist.render(context)
  File "D:\ProgramFiles\Anaconda3\lib\site-packages\django-1.11.8-py3.6.egg\django\template\base.py", line 990, in render
    bit = node.render_annotated(context)
  File "D:\ProgramFiles\Anaconda3\lib\site-packages\django-1.11.8-py3.6.egg\django\template\base.py", line 957, in render_annotated
    return self.render(context)
  File "D:\ProgramFiles\Anaconda3\lib\site-packages\django-1.11.8-py3.6.egg\django\template\defaulttags.py", line 216, in render
    nodelist.append(node.render_annotated(context))
  File "D:\ProgramFiles\Anaconda3\lib\site-packages\django-1.11.8-py3.6.egg\django\template\base.py", line 957, in render_annotated
    return self.render(context)
  File "D:\ProgramFiles\Anaconda3\lib\site-packages\django-1.11.8-py3.6.egg\django\template\base.py", line 1040, in render
    output = self.filter_expression.resolve(context)
  File "D:\ProgramFiles\Anaconda3\lib\site-packages\django-1.11.8-py3.6.egg\django\template\base.py", line 736, in resolve
    new_obj = func(obj, *arg_vals)
  File "D:\tools\Tools\2018年3月5日\Carry\mysite\templatetags\mvote.py", line 22, in name_option
    if not name:
UnboundLocalError: local variable 'name' referenced before assignment
views.py[2018-03-14 14:08:33][ERROR]：execute() missing 1 required positional argument: 'query'
exception.py[2018-03-14 14:08:38][ERROR]：Internal Server Error: /tj/
Traceback (most recent call last):
  File "D:\ProgramFiles\Anaconda3\lib\site-packages\django-1.11.8-py3.6.egg\django\core\handlers\exception.py", line 41, in inner
    response = get_response(request)
  File "D:\ProgramFiles\Anaconda3\lib\site-packages\django-1.11.8-py3.6.egg\django\core\handlers\base.py", line 249, in _legacy_get_response
    response = self._get_response(request)
  File "D:\ProgramFiles\Anaconda3\lib\site-packages\django-1.11.8-py3.6.egg\django\core\handlers\base.py", line 187, in _get_response
    response = self.process_exception_by_middleware(e, request)
  File "D:\ProgramFiles\Anaconda3\lib\site-packages\django-1.11.8-py3.6.egg\django\core\handlers\base.py", line 185, in _get_response
    response = wrapped_callback(request, *callback_args, **callback_kwargs)
  File "D:\tools\Tools\2018年3月5日\Carry\mysite\views.py", line 352, in tongji
    results,id_name=HSD.calculate_earn(rq_date)
  File "D:\tools\Tools\2018年3月5日\Carry\mysite\HSD.py", line 365, in calculate_earn
    sql += f
NameError: name 'f' is not defined
exception.py[2018-03-14 14:11:34][ERROR]：Internal Server Error: /tj/
Traceback (most recent call last):
  File "D:\ProgramFiles\Anaconda3\lib\site-packages\django-1.11.8-py3.6.egg\django\core\handlers\exception.py", line 41, in inner
    response = get_response(request)
  File "D:\ProgramFiles\Anaconda3\lib\site-packages\django-1.11.8-py3.6.egg\django\core\handlers\base.py", line 249, in _legacy_get_response
    response = self._get_response(request)
  File "D:\ProgramFiles\Anaconda3\lib\site-packages\django-1.11.8-py3.6.egg\django\core\handlers\base.py", line 187, in _get_response
    response = self.process_exception_by_middleware(e, request)
  File "D:\ProgramFiles\Anaconda3\lib\site-packages\django-1.11.8-py3.6.egg\django\core\handlers\base.py", line 185, in _get_response
    response = wrapped_callback(request, *callback_args, **callback_kwargs)
  File "D:\tools\Tools\2018年3月5日\Carry\mysite\views.py", line 352, in tongji
    results,id_name=HSD.calculate_earn(rq_date)
  File "D:\tools\Tools\2018年3月5日\Carry\mysite\HSD.py", line 367, in calculate_earn
    id_name = get_idName(cur)
  File "D:\tools\Tools\2018年3月5日\Carry\mysite\HSD.py", line 322, in get_idName
    cur.execute()
TypeError: execute() missing 1 required positional argument: 'query'
exception.py[2018-03-14 17:25:55][ERROR]：Internal Server Error: /
Traceback (most recent call last):
  File "D:\ProgramFiles\Anaconda3\lib\site-packages\django-1.11.8-py3.6.egg\django\core\handlers\exception.py", line 41, in inner
    response = get_response(request)
  File "D:\ProgramFiles\Anaconda3\lib\site-packages\django-1.11.8-py3.6.egg\django\core\handlers\base.py", line 249, in _legacy_get_response
    response = self._get_response(request)
  File "D:\ProgramFiles\Anaconda3\lib\site-packages\django-1.11.8-py3.6.egg\django\core\handlers\base.py", line 187, in _get_response
    response = self.process_exception_by_middleware(e, request)
  File "D:\ProgramFiles\Anaconda3\lib\site-packages\django-1.11.8-py3.6.egg\django\core\handlers\base.py", line 185, in _get_response
    response = wrapped_callback(request, *callback_args, **callback_kwargs)
  File "D:\tools\Tools\2018年3月5日\Carry\mysite\views.py", line 78, in index
    return render(rq, 'index.html')
  File "D:\ProgramFiles\Anaconda3\lib\site-packages\django-1.11.8-py3.6.egg\django\shortcuts.py", line 30, in render
    content = loader.render_to_string(template_name, context, request, using=using)
  File "D:\ProgramFiles\Anaconda3\lib\site-packages\django-1.11.8-py3.6.egg\django\template\loader.py", line 68, in render_to_string
    return template.render(context, request)
  File "D:\ProgramFiles\Anaconda3\lib\site-packages\django-1.11.8-py3.6.egg\django\template\backends\django.py", line 66, in render
    return self.template.render(context)
  File "D:\ProgramFiles\Anaconda3\lib\site-packages\django-1.11.8-py3.6.egg\django\template\base.py", line 207, in render
    return self._render(context)
  File "D:\ProgramFiles\Anaconda3\lib\site-packages\django-1.11.8-py3.6.egg\django\template\base.py", line 199, in _render
    return self.nodelist.render(context)
  File "D:\ProgramFiles\Anaconda3\lib\site-packages\django-1.11.8-py3.6.egg\django\template\base.py", line 990, in render
    bit = node.render_annotated(context)
  File "D:\ProgramFiles\Anaconda3\lib\site-packages\django-1.11.8-py3.6.egg\django\template\base.py", line 957, in render_annotated
    return self.render(context)
  File "D:\ProgramFiles\Anaconda3\lib\site-packages\django-1.11.8-py3.6.egg\django\template\loader_tags.py", line 177, in render
    return compiled_parent._render(context)
  File "D:\ProgramFiles\Anaconda3\lib\site-packages\django-1.11.8-py3.6.egg\django\template\base.py", line 199, in _render
    return self.nodelist.render(context)
  File "D:\ProgramFiles\Anaconda3\lib\site-packages\django-1.11.8-py3.6.egg\django\template\base.py", line 990, in render
    bit = node.render_annotated(context)
  File "D:\ProgramFiles\Anaconda3\lib\site-packages\django-1.11.8-py3.6.egg\django\template\base.py", line 957, in render_annotated
    return self.render(context)
  File "D:\ProgramFiles\Anaconda3\lib\site-packages\django-1.11.8-py3.6.egg\django\template\loader_tags.py", line 72, in render
    result = block.nodelist.render(context)
  File "D:\ProgramFiles\Anaconda3\lib\site-packages\django-1.11.8-py3.6.egg\django\template\base.py", line 990, in render
    bit = node.render_annotated(context)
  File "D:\ProgramFiles\Anaconda3\lib\site-packages\django-1.11.8-py3.6.egg\django\template\base.py", line 957, in render_annotated
    return self.render(context)
  File "D:\ProgramFiles\Anaconda3\lib\site-packages\django-1.11.8-py3.6.egg\django\template\defaulttags.py", line 458, in render
    url = reverse(view_name, args=args, kwargs=kwargs, current_app=current_app)
  File "D:\ProgramFiles\Anaconda3\lib\site-packages\django-1.11.8-py3.6.egg\django\urls\base.py", line 91, in reverse
    return force_text(iri_to_uri(resolver._reverse_with_prefix(view, prefix, *args, **kwargs)))
  File "D:\ProgramFiles\Anaconda3\lib\site-packages\django-1.11.8-py3.6.egg\django\urls\resolvers.py", line 497, in _reverse_with_prefix
    raise NoReverseMatch(msg)
django.urls.exceptions.NoReverseMatch: Reverse for 'zhangting' with arguments '('today',)' not found. 1 pattern(s) tried: ['zhangting/([A-z])/$']
HSD.py[2018-03-14 17:28:06][ERROR]：too many values to unpack (expected 2)
base.py[2018-03-14 20:34:56][WARNING]：Not Found: /favicon.ico
HSD.py[2018-03-15 08:37:31][ERROR]：Expecting property name enclosed in double quotes: line 1 column 447009 (char 447008)
exception.py[2018-03-15 08:37:31][ERROR]：Internal Server Error: /zhangting/tomorrow/
Traceback (most recent call last):
  File "D:\ProgramFiles\Anaconda3\lib\site-packages\django-1.11.8-py3.6.egg\django\core\handlers\exception.py", line 41, in inner
    response = get_response(request)
  File "D:\ProgramFiles\Anaconda3\lib\site-packages\django-1.11.8-py3.6.egg\django\core\handlers\base.py", line 249, in _legacy_get_response
    response = self._get_response(request)
  File "D:\ProgramFiles\Anaconda3\lib\site-packages\django-1.11.8-py3.6.egg\django\core\handlers\base.py", line 187, in _get_response
    response = self.process_exception_by_middleware(e, request)
  File "D:\ProgramFiles\Anaconda3\lib\site-packages\django-1.11.8-py3.6.egg\django\core\handlers\base.py", line 185, in _get_response
    response = wrapped_callback(request, *callback_args, **callback_kwargs)
  File "D:\tools\Tools\2018年3月5日\Carry\mysite\views.py", line 542, in zhangting
    for i in range(len(zt_tomorrow)):
TypeError: object of type 'NoneType' has no len()
base.py[2018-03-15 08:37:31][WARNING]：Not Found: /favicon.ico
HSD.py[2018-03-15 08:38:58][ERROR]：Expecting property name enclosed in double quotes: line 1 column 447009 (char 447008)
HSD.py[2018-03-15 08:42:01][ERROR]：local variable 'dict_data' referenced before assignment
HSD.py[2018-03-15 08:48:37][ERROR]：local variable 'dict_data' referenced before assignment
HSD.py[2018-03-15 08:55:05][ERROR]：Expecting value: line 1 column 1 (char 0)
HSD.py[2018-03-15 08:56:09][ERROR]：Expecting value: line 1 column 1 (char 0)
exception.py[2018-03-15 09:46:39][ERROR]：Internal Server Error: /zhangting/today/
Traceback (most recent call last):
  File "D:\ProgramFiles\Anaconda3\lib\site-packages\urllib3\connection.py", line 141, in _new_conn
    (self.host, self.port), self.timeout, **extra_kw)
  File "D:\ProgramFiles\Anaconda3\lib\site-packages\urllib3\util\connection.py", line 83, in create_connection
    raise err
  File "D:\ProgramFiles\Anaconda3\lib\site-packages\urllib3\util\connection.py", line 73, in create_connection
    sock.connect(sa)
TimeoutError: [WinError 10060] 由于连接方在一段时间后没有正确答复或连接的主机没有反应，连接尝试失败。

During handling of the above exception, another exception occurred:

Traceback (most recent call last):
  File "D:\ProgramFiles\Anaconda3\lib\site-packages\urllib3\connectionpool.py", line 601, in urlopen
    chunked=chunked)
  File "D:\ProgramFiles\Anaconda3\lib\site-packages\urllib3\connectionpool.py", line 357, in _make_request
    conn.request(method, url, **httplib_request_kw)
  File "D:\ProgramFiles\Anaconda3\lib\http\client.py", line 1239, in request
    self._send_request(method, url, body, headers, encode_chunked)
  File "D:\ProgramFiles\Anaconda3\lib\http\client.py", line 1285, in _send_request
    self.endheaders(body, encode_chunked=encode_chunked)
  File "D:\ProgramFiles\Anaconda3\lib\http\client.py", line 1234, in endheaders
    self._send_output(message_body, encode_chunked=encode_chunked)
  File "D:\ProgramFiles\Anaconda3\lib\http\client.py", line 1026, in _send_output
    self.send(msg)
  File "D:\ProgramFiles\Anaconda3\lib\http\client.py", line 964, in send
    self.connect()
  File "D:\ProgramFiles\Anaconda3\lib\site-packages\urllib3\connection.py", line 166, in connect
    conn = self._new_conn()
  File "D:\ProgramFiles\Anaconda3\lib\site-packages\urllib3\connection.py", line 150, in _new_conn
    self, "Failed to establish a new connection: %s" % e)
urllib3.exceptions.NewConnectionError: <urllib3.connection.HTTPConnection object at 0x0000026079BBF198>: Failed to establish a new connection: [WinError 10060] 由于连接方在一段时间后没有正确答复或连接的主机没有反应，连接尝试失败。

During handling of the above exception, another exception occurred:

Traceback (most recent call last):
  File "D:\ProgramFiles\Anaconda3\lib\site-packages\requests\adapters.py", line 440, in send
    timeout=timeout
  File "D:\ProgramFiles\Anaconda3\lib\site-packages\urllib3\connectionpool.py", line 639, in urlopen
    _stacktrace=sys.exc_info()[2])
  File "D:\ProgramFiles\Anaconda3\lib\site-packages\urllib3\util\retry.py", line 388, in increment
    raise MaxRetryError(_pool, url, error or ResponseError(cause))
urllib3.exceptions.MaxRetryError: HTTPConnectionPool(host='qt.gtimg.cn', port=80): Max retries exceeded with url: /q=sh600084,sh603843,sh603488,sz300052,sh600729,sz300526,sz300575,sh600279,sh600939,sz300315,sh600138,sh600106,sh600132,sh600917,sh601158,sz300333,sz000506,sh600088,sz000024,sz000758,sz002883,sz000685,sz002511,sh603018,sh603601,sz300684,sh601872,sz002771,sh600633,sh600036,sz000798,sz002317,sh600999,sh601878,sz000906,sh600158,sh601877,sz002197,sz300435,sh603559,sh600528,sz002092,sz000540,sz000957,sh600522,sh600856,sz000980,sh600373,sz300270,sz000657,sz300364,sh600517,sz002915,sz000839,sz002256,sz000099,sz002772,sh603996,sz300101,sz002707%0A (Caused by NewConnectionError('<urllib3.connection.HTTPConnection object at 0x0000026079BBF198>: Failed to establish a new connection: [WinError 10060] 由于连接方在一段时间后没有正确答复或连接的主机没有反应，连接尝试失败。',))

During handling of the above exception, another exception occurred:

Traceback (most recent call last):
  File "D:\ProgramFiles\Anaconda3\lib\site-packages\django-1.11.8-py3.6.egg\django\core\handlers\exception.py", line 41, in inner
    response = get_response(request)
  File "D:\ProgramFiles\Anaconda3\lib\site-packages\django-1.11.8-py3.6.egg\django\core\handlers\base.py", line 249, in _legacy_get_response
    response = self._get_response(request)
  File "D:\ProgramFiles\Anaconda3\lib\site-packages\django-1.11.8-py3.6.egg\django\core\handlers\base.py", line 187, in _get_response
    response = self.process_exception_by_middleware(e, request)
  File "D:\ProgramFiles\Anaconda3\lib\site-packages\django-1.11.8-py3.6.egg\django\core\handlers\base.py", line 185, in _get_response
    response = wrapped_callback(request, *callback_args, **callback_kwargs)
  File "D:\tools\Tools\2018年3月5日\Carry\mysite\views.py", line 536, in zhangting
    zt=ZT.read_code()
  File "D:\tools\Tools\2018年3月5日\Carry\mysite\HSD.py", line 520, in read_code
    html = requests.get('http://qt.gtimg.cn/q=%s' % code).text
  File "D:\ProgramFiles\Anaconda3\lib\site-packages\requests\api.py", line 72, in get
    return request('get', url, params=params, **kwargs)
  File "D:\ProgramFiles\Anaconda3\lib\site-packages\requests\api.py", line 58, in request
    return session.request(method=method, url=url, **kwargs)
  File "D:\ProgramFiles\Anaconda3\lib\site-packages\requests\sessions.py", line 508, in request
    resp = self.send(prep, **send_kwargs)
  File "D:\ProgramFiles\Anaconda3\lib\site-packages\requests\sessions.py", line 618, in send
    r = adapter.send(request, **kwargs)
  File "D:\ProgramFiles\Anaconda3\lib\site-packages\requests\adapters.py", line 508, in send
    raise ConnectionError(e, request=request)
requests.exceptions.ConnectionError: HTTPConnectionPool(host='qt.gtimg.cn', port=80): Max retries exceeded with url: /q=sh600084,sh603843,sh603488,sz300052,sh600729,sz300526,sz300575,sh600279,sh600939,sz300315,sh600138,sh600106,sh600132,sh600917,sh601158,sz300333,sz000506,sh600088,sz000024,sz000758,sz002883,sz000685,sz002511,sh603018,sh603601,sz300684,sh601872,sz002771,sh600633,sh600036,sz000798,sz002317,sh600999,sh601878,sz000906,sh600158,sh601877,sz002197,sz300435,sh603559,sh600528,sz002092,sz000540,sz000957,sh600522,sh600856,sz000980,sh600373,sz300270,sz000657,sz300364,sh600517,sz002915,sz000839,sz002256,sz000099,sz002772,sh603996,sz300101,sz002707%0A (Caused by NewConnectionError('<urllib3.connection.HTTPConnection object at 0x0000026079BBF198>: Failed to establish a new connection: [WinError 10060] 由于连接方在一段时间后没有正确答复或连接的主机没有反应，连接尝试失败。',))
base.py[2018-03-15 13:01:40][WARNING]：Not Found: /favicon.ico
views.py[2018-03-15 13:35:51][ERROR]：Object of type 'datetime' is not JSON serializable
views.py[2018-03-15 13:36:11][ERROR]：Object of type 'datetime' is not JSON serializable
exception.py[2018-03-15 14:00:54][ERROR]：Internal Server Error: /zhangting/tomorrow/
Traceback (most recent call last):
  File "D:\ProgramFiles\Anaconda3\lib\site-packages\django-1.11.8-py3.6.egg\django\core\handlers\exception.py", line 41, in inner
    response = get_response(request)
  File "D:\ProgramFiles\Anaconda3\lib\site-packages\django-1.11.8-py3.6.egg\django\core\handlers\base.py", line 249, in _legacy_get_response
    response = self._get_response(request)
  File "D:\ProgramFiles\Anaconda3\lib\site-packages\django-1.11.8-py3.6.egg\django\core\handlers\base.py", line 187, in _get_response
    response = self.process_exception_by_middleware(e, request)
  File "D:\ProgramFiles\Anaconda3\lib\site-packages\django-1.11.8-py3.6.egg\django\core\handlers\base.py", line 185, in _get_response
    response = wrapped_callback(request, *callback_args, **callback_kwargs)
  File "D:\tools\Tools\2018年3月5日\Carry\mysite\views.py", line 541, in zhangting
    zt_tomorrow = ZT.yanzen()
  File "D:\tools\Tools\2018年3月5日\Carry\mysite\HSD.py", line 579, in yanzen
    r=mx[i].predict([data[code]])[0]
  File "D:\ProgramFiles\Anaconda3\lib\site-packages\sklearn\svm\base.py", line 548, in predict
    y = super(BaseSVC, self).predict(X)
  File "D:\ProgramFiles\Anaconda3\lib\site-packages\sklearn\svm\base.py", line 308, in predict
    X = self._validate_for_predict(X)
  File "D:\ProgramFiles\Anaconda3\lib\site-packages\sklearn\svm\base.py", line 459, in _validate_for_predict
    (n_features, self.shape_fit_[1]))
ValueError: X.shape[1] = 2 should be equal to 18, the number of features at training time
exception.py[2018-03-15 14:03:46][ERROR]：Internal Server Error: /zhangting/tomorrow/
Traceback (most recent call last):
  File "D:\ProgramFiles\Anaconda3\lib\site-packages\django-1.11.8-py3.6.egg\django\core\handlers\exception.py", line 41, in inner
    response = get_response(request)
  File "D:\ProgramFiles\Anaconda3\lib\site-packages\django-1.11.8-py3.6.egg\django\core\handlers\base.py", line 249, in _legacy_get_response
    response = self._get_response(request)
  File "D:\ProgramFiles\Anaconda3\lib\site-packages\django-1.11.8-py3.6.egg\django\core\handlers\base.py", line 187, in _get_response
    response = self.process_exception_by_middleware(e, request)
  File "D:\ProgramFiles\Anaconda3\lib\site-packages\django-1.11.8-py3.6.egg\django\core\handlers\base.py", line 185, in _get_response
    response = wrapped_callback(request, *callback_args, **callback_kwargs)
  File "D:\tools\Tools\2018年3月5日\Carry\mysite\views.py", line 541, in zhangting
    zt_tomorrow = ZT.yanzen()
  File "D:\tools\Tools\2018年3月5日\Carry\mysite\HSD.py", line 579, in yanzen
    r=mx[i].predict([data[code]])
  File "D:\ProgramFiles\Anaconda3\lib\site-packages\sklearn\svm\base.py", line 548, in predict
    y = super(BaseSVC, self).predict(X)
  File "D:\ProgramFiles\Anaconda3\lib\site-packages\sklearn\svm\base.py", line 308, in predict
    X = self._validate_for_predict(X)
  File "D:\ProgramFiles\Anaconda3\lib\site-packages\sklearn\svm\base.py", line 459, in _validate_for_predict
    (n_features, self.shape_fit_[1]))
ValueError: X.shape[1] = 2 should be equal to 18, the number of features at training time
exception.py[2018-03-15 15:22:42][ERROR]：Internal Server Error: /zhangting/tomorrow/
Traceback (most recent call last):
  File "D:\ProgramFiles\Anaconda3\lib\site-packages\django-1.11.8-py3.6.egg\django\core\handlers\exception.py", line 41, in inner
    response = get_response(request)
  File "D:\ProgramFiles\Anaconda3\lib\site-packages\django-1.11.8-py3.6.egg\django\core\handlers\base.py", line 249, in _legacy_get_response
    response = self._get_response(request)
  File "D:\ProgramFiles\Anaconda3\lib\site-packages\django-1.11.8-py3.6.egg\django\core\handlers\base.py", line 187, in _get_response
    response = self.process_exception_by_middleware(e, request)
  File "D:\ProgramFiles\Anaconda3\lib\site-packages\django-1.11.8-py3.6.egg\django\core\handlers\base.py", line 185, in _get_response
    response = wrapped_callback(request, *callback_args, **callback_kwargs)
  File "D:\tools\Tools\2018年3月5日\Carry\mysite\views.py", line 532, in zhangting
    zt_tomorrow = ZT.yanzen()
  File "D:\tools\Tools\2018年3月5日\Carry\mysite\HSD.py", line 565, in yanzen
    jyzt=json.loads(jyzt)
  File "D:\ProgramFiles\Anaconda3\lib\json\__init__.py", line 354, in loads
    return _default_decoder.decode(s)
  File "D:\ProgramFiles\Anaconda3\lib\json\decoder.py", line 339, in decode
    obj, end = self.raw_decode(s, idx=_w(s, 0).end())
  File "D:\ProgramFiles\Anaconda3\lib\json\decoder.py", line 357, in raw_decode
    raise JSONDecodeError("Expecting value", s, err.value) from None
json.decoder.JSONDecodeError: Expecting value: line 1 column 1 (char 0)
base.py[2018-03-16 10:15:16][WARNING]：Not Found: /favicon.ico
base.py[2018-03-16 16:58:14][WARNING]：Not Found: /favicon.ico
base.py[2018-03-19 11:34:42][WARNING]：Not Found: /favicon.ico
base.py[2018-03-20 10:14:38][WARNING]：Not Found: /favicon.ico
