exception.py[2018-07-23 14:46:44][ERROR]：Internal Server Error: /gxjy/
Traceback (most recent call last):
  File "D:\ProgramFiles\Anaconda3\lib\site-packages\django-1.11.8-py3.6.egg\django\core\handlers\exception.py", line 41, in inner
    response = get_response(request)
  File "D:\ProgramFiles\Anaconda3\lib\site-packages\django-1.11.8-py3.6.egg\django\core\handlers\base.py", line 249, in _legacy_get_response
    response = self._get_response(request)
  File "D:\ProgramFiles\Anaconda3\lib\site-packages\django-1.11.8-py3.6.egg\django\core\handlers\base.py", line 187, in _get_response
    response = self.process_exception_by_middleware(e, request)
  File "D:\ProgramFiles\Anaconda3\lib\site-packages\django-1.11.8-py3.6.egg\django\core\handlers\base.py", line 185, in _get_response
    response = wrapped_callback(request, *callback_args, **callback_kwargs)
  File "D:\tools\Tools\Carry\mysite\views.py", line 1249, in gxjy
    ee = h.entry_exit()
  File "D:\tools\Tools\Carry\mysite\HSD.py", line 1451, in entry_exit
    ee = getSqlData(self.conn, sql)
  File "D:\tools\Tools\Carry\mysite\HSD.py", line 147, in getSqlData
    cur.execute(sql)
  File "D:\ProgramFiles\Anaconda3\lib\site-packages\pymysql\cursors.py", line 165, in execute
    result = self._query(query)
  File "D:\ProgramFiles\Anaconda3\lib\site-packages\pymysql\cursors.py", line 321, in _query
    conn.query(q)
  File "D:\ProgramFiles\Anaconda3\lib\site-packages\pymysql\connections.py", line 860, in query
    self._affected_rows = self._read_query_result(unbuffered=unbuffered)
  File "D:\ProgramFiles\Anaconda3\lib\site-packages\pymysql\connections.py", line 1061, in _read_query_result
    result.read()
  File "D:\ProgramFiles\Anaconda3\lib\site-packages\pymysql\connections.py", line 1349, in read
    first_packet = self.connection._read_packet()
  File "D:\ProgramFiles\Anaconda3\lib\site-packages\pymysql\connections.py", line 1018, in _read_packet
    packet.check_error()
  File "D:\ProgramFiles\Anaconda3\lib\site-packages\pymysql\connections.py", line 384, in check_error
    err.raise_mysql_exception(self._data)
  File "D:\ProgramFiles\Anaconda3\lib\site-packages\pymysql\err.py", line 107, in raise_mysql_exception
    raise errorclass(errno, errval)
pymysql.err.ProgrammingError: (1064, '')
exception.py[2018-07-23 14:49:59][ERROR]：Internal Server Error: /gxjy/
Traceback (most recent call last):
  File "D:\ProgramFiles\Anaconda3\lib\site-packages\django-1.11.8-py3.6.egg\django\core\handlers\exception.py", line 41, in inner
    response = get_response(request)
  File "D:\ProgramFiles\Anaconda3\lib\site-packages\django-1.11.8-py3.6.egg\django\core\handlers\base.py", line 249, in _legacy_get_response
    response = self._get_response(request)
  File "D:\ProgramFiles\Anaconda3\lib\site-packages\django-1.11.8-py3.6.egg\django\core\handlers\base.py", line 187, in _get_response
    response = self.process_exception_by_middleware(e, request)
  File "D:\ProgramFiles\Anaconda3\lib\site-packages\django-1.11.8-py3.6.egg\django\core\handlers\base.py", line 185, in _get_response
    response = wrapped_callback(request, *callback_args, **callback_kwargs)
  File "D:\tools\Tools\Carry\mysite\views.py", line 1264, in gxjy
    ind_s = zx_x.index(zx_x2[0])
IndexError: list index out of range
exception.py[2018-07-23 14:50:43][ERROR]：Internal Server Error: /gxjy/
Traceback (most recent call last):
  File "D:\ProgramFiles\Anaconda3\lib\site-packages\django-1.11.8-py3.6.egg\django\core\handlers\exception.py", line 41, in inner
    response = get_response(request)
  File "D:\ProgramFiles\Anaconda3\lib\site-packages\django-1.11.8-py3.6.egg\django\core\handlers\base.py", line 249, in _legacy_get_response
    response = self._get_response(request)
  File "D:\ProgramFiles\Anaconda3\lib\site-packages\django-1.11.8-py3.6.egg\django\core\handlers\base.py", line 187, in _get_response
    response = self.process_exception_by_middleware(e, request)
  File "D:\ProgramFiles\Anaconda3\lib\site-packages\django-1.11.8-py3.6.egg\django\core\handlers\base.py", line 185, in _get_response
    response = wrapped_callback(request, *callback_args, **callback_kwargs)
  File "D:\tools\Tools\Carry\mysite\views.py", line 1264, in gxjy
    ind_s = zx_x.index(zx_x2[0])
IndexError: list index out of range
HSD.py[2018-07-23 16:56:32][ERROR]：文件 HSD.py 第1237行报错：division by zero
HSD.py[2018-07-23 16:58:29][ERROR]：文件 HSD.py 第1237行报错：division by zero
HSD.py[2018-07-23 17:10:20][ERROR]：文件 HSD.py 第1237行报错：division by zero
HSD.py[2018-07-23 17:10:26][ERROR]：文件 HSD.py 第1237行报错：division by zero
exception.py[2018-07-23 17:55:30][ERROR]：Internal Server Error: /gxjy/
Traceback (most recent call last):
  File "D:\ProgramFiles\Anaconda3\lib\site-packages\django-1.11.8-py3.6.egg\django\core\handlers\exception.py", line 41, in inner
    response = get_response(request)
  File "D:\ProgramFiles\Anaconda3\lib\site-packages\django-1.11.8-py3.6.egg\django\core\handlers\base.py", line 249, in _legacy_get_response
    response = self._get_response(request)
  File "D:\ProgramFiles\Anaconda3\lib\site-packages\django-1.11.8-py3.6.egg\django\core\handlers\base.py", line 187, in _get_response
    response = self.process_exception_by_middleware(e, request)
  File "D:\ProgramFiles\Anaconda3\lib\site-packages\django-1.11.8-py3.6.egg\django\core\handlers\base.py", line 185, in _get_response
    response = wrapped_callback(request, *callback_args, **callback_kwargs)
  File "D:\tools\Tools\Carry\mysite\views.py", line 1271, in gxjy
    hc['alljz'].append((init_money+yk-hc['allsxf'])/jzq) if jzq!=0 else 0
TypeError: unsupported operand type(s) for -: 'float' and 'list'
exception.py[2018-07-23 17:56:27][ERROR]：Internal Server Error: /gxjy/
Traceback (most recent call last):
  File "D:\ProgramFiles\Anaconda3\lib\site-packages\django-1.11.8-py3.6.egg\django\core\handlers\exception.py", line 41, in inner
    response = get_response(request)
  File "D:\ProgramFiles\Anaconda3\lib\site-packages\django-1.11.8-py3.6.egg\django\core\handlers\base.py", line 249, in _legacy_get_response
    response = self._get_response(request)
  File "D:\ProgramFiles\Anaconda3\lib\site-packages\django-1.11.8-py3.6.egg\django\core\handlers\base.py", line 187, in _get_response
    response = self.process_exception_by_middleware(e, request)
  File "D:\ProgramFiles\Anaconda3\lib\site-packages\django-1.11.8-py3.6.egg\django\core\handlers\base.py", line 185, in _get_response
    response = wrapped_callback(request, *callback_args, **callback_kwargs)
  File "D:\tools\Tools\Carry\mysite\views.py", line 1271, in gxjy
    hc['alljz'].append((init_money+yk-hc['allsxf'])/jzq if jzq!=0 else 0)
TypeError: unsupported operand type(s) for -: 'float' and 'list'
exception.py[2018-07-23 17:56:57][ERROR]：Internal Server Error: /gxjy/
Traceback (most recent call last):
  File "D:\ProgramFiles\Anaconda3\lib\site-packages\django-1.11.8-py3.6.egg\django\core\handlers\exception.py", line 41, in inner
    response = get_response(request)
  File "D:\ProgramFiles\Anaconda3\lib\site-packages\django-1.11.8-py3.6.egg\django\core\handlers\base.py", line 249, in _legacy_get_response
    response = self._get_response(request)
  File "D:\ProgramFiles\Anaconda3\lib\site-packages\django-1.11.8-py3.6.egg\django\core\handlers\base.py", line 187, in _get_response
    response = self.process_exception_by_middleware(e, request)
  File "D:\ProgramFiles\Anaconda3\lib\site-packages\django-1.11.8-py3.6.egg\django\core\handlers\base.py", line 185, in _get_response
    response = wrapped_callback(request, *callback_args, **callback_kwargs)
  File "D:\tools\Tools\Carry\mysite\views.py", line 1271, in gxjy
    hc['alljz'].append((init_money+yk-hc['allsxf'][-1])/jzq if jzq!=0 else 0)
TypeError: unsupported operand type(s) for -: 'float' and 'list'
exception.py[2018-07-23 17:58:02][ERROR]：Internal Server Error: /gxjy/
Traceback (most recent call last):
  File "D:\ProgramFiles\Anaconda3\lib\site-packages\django-1.11.8-py3.6.egg\django\core\handlers\exception.py", line 41, in inner
    response = get_response(request)
  File "D:\ProgramFiles\Anaconda3\lib\site-packages\django-1.11.8-py3.6.egg\django\core\handlers\base.py", line 249, in _legacy_get_response
    response = self._get_response(request)
  File "D:\ProgramFiles\Anaconda3\lib\site-packages\django-1.11.8-py3.6.egg\django\core\handlers\base.py", line 187, in _get_response
    response = self.process_exception_by_middleware(e, request)
  File "D:\ProgramFiles\Anaconda3\lib\site-packages\django-1.11.8-py3.6.egg\django\core\handlers\base.py", line 185, in _get_response
    response = wrapped_callback(request, *callback_args, **callback_kwargs)
  File "D:\tools\Tools\Carry\mysite\views.py", line 1272, in gxjy
    hc['alljz'].append((init_money+yk-hc['allsxf'][-1])/jzq if jzq!=0 else 0)
TypeError: unsupported operand type(s) for -: 'float' and 'list'
exception.py[2018-07-24 10:54:18][ERROR]：Internal Server Error: /gxjy/
Traceback (most recent call last):
  File "D:\ProgramFiles\Anaconda3\lib\site-packages\django-1.11.8-py3.6.egg\django\core\handlers\exception.py", line 41, in inner
    response = get_response(request)
  File "D:\ProgramFiles\Anaconda3\lib\site-packages\django-1.11.8-py3.6.egg\django\core\handlers\base.py", line 249, in _legacy_get_response
    response = self._get_response(request)
  File "D:\ProgramFiles\Anaconda3\lib\site-packages\django-1.11.8-py3.6.egg\django\core\handlers\base.py", line 187, in _get_response
    response = self.process_exception_by_middleware(e, request)
  File "D:\ProgramFiles\Anaconda3\lib\site-packages\django-1.11.8-py3.6.egg\django\core\handlers\base.py", line 185, in _get_response
    response = wrapped_callback(request, *callback_args, **callback_kwargs)
  File "D:\tools\Tools\Carry\mysite\views.py", line 1267, in gxjy
    hc['allsxf'].append(max(i[18] for i in data if i[1][:10] == de[0] and i[2]==0)+(hc['allsxf'][-1] if hc['allsxf'] else 0))
ValueError: max() arg is an empty sequence
exception.py[2018-07-24 14:20:30][ERROR]：Internal Server Error: /gxjy/
Traceback (most recent call last):
  File "D:\ProgramFiles\Anaconda3\lib\site-packages\django-1.11.8-py3.6.egg\django\core\handlers\exception.py", line 41, in inner
    response = get_response(request)
  File "D:\ProgramFiles\Anaconda3\lib\site-packages\django-1.11.8-py3.6.egg\django\core\handlers\base.py", line 249, in _legacy_get_response
    response = self._get_response(request)
  File "D:\ProgramFiles\Anaconda3\lib\site-packages\django-1.11.8-py3.6.egg\django\core\handlers\base.py", line 187, in _get_response
    response = self.process_exception_by_middleware(e, request)
  File "D:\ProgramFiles\Anaconda3\lib\site-packages\django-1.11.8-py3.6.egg\django\core\handlers\base.py", line 185, in _get_response
    response = wrapped_callback(request, *callback_args, **callback_kwargs)
  File "D:\tools\Tools\Carry\mysite\views.py", line 1247, in gxjy
    data,pzs = h.ray(dd)
  File "D:\tools\Tools\Carry\mysite\HSD.py", line 1635, in ray
    pzs = {self.code_name.get(k):v for k,v in pzs}
  File "D:\tools\Tools\Carry\mysite\HSD.py", line 1635, in <dictcomp>
    pzs = {self.code_name.get(k):v for k,v in pzs}
ValueError: not enough values to unpack (expected 2, got 1)
exception.py[2018-07-24 16:51:48][ERROR]：Internal Server Error: /gxjy/
Traceback (most recent call last):
  File "D:\ProgramFiles\Anaconda3\lib\site-packages\django-1.11.8-py3.6.egg\django\core\handlers\exception.py", line 41, in inner
    response = get_response(request)
  File "D:\ProgramFiles\Anaconda3\lib\site-packages\django-1.11.8-py3.6.egg\django\core\handlers\base.py", line 249, in _legacy_get_response
    response = self._get_response(request)
  File "D:\ProgramFiles\Anaconda3\lib\site-packages\django-1.11.8-py3.6.egg\django\core\handlers\base.py", line 187, in _get_response
    response = self.process_exception_by_middleware(e, request)
  File "D:\ProgramFiles\Anaconda3\lib\site-packages\django-1.11.8-py3.6.egg\django\core\handlers\base.py", line 185, in _get_response
    response = wrapped_callback(request, *callback_args, **callback_kwargs)
  File "D:\tools\Tools\Carry\mysite\views.py", line 1263, in gxjy
    'pie_value': [{'value':i[0],'name':i[1]} for i in pzs.items()], # 饼图的值
AttributeError: 'list' object has no attribute 'items'
exception.py[2018-07-25 09:49:53][ERROR]：Internal Server Error: /gxjy/
Traceback (most recent call last):
  File "D:\ProgramFiles\Anaconda3\lib\site-packages\django-1.11.8-py3.6.egg\django\core\handlers\exception.py", line 41, in inner
    response = get_response(request)
  File "D:\ProgramFiles\Anaconda3\lib\site-packages\django-1.11.8-py3.6.egg\django\core\handlers\base.py", line 249, in _legacy_get_response
    response = self._get_response(request)
  File "D:\ProgramFiles\Anaconda3\lib\site-packages\django-1.11.8-py3.6.egg\django\core\handlers\base.py", line 187, in _get_response
    response = self.process_exception_by_middleware(e, request)
  File "D:\ProgramFiles\Anaconda3\lib\site-packages\django-1.11.8-py3.6.egg\django\core\handlers\base.py", line 185, in _get_response
    response = wrapped_callback(request, *callback_args, **callback_kwargs)
  File "D:\tools\Tools\Carry\mysite\views.py", line 1285, in gxjy
    dd = h.get_gxjy_sql(code) if code else h.get_gxjy_sql()
  File "D:\tools\Tools\Carry\mysite\HSD.py", line 1418, in get_gxjy_sql
    data = getSqlData(self.conn, sql)
  File "D:\tools\Tools\Carry\mysite\HSD.py", line 147, in getSqlData
    cur.execute(sql)
  File "D:\ProgramFiles\Anaconda3\lib\site-packages\pymysql\cursors.py", line 165, in execute
    result = self._query(query)
  File "D:\ProgramFiles\Anaconda3\lib\site-packages\pymysql\cursors.py", line 321, in _query
    conn.query(q)
  File "D:\ProgramFiles\Anaconda3\lib\site-packages\pymysql\connections.py", line 859, in query
    self._execute_command(COMMAND.COM_QUERY, sql)
  File "D:\ProgramFiles\Anaconda3\lib\site-packages\pymysql\connections.py", line 1075, in _execute_command
    raise err.InterfaceError("(0, '')")
pymysql.err.InterfaceError: (0, '')
exception.py[2018-07-25 09:51:18][ERROR]：Internal Server Error: /gxjy/
Traceback (most recent call last):
  File "D:\ProgramFiles\Anaconda3\lib\site-packages\django-1.11.8-py3.6.egg\django\core\handlers\exception.py", line 41, in inner
    response = get_response(request)
  File "D:\ProgramFiles\Anaconda3\lib\site-packages\django-1.11.8-py3.6.egg\django\core\handlers\base.py", line 249, in _legacy_get_response
    response = self._get_response(request)
  File "D:\ProgramFiles\Anaconda3\lib\site-packages\django-1.11.8-py3.6.egg\django\core\handlers\base.py", line 187, in _get_response
    response = self.process_exception_by_middleware(e, request)
  File "D:\ProgramFiles\Anaconda3\lib\site-packages\django-1.11.8-py3.6.egg\django\core\handlers\base.py", line 185, in _get_response
    response = wrapped_callback(request, *callback_args, **callback_kwargs)
  File "D:\tools\Tools\Carry\mysite\views.py", line 1285, in gxjy
    dd = h.get_gxjy_sql()
  File "D:\tools\Tools\Carry\mysite\HSD.py", line 1418, in get_gxjy_sql
    data = getSqlData(self.conn, sql)
  File "D:\tools\Tools\Carry\mysite\HSD.py", line 147, in getSqlData
    cur.execute(sql)
  File "D:\ProgramFiles\Anaconda3\lib\site-packages\pymysql\cursors.py", line 165, in execute
    result = self._query(query)
  File "D:\ProgramFiles\Anaconda3\lib\site-packages\pymysql\cursors.py", line 321, in _query
    conn.query(q)
  File "D:\ProgramFiles\Anaconda3\lib\site-packages\pymysql\connections.py", line 859, in query
    self._execute_command(COMMAND.COM_QUERY, sql)
  File "D:\ProgramFiles\Anaconda3\lib\site-packages\pymysql\connections.py", line 1075, in _execute_command
    raise err.InterfaceError("(0, '')")
pymysql.err.InterfaceError: (0, '')
exception.py[2018-07-25 10:50:06][ERROR]：Internal Server Error: /tj/
Traceback (most recent call last):
  File "D:\ProgramFiles\Anaconda3\lib\site-packages\django-1.11.8-py3.6.egg\django\core\handlers\exception.py", line 41, in inner
    response = get_response(request)
  File "D:\ProgramFiles\Anaconda3\lib\site-packages\django-1.11.8-py3.6.egg\django\core\handlers\base.py", line 249, in _legacy_get_response
    response = self._get_response(request)
  File "D:\ProgramFiles\Anaconda3\lib\site-packages\django-1.11.8-py3.6.egg\django\core\handlers\base.py", line 187, in _get_response
    response = self.process_exception_by_middleware(e, request)
  File "D:\ProgramFiles\Anaconda3\lib\site-packages\django-1.11.8-py3.6.egg\django\core\handlers\base.py", line 185, in _get_response
    response = wrapped_callback(request, *callback_args, **callback_kwargs)
  File "D:\tools\Tools\Carry\mysite\views.py", line 519, in tongji
    results2, huizong = HSD.sp_order_record(rq_date,end_date)
  File "D:\tools\Tools\Carry\mysite\HSD.py", line 480, in sp_order_record
    data = getSqlData(conn, sql_trade)
  File "D:\tools\Tools\Carry\mysite\HSD.py", line 147, in getSqlData
    cur.execute(sql)
  File "D:\ProgramFiles\Anaconda3\lib\site-packages\pymysql\cursors.py", line 165, in execute
    result = self._query(query)
  File "D:\ProgramFiles\Anaconda3\lib\site-packages\pymysql\cursors.py", line 321, in _query
    conn.query(q)
  File "D:\ProgramFiles\Anaconda3\lib\site-packages\pymysql\connections.py", line 860, in query
    self._affected_rows = self._read_query_result(unbuffered=unbuffered)
  File "D:\ProgramFiles\Anaconda3\lib\site-packages\pymysql\connections.py", line 1061, in _read_query_result
    result.read()
  File "D:\ProgramFiles\Anaconda3\lib\site-packages\pymysql\connections.py", line 1349, in read
    first_packet = self.connection._read_packet()
  File "D:\ProgramFiles\Anaconda3\lib\site-packages\pymysql\connections.py", line 1018, in _read_packet
    packet.check_error()
  File "D:\ProgramFiles\Anaconda3\lib\site-packages\pymysql\connections.py", line 384, in check_error
    err.raise_mysql_exception(self._data)
  File "D:\ProgramFiles\Anaconda3\lib\site-packages\pymysql\err.py", line 107, in raise_mysql_exception
    raise errorclass(errno, errval)
pymysql.err.ProgrammingError: (1064, '')
exception.py[2018-07-25 10:50:11][ERROR]：Internal Server Error: /tj/
Traceback (most recent call last):
  File "D:\ProgramFiles\Anaconda3\lib\site-packages\django-1.11.8-py3.6.egg\django\core\handlers\exception.py", line 41, in inner
    response = get_response(request)
  File "D:\ProgramFiles\Anaconda3\lib\site-packages\django-1.11.8-py3.6.egg\django\core\handlers\base.py", line 249, in _legacy_get_response
    response = self._get_response(request)
  File "D:\ProgramFiles\Anaconda3\lib\site-packages\django-1.11.8-py3.6.egg\django\core\handlers\base.py", line 187, in _get_response
    response = self.process_exception_by_middleware(e, request)
  File "D:\ProgramFiles\Anaconda3\lib\site-packages\django-1.11.8-py3.6.egg\django\core\handlers\base.py", line 185, in _get_response
    response = wrapped_callback(request, *callback_args, **callback_kwargs)
  File "D:\tools\Tools\Carry\mysite\views.py", line 519, in tongji
    results2, huizong = HSD.sp_order_record(rq_date,end_date)
  File "D:\tools\Tools\Carry\mysite\HSD.py", line 480, in sp_order_record
    data = getSqlData(conn, sql_trade)
  File "D:\tools\Tools\Carry\mysite\HSD.py", line 147, in getSqlData
    cur.execute(sql)
  File "D:\ProgramFiles\Anaconda3\lib\site-packages\pymysql\cursors.py", line 165, in execute
    result = self._query(query)
  File "D:\ProgramFiles\Anaconda3\lib\site-packages\pymysql\cursors.py", line 321, in _query
    conn.query(q)
  File "D:\ProgramFiles\Anaconda3\lib\site-packages\pymysql\connections.py", line 860, in query
    self._affected_rows = self._read_query_result(unbuffered=unbuffered)
  File "D:\ProgramFiles\Anaconda3\lib\site-packages\pymysql\connections.py", line 1061, in _read_query_result
    result.read()
  File "D:\ProgramFiles\Anaconda3\lib\site-packages\pymysql\connections.py", line 1349, in read
    first_packet = self.connection._read_packet()
  File "D:\ProgramFiles\Anaconda3\lib\site-packages\pymysql\connections.py", line 1018, in _read_packet
    packet.check_error()
  File "D:\ProgramFiles\Anaconda3\lib\site-packages\pymysql\connections.py", line 384, in check_error
    err.raise_mysql_exception(self._data)
  File "D:\ProgramFiles\Anaconda3\lib\site-packages\pymysql\err.py", line 107, in raise_mysql_exception
    raise errorclass(errno, errval)
pymysql.err.ProgrammingError: (1064, '')
exception.py[2018-07-25 10:50:14][ERROR]：Internal Server Error: /tj/
Traceback (most recent call last):
  File "D:\ProgramFiles\Anaconda3\lib\site-packages\django-1.11.8-py3.6.egg\django\core\handlers\exception.py", line 41, in inner
    response = get_response(request)
  File "D:\ProgramFiles\Anaconda3\lib\site-packages\django-1.11.8-py3.6.egg\django\core\handlers\base.py", line 249, in _legacy_get_response
    response = self._get_response(request)
  File "D:\ProgramFiles\Anaconda3\lib\site-packages\django-1.11.8-py3.6.egg\django\core\handlers\base.py", line 187, in _get_response
    response = self.process_exception_by_middleware(e, request)
  File "D:\ProgramFiles\Anaconda3\lib\site-packages\django-1.11.8-py3.6.egg\django\core\handlers\base.py", line 185, in _get_response
    response = wrapped_callback(request, *callback_args, **callback_kwargs)
  File "D:\tools\Tools\Carry\mysite\views.py", line 519, in tongji
    results2, huizong = HSD.sp_order_record(rq_date,end_date)
  File "D:\tools\Tools\Carry\mysite\HSD.py", line 480, in sp_order_record
    data = getSqlData(conn, sql_trade)
  File "D:\tools\Tools\Carry\mysite\HSD.py", line 147, in getSqlData
    cur.execute(sql)
  File "D:\ProgramFiles\Anaconda3\lib\site-packages\pymysql\cursors.py", line 165, in execute
    result = self._query(query)
  File "D:\ProgramFiles\Anaconda3\lib\site-packages\pymysql\cursors.py", line 321, in _query
    conn.query(q)
  File "D:\ProgramFiles\Anaconda3\lib\site-packages\pymysql\connections.py", line 860, in query
    self._affected_rows = self._read_query_result(unbuffered=unbuffered)
  File "D:\ProgramFiles\Anaconda3\lib\site-packages\pymysql\connections.py", line 1061, in _read_query_result
    result.read()
  File "D:\ProgramFiles\Anaconda3\lib\site-packages\pymysql\connections.py", line 1349, in read
    first_packet = self.connection._read_packet()
  File "D:\ProgramFiles\Anaconda3\lib\site-packages\pymysql\connections.py", line 1018, in _read_packet
    packet.check_error()
  File "D:\ProgramFiles\Anaconda3\lib\site-packages\pymysql\connections.py", line 384, in check_error
    err.raise_mysql_exception(self._data)
  File "D:\ProgramFiles\Anaconda3\lib\site-packages\pymysql\err.py", line 107, in raise_mysql_exception
    raise errorclass(errno, errval)
pymysql.err.ProgrammingError: (1064, '')
exception.py[2018-07-25 10:50:18][ERROR]：Internal Server Error: /tj/
Traceback (most recent call last):
  File "D:\ProgramFiles\Anaconda3\lib\site-packages\django-1.11.8-py3.6.egg\django\core\handlers\exception.py", line 41, in inner
    response = get_response(request)
  File "D:\ProgramFiles\Anaconda3\lib\site-packages\django-1.11.8-py3.6.egg\django\core\handlers\base.py", line 249, in _legacy_get_response
    response = self._get_response(request)
  File "D:\ProgramFiles\Anaconda3\lib\site-packages\django-1.11.8-py3.6.egg\django\core\handlers\base.py", line 187, in _get_response
    response = self.process_exception_by_middleware(e, request)
  File "D:\ProgramFiles\Anaconda3\lib\site-packages\django-1.11.8-py3.6.egg\django\core\handlers\base.py", line 185, in _get_response
    response = wrapped_callback(request, *callback_args, **callback_kwargs)
  File "D:\tools\Tools\Carry\mysite\views.py", line 519, in tongji
    results2, huizong = HSD.sp_order_record(rq_date,end_date)
  File "D:\tools\Tools\Carry\mysite\HSD.py", line 480, in sp_order_record
    data = getSqlData(conn, sql_trade)
  File "D:\tools\Tools\Carry\mysite\HSD.py", line 147, in getSqlData
    cur.execute(sql)
  File "D:\ProgramFiles\Anaconda3\lib\site-packages\pymysql\cursors.py", line 165, in execute
    result = self._query(query)
  File "D:\ProgramFiles\Anaconda3\lib\site-packages\pymysql\cursors.py", line 321, in _query
    conn.query(q)
  File "D:\ProgramFiles\Anaconda3\lib\site-packages\pymysql\connections.py", line 860, in query
    self._affected_rows = self._read_query_result(unbuffered=unbuffered)
  File "D:\ProgramFiles\Anaconda3\lib\site-packages\pymysql\connections.py", line 1061, in _read_query_result
    result.read()
  File "D:\ProgramFiles\Anaconda3\lib\site-packages\pymysql\connections.py", line 1349, in read
    first_packet = self.connection._read_packet()
  File "D:\ProgramFiles\Anaconda3\lib\site-packages\pymysql\connections.py", line 1018, in _read_packet
    packet.check_error()
  File "D:\ProgramFiles\Anaconda3\lib\site-packages\pymysql\connections.py", line 384, in check_error
    err.raise_mysql_exception(self._data)
  File "D:\ProgramFiles\Anaconda3\lib\site-packages\pymysql\err.py", line 107, in raise_mysql_exception
    raise errorclass(errno, errval)
pymysql.err.ProgrammingError: (1064, '')
HSD.py[2018-07-25 12:00:58][ERROR]：文件：HSD.py 第1359行报错： (1064, '')
HSD.py[2018-07-25 12:02:05][ERROR]：文件：HSD.py 第1360行报错： (1064, '')
HSD.py[2018-07-25 12:03:05][ERROR]：文件：HSD.py 第1360行报错： (1064, '')
HSD.py[2018-07-25 13:13:53][ERROR]：文件：HSD.py 第1360行报错： (1064, '')
HSD.py[2018-07-25 13:14:21][ERROR]：文件：HSD.py 第1360行报错： (1064, '')
HSD.py[2018-07-25 13:36:14][ERROR]：文件：HSD.py 第1355行报错： list index out of range
exception.py[2018-07-26 14:58:10][ERROR]：Internal Server Error: /gxjy/
Traceback (most recent call last):
  File "D:\ProgramFiles\Anaconda3\lib\site-packages\django-1.11.8-py3.6.egg\django\core\handlers\exception.py", line 41, in inner
    response = get_response(request)
  File "D:\ProgramFiles\Anaconda3\lib\site-packages\django-1.11.8-py3.6.egg\django\core\handlers\base.py", line 249, in _legacy_get_response
    response = self._get_response(request)
  File "D:\ProgramFiles\Anaconda3\lib\site-packages\django-1.11.8-py3.6.egg\django\core\handlers\base.py", line 187, in _get_response
    response = self.process_exception_by_middleware(e, request)
  File "D:\ProgramFiles\Anaconda3\lib\site-packages\django-1.11.8-py3.6.egg\django\core\handlers\base.py", line 185, in _get_response
    response = wrapped_callback(request, *callback_args, **callback_kwargs)
  File "D:\tools\Tools\Carry\mysite\views.py", line 1192, in gxjy
    h = HSD.GXJY()
  File "D:\tools\Tools\Carry\mysite\HSD.py", line 1402, in __init__
    self.conn = get_conn('carry_investment')
  File "D:\tools\Tools\Carry\mysite\HSD.py", line 165, in get_conn
    return SqlSingleton(db=dataName)
  File "D:\tools\Tools\Carry\mysite\HSD.py", line 149, in __init__
    dbs = str(db) + random.randint(0,size)
TypeError: must be str, not int
exception.py[2018-07-26 14:58:43][ERROR]：Internal Server Error: /gxjy/
Traceback (most recent call last):
  File "D:\ProgramFiles\Anaconda3\lib\site-packages\django-1.11.8-py3.6.egg\django\core\handlers\exception.py", line 41, in inner
    response = get_response(request)
  File "D:\ProgramFiles\Anaconda3\lib\site-packages\django-1.11.8-py3.6.egg\django\core\handlers\base.py", line 249, in _legacy_get_response
    response = self._get_response(request)
  File "D:\ProgramFiles\Anaconda3\lib\site-packages\django-1.11.8-py3.6.egg\django\core\handlers\base.py", line 187, in _get_response
    response = self.process_exception_by_middleware(e, request)
  File "D:\ProgramFiles\Anaconda3\lib\site-packages\django-1.11.8-py3.6.egg\django\core\handlers\base.py", line 185, in _get_response
    response = wrapped_callback(request, *callback_args, **callback_kwargs)
  File "D:\tools\Tools\Carry\mysite\views.py", line 1192, in gxjy
    h = HSD.GXJY()
  File "D:\tools\Tools\Carry\mysite\HSD.py", line 1402, in __init__
    self.conn = get_conn('carry_investment')
  File "D:\tools\Tools\Carry\mysite\HSD.py", line 165, in get_conn
    return SqlSingleton(db=dataName)
  File "D:\tools\Tools\Carry\mysite\HSD.py", line 151, in __init__
    if l < self.size or dbs not in self.__conns:
TypeError: '<' not supported between instances of 'int' and 'NoneType'
exception.py[2018-07-26 14:59:18][ERROR]：Internal Server Error: /gxjy/
Traceback (most recent call last):
  File "D:\ProgramFiles\Anaconda3\lib\site-packages\django-1.11.8-py3.6.egg\django\core\handlers\exception.py", line 41, in inner
    response = get_response(request)
  File "D:\ProgramFiles\Anaconda3\lib\site-packages\django-1.11.8-py3.6.egg\django\core\handlers\base.py", line 249, in _legacy_get_response
    response = self._get_response(request)
  File "D:\ProgramFiles\Anaconda3\lib\site-packages\django-1.11.8-py3.6.egg\django\core\handlers\base.py", line 187, in _get_response
    response = self.process_exception_by_middleware(e, request)
  File "D:\ProgramFiles\Anaconda3\lib\site-packages\django-1.11.8-py3.6.egg\django\core\handlers\base.py", line 185, in _get_response
    response = wrapped_callback(request, *callback_args, **callback_kwargs)
  File "D:\tools\Tools\Carry\mysite\views.py", line 1375, in gxjy
    init_data = h.get_gxjy_sql_all(code) if code else h.get_gxjy_sql_all()
  File "D:\tools\Tools\Carry\mysite\HSD.py", line 1471, in get_gxjy_sql_all
    p = getSqlData(self.conn, sql)  # pd.read_sql(sql, conn)
  File "D:\tools\Tools\Carry\mysite\HSD.py", line 175, in getSqlData
    cur = conn.cursor()
TypeError: 'NoneType' object is not callable
exception.py[2018-07-26 15:02:32][ERROR]：Internal Server Error: /gxjy/
Traceback (most recent call last):
  File "D:\ProgramFiles\Anaconda3\lib\site-packages\django-1.11.8-py3.6.egg\django\core\handlers\exception.py", line 41, in inner
    response = get_response(request)
  File "D:\ProgramFiles\Anaconda3\lib\site-packages\django-1.11.8-py3.6.egg\django\core\handlers\base.py", line 249, in _legacy_get_response
    response = self._get_response(request)
  File "D:\ProgramFiles\Anaconda3\lib\site-packages\django-1.11.8-py3.6.egg\django\core\handlers\base.py", line 187, in _get_response
    response = self.process_exception_by_middleware(e, request)
  File "D:\ProgramFiles\Anaconda3\lib\site-packages\django-1.11.8-py3.6.egg\django\core\handlers\base.py", line 185, in _get_response
    response = wrapped_callback(request, *callback_args, **callback_kwargs)
  File "D:\tools\Tools\Carry\mysite\views.py", line 1375, in gxjy
    init_data = h.get_gxjy_sql_all(code) if code else h.get_gxjy_sql_all()
  File "D:\tools\Tools\Carry\mysite\HSD.py", line 1471, in get_gxjy_sql_all
    p = getSqlData(self.conn, sql)  # pd.read_sql(sql, conn)
  File "D:\tools\Tools\Carry\mysite\HSD.py", line 176, in getSqlData
    cur.execute(sql)
  File "D:\ProgramFiles\Anaconda3\lib\site-packages\pymysql\cursors.py", line 165, in execute
    result = self._query(query)
  File "D:\ProgramFiles\Anaconda3\lib\site-packages\pymysql\cursors.py", line 321, in _query
    conn.query(q)
  File "D:\ProgramFiles\Anaconda3\lib\site-packages\pymysql\connections.py", line 859, in query
    self._execute_command(COMMAND.COM_QUERY, sql)
  File "D:\ProgramFiles\Anaconda3\lib\site-packages\pymysql\connections.py", line 1075, in _execute_command
    raise err.InterfaceError("(0, '')")
pymysql.err.InterfaceError: (0, '')
exception.py[2018-07-26 15:02:41][ERROR]：Internal Server Error: /tj/
Traceback (most recent call last):
  File "D:\ProgramFiles\Anaconda3\lib\site-packages\django-1.11.8-py3.6.egg\django\core\handlers\exception.py", line 41, in inner
    response = get_response(request)
  File "D:\ProgramFiles\Anaconda3\lib\site-packages\django-1.11.8-py3.6.egg\django\core\handlers\base.py", line 249, in _legacy_get_response
    response = self._get_response(request)
  File "D:\ProgramFiles\Anaconda3\lib\site-packages\django-1.11.8-py3.6.egg\django\core\handlers\base.py", line 187, in _get_response
    response = self.process_exception_by_middleware(e, request)
  File "D:\ProgramFiles\Anaconda3\lib\site-packages\django-1.11.8-py3.6.egg\django\core\handlers\base.py", line 185, in _get_response
    response = wrapped_callback(request, *callback_args, **callback_kwargs)
  File "D:\tools\Tools\Carry\mysite\views.py", line 458, in tongji
    id_name = HSD.get_idName()
  File "D:\tools\Tools\Carry\mysite\HSD.py", line 401, in get_idName
    id_name = getSqlData(conn, sql)
  File "D:\tools\Tools\Carry\mysite\HSD.py", line 176, in getSqlData
    cur.execute(sql)
  File "D:\ProgramFiles\Anaconda3\lib\site-packages\pymysql\cursors.py", line 165, in execute
    result = self._query(query)
  File "D:\ProgramFiles\Anaconda3\lib\site-packages\pymysql\cursors.py", line 321, in _query
    conn.query(q)
  File "D:\ProgramFiles\Anaconda3\lib\site-packages\pymysql\connections.py", line 859, in query
    self._execute_command(COMMAND.COM_QUERY, sql)
  File "D:\ProgramFiles\Anaconda3\lib\site-packages\pymysql\connections.py", line 1075, in _execute_command
    raise err.InterfaceError("(0, '')")
pymysql.err.InterfaceError: (0, '')
exception.py[2018-07-26 15:03:08][ERROR]：Internal Server Error: /tj/
Traceback (most recent call last):
  File "D:\ProgramFiles\Anaconda3\lib\site-packages\django-1.11.8-py3.6.egg\django\core\handlers\exception.py", line 41, in inner
    response = get_response(request)
  File "D:\ProgramFiles\Anaconda3\lib\site-packages\django-1.11.8-py3.6.egg\django\core\handlers\base.py", line 249, in _legacy_get_response
    response = self._get_response(request)
  File "D:\ProgramFiles\Anaconda3\lib\site-packages\django-1.11.8-py3.6.egg\django\core\handlers\base.py", line 187, in _get_response
    response = self.process_exception_by_middleware(e, request)
  File "D:\ProgramFiles\Anaconda3\lib\site-packages\django-1.11.8-py3.6.egg\django\core\handlers\base.py", line 185, in _get_response
    response = wrapped_callback(request, *callback_args, **callback_kwargs)
  File "D:\tools\Tools\Carry\mysite\views.py", line 578, in tongji
    result9 = HSD.order_detail(rq_date, end_date)
  File "D:\tools\Tools\Carry\mysite\HSD.py", line 432, in order_detail
    data = getSqlData(conn, sql)
  File "D:\tools\Tools\Carry\mysite\HSD.py", line 176, in getSqlData
    cur.execute(sql)
  File "D:\ProgramFiles\Anaconda3\lib\site-packages\pymysql\cursors.py", line 165, in execute
    result = self._query(query)
  File "D:\ProgramFiles\Anaconda3\lib\site-packages\pymysql\cursors.py", line 321, in _query
    conn.query(q)
  File "D:\ProgramFiles\Anaconda3\lib\site-packages\pymysql\connections.py", line 859, in query
    self._execute_command(COMMAND.COM_QUERY, sql)
  File "D:\ProgramFiles\Anaconda3\lib\site-packages\pymysql\connections.py", line 1075, in _execute_command
    raise err.InterfaceError("(0, '')")
pymysql.err.InterfaceError: (0, '')
exception.py[2018-07-26 15:35:45][ERROR]：Internal Server Error: /gxjy/
Traceback (most recent call last):
  File "D:\ProgramFiles\Anaconda3\lib\site-packages\django-1.11.8-py3.6.egg\django\core\handlers\exception.py", line 41, in inner
    response = get_response(request)
  File "D:\ProgramFiles\Anaconda3\lib\site-packages\django-1.11.8-py3.6.egg\django\core\handlers\base.py", line 249, in _legacy_get_response
    response = self._get_response(request)
  File "D:\ProgramFiles\Anaconda3\lib\site-packages\django-1.11.8-py3.6.egg\django\core\handlers\base.py", line 187, in _get_response
    response = self.process_exception_by_middleware(e, request)
  File "D:\ProgramFiles\Anaconda3\lib\site-packages\django-1.11.8-py3.6.egg\django\core\handlers\base.py", line 185, in _get_response
    response = wrapped_callback(request, *callback_args, **callback_kwargs)
  File "D:\tools\Tools\Carry\mysite\views.py", line 1283, in gxjy
    print(dates[xh+1][0][:7])
IndexError: tuple index out of range
exception.py[2018-07-26 16:50:11][ERROR]：Internal Server Error: /gxjy/
Traceback (most recent call last):
  File "D:\ProgramFiles\Anaconda3\lib\site-packages\django-1.11.8-py3.6.egg\django\core\handlers\exception.py", line 41, in inner
    response = get_response(request)
  File "D:\ProgramFiles\Anaconda3\lib\site-packages\django-1.11.8-py3.6.egg\django\core\handlers\base.py", line 249, in _legacy_get_response
    response = self._get_response(request)
  File "D:\ProgramFiles\Anaconda3\lib\site-packages\django-1.11.8-py3.6.egg\django\core\handlers\base.py", line 187, in _get_response
    response = self.process_exception_by_middleware(e, request)
  File "D:\ProgramFiles\Anaconda3\lib\site-packages\django-1.11.8-py3.6.egg\django\core\handlers\base.py", line 185, in _get_response
    response = wrapped_callback(request, *callback_args, **callback_kwargs)
  File "D:\tools\Tools\Carry\mysite\views.py", line 1298, in gxjy
    f_date2 = datetime.datetime.strptime(dates[xh + 1][0], '%Y-%m-%d')
IndexError: tuple index out of range
exception.py[2018-07-26 17:24:44][ERROR]：Internal Server Error: /gxjy/
Traceback (most recent call last):
  File "D:\ProgramFiles\Anaconda3\lib\site-packages\django-1.11.8-py3.6.egg\django\core\handlers\exception.py", line 41, in inner
    response = get_response(request)
  File "D:\ProgramFiles\Anaconda3\lib\site-packages\django-1.11.8-py3.6.egg\django\core\handlers\base.py", line 249, in _legacy_get_response
    response = self._get_response(request)
  File "D:\ProgramFiles\Anaconda3\lib\site-packages\django-1.11.8-py3.6.egg\django\core\handlers\base.py", line 187, in _get_response
    response = self.process_exception_by_middleware(e, request)
  File "D:\ProgramFiles\Anaconda3\lib\site-packages\django-1.11.8-py3.6.egg\django\core\handlers\base.py", line 185, in _get_response
    response = wrapped_callback(request, *callback_args, **callback_kwargs)
  File "D:\tools\Tools\Carry\mysite\views.py", line 1280, in gxjy
    week = str(week[0])+'-'+str(week[1]) # 星期
UnboundLocalError: local variable 'week' referenced before assignment
exception.py[2018-07-26 17:25:57][ERROR]：Internal Server Error: /gxjy/
Traceback (most recent call last):
  File "D:\ProgramFiles\Anaconda3\lib\site-packages\django-1.11.8-py3.6.egg\django\core\handlers\exception.py", line 41, in inner
    response = get_response(request)
  File "D:\ProgramFiles\Anaconda3\lib\site-packages\django-1.11.8-py3.6.egg\django\core\handlers\base.py", line 249, in _legacy_get_response
    response = self._get_response(request)
  File "D:\ProgramFiles\Anaconda3\lib\site-packages\django-1.11.8-py3.6.egg\django\core\handlers\base.py", line 187, in _get_response
    response = self.process_exception_by_middleware(e, request)
  File "D:\ProgramFiles\Anaconda3\lib\site-packages\django-1.11.8-py3.6.egg\django\core\handlers\base.py", line 185, in _get_response
    response = wrapped_callback(request, *callback_args, **callback_kwargs)
  File "D:\tools\Tools\Carry\mysite\views.py", line 1280, in gxjy
    week = f_date.isocalendar()[:2]
AttributeError: 'tuple' object has no attribute 'isocalendar'
exception.py[2018-07-26 17:30:08][ERROR]：Internal Server Error: /gxjy/
Traceback (most recent call last):
  File "D:\ProgramFiles\Anaconda3\lib\site-packages\django-1.11.8-py3.6.egg\django\core\handlers\exception.py", line 41, in inner
    response = get_response(request)
  File "D:\ProgramFiles\Anaconda3\lib\site-packages\django-1.11.8-py3.6.egg\django\core\handlers\base.py", line 249, in _legacy_get_response
    response = self._get_response(request)
  File "D:\ProgramFiles\Anaconda3\lib\site-packages\django-1.11.8-py3.6.egg\django\core\handlers\base.py", line 187, in _get_response
    response = self.process_exception_by_middleware(e, request)
  File "D:\ProgramFiles\Anaconda3\lib\site-packages\django-1.11.8-py3.6.egg\django\core\handlers\base.py", line 185, in _get_response
    response = wrapped_callback(request, *callback_args, **callback_kwargs)
  File "D:\tools\Tools\Carry\mysite\views.py", line 1346, in gxjy
    week_jlr = {k:v for k,v in week_jlr if v!=0}
  File "D:\tools\Tools\Carry\mysite\views.py", line 1346, in <dictcomp>
    week_jlr = {k:v for k,v in week_jlr if v!=0}
ValueError: too many values to unpack (expected 2)
exception.py[2018-07-26 17:39:31][ERROR]：Internal Server Error: /gxjy/
Traceback (most recent call last):
  File "D:\ProgramFiles\Anaconda3\lib\site-packages\django-1.11.8-py3.6.egg\django\core\handlers\exception.py", line 41, in inner
    response = get_response(request)
  File "D:\ProgramFiles\Anaconda3\lib\site-packages\django-1.11.8-py3.6.egg\django\core\handlers\base.py", line 249, in _legacy_get_response
    response = self._get_response(request)
  File "D:\ProgramFiles\Anaconda3\lib\site-packages\django-1.11.8-py3.6.egg\django\core\handlers\base.py", line 187, in _get_response
    response = self.process_exception_by_middleware(e, request)
  File "D:\ProgramFiles\Anaconda3\lib\site-packages\django-1.11.8-py3.6.egg\django\core\handlers\base.py", line 185, in _get_response
    response = wrapped_callback(request, *callback_args, **callback_kwargs)
  File "D:\tools\Tools\Carry\mysite\views.py", line 1338, in gxjy
    zx_x2 = [i for i in zx_x if start_date<=i<=end_date]
  File "D:\tools\Tools\Carry\mysite\views.py", line 1338, in <listcomp>
    zx_x2 = [i for i in zx_x if start_date<=i<=end_date]
TypeError: '<=' not supported between instances of 'NoneType' and 'str'
exception.py[2018-07-27 14:06:03][ERROR]：Internal Server Error: /hckx/
Traceback (most recent call last):
  File "D:\ProgramFiles\Anaconda3\lib\site-packages\django-1.11.8-py3.6.egg\django\core\handlers\exception.py", line 41, in inner
    response = get_response(request)
  File "D:\ProgramFiles\Anaconda3\lib\site-packages\django-1.11.8-py3.6.egg\django\core\handlers\base.py", line 249, in _legacy_get_response
    response = self._get_response(request)
  File "D:\ProgramFiles\Anaconda3\lib\site-packages\django-1.11.8-py3.6.egg\django\core\handlers\base.py", line 187, in _get_response
    response = self.process_exception_by_middleware(e, request)
  File "D:\ProgramFiles\Anaconda3\lib\site-packages\django-1.11.8-py3.6.egg\django\core\handlers\base.py", line 185, in _get_response
    response = wrapped_callback(request, *callback_args, **callback_kwargs)
  File "D:\tools\Tools\Carry\mysite\views.py", line 1394, in hckx
    return render(rq,'hckx.html')
  File "D:\ProgramFiles\Anaconda3\lib\site-packages\django-1.11.8-py3.6.egg\django\shortcuts.py", line 30, in render
    content = loader.render_to_string(template_name, context, request, using=using)
  File "D:\ProgramFiles\Anaconda3\lib\site-packages\django-1.11.8-py3.6.egg\django\template\loader.py", line 67, in render_to_string
    template = get_template(template_name, using=using)
  File "D:\ProgramFiles\Anaconda3\lib\site-packages\django-1.11.8-py3.6.egg\django\template\loader.py", line 25, in get_template
    raise TemplateDoesNotExist(template_name, chain=chain)
django.template.exceptions.TemplateDoesNotExist: hckx.html
