exception.py[2018-10-09 09:56:10][ERROR]：Internal Server Error: /upload/complete/
Traceback (most recent call last):
  File "D:\ProgramFiles\Anaconda3\lib\site-packages\django-1.11.8-py3.6.egg\django\core\handlers\exception.py", line 41, in inner
    response = get_response(request)
  File "D:\ProgramFiles\Anaconda3\lib\site-packages\django-1.11.8-py3.6.egg\django\core\handlers\base.py", line 249, in _legacy_get_response
    response = self._get_response(request)
  File "D:\ProgramFiles\Anaconda3\lib\site-packages\django-1.11.8-py3.6.egg\django\core\handlers\base.py", line 187, in _get_response
    response = self.process_exception_by_middleware(e, request)
  File "D:\ProgramFiles\Anaconda3\lib\site-packages\django-1.11.8-py3.6.egg\django\core\handlers\base.py", line 185, in _get_response
    response = wrapped_callback(request, *callback_args, **callback_kwargs)
  File "D:\ProgramFiles\Anaconda3\lib\site-packages\django-1.11.8-py3.6.egg\django\views\decorators\csrf.py", line 58, in wrapped_view
    return view_func(*args, **kwargs)
  File "D:\tools\Tools\Carry\mysite\views.py", line 813, in fileMerge
    file_size = upload_file.size / 1024 / 1024
AttributeError: 'str' object has no attribute 'size'
base.py[2018-10-09 10:02:24][WARNING]：Not Found: /favicon.ico
exception.py[2018-10-09 10:02:28][ERROR]：Internal Server Error: /files/upload/
Traceback (most recent call last):
  File "D:\ProgramFiles\Anaconda3\lib\site-packages\django-1.11.8-py3.6.egg\django\core\handlers\exception.py", line 41, in inner
    response = get_response(request)
  File "D:\ProgramFiles\Anaconda3\lib\site-packages\django-1.11.8-py3.6.egg\django\core\handlers\base.py", line 249, in _legacy_get_response
    response = self._get_response(request)
  File "D:\ProgramFiles\Anaconda3\lib\site-packages\django-1.11.8-py3.6.egg\django\core\handlers\base.py", line 187, in _get_response
    response = self.process_exception_by_middleware(e, request)
  File "D:\ProgramFiles\Anaconda3\lib\site-packages\django-1.11.8-py3.6.egg\django\core\handlers\base.py", line 185, in _get_response
    response = wrapped_callback(request, *callback_args, **callback_kwargs)
  File "D:\ProgramFiles\Anaconda3\lib\site-packages\django-1.11.8-py3.6.egg\django\views\decorators\csrf.py", line 58, in wrapped_view
    return view_func(*args, **kwargs)
  File "D:\tools\Tools\Carry\mysite\views.py", line 811, in fileupload
    {'qx': qx, 'msg': msg, 'clouds': clouds, 'user_name': user_name})
UnboundLocalError: local variable 'msg' referenced before assignment
exception.py[2018-10-09 10:08:23][ERROR]：Internal Server Error: /files/upload/
Traceback (most recent call last):
  File "D:\ProgramFiles\Anaconda3\lib\site-packages\django-1.11.8-py3.6.egg\django\core\handlers\exception.py", line 41, in inner
    response = get_response(request)
  File "D:\ProgramFiles\Anaconda3\lib\site-packages\django-1.11.8-py3.6.egg\django\core\handlers\base.py", line 249, in _legacy_get_response
    response = self._get_response(request)
  File "D:\ProgramFiles\Anaconda3\lib\site-packages\django-1.11.8-py3.6.egg\django\core\handlers\base.py", line 198, in _get_response
    "returned None instead." % (callback.__module__, view_name)
ValueError: The view mysite.views.fileupload didn't return an HttpResponse object. It returned None instead.
exception.py[2018-10-09 10:41:59][ERROR]：Internal Server Error: /files/upload/
Traceback (most recent call last):
  File "D:\ProgramFiles\Anaconda3\lib\site-packages\django-1.11.8-py3.6.egg\django\core\handlers\exception.py", line 41, in inner
    response = get_response(request)
  File "D:\ProgramFiles\Anaconda3\lib\site-packages\django-1.11.8-py3.6.egg\django\core\handlers\base.py", line 249, in _legacy_get_response
    response = self._get_response(request)
  File "D:\ProgramFiles\Anaconda3\lib\site-packages\django-1.11.8-py3.6.egg\django\core\handlers\base.py", line 187, in _get_response
    response = self.process_exception_by_middleware(e, request)
  File "D:\ProgramFiles\Anaconda3\lib\site-packages\django-1.11.8-py3.6.egg\django\core\handlers\base.py", line 185, in _get_response
    response = wrapped_callback(request, *callback_args, **callback_kwargs)
  File "D:\ProgramFiles\Anaconda3\lib\site-packages\django-1.11.8-py3.6.egg\django\views\decorators\csrf.py", line 58, in wrapped_view
    return view_func(*args, **kwargs)
  File "D:\tools\Tools\Carry\mysite\views.py", line 799, in fileupload
    if folder_size + file_size > 10240:  # 限制整个目录最大装10G
AttributeError: module 'mysite.HSD' has no attribute 'get_dirs'
exception.py[2018-10-09 10:41:59][ERROR]：Internal Server Error: /files/upload/
Traceback (most recent call last):
  File "D:\ProgramFiles\Anaconda3\lib\site-packages\django-1.11.8-py3.6.egg\django\core\handlers\exception.py", line 41, in inner
    response = get_response(request)
  File "D:\ProgramFiles\Anaconda3\lib\site-packages\django-1.11.8-py3.6.egg\django\core\handlers\base.py", line 249, in _legacy_get_response
    response = self._get_response(request)
  File "D:\ProgramFiles\Anaconda3\lib\site-packages\django-1.11.8-py3.6.egg\django\core\handlers\base.py", line 187, in _get_response
    response = self.process_exception_by_middleware(e, request)
  File "D:\ProgramFiles\Anaconda3\lib\site-packages\django-1.11.8-py3.6.egg\django\core\handlers\base.py", line 185, in _get_response
    response = wrapped_callback(request, *callback_args, **callback_kwargs)
  File "D:\ProgramFiles\Anaconda3\lib\site-packages\django-1.11.8-py3.6.egg\django\views\decorators\csrf.py", line 58, in wrapped_view
    return view_func(*args, **kwargs)
  File "D:\tools\Tools\Carry\mysite\views.py", line 799, in fileupload
    if folder_size + file_size > 10240:  # 限制整个目录最大装10G
AttributeError: module 'mysite.HSD' has no attribute 'get_dirs'
exception.py[2018-10-09 10:42:00][ERROR]：Internal Server Error: /files/upload/
Traceback (most recent call last):
  File "D:\ProgramFiles\Anaconda3\lib\site-packages\django-1.11.8-py3.6.egg\django\core\handlers\exception.py", line 41, in inner
    response = get_response(request)
  File "D:\ProgramFiles\Anaconda3\lib\site-packages\django-1.11.8-py3.6.egg\django\core\handlers\base.py", line 249, in _legacy_get_response
    response = self._get_response(request)
  File "D:\ProgramFiles\Anaconda3\lib\site-packages\django-1.11.8-py3.6.egg\django\core\handlers\base.py", line 187, in _get_response
    response = self.process_exception_by_middleware(e, request)
  File "D:\ProgramFiles\Anaconda3\lib\site-packages\django-1.11.8-py3.6.egg\django\core\handlers\base.py", line 185, in _get_response
    response = wrapped_callback(request, *callback_args, **callback_kwargs)
  File "D:\ProgramFiles\Anaconda3\lib\site-packages\django-1.11.8-py3.6.egg\django\views\decorators\csrf.py", line 58, in wrapped_view
    return view_func(*args, **kwargs)
  File "D:\tools\Tools\Carry\mysite\views.py", line 799, in fileupload
    if folder_size + file_size > 10240:  # 限制整个目录最大装10G
AttributeError: module 'mysite.HSD' has no attribute 'get_dirs'
exception.py[2018-10-09 10:42:00][ERROR]：Internal Server Error: /files/upload/
Traceback (most recent call last):
  File "D:\ProgramFiles\Anaconda3\lib\site-packages\django-1.11.8-py3.6.egg\django\core\handlers\exception.py", line 41, in inner
    response = get_response(request)
  File "D:\ProgramFiles\Anaconda3\lib\site-packages\django-1.11.8-py3.6.egg\django\core\handlers\base.py", line 249, in _legacy_get_response
    response = self._get_response(request)
  File "D:\ProgramFiles\Anaconda3\lib\site-packages\django-1.11.8-py3.6.egg\django\core\handlers\base.py", line 187, in _get_response
    response = self.process_exception_by_middleware(e, request)
  File "D:\ProgramFiles\Anaconda3\lib\site-packages\django-1.11.8-py3.6.egg\django\core\handlers\base.py", line 185, in _get_response
    response = wrapped_callback(request, *callback_args, **callback_kwargs)
  File "D:\ProgramFiles\Anaconda3\lib\site-packages\django-1.11.8-py3.6.egg\django\views\decorators\csrf.py", line 58, in wrapped_view
    return view_func(*args, **kwargs)
  File "D:\tools\Tools\Carry\mysite\views.py", line 799, in fileupload
    if folder_size + file_size > 10240:  # 限制整个目录最大装10G
AttributeError: module 'mysite.HSD' has no attribute 'get_dirs'
exception.py[2018-10-09 10:42:01][ERROR]：Internal Server Error: /files/upload/
Traceback (most recent call last):
  File "D:\ProgramFiles\Anaconda3\lib\site-packages\django-1.11.8-py3.6.egg\django\core\handlers\exception.py", line 41, in inner
    response = get_response(request)
  File "D:\ProgramFiles\Anaconda3\lib\site-packages\django-1.11.8-py3.6.egg\django\core\handlers\base.py", line 249, in _legacy_get_response
    response = self._get_response(request)
  File "D:\ProgramFiles\Anaconda3\lib\site-packages\django-1.11.8-py3.6.egg\django\core\handlers\base.py", line 187, in _get_response
    response = self.process_exception_by_middleware(e, request)
  File "D:\ProgramFiles\Anaconda3\lib\site-packages\django-1.11.8-py3.6.egg\django\core\handlers\base.py", line 185, in _get_response
    response = wrapped_callback(request, *callback_args, **callback_kwargs)
  File "D:\ProgramFiles\Anaconda3\lib\site-packages\django-1.11.8-py3.6.egg\django\views\decorators\csrf.py", line 58, in wrapped_view
    return view_func(*args, **kwargs)
  File "D:\tools\Tools\Carry\mysite\views.py", line 799, in fileupload
    if folder_size + file_size > 10240:  # 限制整个目录最大装10G
AttributeError: module 'mysite.HSD' has no attribute 'get_dirs'
exception.py[2018-10-09 10:42:01][ERROR]：Internal Server Error: /files/upload/
Traceback (most recent call last):
  File "D:\ProgramFiles\Anaconda3\lib\site-packages\django-1.11.8-py3.6.egg\django\core\handlers\exception.py", line 41, in inner
    response = get_response(request)
  File "D:\ProgramFiles\Anaconda3\lib\site-packages\django-1.11.8-py3.6.egg\django\core\handlers\base.py", line 249, in _legacy_get_response
    response = self._get_response(request)
  File "D:\ProgramFiles\Anaconda3\lib\site-packages\django-1.11.8-py3.6.egg\django\core\handlers\base.py", line 187, in _get_response
    response = self.process_exception_by_middleware(e, request)
  File "D:\ProgramFiles\Anaconda3\lib\site-packages\django-1.11.8-py3.6.egg\django\core\handlers\base.py", line 185, in _get_response
    response = wrapped_callback(request, *callback_args, **callback_kwargs)
  File "D:\ProgramFiles\Anaconda3\lib\site-packages\django-1.11.8-py3.6.egg\django\views\decorators\csrf.py", line 58, in wrapped_view
    return view_func(*args, **kwargs)
  File "D:\tools\Tools\Carry\mysite\views.py", line 799, in fileupload
    if folder_size + file_size > 10240:  # 限制整个目录最大装10G
AttributeError: module 'mysite.HSD' has no attribute 'get_dirs'
exception.py[2018-10-09 10:42:01][ERROR]：Internal Server Error: /files/upload/
Traceback (most recent call last):
  File "D:\ProgramFiles\Anaconda3\lib\site-packages\django-1.11.8-py3.6.egg\django\core\handlers\exception.py", line 41, in inner
    response = get_response(request)
  File "D:\ProgramFiles\Anaconda3\lib\site-packages\django-1.11.8-py3.6.egg\django\core\handlers\base.py", line 249, in _legacy_get_response
    response = self._get_response(request)
  File "D:\ProgramFiles\Anaconda3\lib\site-packages\django-1.11.8-py3.6.egg\django\core\handlers\base.py", line 187, in _get_response
    response = self.process_exception_by_middleware(e, request)
  File "D:\ProgramFiles\Anaconda3\lib\site-packages\django-1.11.8-py3.6.egg\django\core\handlers\base.py", line 185, in _get_response
    response = wrapped_callback(request, *callback_args, **callback_kwargs)
  File "D:\ProgramFiles\Anaconda3\lib\site-packages\django-1.11.8-py3.6.egg\django\views\decorators\csrf.py", line 58, in wrapped_view
    return view_func(*args, **kwargs)
  File "D:\tools\Tools\Carry\mysite\views.py", line 799, in fileupload
    if folder_size + file_size > 10240:  # 限制整个目录最大装10G
AttributeError: module 'mysite.HSD' has no attribute 'get_dirs'
exception.py[2018-10-09 11:10:16][ERROR]：Internal Server Error: /user/cloud/public/delete
Traceback (most recent call last):
  File "D:\ProgramFiles\Anaconda3\lib\site-packages\django-1.11.8-py3.6.egg\django\core\handlers\exception.py", line 41, in inner
    response = get_response(request)
  File "D:\ProgramFiles\Anaconda3\lib\site-packages\django-1.11.8-py3.6.egg\django\core\handlers\base.py", line 249, in _legacy_get_response
    response = self._get_response(request)
  File "D:\ProgramFiles\Anaconda3\lib\site-packages\django-1.11.8-py3.6.egg\django\core\handlers\base.py", line 187, in _get_response
    response = self.process_exception_by_middleware(e, request)
  File "D:\ProgramFiles\Anaconda3\lib\site-packages\django-1.11.8-py3.6.egg\django\core\handlers\base.py", line 185, in _get_response
    response = wrapped_callback(request, *callback_args, **callback_kwargs)
  File "D:\tools\Tools\Carry\mysite\views.py", line 866, in user_cloud_public_delete
    os.remove(path_file)
PermissionError: [WinError 32] 另一个程序正在使用此文件，进程无法访问。: 'D:\\cloud\\黄海军_+_Anaconda3-5.0.1-Windows-x86_64.exe'
exception.py[2018-10-09 11:26:55][ERROR]：Internal Server Error: /files/upload/
Traceback (most recent call last):
  File "D:\ProgramFiles\Anaconda3\lib\site-packages\django-1.11.8-py3.6.egg\django\core\handlers\exception.py", line 41, in inner
    response = get_response(request)
  File "D:\ProgramFiles\Anaconda3\lib\site-packages\django-1.11.8-py3.6.egg\django\core\handlers\base.py", line 249, in _legacy_get_response
    response = self._get_response(request)
  File "D:\ProgramFiles\Anaconda3\lib\site-packages\django-1.11.8-py3.6.egg\django\core\handlers\base.py", line 198, in _get_response
    "returned None instead." % (callback.__module__, view_name)
ValueError: The view mysite.views.fileupload didn't return an HttpResponse object. It returned None instead.
exception.py[2018-10-09 11:27:40][ERROR]：Internal Server Error: /files/upload/
Traceback (most recent call last):
  File "D:\ProgramFiles\Anaconda3\lib\site-packages\django-1.11.8-py3.6.egg\django\core\handlers\base.py", line 131, in get_response
    response = middleware_method(request, response)
  File "D:\ProgramFiles\Anaconda3\lib\site-packages\django-1.11.8-py3.6.egg\django\middleware\clickjacking.py", line 32, in process_response
    if response.get('X-Frame-Options') is not None:
AttributeError: 'str' object has no attribute 'get'
exception.py[2018-10-09 11:35:28][ERROR]：Internal Server Error: /files/upload/
Traceback (most recent call last):
  File "D:\ProgramFiles\Anaconda3\lib\site-packages\django-1.11.8-py3.6.egg\django\core\handlers\base.py", line 131, in get_response
    response = middleware_method(request, response)
  File "D:\ProgramFiles\Anaconda3\lib\site-packages\django-1.11.8-py3.6.egg\django\middleware\clickjacking.py", line 32, in process_response
    if response.get('X-Frame-Options') is not None:
AttributeError: type object 'Http404' has no attribute 'get'
exception.py[2018-10-09 11:35:55][ERROR]：Internal Server Error: /files/upload/
Traceback (most recent call last):
  File "D:\ProgramFiles\Anaconda3\lib\site-packages\django-1.11.8-py3.6.egg\django\core\handlers\base.py", line 131, in get_response
    response = middleware_method(request, response)
  File "D:\ProgramFiles\Anaconda3\lib\site-packages\django-1.11.8-py3.6.egg\django\middleware\clickjacking.py", line 32, in process_response
    if response.get('X-Frame-Options') is not None:
AttributeError: 'Http404' object has no attribute 'get'
exception.py[2018-10-09 11:37:35][ERROR]：Internal Server Error: /files/upload/
Traceback (most recent call last):
  File "D:\ProgramFiles\Anaconda3\lib\site-packages\django-1.11.8-py3.6.egg\django\core\handlers\base.py", line 131, in get_response
    response = middleware_method(request, response)
  File "D:\ProgramFiles\Anaconda3\lib\site-packages\django-1.11.8-py3.6.egg\django\middleware\clickjacking.py", line 32, in process_response
    if response.get('X-Frame-Options') is not None:
AttributeError: 'Http404' object has no attribute 'get'
base.py[2018-10-09 11:38:21][WARNING]：Not Found: /files/upload/
base.py[2018-10-09 11:39:03][WARNING]：Not Found: /files/upload/
base.py[2018-10-09 11:39:28][WARNING]：Not Found: /files/upload/
base.py[2018-10-09 11:39:50][WARNING]：Not Found: /files/upload/
base.py[2018-10-09 11:40:23][WARNING]：Not Found: /files/upload/
base.py[2018-10-09 11:40:44][WARNING]：Not Found: /files/upload/
base.py[2018-10-09 11:43:36][WARNING]：Not Found: /files/upload/
base.py[2018-10-09 11:43:36][WARNING]：Not Found: /files/upload/
base.py[2018-10-09 11:43:37][WARNING]：Not Found: /files/upload/
base.py[2018-10-09 11:43:37][WARNING]：Not Found: /files/upload/
base.py[2018-10-09 11:43:37][WARNING]：Not Found: /files/upload/
base.py[2018-10-09 11:43:37][WARNING]：Not Found: /files/upload/
base.py[2018-10-09 11:43:38][WARNING]：Not Found: /files/upload/
base.py[2018-10-09 11:43:38][WARNING]：Not Found: /files/upload/
exception.py[2018-10-09 11:44:22][ERROR]：Internal Server Error: /files/upload/
Traceback (most recent call last):
  File "D:\ProgramFiles\Anaconda3\lib\site-packages\django-1.11.8-py3.6.egg\django\core\handlers\exception.py", line 41, in inner
    response = get_response(request)
  File "D:\ProgramFiles\Anaconda3\lib\site-packages\django-1.11.8-py3.6.egg\django\core\handlers\base.py", line 249, in _legacy_get_response
    response = self._get_response(request)
  File "D:\ProgramFiles\Anaconda3\lib\site-packages\django-1.11.8-py3.6.egg\django\core\handlers\base.py", line 198, in _get_response
    "returned None instead." % (callback.__module__, view_name)
ValueError: The view mysite.views.fileupload didn't return an HttpResponse object. It returned None instead.
exception.py[2018-10-09 11:44:22][ERROR]：Internal Server Error: /files/upload/
Traceback (most recent call last):
  File "D:\ProgramFiles\Anaconda3\lib\site-packages\django-1.11.8-py3.6.egg\django\core\handlers\exception.py", line 41, in inner
    response = get_response(request)
  File "D:\ProgramFiles\Anaconda3\lib\site-packages\django-1.11.8-py3.6.egg\django\core\handlers\base.py", line 249, in _legacy_get_response
    response = self._get_response(request)
  File "D:\ProgramFiles\Anaconda3\lib\site-packages\django-1.11.8-py3.6.egg\django\core\handlers\base.py", line 198, in _get_response
    "returned None instead." % (callback.__module__, view_name)
ValueError: The view mysite.views.fileupload didn't return an HttpResponse object. It returned None instead.
exception.py[2018-10-09 11:44:22][ERROR]：Internal Server Error: /files/upload/
Traceback (most recent call last):
  File "D:\ProgramFiles\Anaconda3\lib\site-packages\django-1.11.8-py3.6.egg\django\core\handlers\exception.py", line 41, in inner
    response = get_response(request)
  File "D:\ProgramFiles\Anaconda3\lib\site-packages\django-1.11.8-py3.6.egg\django\core\handlers\base.py", line 249, in _legacy_get_response
    response = self._get_response(request)
  File "D:\ProgramFiles\Anaconda3\lib\site-packages\django-1.11.8-py3.6.egg\django\core\handlers\base.py", line 198, in _get_response
    "returned None instead." % (callback.__module__, view_name)
ValueError: The view mysite.views.fileupload didn't return an HttpResponse object. It returned None instead.
exception.py[2018-10-09 11:44:22][ERROR]：Internal Server Error: /files/upload/
Traceback (most recent call last):
  File "D:\ProgramFiles\Anaconda3\lib\site-packages\django-1.11.8-py3.6.egg\django\core\handlers\exception.py", line 41, in inner
    response = get_response(request)
  File "D:\ProgramFiles\Anaconda3\lib\site-packages\django-1.11.8-py3.6.egg\django\core\handlers\base.py", line 249, in _legacy_get_response
    response = self._get_response(request)
  File "D:\ProgramFiles\Anaconda3\lib\site-packages\django-1.11.8-py3.6.egg\django\core\handlers\base.py", line 198, in _get_response
    "returned None instead." % (callback.__module__, view_name)
ValueError: The view mysite.views.fileupload didn't return an HttpResponse object. It returned None instead.
exception.py[2018-10-09 11:44:23][ERROR]：Internal Server Error: /files/upload/
Traceback (most recent call last):
  File "D:\ProgramFiles\Anaconda3\lib\site-packages\django-1.11.8-py3.6.egg\django\core\handlers\exception.py", line 41, in inner
    response = get_response(request)
  File "D:\ProgramFiles\Anaconda3\lib\site-packages\django-1.11.8-py3.6.egg\django\core\handlers\base.py", line 249, in _legacy_get_response
    response = self._get_response(request)
  File "D:\ProgramFiles\Anaconda3\lib\site-packages\django-1.11.8-py3.6.egg\django\core\handlers\base.py", line 198, in _get_response
    "returned None instead." % (callback.__module__, view_name)
ValueError: The view mysite.views.fileupload didn't return an HttpResponse object. It returned None instead.
exception.py[2018-10-09 11:44:23][ERROR]：Internal Server Error: /files/upload/
Traceback (most recent call last):
  File "D:\ProgramFiles\Anaconda3\lib\site-packages\django-1.11.8-py3.6.egg\django\core\handlers\exception.py", line 41, in inner
    response = get_response(request)
  File "D:\ProgramFiles\Anaconda3\lib\site-packages\django-1.11.8-py3.6.egg\django\core\handlers\base.py", line 249, in _legacy_get_response
    response = self._get_response(request)
  File "D:\ProgramFiles\Anaconda3\lib\site-packages\django-1.11.8-py3.6.egg\django\core\handlers\base.py", line 198, in _get_response
    "returned None instead." % (callback.__module__, view_name)
ValueError: The view mysite.views.fileupload didn't return an HttpResponse object. It returned None instead.
exception.py[2018-10-09 11:44:23][ERROR]：Internal Server Error: /files/upload/
Traceback (most recent call last):
  File "D:\ProgramFiles\Anaconda3\lib\site-packages\django-1.11.8-py3.6.egg\django\core\handlers\exception.py", line 41, in inner
    response = get_response(request)
  File "D:\ProgramFiles\Anaconda3\lib\site-packages\django-1.11.8-py3.6.egg\django\core\handlers\base.py", line 249, in _legacy_get_response
    response = self._get_response(request)
  File "D:\ProgramFiles\Anaconda3\lib\site-packages\django-1.11.8-py3.6.egg\django\core\handlers\base.py", line 198, in _get_response
    "returned None instead." % (callback.__module__, view_name)
ValueError: The view mysite.views.fileupload didn't return an HttpResponse object. It returned None instead.
exception.py[2018-10-09 11:44:23][ERROR]：Internal Server Error: /files/upload/
Traceback (most recent call last):
  File "D:\ProgramFiles\Anaconda3\lib\site-packages\django-1.11.8-py3.6.egg\django\core\handlers\exception.py", line 41, in inner
    response = get_response(request)
  File "D:\ProgramFiles\Anaconda3\lib\site-packages\django-1.11.8-py3.6.egg\django\core\handlers\base.py", line 249, in _legacy_get_response
    response = self._get_response(request)
  File "D:\ProgramFiles\Anaconda3\lib\site-packages\django-1.11.8-py3.6.egg\django\core\handlers\base.py", line 198, in _get_response
    "returned None instead." % (callback.__module__, view_name)
ValueError: The view mysite.views.fileupload didn't return an HttpResponse object. It returned None instead.
base.py[2018-10-09 11:44:59][WARNING]：Not Found: /files/upload/
base.py[2018-10-09 11:44:59][WARNING]：Not Found: /files/upload/
base.py[2018-10-09 11:44:59][WARNING]：Not Found: /files/upload/
base.py[2018-10-09 11:44:59][WARNING]：Not Found: /files/upload/
base.py[2018-10-09 11:45:00][WARNING]：Not Found: /files/upload/
base.py[2018-10-09 11:45:00][WARNING]：Not Found: /files/upload/
base.py[2018-10-09 11:45:00][WARNING]：Not Found: /files/upload/
base.py[2018-10-09 11:45:01][WARNING]：Not Found: /files/upload/
base.py[2018-10-09 11:45:11][WARNING]：Not Found: /files/upload/
base.py[2018-10-09 11:46:59][WARNING]：Not Found: /files/upload/
base.py[2018-10-09 11:48:02][WARNING]：Not Found: /files/upload/
base.py[2018-10-09 11:48:14][WARNING]：Not Found: /files/upload/
base.py[2018-10-09 11:48:42][WARNING]：Not Found: /files/upload/
base.py[2018-10-09 11:49:06][WARNING]：Not Found: /files/upload/
base.py[2018-10-09 11:49:20][WARNING]：Not Found: /files/upload/
base.py[2018-10-09 11:49:44][WARNING]：Not Found: /files/upload/
base.py[2018-10-09 11:49:54][WARNING]：Not Found: /files/upload/
base.py[2018-10-09 11:50:29][WARNING]：Not Found: /files/upload/
base.py[2018-10-09 11:50:56][WARNING]：Not Found: /files/upload/
base.py[2018-10-09 11:51:09][WARNING]：Not Found: /files/upload/
base.py[2018-10-09 11:51:09][WARNING]：Not Found: /files/upload/
base.py[2018-10-09 11:51:10][WARNING]：Not Found: /files/upload/
base.py[2018-10-09 11:51:10][WARNING]：Not Found: /files/upload/
base.py[2018-10-09 11:51:10][WARNING]：Not Found: /files/upload/
base.py[2018-10-09 11:51:10][WARNING]：Not Found: /files/upload/
base.py[2018-10-09 11:51:11][WARNING]：Not Found: /files/upload/
base.py[2018-10-09 11:51:11][WARNING]：Not Found: /files/upload/
base.py[2018-10-09 11:52:00][WARNING]：Not Found: /files/upload/
base.py[2018-10-09 11:52:16][WARNING]：Not Found: /files/upload/
base.py[2018-10-09 11:55:04][WARNING]：Not Found: /files/upload/
base.py[2018-10-09 11:55:04][WARNING]：Not Found: /files/upload/
base.py[2018-10-09 11:55:05][WARNING]：Not Found: /files/upload/
base.py[2018-10-09 11:55:05][WARNING]：Not Found: /files/upload/
base.py[2018-10-09 11:55:05][WARNING]：Not Found: /files/upload/
base.py[2018-10-09 11:55:05][WARNING]：Not Found: /files/upload/
base.py[2018-10-09 11:55:06][WARNING]：Not Found: /files/upload/
base.py[2018-10-09 11:55:06][WARNING]：Not Found: /files/upload/
base.py[2018-10-09 11:55:11][WARNING]：Not Found: /files/upload/
base.py[2018-10-09 11:55:25][WARNING]：Not Found: /files/upload/
base.py[2018-10-09 11:55:25][WARNING]：Not Found: /files/upload/
base.py[2018-10-09 11:55:26][WARNING]：Not Found: /files/upload/
base.py[2018-10-09 11:55:26][WARNING]：Not Found: /files/upload/
base.py[2018-10-09 11:55:26][WARNING]：Not Found: /files/upload/
base.py[2018-10-09 11:55:26][WARNING]：Not Found: /files/upload/
base.py[2018-10-09 11:55:27][WARNING]：Not Found: /files/upload/
base.py[2018-10-09 11:55:27][WARNING]：Not Found: /files/upload/
base.py[2018-10-09 11:55:53][WARNING]：Not Found: /files/upload/
base.py[2018-10-09 11:55:53][WARNING]：Not Found: /files/upload/
base.py[2018-10-09 11:55:53][WARNING]：Not Found: /files/upload/
base.py[2018-10-09 11:55:53][WARNING]：Not Found: /files/upload/
base.py[2018-10-09 11:55:54][WARNING]：Not Found: /files/upload/
base.py[2018-10-09 11:55:54][WARNING]：Not Found: /files/upload/
base.py[2018-10-09 11:55:54][WARNING]：Not Found: /files/upload/
base.py[2018-10-09 11:55:54][WARNING]：Not Found: /files/upload/
base.py[2018-10-09 11:55:59][WARNING]：Not Found: /files/upload/
base.py[2018-10-09 11:55:59][WARNING]：Not Found: /files/upload/
base.py[2018-10-09 11:56:00][WARNING]：Not Found: /files/upload/
base.py[2018-10-09 11:56:00][WARNING]：Not Found: /files/upload/
base.py[2018-10-09 11:56:00][WARNING]：Not Found: /files/upload/
base.py[2018-10-09 11:56:01][WARNING]：Not Found: /files/upload/
base.py[2018-10-09 11:56:01][WARNING]：Not Found: /files/upload/
base.py[2018-10-09 11:56:01][WARNING]：Not Found: /files/upload/
base.py[2018-10-09 11:56:33][WARNING]：Not Found: /files/upload/
base.py[2018-10-09 11:56:33][WARNING]：Not Found: /files/upload/
base.py[2018-10-09 11:56:34][WARNING]：Not Found: /files/upload/
base.py[2018-10-09 11:56:34][WARNING]：Not Found: /files/upload/
base.py[2018-10-09 11:56:34][WARNING]：Not Found: /files/upload/
base.py[2018-10-09 11:56:34][WARNING]：Not Found: /files/upload/
base.py[2018-10-09 11:56:34][WARNING]：Not Found: /files/upload/
base.py[2018-10-09 11:56:34][WARNING]：Not Found: /files/upload/
base.py[2018-10-09 11:57:23][WARNING]：Not Found: /files/upload/
base.py[2018-10-09 11:57:23][WARNING]：Not Found: /files/upload/
base.py[2018-10-09 11:57:24][WARNING]：Not Found: /files/upload/
base.py[2018-10-09 11:57:24][WARNING]：Not Found: /files/upload/
base.py[2018-10-09 11:57:24][WARNING]：Not Found: /files/upload/
base.py[2018-10-09 11:57:24][WARNING]：Not Found: /files/upload/
base.py[2018-10-09 11:57:25][WARNING]：Not Found: /files/upload/
base.py[2018-10-09 11:57:25][WARNING]：Not Found: /files/upload/
base.py[2018-10-09 11:57:47][WARNING]：Not Found: /files/upload/
base.py[2018-10-09 11:57:47][WARNING]：Not Found: /files/upload/
base.py[2018-10-09 11:57:48][WARNING]：Not Found: /files/upload/
base.py[2018-10-09 11:57:48][WARNING]：Not Found: /files/upload/
base.py[2018-10-09 11:57:48][WARNING]：Not Found: /files/upload/
base.py[2018-10-09 11:57:48][WARNING]：Not Found: /files/upload/
base.py[2018-10-09 11:57:49][WARNING]：Not Found: /files/upload/
base.py[2018-10-09 11:57:49][WARNING]：Not Found: /files/upload/
base.py[2018-10-09 11:58:56][WARNING]：Not Found: /files/upload/
base.py[2018-10-09 11:59:18][WARNING]：Not Found: /files/upload/
base.py[2018-10-09 11:59:29][WARNING]：Not Found: /files/upload/
base.py[2018-10-09 11:59:48][WARNING]：Not Found: /files/upload/
base.py[2018-10-09 12:00:00][WARNING]：Not Found: /files/upload/
base.py[2018-10-09 12:00:16][WARNING]：Not Found: /files/upload/
base.py[2018-10-09 12:00:23][WARNING]：Not Found: /files/upload/
base.py[2018-10-09 12:00:37][WARNING]：Not Found: /files/upload/
base.py[2018-10-09 12:00:49][WARNING]：Not Found: /files/upload/
base.py[2018-10-09 12:01:00][WARNING]：Not Found: /files/upload/
base.py[2018-10-09 12:01:06][WARNING]：Not Found: /files/upload/
base.py[2018-10-09 12:01:06][WARNING]：Not Found: /files/upload/
base.py[2018-10-09 12:01:06][WARNING]：Not Found: /files/upload/
base.py[2018-10-09 12:01:07][WARNING]：Not Found: /files/upload/
base.py[2018-10-09 12:01:07][WARNING]：Not Found: /files/upload/
base.py[2018-10-09 12:01:07][WARNING]：Not Found: /files/upload/
base.py[2018-10-09 12:01:07][WARNING]：Not Found: /files/upload/
base.py[2018-10-09 12:02:35][WARNING]：Not Found: /files/upload/
base.py[2018-10-09 12:02:35][WARNING]：Not Found: /files/upload/
base.py[2018-10-09 12:02:36][WARNING]：Not Found: /files/upload/
base.py[2018-10-09 12:02:36][WARNING]：Not Found: /files/upload/
base.py[2018-10-09 12:02:36][WARNING]：Not Found: /files/upload/
base.py[2018-10-09 12:02:36][WARNING]：Not Found: /files/upload/
base.py[2018-10-09 12:02:37][WARNING]：Not Found: /files/upload/
base.py[2018-10-09 12:02:37][WARNING]：Not Found: /files/upload/
base.py[2018-10-09 12:03:00][WARNING]：Not Found: /files/upload/
base.py[2018-10-09 12:03:00][WARNING]：Not Found: /files/upload/
base.py[2018-10-09 12:03:01][WARNING]：Not Found: /files/upload/
base.py[2018-10-09 12:03:01][WARNING]：Not Found: /files/upload/
base.py[2018-10-09 12:03:01][WARNING]：Not Found: /files/upload/
base.py[2018-10-09 12:03:02][WARNING]：Not Found: /files/upload/
base.py[2018-10-09 12:03:02][WARNING]：Not Found: /files/upload/
base.py[2018-10-09 12:03:02][WARNING]：Not Found: /files/upload/
base.py[2018-10-09 12:28:17][WARNING]：Not Found: /files/upload/
base.py[2018-10-09 12:28:17][WARNING]：Not Found: /files/upload/
base.py[2018-10-09 12:28:17][WARNING]：Not Found: /files/upload/
base.py[2018-10-09 12:28:18][WARNING]：Not Found: /files/upload/
base.py[2018-10-09 12:28:18][WARNING]：Not Found: /files/upload/
base.py[2018-10-09 12:28:19][WARNING]：Not Found: /files/upload/
base.py[2018-10-09 12:28:19][WARNING]：Not Found: /files/upload/
base.py[2018-10-09 12:28:19][WARNING]：Not Found: /files/upload/
exception.py[2018-10-09 14:42:51][ERROR]：Internal Server Error: /tj/
Traceback (most recent call last):
  File "D:\ProgramFiles\Anaconda3\lib\site-packages\django-1.11.8-py3.6.egg\django\core\handlers\exception.py", line 41, in inner
    response = get_response(request)
  File "D:\ProgramFiles\Anaconda3\lib\site-packages\django-1.11.8-py3.6.egg\django\core\handlers\base.py", line 249, in _legacy_get_response
    response = self._get_response(request)
  File "D:\ProgramFiles\Anaconda3\lib\site-packages\django-1.11.8-py3.6.egg\django\core\handlers\base.py", line 187, in _get_response
    response = self.process_exception_by_middleware(e, request)
  File "D:\ProgramFiles\Anaconda3\lib\site-packages\django-1.11.8-py3.6.egg\django\core\handlers\base.py", line 185, in _get_response
    response = wrapped_callback(request, *callback_args, **callback_kwargs)
  File "D:\tools\Tools\Carry\mysite\views.py", line 1226, in tongji
    {'hc': hc, 'hcd': hcd, 'huizong': huizong, 'init_money': init_money, 'user_name': user_name,
UnboundLocalError: local variable 'hc' referenced before assignment
base.py[2018-10-09 17:46:10][WARNING]：Not Found: /files/upload/
base.py[2018-10-09 17:46:10][WARNING]：Not Found: /files/upload/
base.py[2018-10-09 17:46:10][WARNING]：Not Found: /files/upload/
base.py[2018-10-09 17:46:10][WARNING]：Not Found: /files/upload/
base.py[2018-10-09 17:46:11][WARNING]：Not Found: /files/upload/
base.py[2018-10-09 17:46:11][WARNING]：Not Found: /files/upload/
base.py[2018-10-09 17:46:11][WARNING]：Not Found: /files/upload/
base.py[2018-10-09 17:46:11][WARNING]：Not Found: /files/upload/
base.py[2018-10-09 17:48:13][WARNING]：Not Found: /files/upload/
base.py[2018-10-09 17:48:44][WARNING]：Not Found: /files/upload/
base.py[2018-10-09 17:49:22][WARNING]：Not Found: /files/upload/
base.py[2018-10-09 17:49:22][WARNING]：Not Found: /files/upload/
base.py[2018-10-09 17:49:23][WARNING]：Not Found: /files/upload/
base.py[2018-10-09 17:49:23][WARNING]：Not Found: /files/upload/
base.py[2018-10-09 17:49:26][WARNING]：Not Found: /files/upload/
base.py[2018-10-09 17:49:28][WARNING]：Not Found: /files/upload/
base.py[2018-10-09 17:49:30][WARNING]：Not Found: /files/upload/
base.py[2018-10-09 17:49:30][WARNING]：Not Found: /files/upload/
tf_logging.py[2018-10-09 18:27:21][INFO]：Restoring parameters from D:\tools\Tools\Carry\mysite\myfile\captcha_model95\crack_capcha.ckpt-12000
wsgi.py[2018-10-09 18:28:03][INFO]：200 GET /user/cloud/public/ (192.168.2.204) 169.45ms
wsgi.py[2018-10-09 18:28:16][INFO]：200 POST /files/upload/ (192.168.2.204) 1870.51ms
wsgi.py[2018-10-09 18:28:16][INFO]：200 POST /files/upload/ (192.168.2.204) 2219.63ms
wsgi.py[2018-10-09 18:28:18][INFO]：200 POST /files/upload/ (192.168.2.204) 819.18ms
wsgi.py[2018-10-09 18:28:19][INFO]：200 POST /files/upload/ (192.168.2.204) 1223.71ms
wsgi.py[2018-10-09 18:28:22][INFO]：200 POST /files/upload/ (192.168.2.204) 616.64ms
wsgi.py[2018-10-09 18:28:22][INFO]：200 POST /files/upload/ (192.168.2.204) 793.50ms
wsgi.py[2018-10-09 18:28:27][INFO]：200 POST /files/upload/ (192.168.2.204) 2227.28ms
wsgi.py[2018-10-09 18:28:27][INFO]：200 POST /files/upload/ (192.168.2.204) 2453.19ms
wsgi.py[2018-10-09 18:28:35][INFO]：200 GET /upload/complete/?task_id=wu_1cpc5t36b1o9dqf1pd71o9b6h20&filename=vmware12.zip (192.168.2.204) 7943.17ms
wsgi.py[2018-10-09 18:29:25][INFO]：200 GET /user/cloud/public/ (192.168.2.204) 234.67ms
wsgi.py[2018-10-09 18:29:29][INFO]：200 POST /user/cloud/public/delete (192.168.2.204) 173.49ms
wsgi.py[2018-10-09 18:29:35][INFO]：200 POST /user/cloud/public/delete (192.168.2.204) 65.20ms
wsgi.py[2018-10-09 18:29:47][INFO]：200 POST /files/upload/ (192.168.2.204) 551.47ms
wsgi.py[2018-10-09 18:29:49][INFO]：200 POST /files/upload/ (192.168.2.204) 753.00ms
wsgi.py[2018-10-09 18:29:49][INFO]：200 POST /files/upload/ (192.168.2.204) 503.34ms
wsgi.py[2018-10-09 18:29:51][INFO]：200 POST /files/upload/ (192.168.2.204) 541.42ms
wsgi.py[2018-10-09 18:29:51][INFO]：200 POST /files/upload/ (192.168.2.204) 842.24ms
wsgi.py[2018-10-09 18:29:52][INFO]：200 POST /files/upload/ (192.168.2.204) 551.47ms
wsgi.py[2018-10-09 18:29:53][INFO]：200 POST /files/upload/ (192.168.2.204) 1464.62ms
wsgi.py[2018-10-09 18:29:54][INFO]：200 POST /files/upload/ (192.168.2.204) 413.10ms
wsgi.py[2018-10-09 18:29:58][INFO]：200 GET /upload/complete/?task_id=wu_1cpc5vsvv17lb15fd16evsdi1nml0&filename=vmware12.zip (192.168.2.204) 4045.13ms
wsgi.py[2018-10-09 18:30:26][INFO]：200 GET /moni/ (192.168.2.204) 56.15ms
wsgi.py[2018-10-09 18:30:28][INFO]：200 GET /moni/?zsds=100&ydzs=100&zyds=200&cqdc=6&database=1&dates=2018-10-05&end_date=2018-10-09&fa=1 (192.168.2.204) 205.68ms
wsgi.py[2018-10-09 18:30:41][INFO]：200 GET /hc/?dates=2018-10-05&end_date=2018-10-09&fa=1&database=1&zsds=100&ydzs=100&zyds=200&cqdc=6 (192.168.2.204) 171.69ms
wsgi.py[2018-10-09 18:32:04][INFO]：200 GET /moni/?zsds=100&ydzs=100&zyds=200&cqdc=6&database=1&dates=2018-10-05&end_date=2018-10-09&fa=1 (192.168.2.204) 151.40ms
wsgi.py[2018-10-09 18:32:13][INFO]：200 GET /moni/?zsds=100&ydzs=100&zyds=200&cqdc=6&database=1&dates=2018-06-05&end_date=2018-10-09&fa=1 (192.168.2.204) 5015.71ms
wsgi.py[2018-10-09 18:32:59][INFO]：200 GET /hc/?dates=2018-06-05&end_date=2018-10-09&fa=1&database=1&zsds=100&ydzs=100&zyds=200&cqdc=6 (192.168.2.204) 4928.79ms
wsgi.py[2018-10-09 18:34:56][INFO]：200 GET /user/cloud/public/ (192.168.2.204) 11.98ms
wsgi.py[2018-10-09 18:35:13][INFO]：200 POST /files/upload/ (192.168.2.204) 571.52ms
wsgi.py[2018-10-09 18:35:13][INFO]：200 POST /files/upload/ (192.168.2.204) 759.02ms
wsgi.py[2018-10-09 18:35:14][INFO]：200 POST /files/upload/ (192.168.2.204) 174.46ms
wsgi.py[2018-10-09 18:35:14][INFO]：200 GET /upload/complete/?task_id=wu_1cpc69mug17gu77b3svn1hsj90&filename=%E8%81%94%E7%9B%9F%E5%B7%A5%E5%85%B7%E5%8C%85.rar (192.168.2.204) 526.57ms
wsgi.py[2018-10-09 18:35:36][INFO]：200 GET / (192.168.2.204) 23.99ms
wsgi.py[2018-10-09 18:35:39][INFO]：200 GET / (192.168.2.204) 24.06ms
tf_logging.py[2018-10-09 18:41:15][INFO]：Restoring parameters from D:\tools\Tools\Carry\mysite\myfile\captcha_model95\crack_capcha.ckpt-12000
wsgi.py[2018-10-09 18:42:27][INFO]：200 POST /user/cloud/public/delete (192.168.2.204) 301.01ms
wsgi.py[2018-10-09 18:42:32][INFO]：200 POST /user/cloud/public/delete (192.168.2.204) 177.47ms
wsgi.py[2018-10-09 18:42:33][INFO]：200 GET /user/cloud/public/ (192.168.2.204) 15.04ms
wsgi.py[2018-10-09 18:42:43][INFO]：200 POST /files/upload/ (192.168.2.204) 502.34ms
wsgi.py[2018-10-09 18:42:44][INFO]：200 POST /files/upload/ (192.168.2.204) 1049.75ms
wsgi.py[2018-10-09 18:42:45][INFO]：200 POST /files/upload/ (192.168.2.204) 1893.86ms
wsgi.py[2018-10-09 18:42:48][INFO]：200 POST /files/upload/ (192.168.2.204) 543.44ms
wsgi.py[2018-10-09 18:42:48][INFO]：200 POST /files/upload/ (192.168.2.204) 931.06ms
wsgi.py[2018-10-09 18:42:51][INFO]：200 POST /files/upload/ (192.168.2.204) 716.91ms
wsgi.py[2018-10-09 18:42:52][INFO]：200 POST /files/upload/ (192.168.2.204) 1681.67ms
wsgi.py[2018-10-09 18:42:54][INFO]：200 POST /files/upload/ (192.168.2.204) 533.44ms
wsgi.py[2018-10-09 18:43:03][INFO]：200 GET /upload/complete/?task_id=wu_1cpc6nkv04bo4f1not3cfl1v0&filename=vmware12.zip (192.168.2.204) 9400.28ms
wsgi.py[2018-10-09 18:43:14][INFO]：200 GET /user/cloud/public/ (192.168.2.204) 71.16ms
wsgi.py[2018-10-09 18:43:22][INFO]：200 GET /user/cloud/public/ (192.168.2.204) 14.04ms
wsgi.py[2018-10-09 18:43:28][INFO]：200 POST /user/cloud/public/delete (192.168.2.204) 62.16ms
wsgi.py[2018-10-09 18:43:35][INFO]：200 POST /user/cloud/public/delete (192.168.2.204) 12.96ms
wsgi.py[2018-10-09 18:43:40][INFO]：200 POST /files/upload/ (192.168.2.204) 606.61ms
wsgi.py[2018-10-09 18:43:40][INFO]：200 POST /files/upload/ (192.168.2.204) 744.98ms
wsgi.py[2018-10-09 18:43:42][INFO]：200 POST /files/upload/ (192.168.2.204) 541.44ms
wsgi.py[2018-10-09 18:43:42][INFO]：200 POST /files/upload/ (192.168.2.204) 790.10ms
wsgi.py[2018-10-09 18:43:44][INFO]：200 POST /files/upload/ (192.168.2.204) 559.49ms
wsgi.py[2018-10-09 18:43:44][INFO]：200 POST /files/upload/ (192.168.2.204) 475.26ms
wsgi.py[2018-10-09 18:43:46][INFO]：200 POST /files/upload/ (192.168.2.204) 565.50ms
wsgi.py[2018-10-09 18:43:46][INFO]：200 POST /files/upload/ (192.168.2.204) 613.63ms
wsgi.py[2018-10-09 18:43:50][INFO]：200 POST /files/upload/ (192.168.2.204) 640.67ms
wsgi.py[2018-10-09 18:43:51][INFO]：200 POST /files/upload/ (192.168.2.204) 1507.98ms
wsgi.py[2018-10-09 18:43:52][INFO]：200 POST /files/upload/ (192.168.2.204) 172.47ms
wsgi.py[2018-10-09 18:43:59][INFO]：200 GET /upload/complete/?task_id=wu_1cpc6ph501lt91jevnmc9r8uch0&filename=Anaconda3-5.0.1-Windows-x86_64.exe (192.168.2.204) 6846.33ms
wsgi.py[2018-10-09 18:44:45][INFO]：200 POST /files/upload/ (192.168.2.204) 546.45ms
wsgi.py[2018-10-09 18:44:47][INFO]：200 POST /files/upload/ (192.168.2.204) 2811.07ms
wsgi.py[2018-10-09 18:44:52][INFO]：200 POST /files/upload/ (192.168.2.204) 172.46ms
wsgi.py[2018-10-09 18:44:52][INFO]：200 GET /upload/complete/?task_id=wu_1cpc6ph501lt91jevnmc9r8uch0&filename=%E8%81%94%E7%9B%9F%E5%B7%A5%E5%85%B7%E5%8C%85.rar (192.168.2.204) 354.79ms
wsgi.py[2018-10-09 18:45:17][INFO]：200 POST /files/upload/ (192.168.2.204) 502.34ms
wsgi.py[2018-10-09 18:45:19][INFO]：200 POST /files/upload/ (192.168.2.204) 559.49ms
wsgi.py[2018-10-09 18:45:20][INFO]：200 POST /files/upload/ (192.168.2.204) 854.55ms
wsgi.py[2018-10-09 18:45:22][INFO]：200 POST /files/upload/ (192.168.2.204) 472.25ms
wsgi.py[2018-10-09 18:45:22][INFO]：200 POST /files/upload/ (192.168.2.204) 827.70ms
wsgi.py[2018-10-09 18:45:25][INFO]：200 POST /files/upload/ (192.168.2.204) 1811.66ms
wsgi.py[2018-10-09 18:45:26][INFO]：200 POST /files/upload/ (192.168.2.204) 551.47ms
wsgi.py[2018-10-09 18:45:28][INFO]：200 POST /files/upload/ (192.168.2.204) 486.29ms
wsgi.py[2018-10-09 18:45:33][INFO]：200 GET /upload/complete/?task_id=wu_1cpc6ph501lt91jevnmc9r8uch0&filename=vmware12.zip (192.168.2.204) 5240.28ms
wsgi.py[2018-10-09 18:45:46][INFO]：200 GET /user/cloud/public/ (192.168.2.204) 23.06ms
wsgi.py[2018-10-09 18:47:33][INFO]：200 POST /user/cloud/public/delete (192.168.2.204) 43.11ms
wsgi.py[2018-10-09 18:47:35][INFO]：200 POST /user/cloud/public/delete (192.168.2.204) 70.15ms
wsgi.py[2018-10-09 18:47:37][INFO]：200 POST /user/cloud/public/delete (192.168.2.204) 42.11ms
tf_logging.py[2018-10-09 18:47:48][INFO]：Restoring parameters from D:\tools\Tools\Carry\mysite\myfile\captcha_model95\crack_capcha.ckpt-12000
wsgi.py[2018-10-09 18:47:59][INFO]：200 GET /user/cloud/public/ (192.168.2.204) 239.69ms
wsgi.py[2018-10-09 18:48:00][INFO]：200 GET /user/cloud/public/ (192.168.2.204) 169.43ms
wsgi.py[2018-10-09 18:48:00][INFO]：200 GET /user/cloud/public/ (192.168.2.204) 13.03ms
wsgi.py[2018-10-09 18:48:08][INFO]：200 POST /files/upload/ (192.168.2.204) 1053.30ms
wsgi.py[2018-10-09 18:48:08][INFO]：200 POST /files/upload/ (192.168.2.204) 1781.28ms
wsgi.py[2018-10-09 18:48:11][INFO]：200 POST /files/upload/ (192.168.2.204) 1849.45ms
wsgi.py[2018-10-09 18:48:11][INFO]：200 POST /files/upload/ (192.168.2.204) 2505.31ms
wsgi.py[2018-10-09 18:48:13][INFO]：200 POST /files/upload/ (192.168.2.204) 650.73ms
wsgi.py[2018-10-09 18:48:13][INFO]：200 POST /files/upload/ (192.168.2.204) 959.25ms
wsgi.py[2018-10-09 18:48:19][INFO]：200 POST /files/upload/ (192.168.2.204) 5308.47ms
wsgi.py[2018-10-09 18:48:19][INFO]：200 POST /files/upload/ (192.168.2.204) 5023.33ms
wsgi.py[2018-10-09 18:48:21][INFO]：200 GET /upload/complete/?task_id=wu_1cpc71kmoci3kb0rlbqph1cpv0&filename=vmware12.zip (192.168.2.204) 2117.85ms
base.py[2018-10-10 08:57:37][WARNING]：Not Found: /favicon.ico
exception.py[2018-10-10 09:45:14][ERROR]：Internal Server Error: /admin/mysite/worklog/
Traceback (most recent call last):
  File "D:\ProgramFiles\Anaconda3\lib\site-packages\django-1.11.8-py3.6.egg\django\core\handlers\exception.py", line 41, in inner
    response = get_response(request)
  File "D:\ProgramFiles\Anaconda3\lib\site-packages\django-1.11.8-py3.6.egg\django\core\handlers\base.py", line 249, in _legacy_get_response
    response = self._get_response(request)
  File "D:\ProgramFiles\Anaconda3\lib\site-packages\django-1.11.8-py3.6.egg\django\core\handlers\base.py", line 187, in _get_response
    response = self.process_exception_by_middleware(e, request)
  File "D:\ProgramFiles\Anaconda3\lib\site-packages\django-1.11.8-py3.6.egg\django\core\handlers\base.py", line 185, in _get_response
    response = wrapped_callback(request, *callback_args, **callback_kwargs)
  File "D:\ProgramFiles\Anaconda3\lib\site-packages\django-1.11.8-py3.6.egg\django\contrib\admin\options.py", line 551, in wrapper
    return self.admin_site.admin_view(view)(*args, **kwargs)
  File "D:\ProgramFiles\Anaconda3\lib\site-packages\django-1.11.8-py3.6.egg\django\utils\decorators.py", line 149, in _wrapped_view
    response = view_func(request, *args, **kwargs)
  File "D:\ProgramFiles\Anaconda3\lib\site-packages\django-1.11.8-py3.6.egg\django\views\decorators\cache.py", line 57, in _wrapped_view_func
    response = view_func(request, *args, **kwargs)
  File "D:\ProgramFiles\Anaconda3\lib\site-packages\django-1.11.8-py3.6.egg\django\contrib\admin\sites.py", line 224, in inner
    return view(request, *args, **kwargs)
  File "D:\ProgramFiles\Anaconda3\lib\site-packages\django-1.11.8-py3.6.egg\django\utils\decorators.py", line 67, in _wrapper
    return bound_func(*args, **kwargs)
  File "D:\ProgramFiles\Anaconda3\lib\site-packages\django-1.11.8-py3.6.egg\django\utils\decorators.py", line 149, in _wrapped_view
    response = view_func(request, *args, **kwargs)
  File "D:\ProgramFiles\Anaconda3\lib\site-packages\django-1.11.8-py3.6.egg\django\utils\decorators.py", line 63, in bound_func
    return func.__get__(self, type(self))(*args2, **kwargs2)
  File "D:\ProgramFiles\Anaconda3\lib\site-packages\django-1.11.8-py3.6.egg\django\contrib\admin\options.py", line 1542, in changelist_view
    self.list_max_show_all, self.list_editable, self,
  File "D:\ProgramFiles\Anaconda3\lib\site-packages\django-1.11.8-py3.6.egg\django\contrib\admin\views\main.py", line 78, in __init__
    self.queryset = self.get_queryset(request)
  File "D:\ProgramFiles\Anaconda3\lib\site-packages\django-1.11.8-py3.6.egg\django\contrib\admin\views\main.py", line 351, in get_queryset
    qs, search_use_distinct = self.model_admin.get_search_results(request, qs, self.query)
  File "D:\ProgramFiles\Anaconda3\lib\site-packages\django-1.11.8-py3.6.egg\django\contrib\admin\options.py", line 910, in get_search_results
    queryset = queryset.filter(reduce(operator.or_, or_queries))
  File "D:\ProgramFiles\Anaconda3\lib\site-packages\django-1.11.8-py3.6.egg\django\db\models\query.py", line 784, in filter
    return self._filter_or_exclude(False, *args, **kwargs)
  File "D:\ProgramFiles\Anaconda3\lib\site-packages\django-1.11.8-py3.6.egg\django\db\models\query.py", line 802, in _filter_or_exclude
    clone.query.add_q(Q(*args, **kwargs))
  File "D:\ProgramFiles\Anaconda3\lib\site-packages\django-1.11.8-py3.6.egg\django\db\models\sql\query.py", line 1250, in add_q
    clause, _ = self._add_q(q_object, self.used_aliases)
  File "D:\ProgramFiles\Anaconda3\lib\site-packages\django-1.11.8-py3.6.egg\django\db\models\sql\query.py", line 1270, in _add_q
    current_negated, allow_joins, split_subq)
  File "D:\ProgramFiles\Anaconda3\lib\site-packages\django-1.11.8-py3.6.egg\django\db\models\sql\query.py", line 1276, in _add_q
    allow_joins=allow_joins, split_subq=split_subq,
  File "D:\ProgramFiles\Anaconda3\lib\site-packages\django-1.11.8-py3.6.egg\django\db\models\sql\query.py", line 1201, in build_filter
    raise FieldError('Related Field got invalid lookup: {}'.format(lookups[0]))
django.core.exceptions.FieldError: Related Field got invalid lookup: icontains
exception.py[2018-10-10 09:45:20][ERROR]：Internal Server Error: /admin/mysite/worklog/
Traceback (most recent call last):
  File "D:\ProgramFiles\Anaconda3\lib\site-packages\django-1.11.8-py3.6.egg\django\core\handlers\exception.py", line 41, in inner
    response = get_response(request)
  File "D:\ProgramFiles\Anaconda3\lib\site-packages\django-1.11.8-py3.6.egg\django\core\handlers\base.py", line 249, in _legacy_get_response
    response = self._get_response(request)
  File "D:\ProgramFiles\Anaconda3\lib\site-packages\django-1.11.8-py3.6.egg\django\core\handlers\base.py", line 187, in _get_response
    response = self.process_exception_by_middleware(e, request)
  File "D:\ProgramFiles\Anaconda3\lib\site-packages\django-1.11.8-py3.6.egg\django\core\handlers\base.py", line 185, in _get_response
    response = wrapped_callback(request, *callback_args, **callback_kwargs)
  File "D:\ProgramFiles\Anaconda3\lib\site-packages\django-1.11.8-py3.6.egg\django\contrib\admin\options.py", line 551, in wrapper
    return self.admin_site.admin_view(view)(*args, **kwargs)
  File "D:\ProgramFiles\Anaconda3\lib\site-packages\django-1.11.8-py3.6.egg\django\utils\decorators.py", line 149, in _wrapped_view
    response = view_func(request, *args, **kwargs)
  File "D:\ProgramFiles\Anaconda3\lib\site-packages\django-1.11.8-py3.6.egg\django\views\decorators\cache.py", line 57, in _wrapped_view_func
    response = view_func(request, *args, **kwargs)
  File "D:\ProgramFiles\Anaconda3\lib\site-packages\django-1.11.8-py3.6.egg\django\contrib\admin\sites.py", line 224, in inner
    return view(request, *args, **kwargs)
  File "D:\ProgramFiles\Anaconda3\lib\site-packages\django-1.11.8-py3.6.egg\django\utils\decorators.py", line 67, in _wrapper
    return bound_func(*args, **kwargs)
  File "D:\ProgramFiles\Anaconda3\lib\site-packages\django-1.11.8-py3.6.egg\django\utils\decorators.py", line 149, in _wrapped_view
    response = view_func(request, *args, **kwargs)
  File "D:\ProgramFiles\Anaconda3\lib\site-packages\django-1.11.8-py3.6.egg\django\utils\decorators.py", line 63, in bound_func
    return func.__get__(self, type(self))(*args2, **kwargs2)
  File "D:\ProgramFiles\Anaconda3\lib\site-packages\django-1.11.8-py3.6.egg\django\contrib\admin\options.py", line 1542, in changelist_view
    self.list_max_show_all, self.list_editable, self,
  File "D:\ProgramFiles\Anaconda3\lib\site-packages\django-1.11.8-py3.6.egg\django\contrib\admin\views\main.py", line 78, in __init__
    self.queryset = self.get_queryset(request)
  File "D:\ProgramFiles\Anaconda3\lib\site-packages\django-1.11.8-py3.6.egg\django\contrib\admin\views\main.py", line 351, in get_queryset
    qs, search_use_distinct = self.model_admin.get_search_results(request, qs, self.query)
  File "D:\ProgramFiles\Anaconda3\lib\site-packages\django-1.11.8-py3.6.egg\django\contrib\admin\options.py", line 910, in get_search_results
    queryset = queryset.filter(reduce(operator.or_, or_queries))
  File "D:\ProgramFiles\Anaconda3\lib\site-packages\django-1.11.8-py3.6.egg\django\db\models\query.py", line 784, in filter
    return self._filter_or_exclude(False, *args, **kwargs)
  File "D:\ProgramFiles\Anaconda3\lib\site-packages\django-1.11.8-py3.6.egg\django\db\models\query.py", line 802, in _filter_or_exclude
    clone.query.add_q(Q(*args, **kwargs))
  File "D:\ProgramFiles\Anaconda3\lib\site-packages\django-1.11.8-py3.6.egg\django\db\models\sql\query.py", line 1250, in add_q
    clause, _ = self._add_q(q_object, self.used_aliases)
  File "D:\ProgramFiles\Anaconda3\lib\site-packages\django-1.11.8-py3.6.egg\django\db\models\sql\query.py", line 1270, in _add_q
    current_negated, allow_joins, split_subq)
  File "D:\ProgramFiles\Anaconda3\lib\site-packages\django-1.11.8-py3.6.egg\django\db\models\sql\query.py", line 1276, in _add_q
    allow_joins=allow_joins, split_subq=split_subq,
  File "D:\ProgramFiles\Anaconda3\lib\site-packages\django-1.11.8-py3.6.egg\django\db\models\sql\query.py", line 1201, in build_filter
    raise FieldError('Related Field got invalid lookup: {}'.format(lookups[0]))
django.core.exceptions.FieldError: Related Field got invalid lookup: icontains
exception.py[2018-10-10 09:45:37][ERROR]：Internal Server Error: /admin/mysite/worklog/
Traceback (most recent call last):
  File "D:\ProgramFiles\Anaconda3\lib\site-packages\django-1.11.8-py3.6.egg\django\core\handlers\exception.py", line 41, in inner
    response = get_response(request)
  File "D:\ProgramFiles\Anaconda3\lib\site-packages\django-1.11.8-py3.6.egg\django\core\handlers\base.py", line 249, in _legacy_get_response
    response = self._get_response(request)
  File "D:\ProgramFiles\Anaconda3\lib\site-packages\django-1.11.8-py3.6.egg\django\core\handlers\base.py", line 187, in _get_response
    response = self.process_exception_by_middleware(e, request)
  File "D:\ProgramFiles\Anaconda3\lib\site-packages\django-1.11.8-py3.6.egg\django\core\handlers\base.py", line 185, in _get_response
    response = wrapped_callback(request, *callback_args, **callback_kwargs)
  File "D:\ProgramFiles\Anaconda3\lib\site-packages\django-1.11.8-py3.6.egg\django\contrib\admin\options.py", line 551, in wrapper
    return self.admin_site.admin_view(view)(*args, **kwargs)
  File "D:\ProgramFiles\Anaconda3\lib\site-packages\django-1.11.8-py3.6.egg\django\utils\decorators.py", line 149, in _wrapped_view
    response = view_func(request, *args, **kwargs)
  File "D:\ProgramFiles\Anaconda3\lib\site-packages\django-1.11.8-py3.6.egg\django\views\decorators\cache.py", line 57, in _wrapped_view_func
    response = view_func(request, *args, **kwargs)
  File "D:\ProgramFiles\Anaconda3\lib\site-packages\django-1.11.8-py3.6.egg\django\contrib\admin\sites.py", line 224, in inner
    return view(request, *args, **kwargs)
  File "D:\ProgramFiles\Anaconda3\lib\site-packages\django-1.11.8-py3.6.egg\django\utils\decorators.py", line 67, in _wrapper
    return bound_func(*args, **kwargs)
  File "D:\ProgramFiles\Anaconda3\lib\site-packages\django-1.11.8-py3.6.egg\django\utils\decorators.py", line 149, in _wrapped_view
    response = view_func(request, *args, **kwargs)
  File "D:\ProgramFiles\Anaconda3\lib\site-packages\django-1.11.8-py3.6.egg\django\utils\decorators.py", line 63, in bound_func
    return func.__get__(self, type(self))(*args2, **kwargs2)
  File "D:\ProgramFiles\Anaconda3\lib\site-packages\django-1.11.8-py3.6.egg\django\contrib\admin\options.py", line 1542, in changelist_view
    self.list_max_show_all, self.list_editable, self,
  File "D:\ProgramFiles\Anaconda3\lib\site-packages\django-1.11.8-py3.6.egg\django\contrib\admin\views\main.py", line 78, in __init__
    self.queryset = self.get_queryset(request)
  File "D:\ProgramFiles\Anaconda3\lib\site-packages\django-1.11.8-py3.6.egg\django\contrib\admin\views\main.py", line 351, in get_queryset
    qs, search_use_distinct = self.model_admin.get_search_results(request, qs, self.query)
  File "D:\ProgramFiles\Anaconda3\lib\site-packages\django-1.11.8-py3.6.egg\django\contrib\admin\options.py", line 910, in get_search_results
    queryset = queryset.filter(reduce(operator.or_, or_queries))
  File "D:\ProgramFiles\Anaconda3\lib\site-packages\django-1.11.8-py3.6.egg\django\db\models\query.py", line 784, in filter
    return self._filter_or_exclude(False, *args, **kwargs)
  File "D:\ProgramFiles\Anaconda3\lib\site-packages\django-1.11.8-py3.6.egg\django\db\models\query.py", line 802, in _filter_or_exclude
    clone.query.add_q(Q(*args, **kwargs))
  File "D:\ProgramFiles\Anaconda3\lib\site-packages\django-1.11.8-py3.6.egg\django\db\models\sql\query.py", line 1250, in add_q
    clause, _ = self._add_q(q_object, self.used_aliases)
  File "D:\ProgramFiles\Anaconda3\lib\site-packages\django-1.11.8-py3.6.egg\django\db\models\sql\query.py", line 1270, in _add_q
    current_negated, allow_joins, split_subq)
  File "D:\ProgramFiles\Anaconda3\lib\site-packages\django-1.11.8-py3.6.egg\django\db\models\sql\query.py", line 1276, in _add_q
    allow_joins=allow_joins, split_subq=split_subq,
  File "D:\ProgramFiles\Anaconda3\lib\site-packages\django-1.11.8-py3.6.egg\django\db\models\sql\query.py", line 1201, in build_filter
    raise FieldError('Related Field got invalid lookup: {}'.format(lookups[0]))
django.core.exceptions.FieldError: Related Field got invalid lookup: icontains
exception.py[2018-10-10 09:46:27][ERROR]：Internal Server Error: /admin/mysite/worklog/
Traceback (most recent call last):
  File "D:\ProgramFiles\Anaconda3\lib\site-packages\django-1.11.8-py3.6.egg\django\db\backends\utils.py", line 64, in execute
    return self.cursor.execute(sql, params)
  File "D:\ProgramFiles\Anaconda3\lib\site-packages\django-1.11.8-py3.6.egg\django\db\backends\mysql\base.py", line 101, in execute
    return self.cursor.execute(query, args)
  File "D:\ProgramFiles\Anaconda3\lib\site-packages\pymysql\cursors.py", line 165, in execute
    result = self._query(query)
  File "D:\ProgramFiles\Anaconda3\lib\site-packages\pymysql\cursors.py", line 321, in _query
    conn.query(q)
  File "D:\ProgramFiles\Anaconda3\lib\site-packages\pymysql\connections.py", line 860, in query
    self._affected_rows = self._read_query_result(unbuffered=unbuffered)
  File "D:\ProgramFiles\Anaconda3\lib\site-packages\pymysql\connections.py", line 1061, in _read_query_result
    result.read()
  File "D:\ProgramFiles\Anaconda3\lib\site-packages\pymysql\connections.py", line 1349, in read
    first_packet = self.connection._read_packet()
  File "D:\ProgramFiles\Anaconda3\lib\site-packages\pymysql\connections.py", line 1018, in _read_packet
    packet.check_error()
  File "D:\ProgramFiles\Anaconda3\lib\site-packages\pymysql\connections.py", line 384, in check_error
    err.raise_mysql_exception(self._data)
  File "D:\ProgramFiles\Anaconda3\lib\site-packages\pymysql\err.py", line 107, in raise_mysql_exception
    raise errorclass(errno, errval)
pymysql.err.InternalError: (1271, "Illegal mix of collations for operation 'like'")

The above exception was the direct cause of the following exception:

Traceback (most recent call last):
  File "D:\ProgramFiles\Anaconda3\lib\site-packages\django-1.11.8-py3.6.egg\django\core\handlers\exception.py", line 41, in inner
    response = get_response(request)
  File "D:\ProgramFiles\Anaconda3\lib\site-packages\django-1.11.8-py3.6.egg\django\core\handlers\base.py", line 249, in _legacy_get_response
    response = self._get_response(request)
  File "D:\ProgramFiles\Anaconda3\lib\site-packages\django-1.11.8-py3.6.egg\django\core\handlers\base.py", line 187, in _get_response
    response = self.process_exception_by_middleware(e, request)
  File "D:\ProgramFiles\Anaconda3\lib\site-packages\django-1.11.8-py3.6.egg\django\core\handlers\base.py", line 185, in _get_response
    response = wrapped_callback(request, *callback_args, **callback_kwargs)
  File "D:\ProgramFiles\Anaconda3\lib\site-packages\django-1.11.8-py3.6.egg\django\contrib\admin\options.py", line 551, in wrapper
    return self.admin_site.admin_view(view)(*args, **kwargs)
  File "D:\ProgramFiles\Anaconda3\lib\site-packages\django-1.11.8-py3.6.egg\django\utils\decorators.py", line 149, in _wrapped_view
    response = view_func(request, *args, **kwargs)
  File "D:\ProgramFiles\Anaconda3\lib\site-packages\django-1.11.8-py3.6.egg\django\views\decorators\cache.py", line 57, in _wrapped_view_func
    response = view_func(request, *args, **kwargs)
  File "D:\ProgramFiles\Anaconda3\lib\site-packages\django-1.11.8-py3.6.egg\django\contrib\admin\sites.py", line 224, in inner
    return view(request, *args, **kwargs)
  File "D:\ProgramFiles\Anaconda3\lib\site-packages\django-1.11.8-py3.6.egg\django\utils\decorators.py", line 67, in _wrapper
    return bound_func(*args, **kwargs)
  File "D:\ProgramFiles\Anaconda3\lib\site-packages\django-1.11.8-py3.6.egg\django\utils\decorators.py", line 149, in _wrapped_view
    response = view_func(request, *args, **kwargs)
  File "D:\ProgramFiles\Anaconda3\lib\site-packages\django-1.11.8-py3.6.egg\django\utils\decorators.py", line 63, in bound_func
    return func.__get__(self, type(self))(*args2, **kwargs2)
  File "D:\ProgramFiles\Anaconda3\lib\site-packages\django-1.11.8-py3.6.egg\django\contrib\admin\options.py", line 1542, in changelist_view
    self.list_max_show_all, self.list_editable, self,
  File "D:\ProgramFiles\Anaconda3\lib\site-packages\django-1.11.8-py3.6.egg\django\contrib\admin\views\main.py", line 79, in __init__
    self.get_results(request)
  File "D:\ProgramFiles\Anaconda3\lib\site-packages\django-1.11.8-py3.6.egg\django\contrib\admin\views\main.py", line 177, in get_results
    result_count = paginator.count
  File "D:\ProgramFiles\Anaconda3\lib\site-packages\django-1.11.8-py3.6.egg\django\utils\functional.py", line 35, in __get__
    res = instance.__dict__[self.name] = self.func(instance)
  File "D:\ProgramFiles\Anaconda3\lib\site-packages\django-1.11.8-py3.6.egg\django\core\paginator.py", line 79, in count
    return self.object_list.count()
  File "D:\ProgramFiles\Anaconda3\lib\site-packages\django-1.11.8-py3.6.egg\django\db\models\query.py", line 364, in count
    return self.query.get_count(using=self.db)
  File "D:\ProgramFiles\Anaconda3\lib\site-packages\django-1.11.8-py3.6.egg\django\db\models\sql\query.py", line 499, in get_count
    number = obj.get_aggregation(using, ['__count'])['__count']
  File "D:\ProgramFiles\Anaconda3\lib\site-packages\django-1.11.8-py3.6.egg\django\db\models\sql\query.py", line 480, in get_aggregation
    result = compiler.execute_sql(SINGLE)
  File "D:\ProgramFiles\Anaconda3\lib\site-packages\django-1.11.8-py3.6.egg\django\db\models\sql\compiler.py", line 899, in execute_sql
    raise original_exception
  File "D:\ProgramFiles\Anaconda3\lib\site-packages\django-1.11.8-py3.6.egg\django\db\models\sql\compiler.py", line 889, in execute_sql
    cursor.execute(sql, params)
  File "D:\ProgramFiles\Anaconda3\lib\site-packages\django-1.11.8-py3.6.egg\django\db\backends\utils.py", line 79, in execute
    return super(CursorDebugWrapper, self).execute(sql, params)
  File "D:\ProgramFiles\Anaconda3\lib\site-packages\django-1.11.8-py3.6.egg\django\db\backends\utils.py", line 64, in execute
    return self.cursor.execute(sql, params)
  File "D:\ProgramFiles\Anaconda3\lib\site-packages\django-1.11.8-py3.6.egg\django\db\utils.py", line 94, in __exit__
    six.reraise(dj_exc_type, dj_exc_value, traceback)
  File "D:\ProgramFiles\Anaconda3\lib\site-packages\django-1.11.8-py3.6.egg\django\utils\six.py", line 685, in reraise
    raise value.with_traceback(tb)
  File "D:\ProgramFiles\Anaconda3\lib\site-packages\django-1.11.8-py3.6.egg\django\db\backends\utils.py", line 64, in execute
    return self.cursor.execute(sql, params)
  File "D:\ProgramFiles\Anaconda3\lib\site-packages\django-1.11.8-py3.6.egg\django\db\backends\mysql\base.py", line 101, in execute
    return self.cursor.execute(query, args)
  File "D:\ProgramFiles\Anaconda3\lib\site-packages\pymysql\cursors.py", line 165, in execute
    result = self._query(query)
  File "D:\ProgramFiles\Anaconda3\lib\site-packages\pymysql\cursors.py", line 321, in _query
    conn.query(q)
  File "D:\ProgramFiles\Anaconda3\lib\site-packages\pymysql\connections.py", line 860, in query
    self._affected_rows = self._read_query_result(unbuffered=unbuffered)
  File "D:\ProgramFiles\Anaconda3\lib\site-packages\pymysql\connections.py", line 1061, in _read_query_result
    result.read()
  File "D:\ProgramFiles\Anaconda3\lib\site-packages\pymysql\connections.py", line 1349, in read
    first_packet = self.connection._read_packet()
  File "D:\ProgramFiles\Anaconda3\lib\site-packages\pymysql\connections.py", line 1018, in _read_packet
    packet.check_error()
  File "D:\ProgramFiles\Anaconda3\lib\site-packages\pymysql\connections.py", line 384, in check_error
    err.raise_mysql_exception(self._data)
  File "D:\ProgramFiles\Anaconda3\lib\site-packages\pymysql\err.py", line 107, in raise_mysql_exception
    raise errorclass(errno, errval)
django.db.utils.InternalError: (1271, "Illegal mix of collations for operation 'like'")
exception.py[2018-10-10 09:46:55][ERROR]：Internal Server Error: /admin/mysite/worklog/
Traceback (most recent call last):
  File "D:\ProgramFiles\Anaconda3\lib\site-packages\django-1.11.8-py3.6.egg\django\db\backends\utils.py", line 64, in execute
    return self.cursor.execute(sql, params)
  File "D:\ProgramFiles\Anaconda3\lib\site-packages\django-1.11.8-py3.6.egg\django\db\backends\mysql\base.py", line 101, in execute
    return self.cursor.execute(query, args)
  File "D:\ProgramFiles\Anaconda3\lib\site-packages\pymysql\cursors.py", line 165, in execute
    result = self._query(query)
  File "D:\ProgramFiles\Anaconda3\lib\site-packages\pymysql\cursors.py", line 321, in _query
    conn.query(q)
  File "D:\ProgramFiles\Anaconda3\lib\site-packages\pymysql\connections.py", line 860, in query
    self._affected_rows = self._read_query_result(unbuffered=unbuffered)
  File "D:\ProgramFiles\Anaconda3\lib\site-packages\pymysql\connections.py", line 1061, in _read_query_result
    result.read()
  File "D:\ProgramFiles\Anaconda3\lib\site-packages\pymysql\connections.py", line 1349, in read
    first_packet = self.connection._read_packet()
  File "D:\ProgramFiles\Anaconda3\lib\site-packages\pymysql\connections.py", line 1018, in _read_packet
    packet.check_error()
  File "D:\ProgramFiles\Anaconda3\lib\site-packages\pymysql\connections.py", line 384, in check_error
    err.raise_mysql_exception(self._data)
  File "D:\ProgramFiles\Anaconda3\lib\site-packages\pymysql\err.py", line 107, in raise_mysql_exception
    raise errorclass(errno, errval)
pymysql.err.InternalError: (1271, "Illegal mix of collations for operation 'like'")

The above exception was the direct cause of the following exception:

Traceback (most recent call last):
  File "D:\ProgramFiles\Anaconda3\lib\site-packages\django-1.11.8-py3.6.egg\django\core\handlers\exception.py", line 41, in inner
    response = get_response(request)
  File "D:\ProgramFiles\Anaconda3\lib\site-packages\django-1.11.8-py3.6.egg\django\core\handlers\base.py", line 249, in _legacy_get_response
    response = self._get_response(request)
  File "D:\ProgramFiles\Anaconda3\lib\site-packages\django-1.11.8-py3.6.egg\django\core\handlers\base.py", line 187, in _get_response
    response = self.process_exception_by_middleware(e, request)
  File "D:\ProgramFiles\Anaconda3\lib\site-packages\django-1.11.8-py3.6.egg\django\core\handlers\base.py", line 185, in _get_response
    response = wrapped_callback(request, *callback_args, **callback_kwargs)
  File "D:\ProgramFiles\Anaconda3\lib\site-packages\django-1.11.8-py3.6.egg\django\contrib\admin\options.py", line 551, in wrapper
    return self.admin_site.admin_view(view)(*args, **kwargs)
  File "D:\ProgramFiles\Anaconda3\lib\site-packages\django-1.11.8-py3.6.egg\django\utils\decorators.py", line 149, in _wrapped_view
    response = view_func(request, *args, **kwargs)
  File "D:\ProgramFiles\Anaconda3\lib\site-packages\django-1.11.8-py3.6.egg\django\views\decorators\cache.py", line 57, in _wrapped_view_func
    response = view_func(request, *args, **kwargs)
  File "D:\ProgramFiles\Anaconda3\lib\site-packages\django-1.11.8-py3.6.egg\django\contrib\admin\sites.py", line 224, in inner
    return view(request, *args, **kwargs)
  File "D:\ProgramFiles\Anaconda3\lib\site-packages\django-1.11.8-py3.6.egg\django\utils\decorators.py", line 67, in _wrapper
    return bound_func(*args, **kwargs)
  File "D:\ProgramFiles\Anaconda3\lib\site-packages\django-1.11.8-py3.6.egg\django\utils\decorators.py", line 149, in _wrapped_view
    response = view_func(request, *args, **kwargs)
  File "D:\ProgramFiles\Anaconda3\lib\site-packages\django-1.11.8-py3.6.egg\django\utils\decorators.py", line 63, in bound_func
    return func.__get__(self, type(self))(*args2, **kwargs2)
  File "D:\ProgramFiles\Anaconda3\lib\site-packages\django-1.11.8-py3.6.egg\django\contrib\admin\options.py", line 1542, in changelist_view
    self.list_max_show_all, self.list_editable, self,
  File "D:\ProgramFiles\Anaconda3\lib\site-packages\django-1.11.8-py3.6.egg\django\contrib\admin\views\main.py", line 79, in __init__
    self.get_results(request)
  File "D:\ProgramFiles\Anaconda3\lib\site-packages\django-1.11.8-py3.6.egg\django\contrib\admin\views\main.py", line 177, in get_results
    result_count = paginator.count
  File "D:\ProgramFiles\Anaconda3\lib\site-packages\django-1.11.8-py3.6.egg\django\utils\functional.py", line 35, in __get__
    res = instance.__dict__[self.name] = self.func(instance)
  File "D:\ProgramFiles\Anaconda3\lib\site-packages\django-1.11.8-py3.6.egg\django\core\paginator.py", line 79, in count
    return self.object_list.count()
  File "D:\ProgramFiles\Anaconda3\lib\site-packages\django-1.11.8-py3.6.egg\django\db\models\query.py", line 364, in count
    return self.query.get_count(using=self.db)
  File "D:\ProgramFiles\Anaconda3\lib\site-packages\django-1.11.8-py3.6.egg\django\db\models\sql\query.py", line 499, in get_count
    number = obj.get_aggregation(using, ['__count'])['__count']
  File "D:\ProgramFiles\Anaconda3\lib\site-packages\django-1.11.8-py3.6.egg\django\db\models\sql\query.py", line 480, in get_aggregation
    result = compiler.execute_sql(SINGLE)
  File "D:\ProgramFiles\Anaconda3\lib\site-packages\django-1.11.8-py3.6.egg\django\db\models\sql\compiler.py", line 899, in execute_sql
    raise original_exception
  File "D:\ProgramFiles\Anaconda3\lib\site-packages\django-1.11.8-py3.6.egg\django\db\models\sql\compiler.py", line 889, in execute_sql
    cursor.execute(sql, params)
  File "D:\ProgramFiles\Anaconda3\lib\site-packages\django-1.11.8-py3.6.egg\django\db\backends\utils.py", line 79, in execute
    return super(CursorDebugWrapper, self).execute(sql, params)
  File "D:\ProgramFiles\Anaconda3\lib\site-packages\django-1.11.8-py3.6.egg\django\db\backends\utils.py", line 64, in execute
    return self.cursor.execute(sql, params)
  File "D:\ProgramFiles\Anaconda3\lib\site-packages\django-1.11.8-py3.6.egg\django\db\utils.py", line 94, in __exit__
    six.reraise(dj_exc_type, dj_exc_value, traceback)
  File "D:\ProgramFiles\Anaconda3\lib\site-packages\django-1.11.8-py3.6.egg\django\utils\six.py", line 685, in reraise
    raise value.with_traceback(tb)
  File "D:\ProgramFiles\Anaconda3\lib\site-packages\django-1.11.8-py3.6.egg\django\db\backends\utils.py", line 64, in execute
    return self.cursor.execute(sql, params)
  File "D:\ProgramFiles\Anaconda3\lib\site-packages\django-1.11.8-py3.6.egg\django\db\backends\mysql\base.py", line 101, in execute
    return self.cursor.execute(query, args)
  File "D:\ProgramFiles\Anaconda3\lib\site-packages\pymysql\cursors.py", line 165, in execute
    result = self._query(query)
  File "D:\ProgramFiles\Anaconda3\lib\site-packages\pymysql\cursors.py", line 321, in _query
    conn.query(q)
  File "D:\ProgramFiles\Anaconda3\lib\site-packages\pymysql\connections.py", line 860, in query
    self._affected_rows = self._read_query_result(unbuffered=unbuffered)
  File "D:\ProgramFiles\Anaconda3\lib\site-packages\pymysql\connections.py", line 1061, in _read_query_result
    result.read()
  File "D:\ProgramFiles\Anaconda3\lib\site-packages\pymysql\connections.py", line 1349, in read
    first_packet = self.connection._read_packet()
  File "D:\ProgramFiles\Anaconda3\lib\site-packages\pymysql\connections.py", line 1018, in _read_packet
    packet.check_error()
  File "D:\ProgramFiles\Anaconda3\lib\site-packages\pymysql\connections.py", line 384, in check_error
    err.raise_mysql_exception(self._data)
  File "D:\ProgramFiles\Anaconda3\lib\site-packages\pymysql\err.py", line 107, in raise_mysql_exception
    raise errorclass(errno, errval)
django.db.utils.InternalError: (1271, "Illegal mix of collations for operation 'like'")
exception.py[2018-10-10 09:48:30][ERROR]：Internal Server Error: /admin/mysite/worklog/
Traceback (most recent call last):
  File "D:\ProgramFiles\Anaconda3\lib\site-packages\django-1.11.8-py3.6.egg\django\db\backends\utils.py", line 64, in execute
    return self.cursor.execute(sql, params)
  File "D:\ProgramFiles\Anaconda3\lib\site-packages\django-1.11.8-py3.6.egg\django\db\backends\mysql\base.py", line 101, in execute
    return self.cursor.execute(query, args)
  File "D:\ProgramFiles\Anaconda3\lib\site-packages\pymysql\cursors.py", line 165, in execute
    result = self._query(query)
  File "D:\ProgramFiles\Anaconda3\lib\site-packages\pymysql\cursors.py", line 321, in _query
    conn.query(q)
  File "D:\ProgramFiles\Anaconda3\lib\site-packages\pymysql\connections.py", line 860, in query
    self._affected_rows = self._read_query_result(unbuffered=unbuffered)
  File "D:\ProgramFiles\Anaconda3\lib\site-packages\pymysql\connections.py", line 1061, in _read_query_result
    result.read()
  File "D:\ProgramFiles\Anaconda3\lib\site-packages\pymysql\connections.py", line 1349, in read
    first_packet = self.connection._read_packet()
  File "D:\ProgramFiles\Anaconda3\lib\site-packages\pymysql\connections.py", line 1018, in _read_packet
    packet.check_error()
  File "D:\ProgramFiles\Anaconda3\lib\site-packages\pymysql\connections.py", line 384, in check_error
    err.raise_mysql_exception(self._data)
  File "D:\ProgramFiles\Anaconda3\lib\site-packages\pymysql\err.py", line 107, in raise_mysql_exception
    raise errorclass(errno, errval)
pymysql.err.InternalError: (1271, "Illegal mix of collations for operation 'like'")

The above exception was the direct cause of the following exception:

Traceback (most recent call last):
  File "D:\ProgramFiles\Anaconda3\lib\site-packages\django-1.11.8-py3.6.egg\django\core\handlers\exception.py", line 41, in inner
    response = get_response(request)
  File "D:\ProgramFiles\Anaconda3\lib\site-packages\django-1.11.8-py3.6.egg\django\core\handlers\base.py", line 249, in _legacy_get_response
    response = self._get_response(request)
  File "D:\ProgramFiles\Anaconda3\lib\site-packages\django-1.11.8-py3.6.egg\django\core\handlers\base.py", line 187, in _get_response
    response = self.process_exception_by_middleware(e, request)
  File "D:\ProgramFiles\Anaconda3\lib\site-packages\django-1.11.8-py3.6.egg\django\core\handlers\base.py", line 185, in _get_response
    response = wrapped_callback(request, *callback_args, **callback_kwargs)
  File "D:\ProgramFiles\Anaconda3\lib\site-packages\django-1.11.8-py3.6.egg\django\contrib\admin\options.py", line 551, in wrapper
    return self.admin_site.admin_view(view)(*args, **kwargs)
  File "D:\ProgramFiles\Anaconda3\lib\site-packages\django-1.11.8-py3.6.egg\django\utils\decorators.py", line 149, in _wrapped_view
    response = view_func(request, *args, **kwargs)
  File "D:\ProgramFiles\Anaconda3\lib\site-packages\django-1.11.8-py3.6.egg\django\views\decorators\cache.py", line 57, in _wrapped_view_func
    response = view_func(request, *args, **kwargs)
  File "D:\ProgramFiles\Anaconda3\lib\site-packages\django-1.11.8-py3.6.egg\django\contrib\admin\sites.py", line 224, in inner
    return view(request, *args, **kwargs)
  File "D:\ProgramFiles\Anaconda3\lib\site-packages\django-1.11.8-py3.6.egg\django\utils\decorators.py", line 67, in _wrapper
    return bound_func(*args, **kwargs)
  File "D:\ProgramFiles\Anaconda3\lib\site-packages\django-1.11.8-py3.6.egg\django\utils\decorators.py", line 149, in _wrapped_view
    response = view_func(request, *args, **kwargs)
  File "D:\ProgramFiles\Anaconda3\lib\site-packages\django-1.11.8-py3.6.egg\django\utils\decorators.py", line 63, in bound_func
    return func.__get__(self, type(self))(*args2, **kwargs2)
  File "D:\ProgramFiles\Anaconda3\lib\site-packages\django-1.11.8-py3.6.egg\django\contrib\admin\options.py", line 1542, in changelist_view
    self.list_max_show_all, self.list_editable, self,
  File "D:\ProgramFiles\Anaconda3\lib\site-packages\django-1.11.8-py3.6.egg\django\contrib\admin\views\main.py", line 79, in __init__
    self.get_results(request)
  File "D:\ProgramFiles\Anaconda3\lib\site-packages\django-1.11.8-py3.6.egg\django\contrib\admin\views\main.py", line 177, in get_results
    result_count = paginator.count
  File "D:\ProgramFiles\Anaconda3\lib\site-packages\django-1.11.8-py3.6.egg\django\utils\functional.py", line 35, in __get__
    res = instance.__dict__[self.name] = self.func(instance)
  File "D:\ProgramFiles\Anaconda3\lib\site-packages\django-1.11.8-py3.6.egg\django\core\paginator.py", line 79, in count
    return self.object_list.count()
  File "D:\ProgramFiles\Anaconda3\lib\site-packages\django-1.11.8-py3.6.egg\django\db\models\query.py", line 364, in count
    return self.query.get_count(using=self.db)
  File "D:\ProgramFiles\Anaconda3\lib\site-packages\django-1.11.8-py3.6.egg\django\db\models\sql\query.py", line 499, in get_count
    number = obj.get_aggregation(using, ['__count'])['__count']
  File "D:\ProgramFiles\Anaconda3\lib\site-packages\django-1.11.8-py3.6.egg\django\db\models\sql\query.py", line 480, in get_aggregation
    result = compiler.execute_sql(SINGLE)
  File "D:\ProgramFiles\Anaconda3\lib\site-packages\django-1.11.8-py3.6.egg\django\db\models\sql\compiler.py", line 899, in execute_sql
    raise original_exception
  File "D:\ProgramFiles\Anaconda3\lib\site-packages\django-1.11.8-py3.6.egg\django\db\models\sql\compiler.py", line 889, in execute_sql
    cursor.execute(sql, params)
  File "D:\ProgramFiles\Anaconda3\lib\site-packages\django-1.11.8-py3.6.egg\django\db\backends\utils.py", line 79, in execute
    return super(CursorDebugWrapper, self).execute(sql, params)
  File "D:\ProgramFiles\Anaconda3\lib\site-packages\django-1.11.8-py3.6.egg\django\db\backends\utils.py", line 64, in execute
    return self.cursor.execute(sql, params)
  File "D:\ProgramFiles\Anaconda3\lib\site-packages\django-1.11.8-py3.6.egg\django\db\utils.py", line 94, in __exit__
    six.reraise(dj_exc_type, dj_exc_value, traceback)
  File "D:\ProgramFiles\Anaconda3\lib\site-packages\django-1.11.8-py3.6.egg\django\utils\six.py", line 685, in reraise
    raise value.with_traceback(tb)
  File "D:\ProgramFiles\Anaconda3\lib\site-packages\django-1.11.8-py3.6.egg\django\db\backends\utils.py", line 64, in execute
    return self.cursor.execute(sql, params)
  File "D:\ProgramFiles\Anaconda3\lib\site-packages\django-1.11.8-py3.6.egg\django\db\backends\mysql\base.py", line 101, in execute
    return self.cursor.execute(query, args)
  File "D:\ProgramFiles\Anaconda3\lib\site-packages\pymysql\cursors.py", line 165, in execute
    result = self._query(query)
  File "D:\ProgramFiles\Anaconda3\lib\site-packages\pymysql\cursors.py", line 321, in _query
    conn.query(q)
  File "D:\ProgramFiles\Anaconda3\lib\site-packages\pymysql\connections.py", line 860, in query
    self._affected_rows = self._read_query_result(unbuffered=unbuffered)
  File "D:\ProgramFiles\Anaconda3\lib\site-packages\pymysql\connections.py", line 1061, in _read_query_result
    result.read()
  File "D:\ProgramFiles\Anaconda3\lib\site-packages\pymysql\connections.py", line 1349, in read
    first_packet = self.connection._read_packet()
  File "D:\ProgramFiles\Anaconda3\lib\site-packages\pymysql\connections.py", line 1018, in _read_packet
    packet.check_error()
  File "D:\ProgramFiles\Anaconda3\lib\site-packages\pymysql\connections.py", line 384, in check_error
    err.raise_mysql_exception(self._data)
  File "D:\ProgramFiles\Anaconda3\lib\site-packages\pymysql\err.py", line 107, in raise_mysql_exception
    raise errorclass(errno, errval)
django.db.utils.InternalError: (1271, "Illegal mix of collations for operation 'like'")
exception.py[2018-10-10 09:48:42][ERROR]：Internal Server Error: /admin/mysite/worklog/
Traceback (most recent call last):
  File "D:\ProgramFiles\Anaconda3\lib\site-packages\django-1.11.8-py3.6.egg\django\db\backends\utils.py", line 64, in execute
    return self.cursor.execute(sql, params)
  File "D:\ProgramFiles\Anaconda3\lib\site-packages\django-1.11.8-py3.6.egg\django\db\backends\mysql\base.py", line 101, in execute
    return self.cursor.execute(query, args)
  File "D:\ProgramFiles\Anaconda3\lib\site-packages\pymysql\cursors.py", line 165, in execute
    result = self._query(query)
  File "D:\ProgramFiles\Anaconda3\lib\site-packages\pymysql\cursors.py", line 321, in _query
    conn.query(q)
  File "D:\ProgramFiles\Anaconda3\lib\site-packages\pymysql\connections.py", line 860, in query
    self._affected_rows = self._read_query_result(unbuffered=unbuffered)
  File "D:\ProgramFiles\Anaconda3\lib\site-packages\pymysql\connections.py", line 1061, in _read_query_result
    result.read()
  File "D:\ProgramFiles\Anaconda3\lib\site-packages\pymysql\connections.py", line 1349, in read
    first_packet = self.connection._read_packet()
  File "D:\ProgramFiles\Anaconda3\lib\site-packages\pymysql\connections.py", line 1018, in _read_packet
    packet.check_error()
  File "D:\ProgramFiles\Anaconda3\lib\site-packages\pymysql\connections.py", line 384, in check_error
    err.raise_mysql_exception(self._data)
  File "D:\ProgramFiles\Anaconda3\lib\site-packages\pymysql\err.py", line 107, in raise_mysql_exception
    raise errorclass(errno, errval)
pymysql.err.InternalError: (1271, "Illegal mix of collations for operation 'like'")

The above exception was the direct cause of the following exception:

Traceback (most recent call last):
  File "D:\ProgramFiles\Anaconda3\lib\site-packages\django-1.11.8-py3.6.egg\django\core\handlers\exception.py", line 41, in inner
    response = get_response(request)
  File "D:\ProgramFiles\Anaconda3\lib\site-packages\django-1.11.8-py3.6.egg\django\core\handlers\base.py", line 249, in _legacy_get_response
    response = self._get_response(request)
  File "D:\ProgramFiles\Anaconda3\lib\site-packages\django-1.11.8-py3.6.egg\django\core\handlers\base.py", line 187, in _get_response
    response = self.process_exception_by_middleware(e, request)
  File "D:\ProgramFiles\Anaconda3\lib\site-packages\django-1.11.8-py3.6.egg\django\core\handlers\base.py", line 185, in _get_response
    response = wrapped_callback(request, *callback_args, **callback_kwargs)
  File "D:\ProgramFiles\Anaconda3\lib\site-packages\django-1.11.8-py3.6.egg\django\contrib\admin\options.py", line 551, in wrapper
    return self.admin_site.admin_view(view)(*args, **kwargs)
  File "D:\ProgramFiles\Anaconda3\lib\site-packages\django-1.11.8-py3.6.egg\django\utils\decorators.py", line 149, in _wrapped_view
    response = view_func(request, *args, **kwargs)
  File "D:\ProgramFiles\Anaconda3\lib\site-packages\django-1.11.8-py3.6.egg\django\views\decorators\cache.py", line 57, in _wrapped_view_func
    response = view_func(request, *args, **kwargs)
  File "D:\ProgramFiles\Anaconda3\lib\site-packages\django-1.11.8-py3.6.egg\django\contrib\admin\sites.py", line 224, in inner
    return view(request, *args, **kwargs)
  File "D:\ProgramFiles\Anaconda3\lib\site-packages\django-1.11.8-py3.6.egg\django\utils\decorators.py", line 67, in _wrapper
    return bound_func(*args, **kwargs)
  File "D:\ProgramFiles\Anaconda3\lib\site-packages\django-1.11.8-py3.6.egg\django\utils\decorators.py", line 149, in _wrapped_view
    response = view_func(request, *args, **kwargs)
  File "D:\ProgramFiles\Anaconda3\lib\site-packages\django-1.11.8-py3.6.egg\django\utils\decorators.py", line 63, in bound_func
    return func.__get__(self, type(self))(*args2, **kwargs2)
  File "D:\ProgramFiles\Anaconda3\lib\site-packages\django-1.11.8-py3.6.egg\django\contrib\admin\options.py", line 1542, in changelist_view
    self.list_max_show_all, self.list_editable, self,
  File "D:\ProgramFiles\Anaconda3\lib\site-packages\django-1.11.8-py3.6.egg\django\contrib\admin\views\main.py", line 79, in __init__
    self.get_results(request)
  File "D:\ProgramFiles\Anaconda3\lib\site-packages\django-1.11.8-py3.6.egg\django\contrib\admin\views\main.py", line 177, in get_results
    result_count = paginator.count
  File "D:\ProgramFiles\Anaconda3\lib\site-packages\django-1.11.8-py3.6.egg\django\utils\functional.py", line 35, in __get__
    res = instance.__dict__[self.name] = self.func(instance)
  File "D:\ProgramFiles\Anaconda3\lib\site-packages\django-1.11.8-py3.6.egg\django\core\paginator.py", line 79, in count
    return self.object_list.count()
  File "D:\ProgramFiles\Anaconda3\lib\site-packages\django-1.11.8-py3.6.egg\django\db\models\query.py", line 364, in count
    return self.query.get_count(using=self.db)
  File "D:\ProgramFiles\Anaconda3\lib\site-packages\django-1.11.8-py3.6.egg\django\db\models\sql\query.py", line 499, in get_count
    number = obj.get_aggregation(using, ['__count'])['__count']
  File "D:\ProgramFiles\Anaconda3\lib\site-packages\django-1.11.8-py3.6.egg\django\db\models\sql\query.py", line 480, in get_aggregation
    result = compiler.execute_sql(SINGLE)
  File "D:\ProgramFiles\Anaconda3\lib\site-packages\django-1.11.8-py3.6.egg\django\db\models\sql\compiler.py", line 899, in execute_sql
    raise original_exception
  File "D:\ProgramFiles\Anaconda3\lib\site-packages\django-1.11.8-py3.6.egg\django\db\models\sql\compiler.py", line 889, in execute_sql
    cursor.execute(sql, params)
  File "D:\ProgramFiles\Anaconda3\lib\site-packages\django-1.11.8-py3.6.egg\django\db\backends\utils.py", line 79, in execute
    return super(CursorDebugWrapper, self).execute(sql, params)
  File "D:\ProgramFiles\Anaconda3\lib\site-packages\django-1.11.8-py3.6.egg\django\db\backends\utils.py", line 64, in execute
    return self.cursor.execute(sql, params)
  File "D:\ProgramFiles\Anaconda3\lib\site-packages\django-1.11.8-py3.6.egg\django\db\utils.py", line 94, in __exit__
    six.reraise(dj_exc_type, dj_exc_value, traceback)
  File "D:\ProgramFiles\Anaconda3\lib\site-packages\django-1.11.8-py3.6.egg\django\utils\six.py", line 685, in reraise
    raise value.with_traceback(tb)
  File "D:\ProgramFiles\Anaconda3\lib\site-packages\django-1.11.8-py3.6.egg\django\db\backends\utils.py", line 64, in execute
    return self.cursor.execute(sql, params)
  File "D:\ProgramFiles\Anaconda3\lib\site-packages\django-1.11.8-py3.6.egg\django\db\backends\mysql\base.py", line 101, in execute
    return self.cursor.execute(query, args)
  File "D:\ProgramFiles\Anaconda3\lib\site-packages\pymysql\cursors.py", line 165, in execute
    result = self._query(query)
  File "D:\ProgramFiles\Anaconda3\lib\site-packages\pymysql\cursors.py", line 321, in _query
    conn.query(q)
  File "D:\ProgramFiles\Anaconda3\lib\site-packages\pymysql\connections.py", line 860, in query
    self._affected_rows = self._read_query_result(unbuffered=unbuffered)
  File "D:\ProgramFiles\Anaconda3\lib\site-packages\pymysql\connections.py", line 1061, in _read_query_result
    result.read()
  File "D:\ProgramFiles\Anaconda3\lib\site-packages\pymysql\connections.py", line 1349, in read
    first_packet = self.connection._read_packet()
  File "D:\ProgramFiles\Anaconda3\lib\site-packages\pymysql\connections.py", line 1018, in _read_packet
    packet.check_error()
  File "D:\ProgramFiles\Anaconda3\lib\site-packages\pymysql\connections.py", line 384, in check_error
    err.raise_mysql_exception(self._data)
  File "D:\ProgramFiles\Anaconda3\lib\site-packages\pymysql\err.py", line 107, in raise_mysql_exception
    raise errorclass(errno, errval)
django.db.utils.InternalError: (1271, "Illegal mix of collations for operation 'like'")
exception.py[2018-10-10 09:49:36][ERROR]：Internal Server Error: /admin/mysite/worklog/
Traceback (most recent call last):
  File "D:\ProgramFiles\Anaconda3\lib\site-packages\django-1.11.8-py3.6.egg\django\db\backends\utils.py", line 64, in execute
    return self.cursor.execute(sql, params)
  File "D:\ProgramFiles\Anaconda3\lib\site-packages\django-1.11.8-py3.6.egg\django\db\backends\mysql\base.py", line 101, in execute
    return self.cursor.execute(query, args)
  File "D:\ProgramFiles\Anaconda3\lib\site-packages\pymysql\cursors.py", line 165, in execute
    result = self._query(query)
  File "D:\ProgramFiles\Anaconda3\lib\site-packages\pymysql\cursors.py", line 321, in _query
    conn.query(q)
  File "D:\ProgramFiles\Anaconda3\lib\site-packages\pymysql\connections.py", line 860, in query
    self._affected_rows = self._read_query_result(unbuffered=unbuffered)
  File "D:\ProgramFiles\Anaconda3\lib\site-packages\pymysql\connections.py", line 1061, in _read_query_result
    result.read()
  File "D:\ProgramFiles\Anaconda3\lib\site-packages\pymysql\connections.py", line 1349, in read
    first_packet = self.connection._read_packet()
  File "D:\ProgramFiles\Anaconda3\lib\site-packages\pymysql\connections.py", line 1018, in _read_packet
    packet.check_error()
  File "D:\ProgramFiles\Anaconda3\lib\site-packages\pymysql\connections.py", line 384, in check_error
    err.raise_mysql_exception(self._data)
  File "D:\ProgramFiles\Anaconda3\lib\site-packages\pymysql\err.py", line 107, in raise_mysql_exception
    raise errorclass(errno, errval)
pymysql.err.InternalError: (1271, "Illegal mix of collations for operation 'like'")

The above exception was the direct cause of the following exception:

Traceback (most recent call last):
  File "D:\ProgramFiles\Anaconda3\lib\site-packages\django-1.11.8-py3.6.egg\django\core\handlers\exception.py", line 41, in inner
    response = get_response(request)
  File "D:\ProgramFiles\Anaconda3\lib\site-packages\django-1.11.8-py3.6.egg\django\core\handlers\base.py", line 249, in _legacy_get_response
    response = self._get_response(request)
  File "D:\ProgramFiles\Anaconda3\lib\site-packages\django-1.11.8-py3.6.egg\django\core\handlers\base.py", line 187, in _get_response
    response = self.process_exception_by_middleware(e, request)
  File "D:\ProgramFiles\Anaconda3\lib\site-packages\django-1.11.8-py3.6.egg\django\core\handlers\base.py", line 185, in _get_response
    response = wrapped_callback(request, *callback_args, **callback_kwargs)
  File "D:\ProgramFiles\Anaconda3\lib\site-packages\django-1.11.8-py3.6.egg\django\contrib\admin\options.py", line 551, in wrapper
    return self.admin_site.admin_view(view)(*args, **kwargs)
  File "D:\ProgramFiles\Anaconda3\lib\site-packages\django-1.11.8-py3.6.egg\django\utils\decorators.py", line 149, in _wrapped_view
    response = view_func(request, *args, **kwargs)
  File "D:\ProgramFiles\Anaconda3\lib\site-packages\django-1.11.8-py3.6.egg\django\views\decorators\cache.py", line 57, in _wrapped_view_func
    response = view_func(request, *args, **kwargs)
  File "D:\ProgramFiles\Anaconda3\lib\site-packages\django-1.11.8-py3.6.egg\django\contrib\admin\sites.py", line 224, in inner
    return view(request, *args, **kwargs)
  File "D:\ProgramFiles\Anaconda3\lib\site-packages\django-1.11.8-py3.6.egg\django\utils\decorators.py", line 67, in _wrapper
    return bound_func(*args, **kwargs)
  File "D:\ProgramFiles\Anaconda3\lib\site-packages\django-1.11.8-py3.6.egg\django\utils\decorators.py", line 149, in _wrapped_view
    response = view_func(request, *args, **kwargs)
  File "D:\ProgramFiles\Anaconda3\lib\site-packages\django-1.11.8-py3.6.egg\django\utils\decorators.py", line 63, in bound_func
    return func.__get__(self, type(self))(*args2, **kwargs2)
  File "D:\ProgramFiles\Anaconda3\lib\site-packages\django-1.11.8-py3.6.egg\django\contrib\admin\options.py", line 1542, in changelist_view
    self.list_max_show_all, self.list_editable, self,
  File "D:\ProgramFiles\Anaconda3\lib\site-packages\django-1.11.8-py3.6.egg\django\contrib\admin\views\main.py", line 79, in __init__
    self.get_results(request)
  File "D:\ProgramFiles\Anaconda3\lib\site-packages\django-1.11.8-py3.6.egg\django\contrib\admin\views\main.py", line 177, in get_results
    result_count = paginator.count
  File "D:\ProgramFiles\Anaconda3\lib\site-packages\django-1.11.8-py3.6.egg\django\utils\functional.py", line 35, in __get__
    res = instance.__dict__[self.name] = self.func(instance)
  File "D:\ProgramFiles\Anaconda3\lib\site-packages\django-1.11.8-py3.6.egg\django\core\paginator.py", line 79, in count
    return self.object_list.count()
  File "D:\ProgramFiles\Anaconda3\lib\site-packages\django-1.11.8-py3.6.egg\django\db\models\query.py", line 364, in count
    return self.query.get_count(using=self.db)
  File "D:\ProgramFiles\Anaconda3\lib\site-packages\django-1.11.8-py3.6.egg\django\db\models\sql\query.py", line 499, in get_count
    number = obj.get_aggregation(using, ['__count'])['__count']
  File "D:\ProgramFiles\Anaconda3\lib\site-packages\django-1.11.8-py3.6.egg\django\db\models\sql\query.py", line 480, in get_aggregation
    result = compiler.execute_sql(SINGLE)
  File "D:\ProgramFiles\Anaconda3\lib\site-packages\django-1.11.8-py3.6.egg\django\db\models\sql\compiler.py", line 899, in execute_sql
    raise original_exception
  File "D:\ProgramFiles\Anaconda3\lib\site-packages\django-1.11.8-py3.6.egg\django\db\models\sql\compiler.py", line 889, in execute_sql
    cursor.execute(sql, params)
  File "D:\ProgramFiles\Anaconda3\lib\site-packages\django-1.11.8-py3.6.egg\django\db\backends\utils.py", line 79, in execute
    return super(CursorDebugWrapper, self).execute(sql, params)
  File "D:\ProgramFiles\Anaconda3\lib\site-packages\django-1.11.8-py3.6.egg\django\db\backends\utils.py", line 64, in execute
    return self.cursor.execute(sql, params)
  File "D:\ProgramFiles\Anaconda3\lib\site-packages\django-1.11.8-py3.6.egg\django\db\utils.py", line 94, in __exit__
    six.reraise(dj_exc_type, dj_exc_value, traceback)
  File "D:\ProgramFiles\Anaconda3\lib\site-packages\django-1.11.8-py3.6.egg\django\utils\six.py", line 685, in reraise
    raise value.with_traceback(tb)
  File "D:\ProgramFiles\Anaconda3\lib\site-packages\django-1.11.8-py3.6.egg\django\db\backends\utils.py", line 64, in execute
    return self.cursor.execute(sql, params)
  File "D:\ProgramFiles\Anaconda3\lib\site-packages\django-1.11.8-py3.6.egg\django\db\backends\mysql\base.py", line 101, in execute
    return self.cursor.execute(query, args)
  File "D:\ProgramFiles\Anaconda3\lib\site-packages\pymysql\cursors.py", line 165, in execute
    result = self._query(query)
  File "D:\ProgramFiles\Anaconda3\lib\site-packages\pymysql\cursors.py", line 321, in _query
    conn.query(q)
  File "D:\ProgramFiles\Anaconda3\lib\site-packages\pymysql\connections.py", line 860, in query
    self._affected_rows = self._read_query_result(unbuffered=unbuffered)
  File "D:\ProgramFiles\Anaconda3\lib\site-packages\pymysql\connections.py", line 1061, in _read_query_result
    result.read()
  File "D:\ProgramFiles\Anaconda3\lib\site-packages\pymysql\connections.py", line 1349, in read
    first_packet = self.connection._read_packet()
  File "D:\ProgramFiles\Anaconda3\lib\site-packages\pymysql\connections.py", line 1018, in _read_packet
    packet.check_error()
  File "D:\ProgramFiles\Anaconda3\lib\site-packages\pymysql\connections.py", line 384, in check_error
    err.raise_mysql_exception(self._data)
  File "D:\ProgramFiles\Anaconda3\lib\site-packages\pymysql\err.py", line 107, in raise_mysql_exception
    raise errorclass(errno, errval)
django.db.utils.InternalError: (1271, "Illegal mix of collations for operation 'like'")
base.py[2018-10-10 13:10:01][WARNING]：Not Found: /favicon.ico
