exception.py[2018-07-23 14:46:44][ERROR]：Internal Server Error: /gxjy/
Traceback (most recent call last):
  File "D:\ProgramFiles\Anaconda3\lib\site-packages\django-1.11.8-py3.6.egg\django\core\handlers\exception.py", line 41, in inner
    response = get_response(request)
  File "D:\ProgramFiles\Anaconda3\lib\site-packages\django-1.11.8-py3.6.egg\django\core\handlers\base.py", line 249, in _legacy_get_response
    response = self._get_response(request)
  File "D:\ProgramFiles\Anaconda3\lib\site-packages\django-1.11.8-py3.6.egg\django\core\handlers\base.py", line 187, in _get_response
    response = self.process_exception_by_middleware(e, request)
  File "D:\ProgramFiles\Anaconda3\lib\site-packages\django-1.11.8-py3.6.egg\django\core\handlers\base.py", line 185, in _get_response
    response = wrapped_callback(request, *callback_args, **callback_kwargs)
  File "D:\tools\Tools\Carry\mysite\views.py", line 1249, in gxjy
    ee = h.entry_exit()
  File "D:\tools\Tools\Carry\mysite\HSD.py", line 1451, in entry_exit
    ee = getSqlData(self.conn, sql)
  File "D:\tools\Tools\Carry\mysite\HSD.py", line 147, in getSqlData
    cur.execute(sql)
  File "D:\ProgramFiles\Anaconda3\lib\site-packages\pymysql\cursors.py", line 165, in execute
    result = self._query(query)
  File "D:\ProgramFiles\Anaconda3\lib\site-packages\pymysql\cursors.py", line 321, in _query
    conn.query(q)
  File "D:\ProgramFiles\Anaconda3\lib\site-packages\pymysql\connections.py", line 860, in query
    self._affected_rows = self._read_query_result(unbuffered=unbuffered)
  File "D:\ProgramFiles\Anaconda3\lib\site-packages\pymysql\connections.py", line 1061, in _read_query_result
    result.read()
  File "D:\ProgramFiles\Anaconda3\lib\site-packages\pymysql\connections.py", line 1349, in read
    first_packet = self.connection._read_packet()
  File "D:\ProgramFiles\Anaconda3\lib\site-packages\pymysql\connections.py", line 1018, in _read_packet
    packet.check_error()
  File "D:\ProgramFiles\Anaconda3\lib\site-packages\pymysql\connections.py", line 384, in check_error
    err.raise_mysql_exception(self._data)
  File "D:\ProgramFiles\Anaconda3\lib\site-packages\pymysql\err.py", line 107, in raise_mysql_exception
    raise errorclass(errno, errval)
pymysql.err.ProgrammingError: (1064, '')
exception.py[2018-07-23 14:49:59][ERROR]：Internal Server Error: /gxjy/
Traceback (most recent call last):
  File "D:\ProgramFiles\Anaconda3\lib\site-packages\django-1.11.8-py3.6.egg\django\core\handlers\exception.py", line 41, in inner
    response = get_response(request)
  File "D:\ProgramFiles\Anaconda3\lib\site-packages\django-1.11.8-py3.6.egg\django\core\handlers\base.py", line 249, in _legacy_get_response
    response = self._get_response(request)
  File "D:\ProgramFiles\Anaconda3\lib\site-packages\django-1.11.8-py3.6.egg\django\core\handlers\base.py", line 187, in _get_response
    response = self.process_exception_by_middleware(e, request)
  File "D:\ProgramFiles\Anaconda3\lib\site-packages\django-1.11.8-py3.6.egg\django\core\handlers\base.py", line 185, in _get_response
    response = wrapped_callback(request, *callback_args, **callback_kwargs)
  File "D:\tools\Tools\Carry\mysite\views.py", line 1264, in gxjy
    ind_s = zx_x.index(zx_x2[0])
IndexError: list index out of range
exception.py[2018-07-23 14:50:43][ERROR]：Internal Server Error: /gxjy/
Traceback (most recent call last):
  File "D:\ProgramFiles\Anaconda3\lib\site-packages\django-1.11.8-py3.6.egg\django\core\handlers\exception.py", line 41, in inner
    response = get_response(request)
  File "D:\ProgramFiles\Anaconda3\lib\site-packages\django-1.11.8-py3.6.egg\django\core\handlers\base.py", line 249, in _legacy_get_response
    response = self._get_response(request)
  File "D:\ProgramFiles\Anaconda3\lib\site-packages\django-1.11.8-py3.6.egg\django\core\handlers\base.py", line 187, in _get_response
    response = self.process_exception_by_middleware(e, request)
  File "D:\ProgramFiles\Anaconda3\lib\site-packages\django-1.11.8-py3.6.egg\django\core\handlers\base.py", line 185, in _get_response
    response = wrapped_callback(request, *callback_args, **callback_kwargs)
  File "D:\tools\Tools\Carry\mysite\views.py", line 1264, in gxjy
    ind_s = zx_x.index(zx_x2[0])
IndexError: list index out of range
HSD.py[2018-07-23 16:56:32][ERROR]：文件 HSD.py 第1237行报错：division by zero
HSD.py[2018-07-23 16:58:29][ERROR]：文件 HSD.py 第1237行报错：division by zero
HSD.py[2018-07-23 17:10:20][ERROR]：文件 HSD.py 第1237行报错：division by zero
HSD.py[2018-07-23 17:10:26][ERROR]：文件 HSD.py 第1237行报错：division by zero
exception.py[2018-07-23 17:55:30][ERROR]：Internal Server Error: /gxjy/
Traceback (most recent call last):
  File "D:\ProgramFiles\Anaconda3\lib\site-packages\django-1.11.8-py3.6.egg\django\core\handlers\exception.py", line 41, in inner
    response = get_response(request)
  File "D:\ProgramFiles\Anaconda3\lib\site-packages\django-1.11.8-py3.6.egg\django\core\handlers\base.py", line 249, in _legacy_get_response
    response = self._get_response(request)
  File "D:\ProgramFiles\Anaconda3\lib\site-packages\django-1.11.8-py3.6.egg\django\core\handlers\base.py", line 187, in _get_response
    response = self.process_exception_by_middleware(e, request)
  File "D:\ProgramFiles\Anaconda3\lib\site-packages\django-1.11.8-py3.6.egg\django\core\handlers\base.py", line 185, in _get_response
    response = wrapped_callback(request, *callback_args, **callback_kwargs)
  File "D:\tools\Tools\Carry\mysite\views.py", line 1271, in gxjy
    hc['alljz'].append((init_money+yk-hc['allsxf'])/jzq) if jzq!=0 else 0
TypeError: unsupported operand type(s) for -: 'float' and 'list'
exception.py[2018-07-23 17:56:27][ERROR]：Internal Server Error: /gxjy/
Traceback (most recent call last):
  File "D:\ProgramFiles\Anaconda3\lib\site-packages\django-1.11.8-py3.6.egg\django\core\handlers\exception.py", line 41, in inner
    response = get_response(request)
  File "D:\ProgramFiles\Anaconda3\lib\site-packages\django-1.11.8-py3.6.egg\django\core\handlers\base.py", line 249, in _legacy_get_response
    response = self._get_response(request)
  File "D:\ProgramFiles\Anaconda3\lib\site-packages\django-1.11.8-py3.6.egg\django\core\handlers\base.py", line 187, in _get_response
    response = self.process_exception_by_middleware(e, request)
  File "D:\ProgramFiles\Anaconda3\lib\site-packages\django-1.11.8-py3.6.egg\django\core\handlers\base.py", line 185, in _get_response
    response = wrapped_callback(request, *callback_args, **callback_kwargs)
  File "D:\tools\Tools\Carry\mysite\views.py", line 1271, in gxjy
    hc['alljz'].append((init_money+yk-hc['allsxf'])/jzq if jzq!=0 else 0)
TypeError: unsupported operand type(s) for -: 'float' and 'list'
exception.py[2018-07-23 17:56:57][ERROR]：Internal Server Error: /gxjy/
Traceback (most recent call last):
  File "D:\ProgramFiles\Anaconda3\lib\site-packages\django-1.11.8-py3.6.egg\django\core\handlers\exception.py", line 41, in inner
    response = get_response(request)
  File "D:\ProgramFiles\Anaconda3\lib\site-packages\django-1.11.8-py3.6.egg\django\core\handlers\base.py", line 249, in _legacy_get_response
    response = self._get_response(request)
  File "D:\ProgramFiles\Anaconda3\lib\site-packages\django-1.11.8-py3.6.egg\django\core\handlers\base.py", line 187, in _get_response
    response = self.process_exception_by_middleware(e, request)
  File "D:\ProgramFiles\Anaconda3\lib\site-packages\django-1.11.8-py3.6.egg\django\core\handlers\base.py", line 185, in _get_response
    response = wrapped_callback(request, *callback_args, **callback_kwargs)
  File "D:\tools\Tools\Carry\mysite\views.py", line 1271, in gxjy
    hc['alljz'].append((init_money+yk-hc['allsxf'][-1])/jzq if jzq!=0 else 0)
TypeError: unsupported operand type(s) for -: 'float' and 'list'
exception.py[2018-07-23 17:58:02][ERROR]：Internal Server Error: /gxjy/
Traceback (most recent call last):
  File "D:\ProgramFiles\Anaconda3\lib\site-packages\django-1.11.8-py3.6.egg\django\core\handlers\exception.py", line 41, in inner
    response = get_response(request)
  File "D:\ProgramFiles\Anaconda3\lib\site-packages\django-1.11.8-py3.6.egg\django\core\handlers\base.py", line 249, in _legacy_get_response
    response = self._get_response(request)
  File "D:\ProgramFiles\Anaconda3\lib\site-packages\django-1.11.8-py3.6.egg\django\core\handlers\base.py", line 187, in _get_response
    response = self.process_exception_by_middleware(e, request)
  File "D:\ProgramFiles\Anaconda3\lib\site-packages\django-1.11.8-py3.6.egg\django\core\handlers\base.py", line 185, in _get_response
    response = wrapped_callback(request, *callback_args, **callback_kwargs)
  File "D:\tools\Tools\Carry\mysite\views.py", line 1272, in gxjy
    hc['alljz'].append((init_money+yk-hc['allsxf'][-1])/jzq if jzq!=0 else 0)
TypeError: unsupported operand type(s) for -: 'float' and 'list'
exception.py[2018-07-24 10:54:18][ERROR]：Internal Server Error: /gxjy/
Traceback (most recent call last):
  File "D:\ProgramFiles\Anaconda3\lib\site-packages\django-1.11.8-py3.6.egg\django\core\handlers\exception.py", line 41, in inner
    response = get_response(request)
  File "D:\ProgramFiles\Anaconda3\lib\site-packages\django-1.11.8-py3.6.egg\django\core\handlers\base.py", line 249, in _legacy_get_response
    response = self._get_response(request)
  File "D:\ProgramFiles\Anaconda3\lib\site-packages\django-1.11.8-py3.6.egg\django\core\handlers\base.py", line 187, in _get_response
    response = self.process_exception_by_middleware(e, request)
  File "D:\ProgramFiles\Anaconda3\lib\site-packages\django-1.11.8-py3.6.egg\django\core\handlers\base.py", line 185, in _get_response
    response = wrapped_callback(request, *callback_args, **callback_kwargs)
  File "D:\tools\Tools\Carry\mysite\views.py", line 1267, in gxjy
    hc['allsxf'].append(max(i[18] for i in data if i[1][:10] == de[0] and i[2]==0)+(hc['allsxf'][-1] if hc['allsxf'] else 0))
ValueError: max() arg is an empty sequence
exception.py[2018-07-24 14:20:30][ERROR]：Internal Server Error: /gxjy/
Traceback (most recent call last):
  File "D:\ProgramFiles\Anaconda3\lib\site-packages\django-1.11.8-py3.6.egg\django\core\handlers\exception.py", line 41, in inner
    response = get_response(request)
  File "D:\ProgramFiles\Anaconda3\lib\site-packages\django-1.11.8-py3.6.egg\django\core\handlers\base.py", line 249, in _legacy_get_response
    response = self._get_response(request)
  File "D:\ProgramFiles\Anaconda3\lib\site-packages\django-1.11.8-py3.6.egg\django\core\handlers\base.py", line 187, in _get_response
    response = self.process_exception_by_middleware(e, request)
  File "D:\ProgramFiles\Anaconda3\lib\site-packages\django-1.11.8-py3.6.egg\django\core\handlers\base.py", line 185, in _get_response
    response = wrapped_callback(request, *callback_args, **callback_kwargs)
  File "D:\tools\Tools\Carry\mysite\views.py", line 1247, in gxjy
    data,pzs = h.ray(dd)
  File "D:\tools\Tools\Carry\mysite\HSD.py", line 1635, in ray
    pzs = {self.code_name.get(k):v for k,v in pzs}
  File "D:\tools\Tools\Carry\mysite\HSD.py", line 1635, in <dictcomp>
    pzs = {self.code_name.get(k):v for k,v in pzs}
ValueError: not enough values to unpack (expected 2, got 1)
exception.py[2018-07-24 16:51:48][ERROR]：Internal Server Error: /gxjy/
Traceback (most recent call last):
  File "D:\ProgramFiles\Anaconda3\lib\site-packages\django-1.11.8-py3.6.egg\django\core\handlers\exception.py", line 41, in inner
    response = get_response(request)
  File "D:\ProgramFiles\Anaconda3\lib\site-packages\django-1.11.8-py3.6.egg\django\core\handlers\base.py", line 249, in _legacy_get_response
    response = self._get_response(request)
  File "D:\ProgramFiles\Anaconda3\lib\site-packages\django-1.11.8-py3.6.egg\django\core\handlers\base.py", line 187, in _get_response
    response = self.process_exception_by_middleware(e, request)
  File "D:\ProgramFiles\Anaconda3\lib\site-packages\django-1.11.8-py3.6.egg\django\core\handlers\base.py", line 185, in _get_response
    response = wrapped_callback(request, *callback_args, **callback_kwargs)
  File "D:\tools\Tools\Carry\mysite\views.py", line 1263, in gxjy
    'pie_value': [{'value':i[0],'name':i[1]} for i in pzs.items()], # 饼图的值
AttributeError: 'list' object has no attribute 'items'
exception.py[2018-07-25 09:49:53][ERROR]：Internal Server Error: /gxjy/
Traceback (most recent call last):
  File "D:\ProgramFiles\Anaconda3\lib\site-packages\django-1.11.8-py3.6.egg\django\core\handlers\exception.py", line 41, in inner
    response = get_response(request)
  File "D:\ProgramFiles\Anaconda3\lib\site-packages\django-1.11.8-py3.6.egg\django\core\handlers\base.py", line 249, in _legacy_get_response
    response = self._get_response(request)
  File "D:\ProgramFiles\Anaconda3\lib\site-packages\django-1.11.8-py3.6.egg\django\core\handlers\base.py", line 187, in _get_response
    response = self.process_exception_by_middleware(e, request)
  File "D:\ProgramFiles\Anaconda3\lib\site-packages\django-1.11.8-py3.6.egg\django\core\handlers\base.py", line 185, in _get_response
    response = wrapped_callback(request, *callback_args, **callback_kwargs)
  File "D:\tools\Tools\Carry\mysite\views.py", line 1285, in gxjy
    dd = h.get_gxjy_sql(code) if code else h.get_gxjy_sql()
  File "D:\tools\Tools\Carry\mysite\HSD.py", line 1418, in get_gxjy_sql
    data = getSqlData(self.conn, sql)
  File "D:\tools\Tools\Carry\mysite\HSD.py", line 147, in getSqlData
    cur.execute(sql)
  File "D:\ProgramFiles\Anaconda3\lib\site-packages\pymysql\cursors.py", line 165, in execute
    result = self._query(query)
  File "D:\ProgramFiles\Anaconda3\lib\site-packages\pymysql\cursors.py", line 321, in _query
    conn.query(q)
  File "D:\ProgramFiles\Anaconda3\lib\site-packages\pymysql\connections.py", line 859, in query
    self._execute_command(COMMAND.COM_QUERY, sql)
  File "D:\ProgramFiles\Anaconda3\lib\site-packages\pymysql\connections.py", line 1075, in _execute_command
    raise err.InterfaceError("(0, '')")
pymysql.err.InterfaceError: (0, '')
exception.py[2018-07-25 09:51:18][ERROR]：Internal Server Error: /gxjy/
Traceback (most recent call last):
  File "D:\ProgramFiles\Anaconda3\lib\site-packages\django-1.11.8-py3.6.egg\django\core\handlers\exception.py", line 41, in inner
    response = get_response(request)
  File "D:\ProgramFiles\Anaconda3\lib\site-packages\django-1.11.8-py3.6.egg\django\core\handlers\base.py", line 249, in _legacy_get_response
    response = self._get_response(request)
  File "D:\ProgramFiles\Anaconda3\lib\site-packages\django-1.11.8-py3.6.egg\django\core\handlers\base.py", line 187, in _get_response
    response = self.process_exception_by_middleware(e, request)
  File "D:\ProgramFiles\Anaconda3\lib\site-packages\django-1.11.8-py3.6.egg\django\core\handlers\base.py", line 185, in _get_response
    response = wrapped_callback(request, *callback_args, **callback_kwargs)
  File "D:\tools\Tools\Carry\mysite\views.py", line 1285, in gxjy
    dd = h.get_gxjy_sql()
  File "D:\tools\Tools\Carry\mysite\HSD.py", line 1418, in get_gxjy_sql
    data = getSqlData(self.conn, sql)
  File "D:\tools\Tools\Carry\mysite\HSD.py", line 147, in getSqlData
    cur.execute(sql)
  File "D:\ProgramFiles\Anaconda3\lib\site-packages\pymysql\cursors.py", line 165, in execute
    result = self._query(query)
  File "D:\ProgramFiles\Anaconda3\lib\site-packages\pymysql\cursors.py", line 321, in _query
    conn.query(q)
  File "D:\ProgramFiles\Anaconda3\lib\site-packages\pymysql\connections.py", line 859, in query
    self._execute_command(COMMAND.COM_QUERY, sql)
  File "D:\ProgramFiles\Anaconda3\lib\site-packages\pymysql\connections.py", line 1075, in _execute_command
    raise err.InterfaceError("(0, '')")
pymysql.err.InterfaceError: (0, '')
exception.py[2018-07-25 10:50:06][ERROR]：Internal Server Error: /tj/
Traceback (most recent call last):
  File "D:\ProgramFiles\Anaconda3\lib\site-packages\django-1.11.8-py3.6.egg\django\core\handlers\exception.py", line 41, in inner
    response = get_response(request)
  File "D:\ProgramFiles\Anaconda3\lib\site-packages\django-1.11.8-py3.6.egg\django\core\handlers\base.py", line 249, in _legacy_get_response
    response = self._get_response(request)
  File "D:\ProgramFiles\Anaconda3\lib\site-packages\django-1.11.8-py3.6.egg\django\core\handlers\base.py", line 187, in _get_response
    response = self.process_exception_by_middleware(e, request)
  File "D:\ProgramFiles\Anaconda3\lib\site-packages\django-1.11.8-py3.6.egg\django\core\handlers\base.py", line 185, in _get_response
    response = wrapped_callback(request, *callback_args, **callback_kwargs)
  File "D:\tools\Tools\Carry\mysite\views.py", line 519, in tongji
    results2, huizong = HSD.sp_order_record(rq_date,end_date)
  File "D:\tools\Tools\Carry\mysite\HSD.py", line 480, in sp_order_record
    data = getSqlData(conn, sql_trade)
  File "D:\tools\Tools\Carry\mysite\HSD.py", line 147, in getSqlData
    cur.execute(sql)
  File "D:\ProgramFiles\Anaconda3\lib\site-packages\pymysql\cursors.py", line 165, in execute
    result = self._query(query)
  File "D:\ProgramFiles\Anaconda3\lib\site-packages\pymysql\cursors.py", line 321, in _query
    conn.query(q)
  File "D:\ProgramFiles\Anaconda3\lib\site-packages\pymysql\connections.py", line 860, in query
    self._affected_rows = self._read_query_result(unbuffered=unbuffered)
  File "D:\ProgramFiles\Anaconda3\lib\site-packages\pymysql\connections.py", line 1061, in _read_query_result
    result.read()
  File "D:\ProgramFiles\Anaconda3\lib\site-packages\pymysql\connections.py", line 1349, in read
    first_packet = self.connection._read_packet()
  File "D:\ProgramFiles\Anaconda3\lib\site-packages\pymysql\connections.py", line 1018, in _read_packet
    packet.check_error()
  File "D:\ProgramFiles\Anaconda3\lib\site-packages\pymysql\connections.py", line 384, in check_error
    err.raise_mysql_exception(self._data)
  File "D:\ProgramFiles\Anaconda3\lib\site-packages\pymysql\err.py", line 107, in raise_mysql_exception
    raise errorclass(errno, errval)
pymysql.err.ProgrammingError: (1064, '')
exception.py[2018-07-25 10:50:11][ERROR]：Internal Server Error: /tj/
Traceback (most recent call last):
  File "D:\ProgramFiles\Anaconda3\lib\site-packages\django-1.11.8-py3.6.egg\django\core\handlers\exception.py", line 41, in inner
    response = get_response(request)
  File "D:\ProgramFiles\Anaconda3\lib\site-packages\django-1.11.8-py3.6.egg\django\core\handlers\base.py", line 249, in _legacy_get_response
    response = self._get_response(request)
  File "D:\ProgramFiles\Anaconda3\lib\site-packages\django-1.11.8-py3.6.egg\django\core\handlers\base.py", line 187, in _get_response
    response = self.process_exception_by_middleware(e, request)
  File "D:\ProgramFiles\Anaconda3\lib\site-packages\django-1.11.8-py3.6.egg\django\core\handlers\base.py", line 185, in _get_response
    response = wrapped_callback(request, *callback_args, **callback_kwargs)
  File "D:\tools\Tools\Carry\mysite\views.py", line 519, in tongji
    results2, huizong = HSD.sp_order_record(rq_date,end_date)
  File "D:\tools\Tools\Carry\mysite\HSD.py", line 480, in sp_order_record
    data = getSqlData(conn, sql_trade)
  File "D:\tools\Tools\Carry\mysite\HSD.py", line 147, in getSqlData
    cur.execute(sql)
  File "D:\ProgramFiles\Anaconda3\lib\site-packages\pymysql\cursors.py", line 165, in execute
    result = self._query(query)
  File "D:\ProgramFiles\Anaconda3\lib\site-packages\pymysql\cursors.py", line 321, in _query
    conn.query(q)
  File "D:\ProgramFiles\Anaconda3\lib\site-packages\pymysql\connections.py", line 860, in query
    self._affected_rows = self._read_query_result(unbuffered=unbuffered)
  File "D:\ProgramFiles\Anaconda3\lib\site-packages\pymysql\connections.py", line 1061, in _read_query_result
    result.read()
  File "D:\ProgramFiles\Anaconda3\lib\site-packages\pymysql\connections.py", line 1349, in read
    first_packet = self.connection._read_packet()
  File "D:\ProgramFiles\Anaconda3\lib\site-packages\pymysql\connections.py", line 1018, in _read_packet
    packet.check_error()
  File "D:\ProgramFiles\Anaconda3\lib\site-packages\pymysql\connections.py", line 384, in check_error
    err.raise_mysql_exception(self._data)
  File "D:\ProgramFiles\Anaconda3\lib\site-packages\pymysql\err.py", line 107, in raise_mysql_exception
    raise errorclass(errno, errval)
pymysql.err.ProgrammingError: (1064, '')
exception.py[2018-07-25 10:50:14][ERROR]：Internal Server Error: /tj/
Traceback (most recent call last):
  File "D:\ProgramFiles\Anaconda3\lib\site-packages\django-1.11.8-py3.6.egg\django\core\handlers\exception.py", line 41, in inner
    response = get_response(request)
  File "D:\ProgramFiles\Anaconda3\lib\site-packages\django-1.11.8-py3.6.egg\django\core\handlers\base.py", line 249, in _legacy_get_response
    response = self._get_response(request)
  File "D:\ProgramFiles\Anaconda3\lib\site-packages\django-1.11.8-py3.6.egg\django\core\handlers\base.py", line 187, in _get_response
    response = self.process_exception_by_middleware(e, request)
  File "D:\ProgramFiles\Anaconda3\lib\site-packages\django-1.11.8-py3.6.egg\django\core\handlers\base.py", line 185, in _get_response
    response = wrapped_callback(request, *callback_args, **callback_kwargs)
  File "D:\tools\Tools\Carry\mysite\views.py", line 519, in tongji
    results2, huizong = HSD.sp_order_record(rq_date,end_date)
  File "D:\tools\Tools\Carry\mysite\HSD.py", line 480, in sp_order_record
    data = getSqlData(conn, sql_trade)
  File "D:\tools\Tools\Carry\mysite\HSD.py", line 147, in getSqlData
    cur.execute(sql)
  File "D:\ProgramFiles\Anaconda3\lib\site-packages\pymysql\cursors.py", line 165, in execute
    result = self._query(query)
  File "D:\ProgramFiles\Anaconda3\lib\site-packages\pymysql\cursors.py", line 321, in _query
    conn.query(q)
  File "D:\ProgramFiles\Anaconda3\lib\site-packages\pymysql\connections.py", line 860, in query
    self._affected_rows = self._read_query_result(unbuffered=unbuffered)
  File "D:\ProgramFiles\Anaconda3\lib\site-packages\pymysql\connections.py", line 1061, in _read_query_result
    result.read()
  File "D:\ProgramFiles\Anaconda3\lib\site-packages\pymysql\connections.py", line 1349, in read
    first_packet = self.connection._read_packet()
  File "D:\ProgramFiles\Anaconda3\lib\site-packages\pymysql\connections.py", line 1018, in _read_packet
    packet.check_error()
  File "D:\ProgramFiles\Anaconda3\lib\site-packages\pymysql\connections.py", line 384, in check_error
    err.raise_mysql_exception(self._data)
  File "D:\ProgramFiles\Anaconda3\lib\site-packages\pymysql\err.py", line 107, in raise_mysql_exception
    raise errorclass(errno, errval)
pymysql.err.ProgrammingError: (1064, '')
exception.py[2018-07-25 10:50:18][ERROR]：Internal Server Error: /tj/
Traceback (most recent call last):
  File "D:\ProgramFiles\Anaconda3\lib\site-packages\django-1.11.8-py3.6.egg\django\core\handlers\exception.py", line 41, in inner
    response = get_response(request)
  File "D:\ProgramFiles\Anaconda3\lib\site-packages\django-1.11.8-py3.6.egg\django\core\handlers\base.py", line 249, in _legacy_get_response
    response = self._get_response(request)
  File "D:\ProgramFiles\Anaconda3\lib\site-packages\django-1.11.8-py3.6.egg\django\core\handlers\base.py", line 187, in _get_response
    response = self.process_exception_by_middleware(e, request)
  File "D:\ProgramFiles\Anaconda3\lib\site-packages\django-1.11.8-py3.6.egg\django\core\handlers\base.py", line 185, in _get_response
    response = wrapped_callback(request, *callback_args, **callback_kwargs)
  File "D:\tools\Tools\Carry\mysite\views.py", line 519, in tongji
    results2, huizong = HSD.sp_order_record(rq_date,end_date)
  File "D:\tools\Tools\Carry\mysite\HSD.py", line 480, in sp_order_record
    data = getSqlData(conn, sql_trade)
  File "D:\tools\Tools\Carry\mysite\HSD.py", line 147, in getSqlData
    cur.execute(sql)
  File "D:\ProgramFiles\Anaconda3\lib\site-packages\pymysql\cursors.py", line 165, in execute
    result = self._query(query)
  File "D:\ProgramFiles\Anaconda3\lib\site-packages\pymysql\cursors.py", line 321, in _query
    conn.query(q)
  File "D:\ProgramFiles\Anaconda3\lib\site-packages\pymysql\connections.py", line 860, in query
    self._affected_rows = self._read_query_result(unbuffered=unbuffered)
  File "D:\ProgramFiles\Anaconda3\lib\site-packages\pymysql\connections.py", line 1061, in _read_query_result
    result.read()
  File "D:\ProgramFiles\Anaconda3\lib\site-packages\pymysql\connections.py", line 1349, in read
    first_packet = self.connection._read_packet()
  File "D:\ProgramFiles\Anaconda3\lib\site-packages\pymysql\connections.py", line 1018, in _read_packet
    packet.check_error()
  File "D:\ProgramFiles\Anaconda3\lib\site-packages\pymysql\connections.py", line 384, in check_error
    err.raise_mysql_exception(self._data)
  File "D:\ProgramFiles\Anaconda3\lib\site-packages\pymysql\err.py", line 107, in raise_mysql_exception
    raise errorclass(errno, errval)
pymysql.err.ProgrammingError: (1064, '')
HSD.py[2018-07-25 12:00:58][ERROR]：文件：HSD.py 第1359行报错： (1064, '')
HSD.py[2018-07-25 12:02:05][ERROR]：文件：HSD.py 第1360行报错： (1064, '')
HSD.py[2018-07-25 12:03:05][ERROR]：文件：HSD.py 第1360行报错： (1064, '')
HSD.py[2018-07-25 13:13:53][ERROR]：文件：HSD.py 第1360行报错： (1064, '')
HSD.py[2018-07-25 13:14:21][ERROR]：文件：HSD.py 第1360行报错： (1064, '')
HSD.py[2018-07-25 13:36:14][ERROR]：文件：HSD.py 第1355行报错： list index out of range
exception.py[2018-07-26 14:58:10][ERROR]：Internal Server Error: /gxjy/
Traceback (most recent call last):
  File "D:\ProgramFiles\Anaconda3\lib\site-packages\django-1.11.8-py3.6.egg\django\core\handlers\exception.py", line 41, in inner
    response = get_response(request)
  File "D:\ProgramFiles\Anaconda3\lib\site-packages\django-1.11.8-py3.6.egg\django\core\handlers\base.py", line 249, in _legacy_get_response
    response = self._get_response(request)
  File "D:\ProgramFiles\Anaconda3\lib\site-packages\django-1.11.8-py3.6.egg\django\core\handlers\base.py", line 187, in _get_response
    response = self.process_exception_by_middleware(e, request)
  File "D:\ProgramFiles\Anaconda3\lib\site-packages\django-1.11.8-py3.6.egg\django\core\handlers\base.py", line 185, in _get_response
    response = wrapped_callback(request, *callback_args, **callback_kwargs)
  File "D:\tools\Tools\Carry\mysite\views.py", line 1192, in gxjy
    h = HSD.GXJY()
  File "D:\tools\Tools\Carry\mysite\HSD.py", line 1402, in __init__
    self.conn = get_conn('carry_investment')
  File "D:\tools\Tools\Carry\mysite\HSD.py", line 165, in get_conn
    return SqlSingleton(db=dataName)
  File "D:\tools\Tools\Carry\mysite\HSD.py", line 149, in __init__
    dbs = str(db) + random.randint(0,size)
TypeError: must be str, not int
exception.py[2018-07-26 14:58:43][ERROR]：Internal Server Error: /gxjy/
Traceback (most recent call last):
  File "D:\ProgramFiles\Anaconda3\lib\site-packages\django-1.11.8-py3.6.egg\django\core\handlers\exception.py", line 41, in inner
    response = get_response(request)
  File "D:\ProgramFiles\Anaconda3\lib\site-packages\django-1.11.8-py3.6.egg\django\core\handlers\base.py", line 249, in _legacy_get_response
    response = self._get_response(request)
  File "D:\ProgramFiles\Anaconda3\lib\site-packages\django-1.11.8-py3.6.egg\django\core\handlers\base.py", line 187, in _get_response
    response = self.process_exception_by_middleware(e, request)
  File "D:\ProgramFiles\Anaconda3\lib\site-packages\django-1.11.8-py3.6.egg\django\core\handlers\base.py", line 185, in _get_response
    response = wrapped_callback(request, *callback_args, **callback_kwargs)
  File "D:\tools\Tools\Carry\mysite\views.py", line 1192, in gxjy
    h = HSD.GXJY()
  File "D:\tools\Tools\Carry\mysite\HSD.py", line 1402, in __init__
    self.conn = get_conn('carry_investment')
  File "D:\tools\Tools\Carry\mysite\HSD.py", line 165, in get_conn
    return SqlSingleton(db=dataName)
  File "D:\tools\Tools\Carry\mysite\HSD.py", line 151, in __init__
    if l < self.size or dbs not in self.__conns:
TypeError: '<' not supported between instances of 'int' and 'NoneType'
exception.py[2018-07-26 14:59:18][ERROR]：Internal Server Error: /gxjy/
Traceback (most recent call last):
  File "D:\ProgramFiles\Anaconda3\lib\site-packages\django-1.11.8-py3.6.egg\django\core\handlers\exception.py", line 41, in inner
    response = get_response(request)
  File "D:\ProgramFiles\Anaconda3\lib\site-packages\django-1.11.8-py3.6.egg\django\core\handlers\base.py", line 249, in _legacy_get_response
    response = self._get_response(request)
  File "D:\ProgramFiles\Anaconda3\lib\site-packages\django-1.11.8-py3.6.egg\django\core\handlers\base.py", line 187, in _get_response
    response = self.process_exception_by_middleware(e, request)
  File "D:\ProgramFiles\Anaconda3\lib\site-packages\django-1.11.8-py3.6.egg\django\core\handlers\base.py", line 185, in _get_response
    response = wrapped_callback(request, *callback_args, **callback_kwargs)
  File "D:\tools\Tools\Carry\mysite\views.py", line 1375, in gxjy
    init_data = h.get_gxjy_sql_all(code) if code else h.get_gxjy_sql_all()
  File "D:\tools\Tools\Carry\mysite\HSD.py", line 1471, in get_gxjy_sql_all
    p = getSqlData(self.conn, sql)  # pd.read_sql(sql, conn)
  File "D:\tools\Tools\Carry\mysite\HSD.py", line 175, in getSqlData
    cur = conn.cursor()
TypeError: 'NoneType' object is not callable
exception.py[2018-07-26 15:02:32][ERROR]：Internal Server Error: /gxjy/
Traceback (most recent call last):
  File "D:\ProgramFiles\Anaconda3\lib\site-packages\django-1.11.8-py3.6.egg\django\core\handlers\exception.py", line 41, in inner
    response = get_response(request)
  File "D:\ProgramFiles\Anaconda3\lib\site-packages\django-1.11.8-py3.6.egg\django\core\handlers\base.py", line 249, in _legacy_get_response
    response = self._get_response(request)
  File "D:\ProgramFiles\Anaconda3\lib\site-packages\django-1.11.8-py3.6.egg\django\core\handlers\base.py", line 187, in _get_response
    response = self.process_exception_by_middleware(e, request)
  File "D:\ProgramFiles\Anaconda3\lib\site-packages\django-1.11.8-py3.6.egg\django\core\handlers\base.py", line 185, in _get_response
    response = wrapped_callback(request, *callback_args, **callback_kwargs)
  File "D:\tools\Tools\Carry\mysite\views.py", line 1375, in gxjy
    init_data = h.get_gxjy_sql_all(code) if code else h.get_gxjy_sql_all()
  File "D:\tools\Tools\Carry\mysite\HSD.py", line 1471, in get_gxjy_sql_all
    p = getSqlData(self.conn, sql)  # pd.read_sql(sql, conn)
  File "D:\tools\Tools\Carry\mysite\HSD.py", line 176, in getSqlData
    cur.execute(sql)
  File "D:\ProgramFiles\Anaconda3\lib\site-packages\pymysql\cursors.py", line 165, in execute
    result = self._query(query)
  File "D:\ProgramFiles\Anaconda3\lib\site-packages\pymysql\cursors.py", line 321, in _query
    conn.query(q)
  File "D:\ProgramFiles\Anaconda3\lib\site-packages\pymysql\connections.py", line 859, in query
    self._execute_command(COMMAND.COM_QUERY, sql)
  File "D:\ProgramFiles\Anaconda3\lib\site-packages\pymysql\connections.py", line 1075, in _execute_command
    raise err.InterfaceError("(0, '')")
pymysql.err.InterfaceError: (0, '')
exception.py[2018-07-26 15:02:41][ERROR]：Internal Server Error: /tj/
Traceback (most recent call last):
  File "D:\ProgramFiles\Anaconda3\lib\site-packages\django-1.11.8-py3.6.egg\django\core\handlers\exception.py", line 41, in inner
    response = get_response(request)
  File "D:\ProgramFiles\Anaconda3\lib\site-packages\django-1.11.8-py3.6.egg\django\core\handlers\base.py", line 249, in _legacy_get_response
    response = self._get_response(request)
  File "D:\ProgramFiles\Anaconda3\lib\site-packages\django-1.11.8-py3.6.egg\django\core\handlers\base.py", line 187, in _get_response
    response = self.process_exception_by_middleware(e, request)
  File "D:\ProgramFiles\Anaconda3\lib\site-packages\django-1.11.8-py3.6.egg\django\core\handlers\base.py", line 185, in _get_response
    response = wrapped_callback(request, *callback_args, **callback_kwargs)
  File "D:\tools\Tools\Carry\mysite\views.py", line 458, in tongji
    id_name = HSD.get_idName()
  File "D:\tools\Tools\Carry\mysite\HSD.py", line 401, in get_idName
    id_name = getSqlData(conn, sql)
  File "D:\tools\Tools\Carry\mysite\HSD.py", line 176, in getSqlData
    cur.execute(sql)
  File "D:\ProgramFiles\Anaconda3\lib\site-packages\pymysql\cursors.py", line 165, in execute
    result = self._query(query)
  File "D:\ProgramFiles\Anaconda3\lib\site-packages\pymysql\cursors.py", line 321, in _query
    conn.query(q)
  File "D:\ProgramFiles\Anaconda3\lib\site-packages\pymysql\connections.py", line 859, in query
    self._execute_command(COMMAND.COM_QUERY, sql)
  File "D:\ProgramFiles\Anaconda3\lib\site-packages\pymysql\connections.py", line 1075, in _execute_command
    raise err.InterfaceError("(0, '')")
pymysql.err.InterfaceError: (0, '')
exception.py[2018-07-26 15:03:08][ERROR]：Internal Server Error: /tj/
Traceback (most recent call last):
  File "D:\ProgramFiles\Anaconda3\lib\site-packages\django-1.11.8-py3.6.egg\django\core\handlers\exception.py", line 41, in inner
    response = get_response(request)
  File "D:\ProgramFiles\Anaconda3\lib\site-packages\django-1.11.8-py3.6.egg\django\core\handlers\base.py", line 249, in _legacy_get_response
    response = self._get_response(request)
  File "D:\ProgramFiles\Anaconda3\lib\site-packages\django-1.11.8-py3.6.egg\django\core\handlers\base.py", line 187, in _get_response
    response = self.process_exception_by_middleware(e, request)
  File "D:\ProgramFiles\Anaconda3\lib\site-packages\django-1.11.8-py3.6.egg\django\core\handlers\base.py", line 185, in _get_response
    response = wrapped_callback(request, *callback_args, **callback_kwargs)
  File "D:\tools\Tools\Carry\mysite\views.py", line 578, in tongji
    result9 = HSD.order_detail(rq_date, end_date)
  File "D:\tools\Tools\Carry\mysite\HSD.py", line 432, in order_detail
    data = getSqlData(conn, sql)
  File "D:\tools\Tools\Carry\mysite\HSD.py", line 176, in getSqlData
    cur.execute(sql)
  File "D:\ProgramFiles\Anaconda3\lib\site-packages\pymysql\cursors.py", line 165, in execute
    result = self._query(query)
  File "D:\ProgramFiles\Anaconda3\lib\site-packages\pymysql\cursors.py", line 321, in _query
    conn.query(q)
  File "D:\ProgramFiles\Anaconda3\lib\site-packages\pymysql\connections.py", line 859, in query
    self._execute_command(COMMAND.COM_QUERY, sql)
  File "D:\ProgramFiles\Anaconda3\lib\site-packages\pymysql\connections.py", line 1075, in _execute_command
    raise err.InterfaceError("(0, '')")
pymysql.err.InterfaceError: (0, '')
exception.py[2018-07-26 15:35:45][ERROR]：Internal Server Error: /gxjy/
Traceback (most recent call last):
  File "D:\ProgramFiles\Anaconda3\lib\site-packages\django-1.11.8-py3.6.egg\django\core\handlers\exception.py", line 41, in inner
    response = get_response(request)
  File "D:\ProgramFiles\Anaconda3\lib\site-packages\django-1.11.8-py3.6.egg\django\core\handlers\base.py", line 249, in _legacy_get_response
    response = self._get_response(request)
  File "D:\ProgramFiles\Anaconda3\lib\site-packages\django-1.11.8-py3.6.egg\django\core\handlers\base.py", line 187, in _get_response
    response = self.process_exception_by_middleware(e, request)
  File "D:\ProgramFiles\Anaconda3\lib\site-packages\django-1.11.8-py3.6.egg\django\core\handlers\base.py", line 185, in _get_response
    response = wrapped_callback(request, *callback_args, **callback_kwargs)
  File "D:\tools\Tools\Carry\mysite\views.py", line 1283, in gxjy
    print(dates[xh+1][0][:7])
IndexError: tuple index out of range
exception.py[2018-07-26 16:50:11][ERROR]：Internal Server Error: /gxjy/
Traceback (most recent call last):
  File "D:\ProgramFiles\Anaconda3\lib\site-packages\django-1.11.8-py3.6.egg\django\core\handlers\exception.py", line 41, in inner
    response = get_response(request)
  File "D:\ProgramFiles\Anaconda3\lib\site-packages\django-1.11.8-py3.6.egg\django\core\handlers\base.py", line 249, in _legacy_get_response
    response = self._get_response(request)
  File "D:\ProgramFiles\Anaconda3\lib\site-packages\django-1.11.8-py3.6.egg\django\core\handlers\base.py", line 187, in _get_response
    response = self.process_exception_by_middleware(e, request)
  File "D:\ProgramFiles\Anaconda3\lib\site-packages\django-1.11.8-py3.6.egg\django\core\handlers\base.py", line 185, in _get_response
    response = wrapped_callback(request, *callback_args, **callback_kwargs)
  File "D:\tools\Tools\Carry\mysite\views.py", line 1298, in gxjy
    f_date2 = datetime.datetime.strptime(dates[xh + 1][0], '%Y-%m-%d')
IndexError: tuple index out of range
exception.py[2018-07-26 17:24:44][ERROR]：Internal Server Error: /gxjy/
Traceback (most recent call last):
  File "D:\ProgramFiles\Anaconda3\lib\site-packages\django-1.11.8-py3.6.egg\django\core\handlers\exception.py", line 41, in inner
    response = get_response(request)
  File "D:\ProgramFiles\Anaconda3\lib\site-packages\django-1.11.8-py3.6.egg\django\core\handlers\base.py", line 249, in _legacy_get_response
    response = self._get_response(request)
  File "D:\ProgramFiles\Anaconda3\lib\site-packages\django-1.11.8-py3.6.egg\django\core\handlers\base.py", line 187, in _get_response
    response = self.process_exception_by_middleware(e, request)
  File "D:\ProgramFiles\Anaconda3\lib\site-packages\django-1.11.8-py3.6.egg\django\core\handlers\base.py", line 185, in _get_response
    response = wrapped_callback(request, *callback_args, **callback_kwargs)
  File "D:\tools\Tools\Carry\mysite\views.py", line 1280, in gxjy
    week = str(week[0])+'-'+str(week[1]) # 星期
UnboundLocalError: local variable 'week' referenced before assignment
exception.py[2018-07-26 17:25:57][ERROR]：Internal Server Error: /gxjy/
Traceback (most recent call last):
  File "D:\ProgramFiles\Anaconda3\lib\site-packages\django-1.11.8-py3.6.egg\django\core\handlers\exception.py", line 41, in inner
    response = get_response(request)
  File "D:\ProgramFiles\Anaconda3\lib\site-packages\django-1.11.8-py3.6.egg\django\core\handlers\base.py", line 249, in _legacy_get_response
    response = self._get_response(request)
  File "D:\ProgramFiles\Anaconda3\lib\site-packages\django-1.11.8-py3.6.egg\django\core\handlers\base.py", line 187, in _get_response
    response = self.process_exception_by_middleware(e, request)
  File "D:\ProgramFiles\Anaconda3\lib\site-packages\django-1.11.8-py3.6.egg\django\core\handlers\base.py", line 185, in _get_response
    response = wrapped_callback(request, *callback_args, **callback_kwargs)
  File "D:\tools\Tools\Carry\mysite\views.py", line 1280, in gxjy
    week = f_date.isocalendar()[:2]
AttributeError: 'tuple' object has no attribute 'isocalendar'
exception.py[2018-07-26 17:30:08][ERROR]：Internal Server Error: /gxjy/
Traceback (most recent call last):
  File "D:\ProgramFiles\Anaconda3\lib\site-packages\django-1.11.8-py3.6.egg\django\core\handlers\exception.py", line 41, in inner
    response = get_response(request)
  File "D:\ProgramFiles\Anaconda3\lib\site-packages\django-1.11.8-py3.6.egg\django\core\handlers\base.py", line 249, in _legacy_get_response
    response = self._get_response(request)
  File "D:\ProgramFiles\Anaconda3\lib\site-packages\django-1.11.8-py3.6.egg\django\core\handlers\base.py", line 187, in _get_response
    response = self.process_exception_by_middleware(e, request)
  File "D:\ProgramFiles\Anaconda3\lib\site-packages\django-1.11.8-py3.6.egg\django\core\handlers\base.py", line 185, in _get_response
    response = wrapped_callback(request, *callback_args, **callback_kwargs)
  File "D:\tools\Tools\Carry\mysite\views.py", line 1346, in gxjy
    week_jlr = {k:v for k,v in week_jlr if v!=0}
  File "D:\tools\Tools\Carry\mysite\views.py", line 1346, in <dictcomp>
    week_jlr = {k:v for k,v in week_jlr if v!=0}
ValueError: too many values to unpack (expected 2)
exception.py[2018-07-26 17:39:31][ERROR]：Internal Server Error: /gxjy/
Traceback (most recent call last):
  File "D:\ProgramFiles\Anaconda3\lib\site-packages\django-1.11.8-py3.6.egg\django\core\handlers\exception.py", line 41, in inner
    response = get_response(request)
  File "D:\ProgramFiles\Anaconda3\lib\site-packages\django-1.11.8-py3.6.egg\django\core\handlers\base.py", line 249, in _legacy_get_response
    response = self._get_response(request)
  File "D:\ProgramFiles\Anaconda3\lib\site-packages\django-1.11.8-py3.6.egg\django\core\handlers\base.py", line 187, in _get_response
    response = self.process_exception_by_middleware(e, request)
  File "D:\ProgramFiles\Anaconda3\lib\site-packages\django-1.11.8-py3.6.egg\django\core\handlers\base.py", line 185, in _get_response
    response = wrapped_callback(request, *callback_args, **callback_kwargs)
  File "D:\tools\Tools\Carry\mysite\views.py", line 1338, in gxjy
    zx_x2 = [i for i in zx_x if start_date<=i<=end_date]
  File "D:\tools\Tools\Carry\mysite\views.py", line 1338, in <listcomp>
    zx_x2 = [i for i in zx_x if start_date<=i<=end_date]
TypeError: '<=' not supported between instances of 'NoneType' and 'str'
exception.py[2018-07-27 14:06:03][ERROR]：Internal Server Error: /hckx/
Traceback (most recent call last):
  File "D:\ProgramFiles\Anaconda3\lib\site-packages\django-1.11.8-py3.6.egg\django\core\handlers\exception.py", line 41, in inner
    response = get_response(request)
  File "D:\ProgramFiles\Anaconda3\lib\site-packages\django-1.11.8-py3.6.egg\django\core\handlers\base.py", line 249, in _legacy_get_response
    response = self._get_response(request)
  File "D:\ProgramFiles\Anaconda3\lib\site-packages\django-1.11.8-py3.6.egg\django\core\handlers\base.py", line 187, in _get_response
    response = self.process_exception_by_middleware(e, request)
  File "D:\ProgramFiles\Anaconda3\lib\site-packages\django-1.11.8-py3.6.egg\django\core\handlers\base.py", line 185, in _get_response
    response = wrapped_callback(request, *callback_args, **callback_kwargs)
  File "D:\tools\Tools\Carry\mysite\views.py", line 1394, in hckx
    return render(rq,'hckx.html')
  File "D:\ProgramFiles\Anaconda3\lib\site-packages\django-1.11.8-py3.6.egg\django\shortcuts.py", line 30, in render
    content = loader.render_to_string(template_name, context, request, using=using)
  File "D:\ProgramFiles\Anaconda3\lib\site-packages\django-1.11.8-py3.6.egg\django\template\loader.py", line 67, in render_to_string
    template = get_template(template_name, using=using)
  File "D:\ProgramFiles\Anaconda3\lib\site-packages\django-1.11.8-py3.6.egg\django\template\loader.py", line 25, in get_template
    raise TemplateDoesNotExist(template_name, chain=chain)
django.template.exceptions.TemplateDoesNotExist: hckx.html
HSD.py[2018-07-31 11:45:38][ERROR]：文件：manage.py 第580行报错： bad operand type for abs(): 'str'
HSD.py[2018-07-31 11:45:38][ERROR]：文件：manage.py 第580行报错： bad operand type for abs(): 'str'
HSD.py[2018-07-31 11:45:38][ERROR]：文件：manage.py 第580行报错： bad operand type for abs(): 'str'
HSD.py[2018-07-31 11:45:38][ERROR]：文件：manage.py 第580行报错： bad operand type for abs(): 'str'
HSD.py[2018-07-31 11:45:38][ERROR]：文件：manage.py 第580行报错： bad operand type for abs(): 'str'
HSD.py[2018-07-31 11:45:38][ERROR]：文件：manage.py 第580行报错： bad operand type for abs(): 'str'
HSD.py[2018-07-31 11:45:38][ERROR]：文件：manage.py 第580行报错： bad operand type for abs(): 'str'
HSD.py[2018-07-31 11:45:38][ERROR]：文件：manage.py 第580行报错： bad operand type for abs(): 'str'
HSD.py[2018-07-31 11:45:38][ERROR]：文件：manage.py 第580行报错： bad operand type for abs(): 'str'
HSD.py[2018-07-31 11:45:38][ERROR]：文件：manage.py 第580行报错： bad operand type for abs(): 'str'
HSD.py[2018-07-31 11:45:38][ERROR]：文件：manage.py 第580行报错： bad operand type for abs(): 'str'
HSD.py[2018-07-31 11:45:38][ERROR]：文件：manage.py 第580行报错： bad operand type for abs(): 'str'
HSD.py[2018-07-31 11:45:38][ERROR]：文件：manage.py 第580行报错： bad operand type for abs(): 'str'
HSD.py[2018-07-31 11:45:38][ERROR]：文件：manage.py 第580行报错： bad operand type for abs(): 'str'
HSD.py[2018-07-31 11:45:38][ERROR]：文件：manage.py 第580行报错： bad operand type for abs(): 'str'
HSD.py[2018-07-31 11:45:38][ERROR]：文件：manage.py 第580行报错： bad operand type for abs(): 'str'
HSD.py[2018-07-31 11:45:38][ERROR]：文件：manage.py 第580行报错： bad operand type for abs(): 'str'
HSD.py[2018-07-31 11:45:38][ERROR]：文件：manage.py 第580行报错： bad operand type for abs(): 'str'
HSD.py[2018-07-31 11:45:38][ERROR]：文件：manage.py 第580行报错： bad operand type for abs(): 'str'
HSD.py[2018-07-31 11:45:38][ERROR]：文件：manage.py 第580行报错： bad operand type for abs(): 'str'
HSD.py[2018-07-31 11:45:38][ERROR]：文件：manage.py 第580行报错： bad operand type for abs(): 'str'
HSD.py[2018-07-31 11:45:38][ERROR]：文件：manage.py 第580行报错： bad operand type for abs(): 'str'
HSD.py[2018-07-31 11:45:38][ERROR]：文件：manage.py 第580行报错： bad operand type for abs(): 'str'
HSD.py[2018-07-31 11:45:38][ERROR]：文件：manage.py 第580行报错： bad operand type for abs(): 'str'
HSD.py[2018-07-31 11:45:38][ERROR]：文件：manage.py 第580行报错： bad operand type for abs(): 'str'
HSD.py[2018-07-31 11:45:58][ERROR]：文件：manage.py 第580行报错： bad operand type for abs(): 'str'
HSD.py[2018-07-31 11:45:58][ERROR]：文件：manage.py 第580行报错： bad operand type for abs(): 'str'
HSD.py[2018-07-31 11:45:58][ERROR]：文件：manage.py 第580行报错： bad operand type for abs(): 'str'
HSD.py[2018-07-31 11:45:58][ERROR]：文件：manage.py 第580行报错： bad operand type for abs(): 'str'
HSD.py[2018-07-31 11:45:58][ERROR]：文件：manage.py 第580行报错： bad operand type for abs(): 'str'
HSD.py[2018-07-31 11:45:58][ERROR]：文件：manage.py 第580行报错： bad operand type for abs(): 'str'
HSD.py[2018-07-31 11:45:58][ERROR]：文件：manage.py 第580行报错： bad operand type for abs(): 'str'
HSD.py[2018-07-31 11:45:58][ERROR]：文件：manage.py 第580行报错： bad operand type for abs(): 'str'
HSD.py[2018-07-31 11:45:58][ERROR]：文件：manage.py 第580行报错： bad operand type for abs(): 'str'
HSD.py[2018-07-31 11:45:58][ERROR]：文件：manage.py 第580行报错： bad operand type for abs(): 'str'
HSD.py[2018-07-31 11:45:58][ERROR]：文件：manage.py 第580行报错： bad operand type for abs(): 'str'
HSD.py[2018-07-31 11:45:58][ERROR]：文件：manage.py 第580行报错： bad operand type for abs(): 'str'
HSD.py[2018-07-31 11:45:58][ERROR]：文件：manage.py 第580行报错： bad operand type for abs(): 'str'
HSD.py[2018-07-31 11:45:58][ERROR]：文件：manage.py 第580行报错： bad operand type for abs(): 'str'
HSD.py[2018-07-31 11:45:58][ERROR]：文件：manage.py 第580行报错： bad operand type for abs(): 'str'
HSD.py[2018-07-31 11:45:58][ERROR]：文件：manage.py 第580行报错： bad operand type for abs(): 'str'
HSD.py[2018-07-31 11:45:58][ERROR]：文件：manage.py 第580行报错： bad operand type for abs(): 'str'
HSD.py[2018-07-31 11:45:58][ERROR]：文件：manage.py 第580行报错： bad operand type for abs(): 'str'
HSD.py[2018-07-31 11:45:58][ERROR]：文件：manage.py 第580行报错： bad operand type for abs(): 'str'
HSD.py[2018-07-31 11:45:58][ERROR]：文件：manage.py 第580行报错： bad operand type for abs(): 'str'
HSD.py[2018-07-31 11:45:58][ERROR]：文件：manage.py 第580行报错： bad operand type for abs(): 'str'
HSD.py[2018-07-31 11:45:58][ERROR]：文件：manage.py 第580行报错： bad operand type for abs(): 'str'
HSD.py[2018-07-31 11:45:58][ERROR]：文件：manage.py 第580行报错： bad operand type for abs(): 'str'
HSD.py[2018-07-31 11:45:58][ERROR]：文件：manage.py 第580行报错： bad operand type for abs(): 'str'
HSD.py[2018-07-31 11:45:58][ERROR]：文件：manage.py 第580行报错： bad operand type for abs(): 'str'
exception.py[2018-07-31 12:11:34][ERROR]：Internal Server Error: /tj/
Traceback (most recent call last):
  File "D:\ProgramFiles\Anaconda3\lib\site-packages\django-1.11.8-py3.6.egg\django\core\handlers\exception.py", line 41, in inner
    response = get_response(request)
  File "D:\ProgramFiles\Anaconda3\lib\site-packages\django-1.11.8-py3.6.egg\django\core\handlers\base.py", line 249, in _legacy_get_response
    response = self._get_response(request)
  File "D:\ProgramFiles\Anaconda3\lib\site-packages\django-1.11.8-py3.6.egg\django\core\handlers\base.py", line 187, in _get_response
    response = self.process_exception_by_middleware(e, request)
  File "D:\ProgramFiles\Anaconda3\lib\site-packages\django-1.11.8-py3.6.egg\django\core\handlers\base.py", line 185, in _get_response
    response = wrapped_callback(request, *callback_args, **callback_kwargs)
  File "D:\tools\Tools\Carry\mysite\views.py", line 521, in tongji
    results2, huizong = HSD.sp_order_record(rq_date,end_date)
  File "D:\tools\Tools\Carry\mysite\HSD.py", line 585, in sp_order_record
    kc = [[k[5],k[4],k[0],k[1],None,None,None,'多' if i[6] == 'B' else '空',1,'未平仓'] for k in kc]
  File "D:\tools\Tools\Carry\mysite\HSD.py", line 585, in <listcomp>
    kc = [[k[5],k[4],k[0],k[1],None,None,None,'多' if i[6] == 'B' else '空',1,'未平仓'] for k in kc]
TypeError: 'int' object is not subscriptable
csrf.py[2018-07-31 16:15:57][WARNING]：Forbidden (CSRF token missing or incorrect.): /tj/
csrf.py[2018-07-31 16:57:12][WARNING]：Forbidden (CSRF token missing or incorrect.): /login/
csrf.py[2018-07-31 16:57:16][WARNING]：Forbidden (CSRF token missing or incorrect.): /login/
csrf.py[2018-07-31 16:57:30][WARNING]：Forbidden (CSRF token missing or incorrect.): /login/
csrf.py[2018-07-31 17:00:19][WARNING]：Forbidden (CSRF token missing or incorrect.): /login/
csrf.py[2018-07-31 17:02:41][WARNING]：Forbidden (CSRF token missing or incorrect.): /login/
exception.py[2018-07-31 17:05:08][ERROR]：Internal Server Error: /login/
Traceback (most recent call last):
  File "D:\ProgramFiles\Anaconda3\lib\site-packages\django-1.11.8-py3.6.egg\django\core\handlers\base.py", line 131, in get_response
    response = middleware_method(request, response)
  File "D:\ProgramFiles\Anaconda3\lib\site-packages\django-1.11.8-py3.6.egg\django\middleware\clickjacking.py", line 32, in process_response
    if response.get('X-Frame-Options') is not None:
AttributeError: 'str' object has no attribute 'get'
exception.py[2018-07-31 18:18:33][ERROR]：Internal Server Error: /gxjy/
Traceback (most recent call last):
  File "D:\ProgramFiles\Anaconda3\lib\site-packages\django-1.11.8-py3.6.egg\django\core\handlers\exception.py", line 41, in inner
    response = get_response(request)
  File "D:\ProgramFiles\Anaconda3\lib\site-packages\django-1.11.8-py3.6.egg\django\core\handlers\base.py", line 249, in _legacy_get_response
    response = self._get_response(request)
  File "D:\ProgramFiles\Anaconda3\lib\site-packages\django-1.11.8-py3.6.egg\django\core\handlers\base.py", line 187, in _get_response
    response = self.process_exception_by_middleware(e, request)
  File "D:\ProgramFiles\Anaconda3\lib\site-packages\django-1.11.8-py3.6.egg\django\core\handlers\base.py", line 185, in _get_response
    response = wrapped_callback(request, *callback_args, **callback_kwargs)
  File "D:\tools\Tools\Carry\mysite\views.py", line 1274, in gxjy
    json.dumps(f,data)
TypeError: dumps() takes 1 positional argument but 2 were given
exception.py[2018-07-31 18:18:44][ERROR]：Internal Server Error: /gxjy/
Traceback (most recent call last):
  File "D:\ProgramFiles\Anaconda3\lib\site-packages\django-1.11.8-py3.6.egg\django\core\handlers\exception.py", line 41, in inner
    response = get_response(request)
  File "D:\ProgramFiles\Anaconda3\lib\site-packages\django-1.11.8-py3.6.egg\django\core\handlers\base.py", line 249, in _legacy_get_response
    response = self._get_response(request)
  File "D:\ProgramFiles\Anaconda3\lib\site-packages\django-1.11.8-py3.6.egg\django\core\handlers\base.py", line 187, in _get_response
    response = self.process_exception_by_middleware(e, request)
  File "D:\ProgramFiles\Anaconda3\lib\site-packages\django-1.11.8-py3.6.egg\django\core\handlers\base.py", line 185, in _get_response
    response = wrapped_callback(request, *callback_args, **callback_kwargs)
  File "D:\tools\Tools\Carry\mysite\views.py", line 1274, in gxjy
    json.dump(f,data)
  File "D:\ProgramFiles\Anaconda3\lib\json\__init__.py", line 179, in dump
    for chunk in iterable:
  File "D:\ProgramFiles\Anaconda3\lib\json\encoder.py", line 437, in _iterencode
    o = _default(o)
  File "D:\ProgramFiles\Anaconda3\lib\json\encoder.py", line 180, in default
    o.__class__.__name__)
TypeError: Object of type 'TextIOWrapper' is not JSON serializable
exception.py[2018-07-31 18:19:01][ERROR]：Internal Server Error: /gxjy/
Traceback (most recent call last):
  File "D:\ProgramFiles\Anaconda3\lib\site-packages\django-1.11.8-py3.6.egg\django\core\handlers\exception.py", line 41, in inner
    response = get_response(request)
  File "D:\ProgramFiles\Anaconda3\lib\site-packages\django-1.11.8-py3.6.egg\django\core\handlers\base.py", line 249, in _legacy_get_response
    response = self._get_response(request)
  File "D:\ProgramFiles\Anaconda3\lib\site-packages\django-1.11.8-py3.6.egg\django\core\handlers\base.py", line 187, in _get_response
    response = self.process_exception_by_middleware(e, request)
  File "D:\ProgramFiles\Anaconda3\lib\site-packages\django-1.11.8-py3.6.egg\django\core\handlers\base.py", line 185, in _get_response
    response = wrapped_callback(request, *callback_args, **callback_kwargs)
  File "D:\tools\Tools\Carry\mysite\views.py", line 1274, in gxjy
    json.dumps(data,f)
TypeError: dumps() takes 1 positional argument but 2 were given
exception.py[2018-07-31 18:34:58][ERROR]：Internal Server Error: /admin/mysite/users/
Traceback (most recent call last):
  File "D:\ProgramFiles\Anaconda3\lib\site-packages\django-1.11.8-py3.6.egg\django\db\backends\utils.py", line 64, in execute
    return self.cursor.execute(sql, params)
  File "D:\ProgramFiles\Anaconda3\lib\site-packages\django-1.11.8-py3.6.egg\django\db\backends\sqlite3\base.py", line 328, in execute
    return Database.Cursor.execute(self, query, params)
sqlite3.OperationalError: no such column: mysite_users.enabled

The above exception was the direct cause of the following exception:

Traceback (most recent call last):
  File "D:\ProgramFiles\Anaconda3\lib\site-packages\django-1.11.8-py3.6.egg\django\core\handlers\exception.py", line 41, in inner
    response = get_response(request)
  File "D:\ProgramFiles\Anaconda3\lib\site-packages\django-1.11.8-py3.6.egg\django\core\handlers\base.py", line 249, in _legacy_get_response
    response = self._get_response(request)
  File "D:\ProgramFiles\Anaconda3\lib\site-packages\django-1.11.8-py3.6.egg\django\core\handlers\base.py", line 187, in _get_response
    response = self.process_exception_by_middleware(e, request)
  File "D:\ProgramFiles\Anaconda3\lib\site-packages\django-1.11.8-py3.6.egg\django\core\handlers\base.py", line 185, in _get_response
    response = wrapped_callback(request, *callback_args, **callback_kwargs)
  File "D:\ProgramFiles\Anaconda3\lib\site-packages\django-1.11.8-py3.6.egg\django\contrib\admin\options.py", line 551, in wrapper
    return self.admin_site.admin_view(view)(*args, **kwargs)
  File "D:\ProgramFiles\Anaconda3\lib\site-packages\django-1.11.8-py3.6.egg\django\utils\decorators.py", line 149, in _wrapped_view
    response = view_func(request, *args, **kwargs)
  File "D:\ProgramFiles\Anaconda3\lib\site-packages\django-1.11.8-py3.6.egg\django\views\decorators\cache.py", line 57, in _wrapped_view_func
    response = view_func(request, *args, **kwargs)
  File "D:\ProgramFiles\Anaconda3\lib\site-packages\django-1.11.8-py3.6.egg\django\contrib\admin\sites.py", line 224, in inner
    return view(request, *args, **kwargs)
  File "D:\ProgramFiles\Anaconda3\lib\site-packages\django-1.11.8-py3.6.egg\django\utils\decorators.py", line 67, in _wrapper
    return bound_func(*args, **kwargs)
  File "D:\ProgramFiles\Anaconda3\lib\site-packages\django-1.11.8-py3.6.egg\django\utils\decorators.py", line 149, in _wrapped_view
    response = view_func(request, *args, **kwargs)
  File "D:\ProgramFiles\Anaconda3\lib\site-packages\django-1.11.8-py3.6.egg\django\utils\decorators.py", line 63, in bound_func
    return func.__get__(self, type(self))(*args2, **kwargs2)
  File "D:\ProgramFiles\Anaconda3\lib\site-packages\django-1.11.8-py3.6.egg\django\contrib\admin\options.py", line 1662, in changelist_view
    selection_note=_('0 of %(cnt)s selected') % {'cnt': len(cl.result_list)},
  File "D:\ProgramFiles\Anaconda3\lib\site-packages\django-1.11.8-py3.6.egg\django\db\models\query.py", line 232, in __len__
    self._fetch_all()
  File "D:\ProgramFiles\Anaconda3\lib\site-packages\django-1.11.8-py3.6.egg\django\db\models\query.py", line 1118, in _fetch_all
    self._result_cache = list(self._iterable_class(self))
  File "D:\ProgramFiles\Anaconda3\lib\site-packages\django-1.11.8-py3.6.egg\django\db\models\query.py", line 53, in __iter__
    results = compiler.execute_sql(chunked_fetch=self.chunked_fetch)
  File "D:\ProgramFiles\Anaconda3\lib\site-packages\django-1.11.8-py3.6.egg\django\db\models\sql\compiler.py", line 899, in execute_sql
    raise original_exception
  File "D:\ProgramFiles\Anaconda3\lib\site-packages\django-1.11.8-py3.6.egg\django\db\models\sql\compiler.py", line 889, in execute_sql
    cursor.execute(sql, params)
  File "D:\ProgramFiles\Anaconda3\lib\site-packages\django-1.11.8-py3.6.egg\django\db\backends\utils.py", line 79, in execute
    return super(CursorDebugWrapper, self).execute(sql, params)
  File "D:\ProgramFiles\Anaconda3\lib\site-packages\django-1.11.8-py3.6.egg\django\db\backends\utils.py", line 64, in execute
    return self.cursor.execute(sql, params)
  File "D:\ProgramFiles\Anaconda3\lib\site-packages\django-1.11.8-py3.6.egg\django\db\utils.py", line 94, in __exit__
    six.reraise(dj_exc_type, dj_exc_value, traceback)
  File "D:\ProgramFiles\Anaconda3\lib\site-packages\django-1.11.8-py3.6.egg\django\utils\six.py", line 685, in reraise
    raise value.with_traceback(tb)
  File "D:\ProgramFiles\Anaconda3\lib\site-packages\django-1.11.8-py3.6.egg\django\db\backends\utils.py", line 64, in execute
    return self.cursor.execute(sql, params)
  File "D:\ProgramFiles\Anaconda3\lib\site-packages\django-1.11.8-py3.6.egg\django\db\backends\sqlite3\base.py", line 328, in execute
    return Database.Cursor.execute(self, query, params)
django.db.utils.OperationalError: no such column: mysite_users.enabled
exception.py[2018-07-31 18:43:35][ERROR]：Internal Server Error: /admin/mysite/users/
Traceback (most recent call last):
  File "D:\ProgramFiles\Anaconda3\lib\site-packages\django-1.11.8-py3.6.egg\django\db\backends\utils.py", line 64, in execute
    return self.cursor.execute(sql, params)
  File "D:\ProgramFiles\Anaconda3\lib\site-packages\django-1.11.8-py3.6.egg\django\db\backends\sqlite3\base.py", line 328, in execute
    return Database.Cursor.execute(self, query, params)
sqlite3.OperationalError: no such table: mysite_users

The above exception was the direct cause of the following exception:

Traceback (most recent call last):
  File "D:\ProgramFiles\Anaconda3\lib\site-packages\django-1.11.8-py3.6.egg\django\core\handlers\exception.py", line 41, in inner
    response = get_response(request)
  File "D:\ProgramFiles\Anaconda3\lib\site-packages\django-1.11.8-py3.6.egg\django\core\handlers\base.py", line 249, in _legacy_get_response
    response = self._get_response(request)
  File "D:\ProgramFiles\Anaconda3\lib\site-packages\django-1.11.8-py3.6.egg\django\core\handlers\base.py", line 187, in _get_response
    response = self.process_exception_by_middleware(e, request)
  File "D:\ProgramFiles\Anaconda3\lib\site-packages\django-1.11.8-py3.6.egg\django\core\handlers\base.py", line 185, in _get_response
    response = wrapped_callback(request, *callback_args, **callback_kwargs)
  File "D:\ProgramFiles\Anaconda3\lib\site-packages\django-1.11.8-py3.6.egg\django\contrib\admin\options.py", line 551, in wrapper
    return self.admin_site.admin_view(view)(*args, **kwargs)
  File "D:\ProgramFiles\Anaconda3\lib\site-packages\django-1.11.8-py3.6.egg\django\utils\decorators.py", line 149, in _wrapped_view
    response = view_func(request, *args, **kwargs)
  File "D:\ProgramFiles\Anaconda3\lib\site-packages\django-1.11.8-py3.6.egg\django\views\decorators\cache.py", line 57, in _wrapped_view_func
    response = view_func(request, *args, **kwargs)
  File "D:\ProgramFiles\Anaconda3\lib\site-packages\django-1.11.8-py3.6.egg\django\contrib\admin\sites.py", line 224, in inner
    return view(request, *args, **kwargs)
  File "D:\ProgramFiles\Anaconda3\lib\site-packages\django-1.11.8-py3.6.egg\django\utils\decorators.py", line 67, in _wrapper
    return bound_func(*args, **kwargs)
  File "D:\ProgramFiles\Anaconda3\lib\site-packages\django-1.11.8-py3.6.egg\django\utils\decorators.py", line 149, in _wrapped_view
    response = view_func(request, *args, **kwargs)
  File "D:\ProgramFiles\Anaconda3\lib\site-packages\django-1.11.8-py3.6.egg\django\utils\decorators.py", line 63, in bound_func
    return func.__get__(self, type(self))(*args2, **kwargs2)
  File "D:\ProgramFiles\Anaconda3\lib\site-packages\django-1.11.8-py3.6.egg\django\contrib\admin\options.py", line 1542, in changelist_view
    self.list_max_show_all, self.list_editable, self,
  File "D:\ProgramFiles\Anaconda3\lib\site-packages\django-1.11.8-py3.6.egg\django\contrib\admin\views\main.py", line 79, in __init__
    self.get_results(request)
  File "D:\ProgramFiles\Anaconda3\lib\site-packages\django-1.11.8-py3.6.egg\django\contrib\admin\views\main.py", line 177, in get_results
    result_count = paginator.count
  File "D:\ProgramFiles\Anaconda3\lib\site-packages\django-1.11.8-py3.6.egg\django\utils\functional.py", line 35, in __get__
    res = instance.__dict__[self.name] = self.func(instance)
  File "D:\ProgramFiles\Anaconda3\lib\site-packages\django-1.11.8-py3.6.egg\django\core\paginator.py", line 79, in count
    return self.object_list.count()
  File "D:\ProgramFiles\Anaconda3\lib\site-packages\django-1.11.8-py3.6.egg\django\db\models\query.py", line 364, in count
    return self.query.get_count(using=self.db)
  File "D:\ProgramFiles\Anaconda3\lib\site-packages\django-1.11.8-py3.6.egg\django\db\models\sql\query.py", line 499, in get_count
    number = obj.get_aggregation(using, ['__count'])['__count']
  File "D:\ProgramFiles\Anaconda3\lib\site-packages\django-1.11.8-py3.6.egg\django\db\models\sql\query.py", line 480, in get_aggregation
    result = compiler.execute_sql(SINGLE)
  File "D:\ProgramFiles\Anaconda3\lib\site-packages\django-1.11.8-py3.6.egg\django\db\models\sql\compiler.py", line 899, in execute_sql
    raise original_exception
  File "D:\ProgramFiles\Anaconda3\lib\site-packages\django-1.11.8-py3.6.egg\django\db\models\sql\compiler.py", line 889, in execute_sql
    cursor.execute(sql, params)
  File "D:\ProgramFiles\Anaconda3\lib\site-packages\django-1.11.8-py3.6.egg\django\db\backends\utils.py", line 79, in execute
    return super(CursorDebugWrapper, self).execute(sql, params)
  File "D:\ProgramFiles\Anaconda3\lib\site-packages\django-1.11.8-py3.6.egg\django\db\backends\utils.py", line 64, in execute
    return self.cursor.execute(sql, params)
  File "D:\ProgramFiles\Anaconda3\lib\site-packages\django-1.11.8-py3.6.egg\django\db\utils.py", line 94, in __exit__
    six.reraise(dj_exc_type, dj_exc_value, traceback)
  File "D:\ProgramFiles\Anaconda3\lib\site-packages\django-1.11.8-py3.6.egg\django\utils\six.py", line 685, in reraise
    raise value.with_traceback(tb)
  File "D:\ProgramFiles\Anaconda3\lib\site-packages\django-1.11.8-py3.6.egg\django\db\backends\utils.py", line 64, in execute
    return self.cursor.execute(sql, params)
  File "D:\ProgramFiles\Anaconda3\lib\site-packages\django-1.11.8-py3.6.egg\django\db\backends\sqlite3\base.py", line 328, in execute
    return Database.Cursor.execute(self, query, params)
django.db.utils.OperationalError: no such table: mysite_users
exception.py[2018-07-31 18:45:06][ERROR]：Internal Server Error: /admin/mysite/users/
Traceback (most recent call last):
  File "D:\ProgramFiles\Anaconda3\lib\site-packages\django-1.11.8-py3.6.egg\django\db\backends\utils.py", line 64, in execute
    return self.cursor.execute(sql, params)
  File "D:\ProgramFiles\Anaconda3\lib\site-packages\django-1.11.8-py3.6.egg\django\db\backends\sqlite3\base.py", line 328, in execute
    return Database.Cursor.execute(self, query, params)
sqlite3.OperationalError: no such table: mysite_users

The above exception was the direct cause of the following exception:

Traceback (most recent call last):
  File "D:\ProgramFiles\Anaconda3\lib\site-packages\django-1.11.8-py3.6.egg\django\core\handlers\exception.py", line 41, in inner
    response = get_response(request)
  File "D:\ProgramFiles\Anaconda3\lib\site-packages\django-1.11.8-py3.6.egg\django\core\handlers\base.py", line 249, in _legacy_get_response
    response = self._get_response(request)
  File "D:\ProgramFiles\Anaconda3\lib\site-packages\django-1.11.8-py3.6.egg\django\core\handlers\base.py", line 187, in _get_response
    response = self.process_exception_by_middleware(e, request)
  File "D:\ProgramFiles\Anaconda3\lib\site-packages\django-1.11.8-py3.6.egg\django\core\handlers\base.py", line 185, in _get_response
    response = wrapped_callback(request, *callback_args, **callback_kwargs)
  File "D:\ProgramFiles\Anaconda3\lib\site-packages\django-1.11.8-py3.6.egg\django\contrib\admin\options.py", line 551, in wrapper
    return self.admin_site.admin_view(view)(*args, **kwargs)
  File "D:\ProgramFiles\Anaconda3\lib\site-packages\django-1.11.8-py3.6.egg\django\utils\decorators.py", line 149, in _wrapped_view
    response = view_func(request, *args, **kwargs)
  File "D:\ProgramFiles\Anaconda3\lib\site-packages\django-1.11.8-py3.6.egg\django\views\decorators\cache.py", line 57, in _wrapped_view_func
    response = view_func(request, *args, **kwargs)
  File "D:\ProgramFiles\Anaconda3\lib\site-packages\django-1.11.8-py3.6.egg\django\contrib\admin\sites.py", line 224, in inner
    return view(request, *args, **kwargs)
  File "D:\ProgramFiles\Anaconda3\lib\site-packages\django-1.11.8-py3.6.egg\django\utils\decorators.py", line 67, in _wrapper
    return bound_func(*args, **kwargs)
  File "D:\ProgramFiles\Anaconda3\lib\site-packages\django-1.11.8-py3.6.egg\django\utils\decorators.py", line 149, in _wrapped_view
    response = view_func(request, *args, **kwargs)
  File "D:\ProgramFiles\Anaconda3\lib\site-packages\django-1.11.8-py3.6.egg\django\utils\decorators.py", line 63, in bound_func
    return func.__get__(self, type(self))(*args2, **kwargs2)
  File "D:\ProgramFiles\Anaconda3\lib\site-packages\django-1.11.8-py3.6.egg\django\contrib\admin\options.py", line 1542, in changelist_view
    self.list_max_show_all, self.list_editable, self,
  File "D:\ProgramFiles\Anaconda3\lib\site-packages\django-1.11.8-py3.6.egg\django\contrib\admin\views\main.py", line 79, in __init__
    self.get_results(request)
  File "D:\ProgramFiles\Anaconda3\lib\site-packages\django-1.11.8-py3.6.egg\django\contrib\admin\views\main.py", line 177, in get_results
    result_count = paginator.count
  File "D:\ProgramFiles\Anaconda3\lib\site-packages\django-1.11.8-py3.6.egg\django\utils\functional.py", line 35, in __get__
    res = instance.__dict__[self.name] = self.func(instance)
  File "D:\ProgramFiles\Anaconda3\lib\site-packages\django-1.11.8-py3.6.egg\django\core\paginator.py", line 79, in count
    return self.object_list.count()
  File "D:\ProgramFiles\Anaconda3\lib\site-packages\django-1.11.8-py3.6.egg\django\db\models\query.py", line 364, in count
    return self.query.get_count(using=self.db)
  File "D:\ProgramFiles\Anaconda3\lib\site-packages\django-1.11.8-py3.6.egg\django\db\models\sql\query.py", line 499, in get_count
    number = obj.get_aggregation(using, ['__count'])['__count']
  File "D:\ProgramFiles\Anaconda3\lib\site-packages\django-1.11.8-py3.6.egg\django\db\models\sql\query.py", line 480, in get_aggregation
    result = compiler.execute_sql(SINGLE)
  File "D:\ProgramFiles\Anaconda3\lib\site-packages\django-1.11.8-py3.6.egg\django\db\models\sql\compiler.py", line 899, in execute_sql
    raise original_exception
  File "D:\ProgramFiles\Anaconda3\lib\site-packages\django-1.11.8-py3.6.egg\django\db\models\sql\compiler.py", line 889, in execute_sql
    cursor.execute(sql, params)
  File "D:\ProgramFiles\Anaconda3\lib\site-packages\django-1.11.8-py3.6.egg\django\db\backends\utils.py", line 79, in execute
    return super(CursorDebugWrapper, self).execute(sql, params)
  File "D:\ProgramFiles\Anaconda3\lib\site-packages\django-1.11.8-py3.6.egg\django\db\backends\utils.py", line 64, in execute
    return self.cursor.execute(sql, params)
  File "D:\ProgramFiles\Anaconda3\lib\site-packages\django-1.11.8-py3.6.egg\django\db\utils.py", line 94, in __exit__
    six.reraise(dj_exc_type, dj_exc_value, traceback)
  File "D:\ProgramFiles\Anaconda3\lib\site-packages\django-1.11.8-py3.6.egg\django\utils\six.py", line 685, in reraise
    raise value.with_traceback(tb)
  File "D:\ProgramFiles\Anaconda3\lib\site-packages\django-1.11.8-py3.6.egg\django\db\backends\utils.py", line 64, in execute
    return self.cursor.execute(sql, params)
  File "D:\ProgramFiles\Anaconda3\lib\site-packages\django-1.11.8-py3.6.egg\django\db\backends\sqlite3\base.py", line 328, in execute
    return Database.Cursor.execute(self, query, params)
django.db.utils.OperationalError: no such table: mysite_users
exception.py[2018-08-01 10:36:12][ERROR]：Internal Server Error: /gxjy/
Traceback (most recent call last):
  File "D:\ProgramFiles\Anaconda3\lib\site-packages\django-1.11.8-py3.6.egg\django\core\handlers\exception.py", line 41, in inner
    response = get_response(request)
  File "D:\ProgramFiles\Anaconda3\lib\site-packages\django-1.11.8-py3.6.egg\django\core\handlers\base.py", line 249, in _legacy_get_response
    response = self._get_response(request)
  File "D:\ProgramFiles\Anaconda3\lib\site-packages\django-1.11.8-py3.6.egg\django\core\handlers\base.py", line 187, in _get_response
    response = self.process_exception_by_middleware(e, request)
  File "D:\ProgramFiles\Anaconda3\lib\site-packages\django-1.11.8-py3.6.egg\django\core\handlers\base.py", line 185, in _get_response
    response = wrapped_callback(request, *callback_args, **callback_kwargs)
  File "D:\tools\Tools\Carry\mysite\views.py", line 1324, in gxjy
    if rj!=init_money and rj != 0:
UnboundLocalError: local variable 'init_money' referenced before assignment
exception.py[2018-08-01 16:16:17][ERROR]：Internal Server Error: /tj/
Traceback (most recent call last):
  File "D:\ProgramFiles\Anaconda3\lib\site-packages\django-1.11.8-py3.6.egg\django\core\handlers\exception.py", line 41, in inner
    response = get_response(request)
  File "D:\ProgramFiles\Anaconda3\lib\site-packages\django-1.11.8-py3.6.egg\django\core\handlers\base.py", line 249, in _legacy_get_response
    response = self._get_response(request)
  File "D:\ProgramFiles\Anaconda3\lib\site-packages\django-1.11.8-py3.6.egg\django\core\handlers\base.py", line 187, in _get_response
    response = self.process_exception_by_middleware(e, request)
  File "D:\ProgramFiles\Anaconda3\lib\site-packages\django-1.11.8-py3.6.egg\django\core\handlers\base.py", line 185, in _get_response
    response = wrapped_callback(request, *callback_args, **callback_kwargs)
  File "D:\tools\Tools\Carry\mysite\views.py", line 512, in tongji
    res, huizong = viewUtiltongji_huice(res, huizong)
NameError: name 'viewUtiltongji_huice' is not defined
exception.py[2018-08-01 16:27:37][ERROR]：Internal Server Error: /tj/
Traceback (most recent call last):
  File "D:\ProgramFiles\Anaconda3\lib\site-packages\django-1.11.8-py3.6.egg\django\core\handlers\exception.py", line 41, in inner
    response = get_response(request)
  File "D:\ProgramFiles\Anaconda3\lib\site-packages\django-1.11.8-py3.6.egg\django\core\handlers\base.py", line 249, in _legacy_get_response
    response = self._get_response(request)
  File "D:\ProgramFiles\Anaconda3\lib\site-packages\django-1.11.8-py3.6.egg\django\core\handlers\base.py", line 198, in _get_response
    "returned None instead." % (callback.__module__, view_name)
ValueError: The view mysite.views.tongji didn't return an HttpResponse object. It returned None instead.
exception.py[2018-08-01 16:43:54][ERROR]：Internal Server Error: /tj/
Traceback (most recent call last):
  File "D:\ProgramFiles\Anaconda3\lib\site-packages\django-1.11.8-py3.6.egg\django\core\handlers\exception.py", line 41, in inner
    response = get_response(request)
  File "D:\ProgramFiles\Anaconda3\lib\site-packages\django-1.11.8-py3.6.egg\django\core\handlers\base.py", line 249, in _legacy_get_response
    response = self._get_response(request)
  File "D:\ProgramFiles\Anaconda3\lib\site-packages\django-1.11.8-py3.6.egg\django\core\handlers\base.py", line 187, in _get_response
    response = self.process_exception_by_middleware(e, request)
  File "D:\ProgramFiles\Anaconda3\lib\site-packages\django-1.11.8-py3.6.egg\django\core\handlers\base.py", line 185, in _get_response
    response = wrapped_callback(request, *callback_args, **callback_kwargs)
  File "D:\tools\Tools\Carry\mysite\views.py", line 684, in tongji
    herys = viewUtil.tongji_first(rq)
TypeError: tongji_first() takes 0 positional arguments but 1 was given
exception.py[2018-08-01 16:46:23][ERROR]：Internal Server Error: /tj/
Traceback (most recent call last):
  File "D:\ProgramFiles\Anaconda3\lib\site-packages\django-1.11.8-py3.6.egg\django\core\handlers\exception.py", line 41, in inner
    response = get_response(request)
  File "D:\ProgramFiles\Anaconda3\lib\site-packages\django-1.11.8-py3.6.egg\django\core\handlers\base.py", line 249, in _legacy_get_response
    response = self._get_response(request)
  File "D:\ProgramFiles\Anaconda3\lib\site-packages\django-1.11.8-py3.6.egg\django\core\handlers\base.py", line 187, in _get_response
    response = self.process_exception_by_middleware(e, request)
  File "D:\ProgramFiles\Anaconda3\lib\site-packages\django-1.11.8-py3.6.egg\django\core\handlers\base.py", line 185, in _get_response
    response = wrapped_callback(request, *callback_args, **callback_kwargs)
  File "D:\tools\Tools\Carry\mysite\views.py", line 480, in tongji
    res[dt]['mony'] += i[6]
TypeError: unsupported operand type(s) for +=: 'int' and 'NoneType'
exception.py[2018-08-01 16:48:04][ERROR]：Internal Server Error: /tj/
Traceback (most recent call last):
  File "D:\ProgramFiles\Anaconda3\lib\site-packages\django-1.11.8-py3.6.egg\django\core\handlers\exception.py", line 41, in inner
    response = get_response(request)
  File "D:\ProgramFiles\Anaconda3\lib\site-packages\django-1.11.8-py3.6.egg\django\core\handlers\base.py", line 249, in _legacy_get_response
    response = self._get_response(request)
  File "D:\ProgramFiles\Anaconda3\lib\site-packages\django-1.11.8-py3.6.egg\django\core\handlers\base.py", line 187, in _get_response
    response = self.process_exception_by_middleware(e, request)
  File "D:\ProgramFiles\Anaconda3\lib\site-packages\django-1.11.8-py3.6.egg\django\core\handlers\base.py", line 185, in _get_response
    response = wrapped_callback(request, *callback_args, **callback_kwargs)
  File "D:\tools\Tools\Carry\mysite\views.py", line 481, in tongji
    res[dt]['mony'] += i[6]
TypeError: unsupported operand type(s) for +=: 'int' and 'NoneType'
exception.py[2018-08-01 18:17:06][ERROR]：Internal Server Error: /admin/mysite/users/
Traceback (most recent call last):
  File "D:\ProgramFiles\Anaconda3\lib\site-packages\django-1.11.8-py3.6.egg\django\db\backends\utils.py", line 64, in execute
    return self.cursor.execute(sql, params)
  File "D:\ProgramFiles\Anaconda3\lib\site-packages\django-1.11.8-py3.6.egg\django\db\backends\sqlite3\base.py", line 328, in execute
    return Database.Cursor.execute(self, query, params)
sqlite3.OperationalError: no such column: mysite_users.phone

The above exception was the direct cause of the following exception:

Traceback (most recent call last):
  File "D:\ProgramFiles\Anaconda3\lib\site-packages\django-1.11.8-py3.6.egg\django\core\handlers\exception.py", line 41, in inner
    response = get_response(request)
  File "D:\ProgramFiles\Anaconda3\lib\site-packages\django-1.11.8-py3.6.egg\django\core\handlers\base.py", line 249, in _legacy_get_response
    response = self._get_response(request)
  File "D:\ProgramFiles\Anaconda3\lib\site-packages\django-1.11.8-py3.6.egg\django\core\handlers\base.py", line 187, in _get_response
    response = self.process_exception_by_middleware(e, request)
  File "D:\ProgramFiles\Anaconda3\lib\site-packages\django-1.11.8-py3.6.egg\django\core\handlers\base.py", line 185, in _get_response
    response = wrapped_callback(request, *callback_args, **callback_kwargs)
  File "D:\ProgramFiles\Anaconda3\lib\site-packages\django-1.11.8-py3.6.egg\django\contrib\admin\options.py", line 551, in wrapper
    return self.admin_site.admin_view(view)(*args, **kwargs)
  File "D:\ProgramFiles\Anaconda3\lib\site-packages\django-1.11.8-py3.6.egg\django\utils\decorators.py", line 149, in _wrapped_view
    response = view_func(request, *args, **kwargs)
  File "D:\ProgramFiles\Anaconda3\lib\site-packages\django-1.11.8-py3.6.egg\django\views\decorators\cache.py", line 57, in _wrapped_view_func
    response = view_func(request, *args, **kwargs)
  File "D:\ProgramFiles\Anaconda3\lib\site-packages\django-1.11.8-py3.6.egg\django\contrib\admin\sites.py", line 224, in inner
    return view(request, *args, **kwargs)
  File "D:\ProgramFiles\Anaconda3\lib\site-packages\django-1.11.8-py3.6.egg\django\utils\decorators.py", line 67, in _wrapper
    return bound_func(*args, **kwargs)
  File "D:\ProgramFiles\Anaconda3\lib\site-packages\django-1.11.8-py3.6.egg\django\utils\decorators.py", line 149, in _wrapped_view
    response = view_func(request, *args, **kwargs)
  File "D:\ProgramFiles\Anaconda3\lib\site-packages\django-1.11.8-py3.6.egg\django\utils\decorators.py", line 63, in bound_func
    return func.__get__(self, type(self))(*args2, **kwargs2)
  File "D:\ProgramFiles\Anaconda3\lib\site-packages\django-1.11.8-py3.6.egg\django\contrib\admin\options.py", line 1662, in changelist_view
    selection_note=_('0 of %(cnt)s selected') % {'cnt': len(cl.result_list)},
  File "D:\ProgramFiles\Anaconda3\lib\site-packages\django-1.11.8-py3.6.egg\django\db\models\query.py", line 232, in __len__
    self._fetch_all()
  File "D:\ProgramFiles\Anaconda3\lib\site-packages\django-1.11.8-py3.6.egg\django\db\models\query.py", line 1118, in _fetch_all
    self._result_cache = list(self._iterable_class(self))
  File "D:\ProgramFiles\Anaconda3\lib\site-packages\django-1.11.8-py3.6.egg\django\db\models\query.py", line 53, in __iter__
    results = compiler.execute_sql(chunked_fetch=self.chunked_fetch)
  File "D:\ProgramFiles\Anaconda3\lib\site-packages\django-1.11.8-py3.6.egg\django\db\models\sql\compiler.py", line 899, in execute_sql
    raise original_exception
  File "D:\ProgramFiles\Anaconda3\lib\site-packages\django-1.11.8-py3.6.egg\django\db\models\sql\compiler.py", line 889, in execute_sql
    cursor.execute(sql, params)
  File "D:\ProgramFiles\Anaconda3\lib\site-packages\django-1.11.8-py3.6.egg\django\db\backends\utils.py", line 79, in execute
    return super(CursorDebugWrapper, self).execute(sql, params)
  File "D:\ProgramFiles\Anaconda3\lib\site-packages\django-1.11.8-py3.6.egg\django\db\backends\utils.py", line 64, in execute
    return self.cursor.execute(sql, params)
  File "D:\ProgramFiles\Anaconda3\lib\site-packages\django-1.11.8-py3.6.egg\django\db\utils.py", line 94, in __exit__
    six.reraise(dj_exc_type, dj_exc_value, traceback)
  File "D:\ProgramFiles\Anaconda3\lib\site-packages\django-1.11.8-py3.6.egg\django\utils\six.py", line 685, in reraise
    raise value.with_traceback(tb)
  File "D:\ProgramFiles\Anaconda3\lib\site-packages\django-1.11.8-py3.6.egg\django\db\backends\utils.py", line 64, in execute
    return self.cursor.execute(sql, params)
  File "D:\ProgramFiles\Anaconda3\lib\site-packages\django-1.11.8-py3.6.egg\django\db\backends\sqlite3\base.py", line 328, in execute
    return Database.Cursor.execute(self, query, params)
django.db.utils.OperationalError: no such column: mysite_users.phone
exception.py[2018-08-01 18:20:03][ERROR]：Internal Server Error: /admin/mysite/users/
Traceback (most recent call last):
  File "D:\ProgramFiles\Anaconda3\lib\site-packages\django-1.11.8-py3.6.egg\django\db\backends\utils.py", line 64, in execute
    return self.cursor.execute(sql, params)
  File "D:\ProgramFiles\Anaconda3\lib\site-packages\django-1.11.8-py3.6.egg\django\db\backends\sqlite3\base.py", line 328, in execute
    return Database.Cursor.execute(self, query, params)
sqlite3.OperationalError: no such column: mysite_users.phone

The above exception was the direct cause of the following exception:

Traceback (most recent call last):
  File "D:\ProgramFiles\Anaconda3\lib\site-packages\django-1.11.8-py3.6.egg\django\core\handlers\exception.py", line 41, in inner
    response = get_response(request)
  File "D:\ProgramFiles\Anaconda3\lib\site-packages\django-1.11.8-py3.6.egg\django\core\handlers\base.py", line 249, in _legacy_get_response
    response = self._get_response(request)
  File "D:\ProgramFiles\Anaconda3\lib\site-packages\django-1.11.8-py3.6.egg\django\core\handlers\base.py", line 187, in _get_response
    response = self.process_exception_by_middleware(e, request)
  File "D:\ProgramFiles\Anaconda3\lib\site-packages\django-1.11.8-py3.6.egg\django\core\handlers\base.py", line 185, in _get_response
    response = wrapped_callback(request, *callback_args, **callback_kwargs)
  File "D:\ProgramFiles\Anaconda3\lib\site-packages\django-1.11.8-py3.6.egg\django\contrib\admin\options.py", line 551, in wrapper
    return self.admin_site.admin_view(view)(*args, **kwargs)
  File "D:\ProgramFiles\Anaconda3\lib\site-packages\django-1.11.8-py3.6.egg\django\utils\decorators.py", line 149, in _wrapped_view
    response = view_func(request, *args, **kwargs)
  File "D:\ProgramFiles\Anaconda3\lib\site-packages\django-1.11.8-py3.6.egg\django\views\decorators\cache.py", line 57, in _wrapped_view_func
    response = view_func(request, *args, **kwargs)
  File "D:\ProgramFiles\Anaconda3\lib\site-packages\django-1.11.8-py3.6.egg\django\contrib\admin\sites.py", line 224, in inner
    return view(request, *args, **kwargs)
  File "D:\ProgramFiles\Anaconda3\lib\site-packages\django-1.11.8-py3.6.egg\django\utils\decorators.py", line 67, in _wrapper
    return bound_func(*args, **kwargs)
  File "D:\ProgramFiles\Anaconda3\lib\site-packages\django-1.11.8-py3.6.egg\django\utils\decorators.py", line 149, in _wrapped_view
    response = view_func(request, *args, **kwargs)
  File "D:\ProgramFiles\Anaconda3\lib\site-packages\django-1.11.8-py3.6.egg\django\utils\decorators.py", line 63, in bound_func
    return func.__get__(self, type(self))(*args2, **kwargs2)
  File "D:\ProgramFiles\Anaconda3\lib\site-packages\django-1.11.8-py3.6.egg\django\contrib\admin\options.py", line 1662, in changelist_view
    selection_note=_('0 of %(cnt)s selected') % {'cnt': len(cl.result_list)},
  File "D:\ProgramFiles\Anaconda3\lib\site-packages\django-1.11.8-py3.6.egg\django\db\models\query.py", line 232, in __len__
    self._fetch_all()
  File "D:\ProgramFiles\Anaconda3\lib\site-packages\django-1.11.8-py3.6.egg\django\db\models\query.py", line 1118, in _fetch_all
    self._result_cache = list(self._iterable_class(self))
  File "D:\ProgramFiles\Anaconda3\lib\site-packages\django-1.11.8-py3.6.egg\django\db\models\query.py", line 53, in __iter__
    results = compiler.execute_sql(chunked_fetch=self.chunked_fetch)
  File "D:\ProgramFiles\Anaconda3\lib\site-packages\django-1.11.8-py3.6.egg\django\db\models\sql\compiler.py", line 899, in execute_sql
    raise original_exception
  File "D:\ProgramFiles\Anaconda3\lib\site-packages\django-1.11.8-py3.6.egg\django\db\models\sql\compiler.py", line 889, in execute_sql
    cursor.execute(sql, params)
  File "D:\ProgramFiles\Anaconda3\lib\site-packages\django-1.11.8-py3.6.egg\django\db\backends\utils.py", line 79, in execute
    return super(CursorDebugWrapper, self).execute(sql, params)
  File "D:\ProgramFiles\Anaconda3\lib\site-packages\django-1.11.8-py3.6.egg\django\db\backends\utils.py", line 64, in execute
    return self.cursor.execute(sql, params)
  File "D:\ProgramFiles\Anaconda3\lib\site-packages\django-1.11.8-py3.6.egg\django\db\utils.py", line 94, in __exit__
    six.reraise(dj_exc_type, dj_exc_value, traceback)
  File "D:\ProgramFiles\Anaconda3\lib\site-packages\django-1.11.8-py3.6.egg\django\utils\six.py", line 685, in reraise
    raise value.with_traceback(tb)
  File "D:\ProgramFiles\Anaconda3\lib\site-packages\django-1.11.8-py3.6.egg\django\db\backends\utils.py", line 64, in execute
    return self.cursor.execute(sql, params)
  File "D:\ProgramFiles\Anaconda3\lib\site-packages\django-1.11.8-py3.6.egg\django\db\backends\sqlite3\base.py", line 328, in execute
    return Database.Cursor.execute(self, query, params)
django.db.utils.OperationalError: no such column: mysite_users.phone
exception.py[2018-08-01 18:20:05][ERROR]：Internal Server Error: /admin/mysite/users/
Traceback (most recent call last):
  File "D:\ProgramFiles\Anaconda3\lib\site-packages\django-1.11.8-py3.6.egg\django\db\backends\utils.py", line 64, in execute
    return self.cursor.execute(sql, params)
  File "D:\ProgramFiles\Anaconda3\lib\site-packages\django-1.11.8-py3.6.egg\django\db\backends\sqlite3\base.py", line 328, in execute
    return Database.Cursor.execute(self, query, params)
sqlite3.OperationalError: no such column: mysite_users.phone

The above exception was the direct cause of the following exception:

Traceback (most recent call last):
  File "D:\ProgramFiles\Anaconda3\lib\site-packages\django-1.11.8-py3.6.egg\django\core\handlers\exception.py", line 41, in inner
    response = get_response(request)
  File "D:\ProgramFiles\Anaconda3\lib\site-packages\django-1.11.8-py3.6.egg\django\core\handlers\base.py", line 249, in _legacy_get_response
    response = self._get_response(request)
  File "D:\ProgramFiles\Anaconda3\lib\site-packages\django-1.11.8-py3.6.egg\django\core\handlers\base.py", line 187, in _get_response
    response = self.process_exception_by_middleware(e, request)
  File "D:\ProgramFiles\Anaconda3\lib\site-packages\django-1.11.8-py3.6.egg\django\core\handlers\base.py", line 185, in _get_response
    response = wrapped_callback(request, *callback_args, **callback_kwargs)
  File "D:\ProgramFiles\Anaconda3\lib\site-packages\django-1.11.8-py3.6.egg\django\contrib\admin\options.py", line 551, in wrapper
    return self.admin_site.admin_view(view)(*args, **kwargs)
  File "D:\ProgramFiles\Anaconda3\lib\site-packages\django-1.11.8-py3.6.egg\django\utils\decorators.py", line 149, in _wrapped_view
    response = view_func(request, *args, **kwargs)
  File "D:\ProgramFiles\Anaconda3\lib\site-packages\django-1.11.8-py3.6.egg\django\views\decorators\cache.py", line 57, in _wrapped_view_func
    response = view_func(request, *args, **kwargs)
  File "D:\ProgramFiles\Anaconda3\lib\site-packages\django-1.11.8-py3.6.egg\django\contrib\admin\sites.py", line 224, in inner
    return view(request, *args, **kwargs)
  File "D:\ProgramFiles\Anaconda3\lib\site-packages\django-1.11.8-py3.6.egg\django\utils\decorators.py", line 67, in _wrapper
    return bound_func(*args, **kwargs)
  File "D:\ProgramFiles\Anaconda3\lib\site-packages\django-1.11.8-py3.6.egg\django\utils\decorators.py", line 149, in _wrapped_view
    response = view_func(request, *args, **kwargs)
  File "D:\ProgramFiles\Anaconda3\lib\site-packages\django-1.11.8-py3.6.egg\django\utils\decorators.py", line 63, in bound_func
    return func.__get__(self, type(self))(*args2, **kwargs2)
  File "D:\ProgramFiles\Anaconda3\lib\site-packages\django-1.11.8-py3.6.egg\django\contrib\admin\options.py", line 1662, in changelist_view
    selection_note=_('0 of %(cnt)s selected') % {'cnt': len(cl.result_list)},
  File "D:\ProgramFiles\Anaconda3\lib\site-packages\django-1.11.8-py3.6.egg\django\db\models\query.py", line 232, in __len__
    self._fetch_all()
  File "D:\ProgramFiles\Anaconda3\lib\site-packages\django-1.11.8-py3.6.egg\django\db\models\query.py", line 1118, in _fetch_all
    self._result_cache = list(self._iterable_class(self))
  File "D:\ProgramFiles\Anaconda3\lib\site-packages\django-1.11.8-py3.6.egg\django\db\models\query.py", line 53, in __iter__
    results = compiler.execute_sql(chunked_fetch=self.chunked_fetch)
  File "D:\ProgramFiles\Anaconda3\lib\site-packages\django-1.11.8-py3.6.egg\django\db\models\sql\compiler.py", line 899, in execute_sql
    raise original_exception
  File "D:\ProgramFiles\Anaconda3\lib\site-packages\django-1.11.8-py3.6.egg\django\db\models\sql\compiler.py", line 889, in execute_sql
    cursor.execute(sql, params)
  File "D:\ProgramFiles\Anaconda3\lib\site-packages\django-1.11.8-py3.6.egg\django\db\backends\utils.py", line 79, in execute
    return super(CursorDebugWrapper, self).execute(sql, params)
  File "D:\ProgramFiles\Anaconda3\lib\site-packages\django-1.11.8-py3.6.egg\django\db\backends\utils.py", line 64, in execute
    return self.cursor.execute(sql, params)
  File "D:\ProgramFiles\Anaconda3\lib\site-packages\django-1.11.8-py3.6.egg\django\db\utils.py", line 94, in __exit__
    six.reraise(dj_exc_type, dj_exc_value, traceback)
  File "D:\ProgramFiles\Anaconda3\lib\site-packages\django-1.11.8-py3.6.egg\django\utils\six.py", line 685, in reraise
    raise value.with_traceback(tb)
  File "D:\ProgramFiles\Anaconda3\lib\site-packages\django-1.11.8-py3.6.egg\django\db\backends\utils.py", line 64, in execute
    return self.cursor.execute(sql, params)
  File "D:\ProgramFiles\Anaconda3\lib\site-packages\django-1.11.8-py3.6.egg\django\db\backends\sqlite3\base.py", line 328, in execute
    return Database.Cursor.execute(self, query, params)
django.db.utils.OperationalError: no such column: mysite_users.phone
exception.py[2018-08-02 12:19:30][ERROR]：Internal Server Error: /register/
Traceback (most recent call last):
  File "D:\ProgramFiles\Anaconda3\lib\site-packages\django-1.11.8-py3.6.egg\django\db\backends\utils.py", line 64, in execute
    return self.cursor.execute(sql, params)
  File "D:\ProgramFiles\Anaconda3\lib\site-packages\django-1.11.8-py3.6.egg\django\db\backends\mysql\base.py", line 101, in execute
    return self.cursor.execute(query, args)
  File "D:\ProgramFiles\Anaconda3\lib\site-packages\pymysql\cursors.py", line 165, in execute
    result = self._query(query)
  File "D:\ProgramFiles\Anaconda3\lib\site-packages\pymysql\cursors.py", line 321, in _query
    conn.query(q)
  File "D:\ProgramFiles\Anaconda3\lib\site-packages\pymysql\connections.py", line 860, in query
    self._affected_rows = self._read_query_result(unbuffered=unbuffered)
  File "D:\ProgramFiles\Anaconda3\lib\site-packages\pymysql\connections.py", line 1061, in _read_query_result
    result.read()
  File "D:\ProgramFiles\Anaconda3\lib\site-packages\pymysql\connections.py", line 1349, in read
    first_packet = self.connection._read_packet()
  File "D:\ProgramFiles\Anaconda3\lib\site-packages\pymysql\connections.py", line 1018, in _read_packet
    packet.check_error()
  File "D:\ProgramFiles\Anaconda3\lib\site-packages\pymysql\connections.py", line 384, in check_error
    err.raise_mysql_exception(self._data)
  File "D:\ProgramFiles\Anaconda3\lib\site-packages\pymysql\err.py", line 107, in raise_mysql_exception
    raise errorclass(errno, errval)
pymysql.err.ProgrammingError: (1146, 'Unknown error 1146')

The above exception was the direct cause of the following exception:

Traceback (most recent call last):
  File "D:\ProgramFiles\Anaconda3\lib\site-packages\django-1.11.8-py3.6.egg\django\core\handlers\exception.py", line 41, in inner
    response = get_response(request)
  File "D:\ProgramFiles\Anaconda3\lib\site-packages\django-1.11.8-py3.6.egg\django\core\handlers\base.py", line 249, in _legacy_get_response
    response = self._get_response(request)
  File "D:\ProgramFiles\Anaconda3\lib\site-packages\django-1.11.8-py3.6.egg\django\core\handlers\base.py", line 187, in _get_response
    response = self.process_exception_by_middleware(e, request)
  File "D:\ProgramFiles\Anaconda3\lib\site-packages\django-1.11.8-py3.6.egg\django\core\handlers\base.py", line 185, in _get_response
    response = wrapped_callback(request, *callback_args, **callback_kwargs)
  File "D:\tools\Tools\Carry\mysite\views.py", line 229, in register
    return render(rq,'register.html',{'form':form})
  File "D:\ProgramFiles\Anaconda3\lib\site-packages\django-1.11.8-py3.6.egg\django\shortcuts.py", line 30, in render
    content = loader.render_to_string(template_name, context, request, using=using)
  File "D:\ProgramFiles\Anaconda3\lib\site-packages\django-1.11.8-py3.6.egg\django\template\loader.py", line 68, in render_to_string
    return template.render(context, request)
  File "D:\ProgramFiles\Anaconda3\lib\site-packages\django-1.11.8-py3.6.egg\django\template\backends\django.py", line 66, in render
    return self.template.render(context)
  File "D:\ProgramFiles\Anaconda3\lib\site-packages\django-1.11.8-py3.6.egg\django\template\base.py", line 207, in render
    return self._render(context)
  File "D:\ProgramFiles\Anaconda3\lib\site-packages\django-1.11.8-py3.6.egg\django\template\base.py", line 199, in _render
    return self.nodelist.render(context)
  File "D:\ProgramFiles\Anaconda3\lib\site-packages\django-1.11.8-py3.6.egg\django\template\base.py", line 990, in render
    bit = node.render_annotated(context)
  File "D:\ProgramFiles\Anaconda3\lib\site-packages\django-1.11.8-py3.6.egg\django\template\base.py", line 957, in render_annotated
    return self.render(context)
  File "D:\ProgramFiles\Anaconda3\lib\site-packages\django-1.11.8-py3.6.egg\django\template\loader_tags.py", line 177, in render
    return compiled_parent._render(context)
  File "D:\ProgramFiles\Anaconda3\lib\site-packages\django-1.11.8-py3.6.egg\django\template\base.py", line 199, in _render
    return self.nodelist.render(context)
  File "D:\ProgramFiles\Anaconda3\lib\site-packages\django-1.11.8-py3.6.egg\django\template\base.py", line 990, in render
    bit = node.render_annotated(context)
  File "D:\ProgramFiles\Anaconda3\lib\site-packages\django-1.11.8-py3.6.egg\django\template\base.py", line 957, in render_annotated
    return self.render(context)
  File "D:\ProgramFiles\Anaconda3\lib\site-packages\django-1.11.8-py3.6.egg\django\template\loader_tags.py", line 72, in render
    result = block.nodelist.render(context)
  File "D:\ProgramFiles\Anaconda3\lib\site-packages\django-1.11.8-py3.6.egg\django\template\base.py", line 990, in render
    bit = node.render_annotated(context)
  File "D:\ProgramFiles\Anaconda3\lib\site-packages\django-1.11.8-py3.6.egg\django\template\base.py", line 957, in render_annotated
    return self.render(context)
  File "D:\ProgramFiles\Anaconda3\lib\site-packages\django-1.11.8-py3.6.egg\django\template\loader_tags.py", line 72, in render
    result = block.nodelist.render(context)
  File "D:\ProgramFiles\Anaconda3\lib\site-packages\django-1.11.8-py3.6.egg\django\template\base.py", line 990, in render
    bit = node.render_annotated(context)
  File "D:\ProgramFiles\Anaconda3\lib\site-packages\django-1.11.8-py3.6.egg\django\template\base.py", line 957, in render_annotated
    return self.render(context)
  File "D:\ProgramFiles\Anaconda3\lib\site-packages\django-1.11.8-py3.6.egg\django\template\base.py", line 1040, in render
    output = self.filter_expression.resolve(context)
  File "D:\ProgramFiles\Anaconda3\lib\site-packages\django-1.11.8-py3.6.egg\django\template\base.py", line 708, in resolve
    obj = self.var.resolve(context)
  File "D:\ProgramFiles\Anaconda3\lib\site-packages\django-1.11.8-py3.6.egg\django\template\base.py", line 849, in resolve
    value = self._resolve_lookup(context)
  File "D:\ProgramFiles\Anaconda3\lib\site-packages\django-1.11.8-py3.6.egg\django\template\base.py", line 911, in _resolve_lookup
    current = current()
  File "D:\ProgramFiles\Anaconda3\lib\site-packages\django-1.11.8-py3.6.egg\django\forms\forms.py", line 303, in as_p
    errors_on_separate_row=True)
  File "D:\ProgramFiles\Anaconda3\lib\site-packages\django-1.11.8-py3.6.egg\django\forms\forms.py", line 240, in _html_output
    'field': six.text_type(bf),
  File "D:\ProgramFiles\Anaconda3\lib\site-packages\django-1.11.8-py3.6.egg\django\utils\html.py", line 385, in <lambda>
    klass.__str__ = lambda self: mark_safe(klass_str(self))
  File "D:\ProgramFiles\Anaconda3\lib\site-packages\django-1.11.8-py3.6.egg\django\forms\boundfield.py", line 41, in __str__
    return self.as_widget()
  File "D:\ProgramFiles\Anaconda3\lib\site-packages\django-1.11.8-py3.6.egg\django\forms\boundfield.py", line 127, in as_widget
    **kwargs
  File "D:\ProgramFiles\Anaconda3\lib\site-packages\captcha\fields.py", line 167, in render
    self.fetch_captcha_store(name, value, attrs, self.generator)
  File "D:\ProgramFiles\Anaconda3\lib\site-packages\captcha\fields.py", line 64, in fetch_captcha_store
    key = CaptchaStore.generate_key(generator)
  File "D:\ProgramFiles\Anaconda3\lib\site-packages\captcha\models.py", line 56, in generate_key
    store = cls.objects.create(challenge=challenge, response=response)
  File "D:\ProgramFiles\Anaconda3\lib\site-packages\django-1.11.8-py3.6.egg\django\db\models\manager.py", line 85, in manager_method
    return getattr(self.get_queryset(), name)(*args, **kwargs)
  File "D:\ProgramFiles\Anaconda3\lib\site-packages\django-1.11.8-py3.6.egg\django\db\models\query.py", line 394, in create
    obj.save(force_insert=True, using=self.db)
  File "D:\ProgramFiles\Anaconda3\lib\site-packages\captcha\models.py", line 44, in save
    super(CaptchaStore, self).save(*args, **kwargs)
  File "D:\ProgramFiles\Anaconda3\lib\site-packages\django-1.11.8-py3.6.egg\django\db\models\base.py", line 808, in save
    force_update=force_update, update_fields=update_fields)
  File "D:\ProgramFiles\Anaconda3\lib\site-packages\django-1.11.8-py3.6.egg\django\db\models\base.py", line 838, in save_base
    updated = self._save_table(raw, cls, force_insert, force_update, using, update_fields)
  File "D:\ProgramFiles\Anaconda3\lib\site-packages\django-1.11.8-py3.6.egg\django\db\models\base.py", line 924, in _save_table
    result = self._do_insert(cls._base_manager, using, fields, update_pk, raw)
  File "D:\ProgramFiles\Anaconda3\lib\site-packages\django-1.11.8-py3.6.egg\django\db\models\base.py", line 963, in _do_insert
    using=using, raw=raw)
  File "D:\ProgramFiles\Anaconda3\lib\site-packages\django-1.11.8-py3.6.egg\django\db\models\manager.py", line 85, in manager_method
    return getattr(self.get_queryset(), name)(*args, **kwargs)
  File "D:\ProgramFiles\Anaconda3\lib\site-packages\django-1.11.8-py3.6.egg\django\db\models\query.py", line 1076, in _insert
    return query.get_compiler(using=using).execute_sql(return_id)
  File "D:\ProgramFiles\Anaconda3\lib\site-packages\django-1.11.8-py3.6.egg\django\db\models\sql\compiler.py", line 1112, in execute_sql
    cursor.execute(sql, params)
  File "D:\ProgramFiles\Anaconda3\lib\site-packages\django-1.11.8-py3.6.egg\django\db\backends\utils.py", line 79, in execute
    return super(CursorDebugWrapper, self).execute(sql, params)
  File "D:\ProgramFiles\Anaconda3\lib\site-packages\django-1.11.8-py3.6.egg\django\db\backends\utils.py", line 64, in execute
    return self.cursor.execute(sql, params)
  File "D:\ProgramFiles\Anaconda3\lib\site-packages\django-1.11.8-py3.6.egg\django\db\utils.py", line 94, in __exit__
    six.reraise(dj_exc_type, dj_exc_value, traceback)
  File "D:\ProgramFiles\Anaconda3\lib\site-packages\django-1.11.8-py3.6.egg\django\utils\six.py", line 685, in reraise
    raise value.with_traceback(tb)
  File "D:\ProgramFiles\Anaconda3\lib\site-packages\django-1.11.8-py3.6.egg\django\db\backends\utils.py", line 64, in execute
    return self.cursor.execute(sql, params)
  File "D:\ProgramFiles\Anaconda3\lib\site-packages\django-1.11.8-py3.6.egg\django\db\backends\mysql\base.py", line 101, in execute
    return self.cursor.execute(query, args)
  File "D:\ProgramFiles\Anaconda3\lib\site-packages\pymysql\cursors.py", line 165, in execute
    result = self._query(query)
  File "D:\ProgramFiles\Anaconda3\lib\site-packages\pymysql\cursors.py", line 321, in _query
    conn.query(q)
  File "D:\ProgramFiles\Anaconda3\lib\site-packages\pymysql\connections.py", line 860, in query
    self._affected_rows = self._read_query_result(unbuffered=unbuffered)
  File "D:\ProgramFiles\Anaconda3\lib\site-packages\pymysql\connections.py", line 1061, in _read_query_result
    result.read()
  File "D:\ProgramFiles\Anaconda3\lib\site-packages\pymysql\connections.py", line 1349, in read
    first_packet = self.connection._read_packet()
  File "D:\ProgramFiles\Anaconda3\lib\site-packages\pymysql\connections.py", line 1018, in _read_packet
    packet.check_error()
  File "D:\ProgramFiles\Anaconda3\lib\site-packages\pymysql\connections.py", line 384, in check_error
    err.raise_mysql_exception(self._data)
  File "D:\ProgramFiles\Anaconda3\lib\site-packages\pymysql\err.py", line 107, in raise_mysql_exception
    raise errorclass(errno, errval)
django.db.utils.ProgrammingError: (1146, 'Unknown error 1146')
exception.py[2018-08-02 12:21:48][ERROR]：Internal Server Error: /register/
Traceback (most recent call last):
  File "D:\ProgramFiles\Anaconda3\lib\site-packages\django-1.11.8-py3.6.egg\django\core\handlers\exception.py", line 41, in inner
    response = get_response(request)
  File "D:\ProgramFiles\Anaconda3\lib\site-packages\django-1.11.8-py3.6.egg\django\core\handlers\base.py", line 249, in _legacy_get_response
    response = self._get_response(request)
  File "D:\ProgramFiles\Anaconda3\lib\site-packages\django-1.11.8-py3.6.egg\django\core\handlers\base.py", line 187, in _get_response
    response = self.process_exception_by_middleware(e, request)
  File "D:\ProgramFiles\Anaconda3\lib\site-packages\django-1.11.8-py3.6.egg\django\core\handlers\base.py", line 185, in _get_response
    response = wrapped_callback(request, *callback_args, **callback_kwargs)
  File "D:\tools\Tools\Carry\mysite\views.py", line 228, in register
    form = forms.UsersForm()
  File "D:\tools\Tools\Carry\mysite\forms.py", line 18, in __init__
    self.fields['passwordr'].label = '再次输入密码'
KeyError: 'passwordr'
exception.py[2018-08-02 13:53:56][ERROR]：Internal Server Error: /gxjy/
Traceback (most recent call last):
  File "D:\ProgramFiles\Anaconda3\lib\site-packages\django-1.11.8-py3.6.egg\django\core\handlers\exception.py", line 41, in inner
    response = get_response(request)
  File "D:\ProgramFiles\Anaconda3\lib\site-packages\django-1.11.8-py3.6.egg\django\core\handlers\base.py", line 249, in _legacy_get_response
    response = self._get_response(request)
  File "D:\ProgramFiles\Anaconda3\lib\site-packages\django-1.11.8-py3.6.egg\django\core\handlers\base.py", line 187, in _get_response
    response = self.process_exception_by_middleware(e, request)
  File "D:\ProgramFiles\Anaconda3\lib\site-packages\django-1.11.8-py3.6.egg\django\core\handlers\base.py", line 185, in _get_response
    response = wrapped_callback(request, *callback_args, **callback_kwargs)
  File "D:\tools\Tools\Carry\mysite\views.py", line 1306, in gxjy
    ind_s = zx_x.index(zx_x2[0])
IndexError: list index out of range
exception.py[2018-08-02 13:55:10][ERROR]：Internal Server Error: /gxjy/
Traceback (most recent call last):
  File "D:\ProgramFiles\Anaconda3\lib\site-packages\django-1.11.8-py3.6.egg\django\core\handlers\exception.py", line 41, in inner
    response = get_response(request)
  File "D:\ProgramFiles\Anaconda3\lib\site-packages\django-1.11.8-py3.6.egg\django\core\handlers\base.py", line 249, in _legacy_get_response
    response = self._get_response(request)
  File "D:\ProgramFiles\Anaconda3\lib\site-packages\django-1.11.8-py3.6.egg\django\core\handlers\base.py", line 187, in _get_response
    response = self.process_exception_by_middleware(e, request)
  File "D:\ProgramFiles\Anaconda3\lib\site-packages\django-1.11.8-py3.6.egg\django\core\handlers\base.py", line 185, in _get_response
    response = wrapped_callback(request, *callback_args, **callback_kwargs)
  File "D:\tools\Tools\Carry\mysite\views.py", line 1307, in gxjy
    ind_s = zx_x.index(zx_x2[0])
IndexError: list index out of range
exception.py[2018-08-02 13:55:52][ERROR]：Internal Server Error: /gxjy/
Traceback (most recent call last):
  File "D:\ProgramFiles\Anaconda3\lib\site-packages\django-1.11.8-py3.6.egg\django\core\handlers\exception.py", line 41, in inner
    response = get_response(request)
  File "D:\ProgramFiles\Anaconda3\lib\site-packages\django-1.11.8-py3.6.egg\django\core\handlers\base.py", line 249, in _legacy_get_response
    response = self._get_response(request)
  File "D:\ProgramFiles\Anaconda3\lib\site-packages\django-1.11.8-py3.6.egg\django\core\handlers\base.py", line 187, in _get_response
    response = self.process_exception_by_middleware(e, request)
  File "D:\ProgramFiles\Anaconda3\lib\site-packages\django-1.11.8-py3.6.egg\django\core\handlers\base.py", line 185, in _get_response
    response = wrapped_callback(request, *callback_args, **callback_kwargs)
  File "D:\tools\Tools\Carry\mysite\views.py", line 1307, in gxjy
    ind_s = zx_x.index(zx_x2[0])
IndexError: list index out of range
exception.py[2018-08-02 13:59:31][ERROR]：Internal Server Error: /gxjy/
Traceback (most recent call last):
  File "D:\ProgramFiles\Anaconda3\lib\site-packages\django-1.11.8-py3.6.egg\django\core\handlers\exception.py", line 41, in inner
    response = get_response(request)
  File "D:\ProgramFiles\Anaconda3\lib\site-packages\django-1.11.8-py3.6.egg\django\core\handlers\base.py", line 249, in _legacy_get_response
    response = self._get_response(request)
  File "D:\ProgramFiles\Anaconda3\lib\site-packages\django-1.11.8-py3.6.egg\django\core\handlers\base.py", line 187, in _get_response
    response = self.process_exception_by_middleware(e, request)
  File "D:\ProgramFiles\Anaconda3\lib\site-packages\django-1.11.8-py3.6.egg\django\core\handlers\base.py", line 185, in _get_response
    response = wrapped_callback(request, *callback_args, **callback_kwargs)
  File "D:\tools\Tools\Carry\mysite\views.py", line 1301, in gxjy
    f_date = datetime.datetime.strptime(end_date, '%Y-%m-%d').isocalendar()[:2]
  File "D:\ProgramFiles\Anaconda3\lib\_strptime.py", line 565, in _strptime_datetime
    tt, fraction = _strptime(data_string, format)
  File "D:\ProgramFiles\Anaconda3\lib\_strptime.py", line 362, in _strptime
    (data_string, format))
ValueError: time data '2018-06-' does not match format '%Y-%m-%d'
exception.py[2018-08-02 14:32:09][ERROR]：Internal Server Error: /register/
Traceback (most recent call last):
  File "D:\ProgramFiles\Anaconda3\lib\site-packages\django-1.11.8-py3.6.egg\django\core\handlers\exception.py", line 41, in inner
    response = get_response(request)
  File "D:\ProgramFiles\Anaconda3\lib\site-packages\django-1.11.8-py3.6.egg\django\core\handlers\base.py", line 249, in _legacy_get_response
    response = self._get_response(request)
  File "D:\ProgramFiles\Anaconda3\lib\site-packages\django-1.11.8-py3.6.egg\django\core\handlers\base.py", line 187, in _get_response
    response = self.process_exception_by_middleware(e, request)
  File "D:\ProgramFiles\Anaconda3\lib\site-packages\django-1.11.8-py3.6.egg\django\core\handlers\base.py", line 185, in _get_response
    response = wrapped_callback(request, *callback_args, **callback_kwargs)
  File "D:\tools\Tools\Carry\mysite\views.py", line 229, in register
    if request.method == 'GET' and request.is_ajax():
AttributeError: module 'urllib.request' has no attribute 'method'
exception.py[2018-08-02 14:44:29][ERROR]：Internal Server Error: /register/
Traceback (most recent call last):
  File "D:\ProgramFiles\Anaconda3\lib\site-packages\django-1.11.8-py3.6.egg\django\db\backends\utils.py", line 64, in execute
    return self.cursor.execute(sql, params)
  File "D:\ProgramFiles\Anaconda3\lib\site-packages\django-1.11.8-py3.6.egg\django\db\backends\mysql\base.py", line 101, in execute
    return self.cursor.execute(query, args)
  File "D:\ProgramFiles\Anaconda3\lib\site-packages\pymysql\cursors.py", line 165, in execute
    result = self._query(query)
  File "D:\ProgramFiles\Anaconda3\lib\site-packages\pymysql\cursors.py", line 321, in _query
    conn.query(q)
  File "D:\ProgramFiles\Anaconda3\lib\site-packages\pymysql\connections.py", line 860, in query
    self._affected_rows = self._read_query_result(unbuffered=unbuffered)
  File "D:\ProgramFiles\Anaconda3\lib\site-packages\pymysql\connections.py", line 1061, in _read_query_result
    result.read()
  File "D:\ProgramFiles\Anaconda3\lib\site-packages\pymysql\connections.py", line 1349, in read
    first_packet = self.connection._read_packet()
  File "D:\ProgramFiles\Anaconda3\lib\site-packages\pymysql\connections.py", line 1018, in _read_packet
    packet.check_error()
  File "D:\ProgramFiles\Anaconda3\lib\site-packages\pymysql\connections.py", line 384, in check_error
    err.raise_mysql_exception(self._data)
  File "D:\ProgramFiles\Anaconda3\lib\site-packages\pymysql\err.py", line 107, in raise_mysql_exception
    raise errorclass(errno, errval)
pymysql.err.DataError: (1406, '')

The above exception was the direct cause of the following exception:

Traceback (most recent call last):
  File "D:\ProgramFiles\Anaconda3\lib\site-packages\django-1.11.8-py3.6.egg\django\core\handlers\exception.py", line 41, in inner
    response = get_response(request)
  File "D:\ProgramFiles\Anaconda3\lib\site-packages\django-1.11.8-py3.6.egg\django\core\handlers\base.py", line 249, in _legacy_get_response
    response = self._get_response(request)
  File "D:\ProgramFiles\Anaconda3\lib\site-packages\django-1.11.8-py3.6.egg\django\core\handlers\base.py", line 187, in _get_response
    response = self.process_exception_by_middleware(e, request)
  File "D:\ProgramFiles\Anaconda3\lib\site-packages\django-1.11.8-py3.6.egg\django\core\handlers\base.py", line 185, in _get_response
    response = wrapped_callback(request, *callback_args, **callback_kwargs)
  File "D:\tools\Tools\Carry\mysite\views.py", line 253, in register
    users = models.Users.objects.create(name=name, password=password, phone=phone, email=email, enabled=1, jurisdiction=1)
  File "D:\ProgramFiles\Anaconda3\lib\site-packages\django-1.11.8-py3.6.egg\django\db\models\manager.py", line 85, in manager_method
    return getattr(self.get_queryset(), name)(*args, **kwargs)
  File "D:\ProgramFiles\Anaconda3\lib\site-packages\django-1.11.8-py3.6.egg\django\db\models\query.py", line 394, in create
    obj.save(force_insert=True, using=self.db)
  File "D:\ProgramFiles\Anaconda3\lib\site-packages\django-1.11.8-py3.6.egg\django\db\models\base.py", line 808, in save
    force_update=force_update, update_fields=update_fields)
  File "D:\ProgramFiles\Anaconda3\lib\site-packages\django-1.11.8-py3.6.egg\django\db\models\base.py", line 838, in save_base
    updated = self._save_table(raw, cls, force_insert, force_update, using, update_fields)
  File "D:\ProgramFiles\Anaconda3\lib\site-packages\django-1.11.8-py3.6.egg\django\db\models\base.py", line 924, in _save_table
    result = self._do_insert(cls._base_manager, using, fields, update_pk, raw)
  File "D:\ProgramFiles\Anaconda3\lib\site-packages\django-1.11.8-py3.6.egg\django\db\models\base.py", line 963, in _do_insert
    using=using, raw=raw)
  File "D:\ProgramFiles\Anaconda3\lib\site-packages\django-1.11.8-py3.6.egg\django\db\models\manager.py", line 85, in manager_method
    return getattr(self.get_queryset(), name)(*args, **kwargs)
  File "D:\ProgramFiles\Anaconda3\lib\site-packages\django-1.11.8-py3.6.egg\django\db\models\query.py", line 1076, in _insert
    return query.get_compiler(using=using).execute_sql(return_id)
  File "D:\ProgramFiles\Anaconda3\lib\site-packages\django-1.11.8-py3.6.egg\django\db\models\sql\compiler.py", line 1112, in execute_sql
    cursor.execute(sql, params)
  File "D:\ProgramFiles\Anaconda3\lib\site-packages\django-1.11.8-py3.6.egg\django\db\backends\utils.py", line 79, in execute
    return super(CursorDebugWrapper, self).execute(sql, params)
  File "D:\ProgramFiles\Anaconda3\lib\site-packages\django-1.11.8-py3.6.egg\django\db\backends\utils.py", line 64, in execute
    return self.cursor.execute(sql, params)
  File "D:\ProgramFiles\Anaconda3\lib\site-packages\django-1.11.8-py3.6.egg\django\db\utils.py", line 94, in __exit__
    six.reraise(dj_exc_type, dj_exc_value, traceback)
  File "D:\ProgramFiles\Anaconda3\lib\site-packages\django-1.11.8-py3.6.egg\django\utils\six.py", line 685, in reraise
    raise value.with_traceback(tb)
  File "D:\ProgramFiles\Anaconda3\lib\site-packages\django-1.11.8-py3.6.egg\django\db\backends\utils.py", line 64, in execute
    return self.cursor.execute(sql, params)
  File "D:\ProgramFiles\Anaconda3\lib\site-packages\django-1.11.8-py3.6.egg\django\db\backends\mysql\base.py", line 101, in execute
    return self.cursor.execute(query, args)
  File "D:\ProgramFiles\Anaconda3\lib\site-packages\pymysql\cursors.py", line 165, in execute
    result = self._query(query)
  File "D:\ProgramFiles\Anaconda3\lib\site-packages\pymysql\cursors.py", line 321, in _query
    conn.query(q)
  File "D:\ProgramFiles\Anaconda3\lib\site-packages\pymysql\connections.py", line 860, in query
    self._affected_rows = self._read_query_result(unbuffered=unbuffered)
  File "D:\ProgramFiles\Anaconda3\lib\site-packages\pymysql\connections.py", line 1061, in _read_query_result
    result.read()
  File "D:\ProgramFiles\Anaconda3\lib\site-packages\pymysql\connections.py", line 1349, in read
    first_packet = self.connection._read_packet()
  File "D:\ProgramFiles\Anaconda3\lib\site-packages\pymysql\connections.py", line 1018, in _read_packet
    packet.check_error()
  File "D:\ProgramFiles\Anaconda3\lib\site-packages\pymysql\connections.py", line 384, in check_error
    err.raise_mysql_exception(self._data)
  File "D:\ProgramFiles\Anaconda3\lib\site-packages\pymysql\err.py", line 107, in raise_mysql_exception
    raise errorclass(errno, errval)
django.db.utils.DataError: (1406, '')
exception.py[2018-08-02 15:33:00][ERROR]：Internal Server Error: /login/
Traceback (most recent call last):
  File "D:\ProgramFiles\Anaconda3\lib\site-packages\django-1.11.8-py3.6.egg\django\core\handlers\exception.py", line 41, in inner
    response = get_response(request)
  File "D:\ProgramFiles\Anaconda3\lib\site-packages\django-1.11.8-py3.6.egg\django\core\handlers\base.py", line 249, in _legacy_get_response
    response = self._get_response(request)
  File "D:\ProgramFiles\Anaconda3\lib\site-packages\django-1.11.8-py3.6.egg\django\core\handlers\base.py", line 187, in _get_response
    response = self.process_exception_by_middleware(e, request)
  File "D:\ProgramFiles\Anaconda3\lib\site-packages\django-1.11.8-py3.6.egg\django\core\handlers\base.py", line 185, in _get_response
    response = wrapped_callback(request, *callback_args, **callback_kwargs)
  File "D:\ProgramFiles\Anaconda3\lib\site-packages\django-1.11.8-py3.6.egg\django\views\decorators\csrf.py", line 58, in wrapped_view
    return view_func(*args, **kwargs)
  File "D:\tools\Tools\Carry\mysite\views.py", line 234, in login
    print(user.name)
AttributeError: 'QuerySet' object has no attribute 'name'
exception.py[2018-08-02 15:33:29][ERROR]：Internal Server Error: /login/
Traceback (most recent call last):
  File "D:\ProgramFiles\Anaconda3\lib\site-packages\django-1.11.8-py3.6.egg\django\core\handlers\exception.py", line 41, in inner
    response = get_response(request)
  File "D:\ProgramFiles\Anaconda3\lib\site-packages\django-1.11.8-py3.6.egg\django\core\handlers\base.py", line 249, in _legacy_get_response
    response = self._get_response(request)
  File "D:\ProgramFiles\Anaconda3\lib\site-packages\django-1.11.8-py3.6.egg\django\core\handlers\base.py", line 187, in _get_response
    response = self.process_exception_by_middleware(e, request)
  File "D:\ProgramFiles\Anaconda3\lib\site-packages\django-1.11.8-py3.6.egg\django\core\handlers\base.py", line 185, in _get_response
    response = wrapped_callback(request, *callback_args, **callback_kwargs)
  File "D:\ProgramFiles\Anaconda3\lib\site-packages\django-1.11.8-py3.6.egg\django\views\decorators\csrf.py", line 58, in wrapped_view
    return view_func(*args, **kwargs)
  File "D:\tools\Tools\Carry\mysite\views.py", line 234, in login
    print(user[0]['name'])
TypeError: 'Users' object is not subscriptable
exception.py[2018-08-02 15:33:46][ERROR]：Internal Server Error: /login/
Traceback (most recent call last):
  File "D:\ProgramFiles\Anaconda3\lib\site-packages\django-1.11.8-py3.6.egg\django\core\handlers\exception.py", line 41, in inner
    response = get_response(request)
  File "D:\ProgramFiles\Anaconda3\lib\site-packages\django-1.11.8-py3.6.egg\django\core\handlers\base.py", line 249, in _legacy_get_response
    response = self._get_response(request)
  File "D:\ProgramFiles\Anaconda3\lib\site-packages\django-1.11.8-py3.6.egg\django\core\handlers\base.py", line 187, in _get_response
    response = self.process_exception_by_middleware(e, request)
  File "D:\ProgramFiles\Anaconda3\lib\site-packages\django-1.11.8-py3.6.egg\django\core\handlers\base.py", line 185, in _get_response
    response = wrapped_callback(request, *callback_args, **callback_kwargs)
  File "D:\ProgramFiles\Anaconda3\lib\site-packages\django-1.11.8-py3.6.egg\django\views\decorators\csrf.py", line 58, in wrapped_view
    return view_func(*args, **kwargs)
  File "D:\tools\Tools\Carry\mysite\views.py", line 234, in login
    print(user['name'])
  File "D:\ProgramFiles\Anaconda3\lib\site-packages\django-1.11.8-py3.6.egg\django\db\models\query.py", line 265, in __getitem__
    raise TypeError
TypeError
exception.py[2018-08-02 17:24:01][ERROR]：Internal Server Error: /tongji_update_del/
Traceback (most recent call last):
  File "D:\ProgramFiles\Anaconda3\lib\site-packages\django-1.11.8-py3.6.egg\django\core\handlers\exception.py", line 41, in inner
    response = get_response(request)
  File "D:\ProgramFiles\Anaconda3\lib\site-packages\django-1.11.8-py3.6.egg\django\core\handlers\base.py", line 249, in _legacy_get_response
    response = self._get_response(request)
  File "D:\ProgramFiles\Anaconda3\lib\site-packages\django-1.11.8-py3.6.egg\django\core\handlers\base.py", line 187, in _get_response
    response = self.process_exception_by_middleware(e, request)
  File "D:\ProgramFiles\Anaconda3\lib\site-packages\django-1.11.8-py3.6.egg\django\core\handlers\base.py", line 185, in _get_response
    response = wrapped_callback(request, *callback_args, **callback_kwargs)
  File "D:\tools\Tools\Carry\mysite\views.py", line 485, in tongji_update_del
    messagess = tongji_adus(rq)
  File "D:\tools\Tools\Carry\mysite\views.py", line 191, in tongji_adus
    if passwd == eval(HSD.get_config('U', 'ud')) and id:
  File "<string>", line 1, in <module>
NameError: name 'dates' is not defined
exception.py[2018-08-02 17:59:12][ERROR]：Internal Server Error: /tongji_update_del/
Traceback (most recent call last):
  File "D:\ProgramFiles\Anaconda3\lib\site-packages\django-1.11.8-py3.6.egg\django\core\handlers\exception.py", line 41, in inner
    response = get_response(request)
  File "D:\ProgramFiles\Anaconda3\lib\site-packages\django-1.11.8-py3.6.egg\django\core\handlers\base.py", line 249, in _legacy_get_response
    response = self._get_response(request)
  File "D:\ProgramFiles\Anaconda3\lib\site-packages\django-1.11.8-py3.6.egg\django\core\handlers\base.py", line 187, in _get_response
    response = self.process_exception_by_middleware(e, request)
  File "D:\ProgramFiles\Anaconda3\lib\site-packages\django-1.11.8-py3.6.egg\django\core\handlers\base.py", line 185, in _get_response
    response = wrapped_callback(request, *callback_args, **callback_kwargs)
  File "D:\tools\Tools\Carry\mysite\views.py", line 483, in tongji_update_del
    return render('')
TypeError: render() missing 1 required positional argument: 'template_name'
